Workbook

Sheet Data & Analisa
A1: Analisa Uji Angkur GA 22. P 2 terhadap BS 8081 (On-site acceptance test)
A2: Teks biru = input (dapat diubah); teks hitam = rumus. Semua hasil dihitung ulang otomatis.
A4: DATA ANGKUR
A5: Testing date | B5: 02.10.2026 | C5: Dari Anchor_Extension_Record.xlsx
A6: Anchor ID | B6: GA 22. P 2 | C6: Dari record
A7: Anchor type | B7: PGA2-R2 | C7: Dari record
A8: Working load, Tw (kN) | B8: 460 | C8: Dari record
A9: Free length, Lf (m) | B9: 8 | C9: Dari record
A10: Fixed / bond length, Lb (m) | B10: 18 | C10: Dari record
A11: Jumlah strand | B11: 5 | C11: Dari record: 5 nos dia 0.5"
A12: Luas 1 strand (mm²) | B12: 98.7 | C12: Asumsi: strand 12.7 mm (0.5") standar, 98.7 mm²
A13: Modulus elastisitas Es (kN/mm²) | B13: 195 | C13: Asumsi: nilai tipikal strand 7-wire; ganti dengan sertifikat pabrik
A14: Panjang tendon di dalam jack (m) | B14: 0 | C14: Asumsi 0 — isi bila diketahui (menambah panjang bebas efektif)
A15: Theoretical ext'n lower (mm) | B15: 55 | C15: Dari record
A16: Theoretical ext'n upper (mm) | B16: 68 | C16: Dari record
A18: Luas tendon At (mm²) | B18: =$B$11*$B$12 -> 493.5
A19: Beban datum T0 (kN) | B19: =B26 -> 57.2
A20: Beban uji Tp (kN) | B20: =B29 -> 697.78
A21: Tp / Tw | B21: =B20/$B$8 -> 1.516913
A22: Perpanjangan teoritis per m (mm/m) = (Tp-T0)·1000/(At·Es) | B22: =(B20-B19)*1000/(B18*$B$13) -> 6.6565869
A24: Siklus | B24: Beban (kN) | C24: % Tw | D24: Gauge (psi) | E24: Tahan (menit) | F24: Ram ext. (mm) | G24: Perpindahan relatif thd awal (mm) | H24: Perpindahan dlm siklus (mm)
A25: Data uji (sumber: Anchor_Extension_Record.xlsx)
A26: 1st Cycle | B26: 57.2 | C26: =B26/$B$8 -> 0.12434783 | D26: 250 | E26: - | F26: 25 | G26: =F26-$F$26 -> 0 | H26: =F26-$F$26 -> 0
A27: 1st Cycle | B27: 240.22 | C27: =B27/$B$8 -> 0.52221739 | D27: 1050 | E27: - | F27: 40 | G27: =F27-$F$26 -> 15 | H27: =F27-$F$26 -> 15
A28: 1st Cycle | B28: 469 | C28: =B28/$B$8 -> 1.0195652 | D28: 2050 | E28: - | F28: 54 | G28: =F28-$F$26 -> 29 | H28: =F28-$F$26 -> 29
A29: 1st Cycle | B29: 697.78 | C29: =B29/$B$8 -> 1.516913 | D29: 3050 | E29: 15 | F29: 70 | G29: =F29-$F$26 -> 45 | H29: =F29-$F$26 -> 45
A30: 1st Cycle | B30: 469 | C30: =B30/$B$8 -> 1.0195652 | D30: 2050 | E30: - | F30: 64 | G30: =F30-$F$26 -> 39 | H30: =F30-$F$26 -> 39
A31: 1st Cycle | B31: 240.22 | C31: =B31/$B$8 -> 0.52221739 | D31: 1050 | E31: - | F31: 53 | G31: =F31-$F$26 -> 28 | H31: =F31-$F$26 -> 28
A32: 1st Cycle | B32: 57.2 | C32: =B32/$B$8 -> 0.12434783 | D32: 250 | E32: - | F32: 37 | G32: =F32-$F$26 -> 12 | H32: =F32-$F$26 -> 12
A33: 2nd Cycle | B33: 57.2 | C33: =B33/$B$8 -> 0.12434783 | D33: 250 | E33: 1 | F33: 37 | G33: =F33-$F$26 -> 12 | H33: =F33-$F$33 -> 0
A34: 2nd Cycle | B34: 240.22 | C34: =B34/$B$8 -> 0.52221739 | D34: 1050 | E34: 1 | F34: 44 | G34: =F34-$F$26 -> 19 | H34: =F34-$F$33 -> 7
A35: 2nd Cycle | B35: 469 | C35: =B35/$B$8 -> 1.0195652 | D35: 2050 | E35: 1 | F35: 53 | G35: =F35-$F$26 -> 28 | H35: =F35-$F$33 -> 16
A36: 2nd Cycle | B36: 697.78 | C36: =B36/$B$8 -> 1.516913 | D36: 3050 | E36: 15 | F36: 75 | G36: =F36-$F$26 -> 50 | H36: =F36-$F$33 -> 38
A37: 2nd Cycle | B37: 469 | C37: =B37/$B$8 -> 1.0195652 | D37: 2050 | E37: 1 | F37: 67 | G37: =F37-$F$26 -> 42 | H37: =F37-$F$33 -> 30
A38: 2nd Cycle | B38: 240.22 | C38: =B38/$B$8 -> 0.52221739 | D38: 1050 | E38: 1 | F38: 50 | G38: =F38-$F$26 -> 25 | H38: =F38-$F$33 -> 13
A39: 2nd Cycle | B39: 57.2 | C39: =B39/$B$8 -> 0.12434783 | D39: 250 | E39: 1 | F39: 19 | G39: =F39-$F$26 -> -6 | H39: =F39-$F$33 -> -18
A40: 3rd Cycle | B40: 57.2 | C40: =B40/$B$8 -> 0.12434783 | D40: 250 | E40: 1 | F40: 19 | G40: =F40-$F$26 -> -6 | H40: =F40-$F$40 -> 0
A41: 3rd Cycle | B41: 240.22 | C41: =B41/$B$8 -> 0.52221739 | D41: 1050 | E41: 1 | F41: 45 | G41: =F41-$F$26 -> 20 | H41: =F41-$F$40 -> 26
A42: 3rd Cycle | B42: 469 | C42: =B42/$B$8 -> 1.0195652 | D42: 2050 | E42: 1 | F42: 60 | G42: =F42-$F$26 -> 35 | H42: =F42-$F$40 -> 41
A43: 3rd Cycle | B43: 697.78 | C43: =B43/$B$8 -> 1.516913 | D43: 3050 | E43: 15 | F43: 75 | G43: =F43-$F$26 -> 50 | H43: =F43-$F$40 -> 56
...

Sheet Perbandingan Pola
A1: Pola tipikal BS 8081 (angkur permanen, 3 siklus) vs data uji — dinormalisasi
A2: Pola standar didigitasi secara skematik dari gambar BS 8081 'Load increments and minimum periods of observation for on-site acceptance tests — (b) Permanent anchorage' (gambar yang ada di record). Sumbu perpindahan pada standar tidak berskala, maka kedua pola dinormalisasi: 0 = bacaan awal, 1 = perpindahan maksimum.
B3: Pola standar (normalisasi, input digitasi) | E3: Data uji (normalisasi, rumus)
A4: Beban (% Tw) | B4: Std S1 | C4: Std S2 | D4: Std S3 | E4: Uji S1 | F4: Uji S2 | G4: Uji S3
A5: 10 | B5: 0 | C5: 0.233 | D5: 0.406 | E5: =('Data & Analisa'!F26-MIN('Data & Analisa'!$F$26:$F$46))/(MAX('Data & Analisa'!$F$26:$F$46)-MIN('Data & Analisa'!$F$26:$F$46)) -> 0.15254237 | F5: =('Data & Analisa'!F33-MIN('Data & Analisa'!$F$26:$F$46))/(MAX('Data & Analisa'!$F$26:$F$46)-MIN('Data & Analisa'!$F$26:$F$46)) -> 0.3559322 | G5: =('Data & Analisa'!F40-MIN('Data & Analisa'!$F$26:$F$46))/(MAX('Data & Analisa'!$F$26:$F$46)-MIN('Data & Analisa'!$F$26:$F$46)) -> 0.050847458
A6: 50 | B6: 0.069 | C6: 0.267 | D6: 0.416 | E6: =('Data & Analisa'!F27-MIN('Data & Analisa'!$F$26:$F$46))/(MAX('Data & Analisa'!$F$26:$F$46)-MIN('Data & Analisa'!$F$26:$F$46)) -> 0.40677966 | F6: =('Data & Analisa'!F34-MIN('Data & Analisa'!$F$26:$F$46))/(MAX('Data & Analisa'!$F$26:$F$46)-MIN('Data & Analisa'!$F$26:$F$46)) -> 0.47457627 | G6: =('Data & Analisa'!F41-MIN('Data & Analisa'!$F$26:$F$46))/(MAX('Data & Analisa'!$F$26:$F$46)-MIN('Data & Analisa'!$F$26:$F$46)) -> 0.49152542
A7: 100 | B7: 0.208 | C7: 0.554 | D7: 0.629 | E7: =('Data & Analisa'!F28-MIN('Data & Analisa'!$F$26:$F$46))/(MAX('Data & Analisa'!$F$26:$F$46)-MIN('Data & Analisa'!$F$26:$F$46)) -> 0.6440678 | F7: =('Data & Analisa'!F35-MIN('Data & Analisa'!$F$26:$F$46))/(MAX('Data & Analisa'!$F$26:$F$46)-MIN('Data & Analisa'!$F$26:$F$46)) -> 0.62711864 | G7: =('Data & Analisa'!F42-MIN('Data & Analisa'!$F$26:$F$46))/(MAX('Data & Analisa'!$F$26:$F$46)-MIN('Data & Analisa'!$F$26:$F$46)) -> 0.74576271
A8: 150 | B8: 0.619 | C8: 0.817 | D8: 1 | E8: =('Data & Analisa'!F29-MIN('Data & Analisa'!$F$26:$F$46))/(MAX('Data & Analisa'!$F$26:$F$46)-MIN('Data & Analisa'!$F$26:$F$46)) -> 0.91525424 | F8: =('Data & Analisa'!F36-MIN('Data & Analisa'!$F$26:$F$46))/(MAX('Data & Analisa'!$F$26:$F$46)-MIN('Data & Analisa'!$F$26:$F$46)) -> 1 | G8: =('Data & Analisa'!F43-MIN('Data & Analisa'!$F$26:$F$46))/(MAX('Data & Analisa'!$F$26:$F$46)-MIN('Data & Analisa'!$F$26:$F$46)) -> 1
A9: 100 | B9: 0.579 | C9: 0.777 | D9: 0.965 | E9: =('Data & Analisa'!F30-MIN('Data & Analisa'!$F$26:$F$46))/(MAX('Data & Analisa'!$F$26:$F$46)-MIN('Data & Analisa'!$F$26:$F$46)) -> 0.81355932 | F9: =('Data & Analisa'!F37-MIN('Data & Analisa'!$F$26:$F$46))/(MAX('Data & Analisa'!$F$26:$F$46)-MIN('Data & Analisa'!$F$26:$F$46)) -> 0.86440678 | G9: =('Data & Analisa'!F44-MIN('Data & Analisa'!$F$26:$F$46))/(MAX('Data & Analisa'!$F$26:$F$46)-MIN('Data & Analisa'!$F$26:$F$46)) -> 0.86440678
A10: 50 | B10: 0.455 | C10: 0.629 | D10: 0.827 | E10: =('Data & Analisa'!F31-MIN('Data & Analisa'!$F$26:$F$46))/(MAX('Data & Analisa'!$F$26:$F$46)-MIN('Data & Analisa'!$F$26:$F$46)) -> 0.62711864 | F10: =('Data & Analisa'!F38-MIN('Data & Analisa'!$F$26:$F$46))/(MAX('Data & Analisa'!$F$26:$F$46)-MIN('Data & Analisa'!$F$26:$F$46)) -> 0.57627119 | G10: =('Data & Analisa'!F45-MIN('Data & Analisa'!$F$26:$F$46))/(MAX('Data & Analisa'!$F$26:$F$46)-MIN('Data & Analisa'!$F$26:$F$46)) -> 0.62711864
A11: 10 | B11: 0.233 | C11: 0.406 | D11: 0.703 | E11: =('Data & Analisa'!F32-MIN('Data & Analisa'!$F$26:$F$46))/(MAX('Data & Analisa'!$F$26:$F$46)-MIN('Data & Analisa'!$F$26:$F$46)) -> 0.3559322 | F11: =('Data & Analisa'!F39-MIN('Data & Analisa'!$F$26:$F$46))/(MAX('Data & Analisa'!$F$26:$F$46)-MIN('Data & Analisa'!$F$26:$F$46)) -> 0.050847458 | G11: =('Data & Analisa'!F46-MIN('Data & Analisa'!$F$26:$F$46))/(MAX('Data & Analisa'!$F$26:$F$46)-MIN('Data & Analisa'!$F$26:$F$46)) -> 0
A13: PERBANDINGAN KARAKTERISTIK
A14: Aspek | B14: Pola umum BS 8081 | C14: Data uji GA 22. P 2 | D14: Sesuai?
A15: Bentuk kurva pembebanan | B15: Cekung ke bawah (kekakuan menurun saat beban naik), kurva bongkar lebih curam dari kurva muat (histeresis). | C15: Kurva muat & bongkar membentuk loop histeresis; kurva bongkar lebih curam di siklus 1–3. | D15: Ya
A16: Pergeseran loop antar siklus | B16: Tiap siklus bergeser ke kanan: perpindahan permanen di datum bertambah (S1 < S2 < S3). | C16: ="Bacaan datum TURUN: "&'Data & Analisa'!F32&" → "&'Data & Analisa'!F39&" → "&'Data & Analisa'!F46&" mm (loop bergeser ke kiri)." -> Bacaan datum TURUN: 37 → 19 → 16 mm (loop bergeser ke kiri). | D16: Tidak
A17: Perpindahan di Tp tiap siklus | B17: Meningkat sedikit tiap siklus (akumulasi permanen + creep). | C17: ='Data & Analisa'!F29&" → "&'Data & Analisa'!F36&" → "&'Data & Analisa'!F43&" mm (naik lalu tetap)." -> 70 → 75 → 75 mm (naik lalu tetap). | D17: Sebagian
A18: Perpindahan elastik tiap siklus | B18: Relatif konsisten antar siklus dan dalam batas 0.9Lf … Lf+0.5Lb. | C18: ='Data & Analisa'!D50&" / "&'Data & Analisa'!D51&" / "&'Data & Analisa'!D52&" mm — siklus 1 jauh lebih kecil; siklus 2 & 3 konsisten dan dalam batas." -> 33 / 56 / 59 mm — siklus 1 jauh lebih kecil; siklus 2 & 3 konsisten dan dalam batas. | D18: Sebagian
A19: Tahanan 15 menit di Tp | B19: Segmen horizontal kecil (creep) yang tercatat pada beberapa bacaan waktu. | C19: Hanya satu bacaan per tahanan — creep tidak dapat dinilai. | D19: Tidak dapat dinilai
A20: Perpindahan permanen akhir | B20: Positif dan bertambah; sisa setelah siklus 3 > siklus 1. | C20: ='Data & Analisa'!E52&" mm (negatif) — tidak wajar secara fisik; cek re-stroke ram / slip wedge / pencatatan." -> -9 mm (negatif) — tidak wajar secara fisik; cek re-stroke ram / slip wedge / pencatatan. | D20: Tidak

Sheet Grafik
A1: Grafik uji angkur GA 22. P 2 — format sesuai rekomendasi BS 8081
A73: Catatan: grafik (c) adalah digitasi skematik dari gambar standar (sumbu perpindahan pada standar tidak berskala); perbandingan bersifat kualitatif (bentuk & urutan loop).
A75: Gambar acuan dari record (BS 8081): (a) temporary, (b) permanent anchorage
