Workbook

Sheet Input
A1: ANALISIS DAYA DUKUNG & PENURUNAN TANAH DASAR - TIMBUNAN WELLPAD
A2: Geotechnical Investigation & DED Geothermal Wellpad - PSPE Bora Pulu (PT EDC Panas Bumi Indonesia)
A3: Sel kuning = input. Semua sheet BH dan Ringkasan dihitung dari sheet ini.
A5: A. BEBAN
A6: Tinggi timbunan | F6: Hf | G6: 2 | H6: m | I6: arahan desain: timbunan 2 m di semua area
A7: Berat isi material timbunan (dipadatkan) | F7: γf | G7: 18 | H7: kN/m³ | I7: asumsi timbunan pilihan dipadatkan
A8: Beban merata di atas timbunan | F8: qs | G8: 100 | H8: kPa | I8: arahan desain: 100 kPa di semua area
A9: Tekanan total pada tanah dasar | F9: q | G9: =G6*G7+G8 | H9: kPa | I9: q = Hf·γf + qs
A10: Lebar area pembebanan | F10: B | G10: 40 | H10: m | I10: ASUMSI ukuran platform/area beban - sesuaikan
A11: Panjang area pembebanan | F11: L | G11: 60 | H11: m | I11: ASUMSI - sesuaikan (L ≥ B)
A13: B. KRITERIA
A14: Faktor keamanan daya dukung | F14: SF | G14: 3 | H14: - | I14: SNI 8460:2017 (daya dukung fondasi dangkal)
A15: Kedalaman tinjauan kekuatan tanah daya dukung | F15: Hb | G15: 5 | H15: m | I15: rata-rata parameter kuat geser 0 - Hb (sama dengan template)
A16: Batas penurunan total (informasi) | F16: S izin | G16: 100 | H16: mm | I16: ASUMSI untuk platform timbunan - sesuaikan
A18: C. KORELASI PARAMETER (dari N-SPT bila tidak ada uji lab)
A19: Kuat geser undrained lempung/lanau: cu = k·N | F19: k | G19: 5 | H19: kPa/N | I19: Stroud (1974), k ≈ 4,4-6; sama dengan PBCP & template
A20: Koreksi energi N60 = CE·N | F20: CE | G20: 1.083 | H20: - | I20: sama dengan analisis likuefaksi (ER 65%)
A21: Modulus pasir: Es = k·N60 | F21: k | G21: 1000 | H21: kPa | I21: Kulhawy & Mayne (1990): E/pa = 10·N60 (pasir berlanau); sama dgn E50 = 1000N template
A22: Modulus undrained lempung/lanau: Eu = k·cu | F22: k | G22: 500 | H22: - | I22: Bowles (1996), Eu = 500-1500 cu (konservatif)
A23: Rasio Cr / Cc | F23: - | G23: 0.2 | H23: - | I23: Cr ≈ 0,1-0,2 Cc (Das 2019)
A24: Rasio su / σ'p | F24: - | G24: 0.22 | H24: - | I24: Mesri (1975): σ'p = cu / 0,22
A25: Faktor waktu Tv untuk U = 90% | F25: Tv | G25: 0.848 | H25: - | I25: Terzaghi
A26: Poisson ratio pasir (drained) | F26: ν | G26: 0.3 | H26: - | I26: lanau/lempung undrained ν = 0,5
A27: Batas kedalaman pengaruh penurunan: Δσz/σ'v0 ≥ | F27: - | G27: 0.1 | H27: - | I27: lapisan dengan Δσz < 10% σ'v0 diabaikan (Das 2019)
A29: D. MATERIAL PENGGANTI (REPLACEMENT)
A30: Berat isi material pengganti (granular dipadatkan) | F30: γr | G30: 19 | H30: kN/m³ | I30: sirtu/selected fill dipadatkan
A31: Sudut geser material pengganti | F31: φ'r | G31: 35 | H31: ° | I31: granular dipadatkan
A32: Kedalaman penggantian Dr diisi per borehole (sheet BH, sel G8).
A34: Cc = 0,009(LL-10) (Terzaghi & Peck 1967); φ' pasir = 27,1 + 0,3N60 - 0,00054N60² (Wolff 1989); φ' lanau/lempung: sin φ' = 0,8 - 0,094 ln PI (Terzaghi, Peck & Mesri 1996), dibatasi 20-30°.
A35: Cv dari LL (NAVFAC DM-7.1, Fig. 5-7, contoh tak terganggu) - tabel di sheet Korelasi. Tidak ada uji konsolidasi (oedometer) pada penyelidikan ini.

Sheet Ringkasan
A1: RINGKASAN DAYA DUKUNG & PENURUNAN TANAH DASAR
A2: =" Beban: timbunan "&TEXT(Input!G6,"0.0")&" m + beban merata "&TEXT(Input!G8,"0")&" kPa → q = "&TEXT(Input!G9,"0")&" kPa; area "&TEXT(Input!G10,"0")&" × "&TEXT(Input!G11,"0")&" m"
A4: Borehole | B4: Area | C4: Lanau/lempung 0-Hb (m) | D4: cu (kPa) | E4: φ' (°) | F4: qall tanpa perbaikan (kPa) | G4: FS tanpa perbaikan | H4: Kontrol | I4: Dr replacement (m) | J4: qall desain (kPa) | K4: FS desain | L4: Kontrol desain | M4: H timbunan izin desain (m) | N4: qa pasir S=25 mm (kPa) | O4: Si elastis (mm) | P4: Si pasir B&B (mm) | Q4: Sc (mm) | R4: t90 (tahun) | S4: S total (mm)
A5: BH-01 | B5: Wellpad D | C5: ='BH-01'!$G$59 | D5: ='BH-01'!$G$60 | E5: ='BH-01'!$G$61 | F5: ='BH-01'!$G$70 | G5: ='BH-01'!$G$73 | H5: ='BH-01'!$G$72 | I5: ='BH-01'!$G$8 | J5: ='BH-01'!$G$88 | K5: ='BH-01'!$G$91 | L5: ='BH-01'!$G$90 | M5: ='BH-01'!$G$92 | N5: ='BH-01'!$G$96 | O5: ='BH-01'!$G$101 | P5: ='BH-01'!$G$110 | Q5: ='BH-01'!$G$115 | R5: ='BH-01'!$G$116 | S5: ='BH-01'!$G$119
A6: BH-02 | B6: Wellpad A | C6: ='BH-02'!$G$59 | D6: ='BH-02'!$G$60 | E6: ='BH-02'!$G$61 | F6: ='BH-02'!$G$70 | G6: ='BH-02'!$G$73 | H6: ='BH-02'!$G$72 | I6: ='BH-02'!$G$8 | J6: ='BH-02'!$G$88 | K6: ='BH-02'!$G$91 | L6: ='BH-02'!$G$90 | M6: ='BH-02'!$G$92 | N6: ='BH-02'!$G$96 | O6: ='BH-02'!$G$101 | P6: ='BH-02'!$G$110 | Q6: ='BH-02'!$G$115 | R6: ='BH-02'!$G$116 | S6: ='BH-02'!$G$119
A7: BH-03 | B7: Log Yard | C7: ='BH-03'!$G$59 | D7: ='BH-03'!$G$60 | E7: ='BH-03'!$G$61 | F7: ='BH-03'!$G$70 | G7: ='BH-03'!$G$73 | H7: ='BH-03'!$G$72 | I7: ='BH-03'!$G$8 | J7: ='BH-03'!$G$88 | K7: ='BH-03'!$G$91 | L7: ='BH-03'!$G$90 | M7: ='BH-03'!$G$92 | N7: ='BH-03'!$G$96 | O7: ='BH-03'!$G$101 | P7: ='BH-03'!$G$110 | Q7: ='BH-03'!$G$115 | R7: ='BH-03'!$G$116 | S7: ='BH-03'!$G$119
A8: BH-04 | B8: Wellpad D | C8: ='BH-04'!$G$59 | D8: ='BH-04'!$G$60 | E8: ='BH-04'!$G$61 | F8: ='BH-04'!$G$70 | G8: ='BH-04'!$G$73 | H8: ='BH-04'!$G$72 | I8: ='BH-04'!$G$8 | J8: ='BH-04'!$G$88 | K8: ='BH-04'!$G$91 | L8: ='BH-04'!$G$90 | M8: ='BH-04'!$G$92 | N8: ='BH-04'!$G$96 | O8: ='BH-04'!$G$101 | P8: ='BH-04'!$G$110 | Q8: ='BH-04'!$G$115 | R8: ='BH-04'!$G$116 | S8: ='BH-04'!$G$119
A9: BH-05 | B9: Wellpad A | C9: ='BH-05'!$G$59 | D9: ='BH-05'!$G$60 | E9: ='BH-05'!$G$61 | F9: ='BH-05'!$G$70 | G9: ='BH-05'!$G$73 | H9: ='BH-05'!$G$72 | I9: ='BH-05'!$G$8 | J9: ='BH-05'!$G$88 | K9: ='BH-05'!$G$91 | L9: ='BH-05'!$G$90 | M9: ='BH-05'!$G$92 | N9: ='BH-05'!$G$96 | O9: ='BH-05'!$G$101 | P9: ='BH-05'!$G$110 | Q9: ='BH-05'!$G$115 | R9: ='BH-05'!$G$116 | S9: ='BH-05'!$G$119
A11: CATATAN
A12: 1. Daya dukung: undrained (cu·Nc) bila ada lanau/lempung dalam 0 - Hb; drained (Vesic) untuk pasir. Pada area beban lebar (B besar) suku Nγ membuat qu drained sangat besar -
A13: artinya keruntuhan geser tidak menentukan; yang menentukan adalah penurunan.
A14: 2. Cara analisis tanah pasiran: (a) daya dukung drained dengan φ' dari N-SPT; (b) qa berbasis penurunan 25 mm (Meyerhof/Bowles); (c) penurunan segera dengan
A15: teori elastis berlapis (E dari N-SPT, batas atas konservatif karena E dianggap konstan) dan Burland & Burbidge (empiris, lebih realistis untuk pasir);
A16: (d) pasir tidak mengalami konsolidasi primer; (e) pasir jenuh lepas: tambahkan penurunan pasca-likuefaksi pada kondisi gempa.
A17: 3. Ukuran area beban B×L di sheet Input adalah ASUMSI (40 × 60 m). Penurunan sangat dipengaruhi ukuran area: untuk B = L = 10 m, Si turun ±50-75%.
A18: 4. Penurunan pasca-likuefaksi saat gempa (laporan likuefaksi Tabel 5.4): BH-01 289, BH-02 383, BH-03 227, BH-04 159, BH-05 100 mm - ditinjau terpisah.
A19: 5. BH-01 kedalaman 1,5 m: data SPT = lempung N5, laporan likuefaksi/lab = pasir SP N12. Dipakai data SPT (konservatif).

Sheet Korelasi
A1: TABEL KORELASI Cv - LL (NAVFAC DM-7.1)
A4: LL (%) | B4: Cv (cm²/s) | C4: log10 Cv
A5: 30 | B5: 0.003 | C5: =LOG10(B5)
A6: 40 | B6: 0.0015 | C6: =LOG10(B6)
A7: 50 | B7: 0.0007 | C7: =LOG10(B7)
A8: 60 | B8: 0.0004 | C8: =LOG10(B8)
A9: 80 | B9: 0.0002 | C9: =LOG10(B9)
A10: 100 | B10: 0.00012 | C10: =LOG10(B10)
A11: 120 | B11: 8e-05 | C11: =LOG10(B11)

Sheet BH-01
A1: ANALISIS DAYA DUKUNG, PENURUNAN SEGERA & KONSOLIDASI - BH-01 (Wellpad D)
A2: PSPE Bora Pulu - timbunan + beban merata (lihat sheet Input)
A4: 1. PARAMETER BOREHOLE
A5: Muka air tanah (GWL) | G5: 9 | H5: m | I5: GWL analisis likuefaksi (Report BP-00-GEO-RPT-003)
A6: Berat isi di atas GWL | G6: 17.8 | H6: kN/m³ | I6: Report Tabel 5.1 (hasil lab)
A7: Berat isi di bawah GWL | G7: 19.2 | H7: kN/m³ | I7: Report Tabel 5.1 (hasil lab)
A8: Kedalaman penggantian tanah (replacement) - kondisi desain | G8: 3 | H8: m | I8: 0 = tanpa perbaikan; tanah 0 - Dr diganti material granular (sheet Input bagian D)
A10: 2. TABEL TANAH & PERHITUNGAN PER LAPISAN (sublapisan = interval SPT 1,5 m)
A11: No | B11: Atas | C11: Bawah | D11: Tebal h | E11: Tengah z | F11: Jenis | G11: N-SPT | H11: γ | I11: σv bawah | J11: σ'v0 tengah | K11: LL | L11: PL | M11: PI | N11: e0 | O11: cu | P11: φ' | Q11: E | R11: ν | S11: m=B/2z | T11: n=L/2z | U11: I Bouss. | V11: Δσz pusat | W11: F1 (bawah) | X11: F2 (bawah) | Y11: faktor aktif | Z11: Si | AA11: Cc | AB11: Cr | AC11: σ'p | AD11: Sc | AE11: Cv | AF11: t90 | AG11: Δ 0-Hb | AH11: Δ 0-Hb sisa | AI11: Δ 0-zI | AJ11: Ket.
B12: m | C12: m | D12: m | E12: m | H12: kN/m³ | I12: kPa | J12: kPa | K12: % | L12: % | M12: % | N12: - | O12: kPa | P12: ° | Q12: kPa | R12: - | S12: - | T12: - | U12: - | V12: kPa | W12: - | X12: - | Y12: - | Z12: mm | AA12: - | AB12: - | AC12: kPa | AD12: mm | AE12: cm²/s | AF12: tahun | AG12: m | AH12: m | AI12: m
A13: 1 | B13: 0 | C13: 1.5 | D13: =C13-B13 | E13: =(B13+C13)/2 | F13: Clay | G13: 5 | H13: =IF(E13>$G$5,$G$7,$G$6) | I13: =H13*D13 | J13: =I13-H13*D13/2-10*MAX(E13-$G$5,0) | K13: 29.665 | L13: 19.806 | M13: =IF(K13="","",K13-L13) | N13: 0.681 | O13: =IF(F13="Sand",0,Input!$G$19*G13) | P13: =IF(F13="Sand",27.1+0.3*MIN(Input!$G$20*G13,60)-0.00054*MIN(Input!$G$20*G13,60)^2,MIN(MAX(DEGREES(ASIN(0.8-0.094*LN(MAX(IF(M13="",10,M13),5)))),20),30)) | Q13: =IF(F13="Sand",Input!$G$21*Input!$G$20*G13,Input!$G$22*O13) | R13: =IF(F13="Sand",Input!$G$26,0.5) | S13: =Input!$G$10/2/E13 | T13: =Input!$G$11/2/E13 | U13: =1/(4*PI())*(2*S13*T13*SQRT(S13^2+T13^2+1)/(S13^2+T13^2+1+S13^2*T13^2)*(S13^2+T13^2+2)/(S13^2+T13^2+1)+ATAN2(S13^2+T13^2+1-S13^2*T13^2,2*S13*T13*SQRT(S13^2+T13^2+1))) | V13: =4*Input!$G$9*U13 | W13: =((Input!$G$11/Input!$G$10)*LN((1+SQRT((Input!$G$11/Input!$G$10)^2+1))*SQRT((Input!$G$11/Input!$G$10)^2+(C13/(Input!$G$10/2))^2)/((Input!$G$11/Input!$G$10)*(1+SQRT((Input!$G$11/Input!$G$10)^2+(C13/(Input!$G$10/2))^2+1))))+LN(((Input!$G$11/Input!$G$10)+SQRT((Input!$G$11/Input!$G$10)^2+1))*SQRT(1+(C13/(Input!$G$10/2))^2)/((Input!$G$11/Input!$G$10)+SQRT((Input!$G$11/Input!$G$10)^2+(C13/(Input!$G$10/2))^2+1))))/PI() | X13: =(C13/(Input!$G$10/2))/(2*PI())*ATAN((Input!$G$11/Input!$G$10)/((C13/(Input!$G$10/2))*SQRT((Input!$G$11/Input!$G$10)^2+(C13/(Input!$G$10/2))^2+1))) | Y13: =MAX(0,C13-MAX(B13,$G$8))/D13*IF(V13>=Input!$G$27*J13,1,0) | Z13: =4*Input!$G$9*(Input!$G$10/2)*(1-R13^2)/Q13*((W13-0)+(1-2*R13)/(1-R13)*(X13-0))*1000*Y13 | AA13: =IF(F13="Sand",0,0.009*(K13-10)) | AB13: =AA13*Input!$G$23 | AC13: =IF(F13="Sand",0,MAX(O13/Input!$G$24,J13)) | AD13: =IF(F13="Sand",0,1000*D13/(1+N13)*IF(J13+V13<=AC13,AB13*LOG10((J13+V13)/J13),AB13*LOG10(AC13/J13)+AA13*LOG10((J13+V13)/AC13)))*Y13 | AE13: =IF(F13="Sand",0,10^(INDEX(Korelasi!$C$5:$C$11,MIN(MATCH(MIN(MAX(K13,30),120),Korelasi!$A$5:$A$11,1),6))+(MIN(MAX(K13,30),120)-INDEX(Korelasi!$A$5:$A$11,MIN(MATCH(MIN(MAX(K13,30),120),Korelasi!$A$5:$A$11,1),6)))/(INDEX(Korelasi!$A$5:$A$11,MIN(MATCH(MIN(MAX(K13,30),120),Korelasi!$A$5:$A$11,1),6)+1)-INDEX(Korelasi!$A$5:$A$11,MIN(MATCH(MIN(MAX(K13,30),120),Korelasi!$A$5:$A$11,1),6)))*(INDEX(Korelasi!$C$5:$C$11,MIN(MATCH(MIN(MAX(K13,30),120),Korelasi!$A$5:$A$11,1),6)+1)-INDEX(Korelasi!$C$5:$C$11,MIN(MATCH(MIN(MAX(K13,30),120),Korelasi!$A$5:$A$11,1),6))))) | AF13: =IF(OR(F13="Sand",Y13=0),0,Input!$G$25*(D13/2)^2/(AE13*1E-4*31536000)) | AG13: =MAX(0,MIN(C13,Input!$G$15)-B13) | AH13: =MAX(0,MIN(C13,Input!$G$15)-MAX(B13,$G$8)) | AI13: =MAX(0,MIN(C13,$G$106)-B13) | AJ13: 0-1,5 m tidak di-SPT: N lapisan berikut; LL/PL/e0 = rata-rata BH
A14: 2 | B14: 1.5 | C14: 3 | D14: =C14-B14 | E14: =(B14+C14)/2 | F14: Clay | G14: 5 | H14: =IF(E14>$G$5,$G$7,$G$6) | I14: =I13+H14*D14 | J14: =I14-H14*D14/2-10*MAX(E14-$G$5,0) | K14: 29.665 | L14: 19.806 | M14: =IF(K14="","",K14-L14) | N14: 0.952 | O14: =IF(F14="Sand",0,Input!$G$19*G14) | P14: =IF(F14="Sand",27.1+0.3*MIN(Input!$G$20*G14,60)-0.00054*MIN(Input!$G$20*G14,60)^2,MIN(MAX(DEGREES(ASIN(0.8-0.094*LN(MAX(IF(M14="",10,M14),5)))),20),30)) | Q14: =IF(F14="Sand",Input!$G$21*Input!$G$20*G14,Input!$G$22*O14) | R14: =IF(F14="Sand",Input!$G$26,0.5) | S14: =Input!$G$10/2/E14 | T14: =Input!$G$11/2/E14 | U14: =1/(4*PI())*(2*S14*T14*SQRT(S14^2+T14^2+1)/(S14^2+T14^2+1+S14^2*T14^2)*(S14^2+T14^2+2)/(S14^2+T14^2+1)+ATAN2(S14^2+T14^2+1-S14^2*T14^2,2*S14*T14*SQRT(S14^2+T14^2+1))) | V14: =4*Input!$G$9*U14 | W14: =((Input!$G$11/Input!$G$10)*LN((1+SQRT((Input!$G$11/Input!$G$10)^2+1))*SQRT((Input!$G$11/Input!$G$10)^2+(C14/(Input!$G$10/2))^2)/((Input!$G$11/Input!$G$10)*(1+SQRT((Input!$G$11/Input!$G$10)^2+(C14/(Input!$G$10/2))^2+1))))+LN(((Input!$G$11/Input!$G$10)+SQRT((Input!$G$11/Input!$G$10)^2+1))*SQRT(1+(C14/(Input!$G$10/2))^2)/((Input!$G$11/Input!$G$10)+SQRT((Input!$G$11/Input!$G$10)^2+(C14/(Input!$G$10/2))^2+1))))/PI() | X14: =(C14/(Input!$G$10/2))/(2*PI())*ATAN((Input!$G$11/Input!$G$10)/((C14/(Input!$G$10/2))*SQRT((Input!$G$11/Input!$G$10)^2+(C14/(Input!$G$10/2))^2+1))) | Y14: =MAX(0,C14-MAX(B14,$G$8))/D14*IF(V14>=Input!$G$27*J14,1,0) | Z14: =4*Input!$G$9*(Input!$G$10/2)*(1-R14^2)/Q14*((W14-W13)+(1-2*R14)/(1-R14)*(X14-X13))*1000*Y14 | AA14: =IF(F14="Sand",0,0.009*(K14-10)) | AB14: =AA14*Input!$G$23 | AC14: =IF(F14="Sand",0,MAX(O14/Input!$G$24,J14)) | AD14: =IF(F14="Sand",0,1000*D14/(1+N14)*IF(J14+V14<=AC14,AB14*LOG10((J14+V14)/J14),AB14*LOG10(AC14/J14)+AA14*LOG10((J14+V14)/AC14)))*Y14 | AE14: =IF(F14="Sand",0,10^(INDEX(Korelasi!$C$5:$C$11,MIN(MATCH(MIN(MAX(K14,30),120),Korelasi!$A$5:$A$11,1),6))+(MIN(MAX(K14,30),120)-INDEX(Korelasi!$A$5:$A$11,MIN(MATCH(MIN(MAX(K14,30),120),Korelasi!$A$5:$A$11,1),6)))/(INDEX(Korelasi!$A$5:$A$11,MIN(MATCH(MIN(MAX(K14,30),120),Korelasi!$A$5:$A$11,1),6)+1)-INDEX(Korelasi!$A$5:$A$11,MIN(MATCH(MIN(MAX(K14,30),120),Korelasi!$A$5:$A$11,1),6)))*(INDEX(Korelasi!$C$5:$C$11,MIN(MATCH(MIN(MAX(K14,30),120),Korelasi!$A$5:$A$11,1),6)+1)-INDEX(Korelasi!$C$5:$C$11,MIN(MATCH(MIN(MAX(K14,30),120),Korelasi!$A$5:$A$11,1),6))))) | AF14: =IF(OR(F14="Sand",Y14=0),0,Input!$G$25*(D14/2)^2/(AE14*1E-4*31536000)) | AG14: =MAX(0,MIN(C14,Input!$G$15)-B14) | AH14: =MAX(0,MIN(C14,Input!$G$15)-MAX(B14,$G$8)) | AI14: =MAX(0,MIN(C14,$G$106)-B14) | AJ14: LL/PL/e0 = rata-rata BH
A15: 3 | B15: 3 | C15: 5.5 | D15: =C15-B15 | E15: =(B15+C15)/2 | F15: Sand | G15: 18 | H15: =IF(E15>$G$5,$G$7,$G$6) | I15: =I14+H15*D15 | J15: =I15-H15*D15/2-10*MAX(E15-$G$5,0) | M15: =IF(K15="","",K15-L15) | N15: 0.759 | O15: =IF(F15="Sand",0,Input!$G$19*G15) | P15: =IF(F15="Sand",27.1+0.3*MIN(Input!$G$20*G15,60)-0.00054*MIN(Input!$G$20*G15,60)^2,MIN(MAX(DEGREES(ASIN(0.8-0.094*LN(MAX(IF(M15="",10,M15),5)))),20),30)) | Q15: =IF(F15="Sand",Input!$G$21*Input!$G$20*G15,Input!$G$22*O15) | R15: =IF(F15="Sand",Input!$G$26,0.5) | S15: =Input!$G$10/2/E15 | T15: =Input!$G$11/2/E15 | U15: =1/(4*PI())*(2*S15*T15*SQRT(S15^2+T15^2+1)/(S15^2+T15^2+1+S15^2*T15^2)*(S15^2+T15^2+2)/(S15^2+T15^2+1)+ATAN2(S15^2+T15^2+1-S15^2*T15^2,2*S15*T15*SQRT(S15^2+T15^2+1))) | V15: =4*Input!$G$9*U15 | W15: =((Input!$G$11/Input!$G$10)*LN((1+SQRT((Input!$G$11/Input!$G$10)^2+1))*SQRT((Input!$G$11/Input!$G$10)^2+(C15/(Input!$G$10/2))^2)/((Input!$G$11/Input!$G$10)*(1+SQRT((Input!$G$11/Input!$G$10)^2+(C15/(Input!$G$10/2))^2+1))))+LN(((Input!$G$11/Input!$G$10)+SQRT((Input!$G$11/Input!$G$10)^2+1))*SQRT(1+(C15/(Input!$G$10/2))^2)/((Input!$G$11/Input!$G$10)+SQRT((Input!$G$11/Input!$G$10)^2+(C15/(Input!$G$10/2))^2+1))))/PI() | X15: =(C15/(Input!$G$10/2))/(2*PI())*ATAN((Input!$G$11/Input!$G$10)/((C15/(Input!$G$10/2))*SQRT((Input!$G$11/Input!$G$10)^2+(C15/(Input!$G$10/2))^2+1))) | Y15: =MAX(0,C15-MAX(B15,$G$8))/D15*IF(V15>=Input!$G$27*J15,1,0) | Z15: =4*Input!$G$9*(Input!$G$10/2)*(1-R15^2)/Q15*((W15-W14)+(1-2*R15)/(1-R15)*(X15-X14))*1000*Y15 | AA15: =IF(F15="Sand",0,0.009*(K15-10)) | AB15: =AA15*Input!$G$23 | AC15: =IF(F15="Sand",0,MAX(O15/Input!$G$24,J15)) | AD15: =IF(F15="Sand",0,1000*D15/(1+N15)*IF(J15+V15<=AC15,AB15*LOG10((J15+V15)/J15),AB15*LOG10(AC15/J15)+AA15*LOG10((J15+V15)/AC15)))*Y15 | AE15: =IF(F15="Sand",0,10^(INDEX(Korelasi!$C$5:$C$11,MIN(MATCH(MIN(MAX(K15,30),120),Korelasi!$A$5:$A$11,1),6))+(MIN(MAX(K15,30),120)-INDEX(Korelasi!$A$5:$A$11,MIN(MATCH(MIN(MAX(K15,30),120),Korelasi!$A$5:$A$11,1),6)))/(INDEX(Korelasi!$A$5:$A$11,MIN(MATCH(MIN(MAX(K15,30),120),Korelasi!$A$5:$A$11,1),6)+1)-INDEX(Korelasi!$A$5:$A$11,MIN(MATCH(MIN(MAX(K15,30),120),Korelasi!$A$5:$A$11,1),6)))*(INDEX(Korelasi!$C$5:$C$11,MIN(MATCH(MIN(MAX(K15,30),120),Korelasi!$A$5:$A$11,1),6)+1)-INDEX(Korelasi!$C$5:$C$11,MIN(MATCH(MIN(MAX(K15,30),120),Korelasi!$A$5:$A$11,1),6))))) | AF15: =IF(OR(F15="Sand",Y15=0),0,Input!$G$25*(D15/2)^2/(AE15*1E-4*31536000)) | AG15: =MAX(0,MIN(C15,Input!$G$15)-B15) | AH15: =MAX(0,MIN(C15,Input!$G$15)-MAX(B15,$G$8)) | AI15: =MAX(0,MIN(C15,$G$106)-B15)
A16: 4 | B16: 5.5 | C16: 6 | D16: =C16-B16 | E16: =(B16+C16)/2 | F16: Silt | G16: 28 | H16: =IF(E16>$G$5,$G$7,$G$6) | I16: =I15+H16*D16 | J16: =I16-H16*D16/2-10*MAX(E16-$G$5,0) | K16: 29.665 | L16: 19.806 | M16: =IF(K16="","",K16-L16) | N16: 0.681 | O16: =IF(F16="Sand",0,Input!$G$19*G16) | P16: =IF(F16="Sand",27.1+0.3*MIN(Input!$G$20*G16,60)-0.00054*MIN(Input!$G$20*G16,60)^2,MIN(MAX(DEGREES(ASIN(0.8-0.094*LN(MAX(IF(M16="",10,M16),5)))),20),30)) | Q16: =IF(F16="Sand",Input!$G$21*Input!$G$20*G16,Input!$G$22*O16) | R16: =IF(F16="Sand",Input!$G$26,0.5) | S16: =Input!$G$10/2/E16 | T16: =Input!$G$11/2/E16 | U16: =1/(4*PI())*(2*S16*T16*SQRT(S16^2+T16^2+1)/(S16^2+T16^2+1+S16^2*T16^2)*(S16^2+T16^2+2)/(S16^2+T16^2+1)+ATAN2(S16^2+T16^2+1-S16^2*T16^2,2*S16*T16*SQRT(S16^2+T16^2+1))) | V16: =4*Input!$G$9*U16 | W16: =((Input!$G$11/Input!$G$10)*LN((1+SQRT((Input!$G$11/Input!$G$10)^2+1))*SQRT((Input!$G$11/Input!$G$10)^2+(C16/(Input!$G$10/2))^2)/((Input!$G$11/Input!$G$10)*(1+SQRT((Input!$G$11/Input!$G$10)^2+(C16/(Input!$G$10/2))^2+1))))+LN(((Input!$G$11/Input!$G$10)+SQRT((Input!$G$11/Input!$G$10)^2+1))*SQRT(1+(C16/(Input!$G$10/2))^2)/((Input!$G$11/Input!$G$10)+SQRT((Input!$G$11/Input!$G$10)^2+(C16/(Input!$G$10/2))^2+1))))/PI() | X16: =(C16/(Input!$G$10/2))/(2*PI())*ATAN((Input!$G$11/Input!$G$10)/((C16/(Input!$G$10/2))*SQRT((Input!$G$11/Input!$G$10)^2+(C16/(Input!$G$10/2))^2+1))) | Y16: =MAX(0,C16-MAX(B16,$G$8))/D16*IF(V16>=Input!$G$27*J16,1,0) | Z16: =4*Input!$G$9*(Input!$G$10/2)*(1-R16^2)/Q16*((W16-W15)+(1-2*R16)/(1-R16)*(X16-X15))*1000*Y16 | AA16: =IF(F16="Sand",0,0.009*(K16-10)) | AB16: =AA16*Input!$G$23 | AC16: =IF(F16="Sand",0,MAX(O16/Input!$G$24,J16)) | AD16: =IF(F16="Sand",0,1000*D16/(1+N16)*IF(J16+V16<=AC16,AB16*LOG10((J16+V16)/J16),AB16*LOG10(AC16/J16)+AA16*LOG10((J16+V16)/AC16)))*Y16 | AE16: =IF(F16="Sand",0,10^(INDEX(Korelasi!$C$5:$C$11,MIN(MATCH(MIN(MAX(K16,30),120),Korelasi!$A$5:$A$11,1),6))+(MIN(MAX(K16,30),120)-INDEX(Korelasi!$A$5:$A$11,MIN(MATCH(MIN(MAX(K16,30),120),Korelasi!$A$5:$A$11,1),6)))/(INDEX(Korelasi!$A$5:$A$11,MIN(MATCH(MIN(MAX(K16,30),120),Korelasi!$A$5:$A$11,1),6)+1)-INDEX(Korelasi!$A$5:$A$11,MIN(MATCH(MIN(MAX(K16,30),120),Korelasi!$A$5:$A$11,1),6)))*(INDEX(Korelasi!$C$5:$C$11,MIN(MATCH(MIN(MAX(K16,30),120),Korelasi!$A$5:$A$11,1),6)+1)-INDEX(Korelasi!$C$5:$C$11,MIN(MATCH(MIN(MAX(K16,30),120),Korelasi!$A$5:$A$11,1),6))))) | AF16: =IF(OR(F16="Sand",Y16=0),0,Input!$G$25*(D16/2)^2/(AE16*1E-4*31536000)) | AG16: =MAX(0,MIN(C16,Input!$G$15)-B16) | AH16: =MAX(0,MIN(C16,Input!$G$15)-MAX(B16,$G$8)) | AI16: =MAX(0,MIN(C16,$G$106)-B16) | AJ16: LL/PL/e0 = rata-rata BH
A17: 5 | B17: 6 | C17: 7.5 | D17: =C17-B17 | E17: =(B17+C17)/2 | F17: Silt | G17: 30 | H17: =IF(E17>$G$5,$G$7,$G$6) | I17: =I16+H17*D17 | J17: =I17-H17*D17/2-10*MAX(E17-$G$5,0) | K17: 29.665 | L17: 19.806 | M17: =IF(K17="","",K17-L17) | N17: 0.681 | O17: =IF(F17="Sand",0,Input!$G$19*G17) | P17: =IF(F17="Sand",27.1+0.3*MIN(Input!$G$20*G17,60)-0.00054*MIN(Input!$G$20*G17,60)^2,MIN(MAX(DEGREES(ASIN(0.8-0.094*LN(MAX(IF(M17="",10,M17),5)))),20),30)) | Q17: =IF(F17="Sand",Input!$G$21*Input!$G$20*G17,Input!$G$22*O17) | R17: =IF(F17="Sand",Input!$G$26,0.5) | S17: =Input!$G$10/2/E17 | T17: =Input!$G$11/2/E17 | U17: =1/(4*PI())*(2*S17*T17*SQRT(S17^2+T17^2+1)/(S17^2+T17^2+1+S17^2*T17^2)*(S17^2+T17^2+2)/(S17^2+T17^2+1)+ATAN2(S17^2+T17^2+1-S17^2*T17^2,2*S17*T17*SQRT(S17^2+T17^2+1))) | V17: =4*Input!$G$9*U17 | W17: =((Input!$G$11/Input!$G$10)*LN((1+SQRT((Input!$G$11/Input!$G$10)^2+1))*SQRT((Input!$G$11/Input!$G$10)^2+(C17/(Input!$G$10/2))^2)/((Input!$G$11/Input!$G$10)*(1+SQRT((Input!$G$11/Input!$G$10)^2+(C17/(Input!$G$10/2))^2+1))))+LN(((Input!$G$11/Input!$G$10)+SQRT((Input!$G$11/Input!$G$10)^2+1))*SQRT(1+(C17/(Input!$G$10/2))^2)/((Input!$G$11/Input!$G$10)+SQRT((Input!$G$11/Input!$G$10)^2+(C17/(Input!$G$10/2))^2+1))))/PI() | X17: =(C17/(Input!$G$10/2))/(2*PI())*ATAN((Input!$G$11/Input!$G$10)/((C17/(Input!$G$10/2))*SQRT((Input!$G$11/Input!$G$10)^2+(C17/(Input!$G$10/2))^2+1))) | Y17: =MAX(0,C17-MAX(B17,$G$8))/D17*IF(V17>=Input!$G$27*J17,1,0) | Z17: =4*Input!$G$9*(Input!$G$10/2)*(1-R17^2)/Q17*((W17-W16)+(1-2*R17)/(1-R17)*(X17-X16))*1000*Y17 | AA17: =IF(F17="Sand",0,0.009*(K17-10)) | AB17: =AA17*Input!$G$23 | AC17: =IF(F17="Sand",0,MAX(O17/Input!$G$24,J17)) | AD17: =IF(F17="Sand",0,1000*D17/(1+N17)*IF(J17+V17<=AC17,AB17*LOG10((J17+V17)/J17),AB17*LOG10(AC17/J17)+AA17*LOG10((J17+V17)/AC17)))*Y17 | AE17: =IF(F17="Sand",0,10^(INDEX(Korelasi!$C$5:$C$11,MIN(MATCH(MIN(MAX(K17,30),120),Korelasi!$A$5:$A$11,1),6))+(MIN(MAX(K17,30),120)-INDEX(Korelasi!$A$5:$A$11,MIN(MATCH(MIN(MAX(K17,30),120),Korelasi!$A$5:$A$11,1),6)))/(INDEX(Korelasi!$A$5:$A$11,MIN(MATCH(MIN(MAX(K17,30),120),Korelasi!$A$5:$A$11,1),6)+1)-INDEX(Korelasi!$A$5:$A$11,MIN(MATCH(MIN(MAX(K17,30),120),Korelasi!$A$5:$A$11,1),6)))*(INDEX(Korelasi!$C$5:$C$11,MIN(MATCH(MIN(MAX(K17,30),120),Korelasi!$A$5:$A$11,1),6)+1)-INDEX(Korelasi!$C$5:$C$11,MIN(MATCH(MIN(MAX(K17,30),120),Korelasi!$A$5:$A$11,1),6))))) | AF17: =IF(OR(F17="Sand",Y17=0),0,Input!$G$25*(D17/2)^2/(AE17*1E-4*31536000)) | AG17: =MAX(0,MIN(C17,Input!$G$15)-B17) | AH17: =MAX(0,MIN(C17,Input!$G$15)-MAX(B17,$G$8)) | AI17: =MAX(0,MIN(C17,$G$106)-B17) | AJ17: LL/PL/e0 = rata-rata BH
A18: 6 | B18: 7.5 | C18: 9 | D18: =C18-B18 | E18: =(B18+C18)/2 | F18: Sand | G18: 35 | H18: =IF(E18>$G$5,$G$7,$G$6) | I18: =I17+H18*D18 | J18: =I18-H18*D18/2-10*MAX(E18-$G$5,0) | M18: =IF(K18="","",K18-L18) | N18: 0.65 | O18: =IF(F18="Sand",0,Input!$G$19*G18) | P18: =IF(F18="Sand",27.1+0.3*MIN(Input!$G$20*G18,60)-0.00054*MIN(Input!$G$20*G18,60)^2,MIN(MAX(DEGREES(ASIN(0.8-0.094*LN(MAX(IF(M18="",10,M18),5)))),20),30)) | Q18: =IF(F18="Sand",Input!$G$21*Input!$G$20*G18,Input!$G$22*O18) | R18: =IF(F18="Sand",Input!$G$26,0.5) | S18: =Input!$G$10/2/E18 | T18: =Input!$G$11/2/E18 | U18: =1/(4*PI())*(2*S18*T18*SQRT(S18^2+T18^2+1)/(S18^2+T18^2+1+S18^2*T18^2)*(S18^2+T18^2+2)/(S18^2+T18^2+1)+ATAN2(S18^2+T18^2+1-S18^2*T18^2,2*S18*T18*SQRT(S18^2+T18^2+1))) | V18: =4*Input!$G$9*U18 | W18: =((Input!$G$11/Input!$G$10)*LN((1+SQRT((Input!$G$11/Input!$G$10)^2+1))*SQRT((Input!$G$11/Input!$G$10)^2+(C18/(Input!$G$10/2))^2)/((Input!$G$11/Input!$G$10)*(1+SQRT((Input!$G$11/Input!$G$10)^2+(C18/(Input!$G$10/2))^2+1))))+LN(((Input!$G$11/Input!$G$10)+SQRT((Input!$G$11/Input!$G$10)^2+1))*SQRT(1+(C18/(Input!$G$10/2))^2)/((Input!$G$11/Input!$G$10)+SQRT((Input!$G$11/Input!$G$10)^2+(C18/(Input!$G$10/2))^2+1))))/PI() | X18: =(C18/(Input!$G$10/2))/(2*PI())*ATAN((Input!$G$11/Input!$G$10)/((C18/(Input!$G$10/2))*SQRT((Input!$G$11/Input!$G$10)^2+(C18/(Input!$G$10/2))^2+1))) | Y18: =MAX(0,C18-MAX(B18,$G$8))/D18*IF(V18>=Input!$G$27*J18,1,0) | Z18: =4*Input!$G$9*(Input!$G$10/2)*(1-R18^2)/Q18*((W18-W17)+(1-2*R18)/(1-R18)*(X18-X17))*1000*Y18 | AA18: =IF(F18="Sand",0,0.009*(K18-10)) | AB18: =AA18*Input!$G$23 | AC18: =IF(F18="Sand",0,MAX(O18/Input!$G$24,J18)) | AD18: =IF(F18="Sand",0,1000*D18/(1+N18)*IF(J18+V18<=AC18,AB18*LOG10((J18+V18)/J18),AB18*LOG10(AC18/J18)+AA18*LOG10((J18+V18)/AC18)))*Y18 | AE18: =IF(F18="Sand",0,10^(INDEX(Korelasi!$C$5:$C$11,MIN(MATCH(MIN(MAX(K18,30),120),Korelasi!$A$5:$A$11,1),6))+(MIN(MAX(K18,30),120)-INDEX(Korelasi!$A$5:$A$11,MIN(MATCH(MIN(MAX(K18,30),120),Korelasi!$A$5:$A$11,1),6)))/(INDEX(Korelasi!$A$5:$A$11,MIN(MATCH(MIN(MAX(K18,30),120),Korelasi!$A$5:$A$11,1),6)+1)-INDEX(Korelasi!$A$5:$A$11,MIN(MATCH(MIN(MAX(K18,30),120),Korelasi!$A$5:$A$11,1),6)))*(INDEX(Korelasi!$C$5:$C$11,MIN(MATCH(MIN(MAX(K18,30),120),Korelasi!$A$5:$A$11,1),6)+1)-INDEX(Korelasi!$C$5:$C$11,MIN(MATCH(MIN(MAX(K18,30),120),Korelasi!$A$5:$A$11,1),6))))) | AF18: =IF(OR(F18="Sand",Y18=0),0,Input!$G$25*(D18/2)^2/(AE18*1E-4*31536000)) | AG18: =MAX(0,MIN(C18,Input!$G$15)-B18) | AH18: =MAX(0,MIN(C18,Input!$G$15)-MAX(B18,$G$8)) | AI18: =MAX(0,MIN(C18,$G$106)-B18)
A19: 7 | B19: 9 | C19: 10.5 | D19: =C19-B19 | E19: =(B19+C19)/2 | F19: Sand | G19: 34 | H19: =IF(E19>$G$5,$G$7,$G$6) | I19: =I18+H19*D19 | J19: =I19-H19*D19/2-10*MAX(E19-$G$5,0) | M19: =IF(K19="","",K19-L19) | N19: 0.465 | O19: =IF(F19="Sand",0,Input!$G$19*G19) | P19: =IF(F19="Sand",27.1+0.3*MIN(Input!$G$20*G19,60)-0.00054*MIN(Input!$G$20*G19,60)^2,MIN(MAX(DEGREES(ASIN(0.8-0.094*LN(MAX(IF(M19="",10,M19),5)))),20),30)) | Q19: =IF(F19="Sand",Input!$G$21*Input!$G$20*G19,Input!$G$22*O19) | R19: =IF(F19="Sand",Input!$G$26,0.5) | S19: =Input!$G$10/2/E19 | T19: =Input!$G$11/2/E19 | U19: =1/(4*PI())*(2*S19*T19*SQRT(S19^2+T19^2+1)/(S19^2+T19^2+1+S19^2*T19^2)*(S19^2+T19^2+2)/(S19^2+T19^2+1)+ATAN2(S19^2+T19^2+1-S19^2*T19^2,2*S19*T19*SQRT(S19^2+T19^2+1))) | V19: =4*Input!$G$9*U19 | W19: =((Input!$G$11/Input!$G$10)*LN((1+SQRT((Input!$G$11/Input!$G$10)^2+1))*SQRT((Input!$G$11/Input!$G$10)^2+(C19/(Input!$G$10/2))^2)/((Input!$G$11/Input!$G$10)*(1+SQRT((Input!$G$11/Input!$G$10)^2+(C19/(Input!$G$10/2))^2+1))))+LN(((Input!$G$11/Input!$G$10)+SQRT((Input!$G$11/Input!$G$10)^2+1))*SQRT(1+(C19/(Input!$G$10/2))^2)/((Input!$G$11/Input!$G$10)+SQRT((Input!$G$11/Input!$G$10)^2+(C19/(Input!$G$10/2))^2+1))))/PI() | X19: =(C19/(Input!$G$10/2))/(2*PI())*ATAN((Input!$G$11/Input!$G$10)/((C19/(Input!$G$10/2))*SQRT((Input!$G$11/Input!$G$10)^2+(C19/(Input!$G$10/2))^2+1))) | Y19: =MAX(0,C19-MAX(B19,$G$8))/D19*IF(V19>=Input!$G$27*J19,1,0) | Z19: =4*Input!$G$9*(Input!$G$10/2)*(1-R19^2)/Q19*((W19-W18)+(1-2*R19)/(1-R19)*(X19-X18))*1000*Y19 | AA19: =IF(F19="Sand",0,0.009*(K19-10)) | AB19: =AA19*Input!$G$23 | AC19: =IF(F19="Sand",0,MAX(O19/Input!$G$24,J19)) | AD19: =IF(F19="Sand",0,1000*D19/(1+N19)*IF(J19+V19<=AC19,AB19*LOG10((J19+V19)/J19),AB19*LOG10(AC19/J19)+AA19*LOG10((J19+V19)/AC19)))*Y19 | AE19: =IF(F19="Sand",0,10^(INDEX(Korelasi!$C$5:$C$11,MIN(MATCH(MIN(MAX(K19,30),120),Korelasi!$A$5:$A$11,1),6))+(MIN(MAX(K19,30),120)-INDEX(Korelasi!$A$5:$A$11,MIN(MATCH(MIN(MAX(K19,30),120),Korelasi!$A$5:$A$11,1),6)))/(INDEX(Korelasi!$A$5:$A$11,MIN(MATCH(MIN(MAX(K19,30),120),Korelasi!$A$5:$A$11,1),6)+1)-INDEX(Korelasi!$A$5:$A$11,MIN(MATCH(MIN(MAX(K19,30),120),Korelasi!$A$5:$A$11,1),6)))*(INDEX(Korelasi!$C$5:$C$11,MIN(MATCH(MIN(MAX(K19,30),120),Korelasi!$A$5:$A$11,1),6)+1)-INDEX(Korelasi!$C$5:$C$11,MIN(MATCH(MIN(MAX(K19,30),120),Korelasi!$A$5:$A$11,1),6))))) | AF19: =IF(OR(F19="Sand",Y19=0),0,Input!$G$25*(D19/2)^2/(AE19*1E-4*31536000)) | AG19: =MAX(0,MIN(C19,Input!$G$15)-B19) | AH19: =MAX(0,MIN(C19,Input!$G$15)-MAX(B19,$G$8)) | AI19: =MAX(0,MIN(C19,$G$106)-B19)
A20: 8 | B20: 10.5 | C20: 12 | D20: =C20-B20 | E20: =(B20+C20)/2 | F20: Sand | G20: 13 | H20: =IF(E20>$G$5,$G$7,$G$6) | I20: =I19+H20*D20 | J20: =I20-H20*D20/2-10*MAX(E20-$G$5,0) | M20: =IF(K20="","",K20-L20) | N20: 0.65 | O20: =IF(F20="Sand",0,Input!$G$19*G20) | P20: =IF(F20="Sand",27.1+0.3*MIN(Input!$G$20*G20,60)-0.00054*MIN(Input!$G$20*G20,60)^2,MIN(MAX(DEGREES(ASIN(0.8-0.094*LN(MAX(IF(M20="",10,M20),5)))),20),30)) | Q20: =IF(F20="Sand",Input!$G$21*Input!$G$20*G20,Input!$G$22*O20) | R20: =IF(F20="Sand",Input!$G$26,0.5) | S20: =Input!$G$10/2/E20 | T20: =Input!$G$11/2/E20 | U20: =1/(4*PI())*(2*S20*T20*SQRT(S20^2+T20^2+1)/(S20^2+T20^2+1+S20^2*T20^2)*(S20^2+T20^2+2)/(S20^2+T20^2+1)+ATAN2(S20^2+T20^2+1-S20^2*T20^2,2*S20*T20*SQRT(S20^2+T20^2+1))) | V20: =4*Input!$G$9*U20 | W20: =((Input!$G$11/Input!$G$10)*LN((1+SQRT((Input!$G$11/Input!$G$10)^2+1))*SQRT((Input!$G$11/Input!$G$10)^2+(C20/(Input!$G$10/2))^2)/((Input!$G$11/Input!$G$10)*(1+SQRT((Input!$G$11/Input!$G$10)^2+(C20/(Input!$G$10/2))^2+1))))+LN(((Input!$G$11/Input!$G$10)+SQRT((Input!$G$11/Input!$G$10)^2+1))*SQRT(1+(C20/(Input!$G$10/2))^2)/((Input!$G$11/Input!$G$10)+SQRT((Input!$G$11/Input!$G$10)^2+(C20/(Input!$G$10/2))^2+1))))/PI() | X20: =(C20/(Input!$G$10/2))/(2*PI())*ATAN((Input!$G$11/Input!$G$10)/((C20/(Input!$G$10/2))*SQRT((Input!$G$11/Input!$G$10)^2+(C20/(Input!$G$10/2))^2+1))) | Y20: =MAX(0,C20-MAX(B20,$G$8))/D20*IF(V20>=Input!$G$27*J20,1,0) | Z20: =4*Input!$G$9*(Input!$G$10/2)*(1-R20^2)/Q20*((W20-W19)+(1-2*R20)/(1-R20)*(X20-X19))*1000*Y20 | AA20: =IF(F20="Sand",0,0.009*(K20-10)) | AB20: =AA20*Input!$G$23 | AC20: =IF(F20="Sand",0,MAX(O20/Input!$G$24,J20)) | AD20: =IF(F20="Sand",0,1000*D20/(1+N20)*IF(J20+V20<=AC20,AB20*LOG10((J20+V20)/J20),AB20*LOG10(AC20/J20)+AA20*LOG10((J20+V20)/AC20)))*Y20 | AE20: =IF(F20="Sand",0,10^(INDEX(Korelasi!$C$5:$C$11,MIN(MATCH(MIN(MAX(K20,30),120),Korelasi!$A$5:$A$11,1),6))+(MIN(MAX(K20,30),120)-INDEX(Korelasi!$A$5:$A$11,MIN(MATCH(MIN(MAX(K20,30),120),Korelasi!$A$5:$A$11,1),6)))/(INDEX(Korelasi!$A$5:$A$11,MIN(MATCH(MIN(MAX(K20,30),120),Korelasi!$A$5:$A$11,1),6)+1)-INDEX(Korelasi!$A$5:$A$11,MIN(MATCH(MIN(MAX(K20,30),120),Korelasi!$A$5:$A$11,1),6)))*(INDEX(Korelasi!$C$5:$C$11,MIN(MATCH(MIN(MAX(K20,30),120),Korelasi!$A$5:$A$11,1),6)+1)-INDEX(Korelasi!$C$5:$C$11,MIN(MATCH(MIN(MAX(K20,30),120),Korelasi!$A$5:$A$11,1),6))))) | AF20: =IF(OR(F20="Sand",Y20=0),0,Input!$G$25*(D20/2)^2/(AE20*1E-4*31536000)) | AG20: =MAX(0,MIN(C20,Input!$G$15)-B20) | AH20: =MAX(0,MIN(C20,Input!$G$15)-MAX(B20,$G$8)) | AI20: =MAX(0,MIN(C20,$G$106)-B20)
A21: 9 | B21: 12 | C21: 13.5 | D21: =C21-B21 | E21: =(B21+C21)/2 | F21: Sand | G21: 17 | H21: =IF(E21>$G$5,$G$7,$G$6) | I21: =I20+H21*D21 | J21: =I21-H21*D21/2-10*MAX(E21-$G$5,0) | M21: =IF(K21="","",K21-L21) | N21: 0.414 | O21: =IF(F21="Sand",0,Input!$G$19*G21) | P21: =IF(F21="Sand",27.1+0.3*MIN(Input!$G$20*G21,60)-0.00054*MIN(Input!$G$20*G21,60)^2,MIN(MAX(DEGREES(ASIN(0.8-0.094*LN(MAX(IF(M21="",10,M21),5)))),20),30)) | Q21: =IF(F21="Sand",Input!$G$21*Input!$G$20*G21,Input!$G$22*O21) | R21: =IF(F21="Sand",Input!$G$26,0.5) | S21: =Input!$G$10/2/E21 | T21: =Input!$G$11/2/E21 | U21: =1/(4*PI())*(2*S21*T21*SQRT(S21^2+T21^2+1)/(S21^2+T21^2+1+S21^2*T21^2)*(S21^2+T21^2+2)/(S21^2+T21^2+1)+ATAN2(S21^2+T21^2+1-S21^2*T21^2,2*S21*T21*SQRT(S21^2+T21^2+1))) | V21: =4*Input!$G$9*U21 | W21: =((Input!$G$11/Input!$G$10)*LN((1+SQRT((Input!$G$11/Input!$G$10)^2+1))*SQRT((Input!$G$11/Input!$G$10)^2+(C21/(Input!$G$10/2))^2)/((Input!$G$11/Input!$G$10)*(1+SQRT((Input!$G$11/Input!$G$10)^2+(C21/(Input!$G$10/2))^2+1))))+LN(((Input!$G$11/Input!$G$10)+SQRT((Input!$G$11/Input!$G$10)^2+1))*SQRT(1+(C21/(Input!$G$10/2))^2)/((Input!$G$11/Input!$G$10)+SQRT((Input!$G$11/Input!$G$10)^2+(C21/(Input!$G$10/2))^2+1))))/PI() | X21: =(C21/(Input!$G$10/2))/(2*PI())*ATAN((Input!$G$11/Input!$G$10)/((C21/(Input!$G$10/2))*SQRT((Input!$G$11/Input!$G$10)^2+(C21/(Input!$G$10/2))^2+1))) | Y21: =MAX(0,C21-MAX(B21,$G$8))/D21*IF(V21>=Input!$G$27*J21,1,0) | Z21: =4*Input!$G$9*(Input!$G$10/2)*(1-R21^2)/Q21*((W21-W20)+(1-2*R21)/(1-R21)*(X21-X20))*1000*Y21 | AA21: =IF(F21="Sand",0,0.009*(K21-10)) | AB21: =AA21*Input!$G$23 | AC21: =IF(F21="Sand",0,MAX(O21/Input!$G$24,J21)) | AD21: =IF(F21="Sand",0,1000*D21/(1+N21)*IF(J21+V21<=AC21,AB21*LOG10((J21+V21)/J21),AB21*LOG10(AC21/J21)+AA21*LOG10((J21+V21)/AC21)))*Y21 | AE21: =IF(F21="Sand",0,10^(INDEX(Korelasi!$C$5:$C$11,MIN(MATCH(MIN(MAX(K21,30),120),Korelasi!$A$5:$A$11,1),6))+(MIN(MAX(K21,30),120)-INDEX(Korelasi!$A$5:$A$11,MIN(MATCH(MIN(MAX(K21,30),120),Korelasi!$A$5:$A$11,1),6)))/(INDEX(Korelasi!$A$5:$A$11,MIN(MATCH(MIN(MAX(K21,30),120),Korelasi!$A$5:$A$11,1),6)+1)-INDEX(Korelasi!$A$5:$A$11,MIN(MATCH(MIN(MAX(K21,30),120),Korelasi!$A$5:$A$11,1),6)))*(INDEX(Korelasi!$C$5:$C$11,MIN(MATCH(MIN(MAX(K21,30),120),Korelasi!$A$5:$A$11,1),6)+1)-INDEX(Korelasi!$C$5:$C$11,MIN(MATCH(MIN(MAX(K21,30),120),Korelasi!$A$5:$A$11,1),6))))) | AF21: =IF(OR(F21="Sand",Y21=0),0,Input!$G$25*(D21/2)^2/(AE21*1E-4*31536000)) | AG21: =MAX(0,MIN(C21,Input!$G$15)-B21) | AH21: =MAX(0,MIN(C21,Input!$G$15)-MAX(B21,$G$8)) | AI21: =MAX(0,MIN(C21,$G$106)-B21)
A22: 10 | B22: 13.5 | C22: 15 | D22: =C22-B22 | E22: =(B22+C22)/2 | F22: Sand | G22: 18 | H22: =IF(E22>$G$5,$G$7,$G$6) | I22: =I21+H22*D22 | J22: =I22-H22*D22/2-10*MAX(E22-$G$5,0) | M22: =IF(K22="","",K22-L22) | N22: 0.747 | O22: =IF(F22="Sand",0,Input!$G$19*G22) | P22: =IF(F22="Sand",27.1+0.3*MIN(Input!$G$20*G22,60)-0.00054*MIN(Input!$G$20*G22,60)^2,MIN(MAX(DEGREES(ASIN(0.8-0.094*LN(MAX(IF(M22="",10,M22),5)))),20),30)) | Q22: =IF(F22="Sand",Input!$G$21*Input!$G$20*G22,Input!$G$22*O22) | R22: =IF(F22="Sand",Input!$G$26,0.5) | S22: =Input!$G$10/2/E22 | T22: =Input!$G$11/2/E22 | U22: =1/(4*PI())*(2*S22*T22*SQRT(S22^2+T22^2+1)/(S22^2+T22^2+1+S22^2*T22^2)*(S22^2+T22^2+2)/(S22^2+T22^2+1)+ATAN2(S22^2+T22^2+1-S22^2*T22^2,2*S22*T22*SQRT(S22^2+T22^2+1))) | V22: =4*Input!$G$9*U22 | W22: =((Input!$G$11/Input!$G$10)*LN((1+SQRT((Input!$G$11/Input!$G$10)^2+1))*SQRT((Input!$G$11/Input!$G$10)^2+(C22/(Input!$G$10/2))^2)/((Input!$G$11/Input!$G$10)*(1+SQRT((Input!$G$11/Input!$G$10)^2+(C22/(Input!$G$10/2))^2+1))))+LN(((Input!$G$11/Input!$G$10)+SQRT((Input!$G$11/Input!$G$10)^2+1))*SQRT(1+(C22/(Input!$G$10/2))^2)/((Input!$G$11/Input!$G$10)+SQRT((Input!$G$11/Input!$G$10)^2+(C22/(Input!$G$10/2))^2+1))))/PI() | X22: =(C22/(Input!$G$10/2))/(2*PI())*ATAN((Input!$G$11/Input!$G$10)/((C22/(Input!$G$10/2))*SQRT((Input!$G$11/Input!$G$10)^2+(C22/(Input!$G$10/2))^2+1))) | Y22: =MAX(0,C22-MAX(B22,$G$8))/D22*IF(V22>=Input!$G$27*J22,1,0) | Z22: =4*Input!$G$9*(Input!$G$10/2)*(1-R22^2)/Q22*((W22-W21)+(1-2*R22)/(1-R22)*(X22-X21))*1000*Y22 | AA22: =IF(F22="Sand",0,0.009*(K22-10)) | AB22: =AA22*Input!$G$23 | AC22: =IF(F22="Sand",0,MAX(O22/Input!$G$24,J22)) | AD22: =IF(F22="Sand",0,1000*D22/(1+N22)*IF(J22+V22<=AC22,AB22*LOG10((J22+V22)/J22),AB22*LOG10(AC22/J22)+AA22*LOG10((J22+V22)/AC22)))*Y22 | AE22: =IF(F22="Sand",0,10^(INDEX(Korelasi!$C$5:$C$11,MIN(MATCH(MIN(MAX(K22,30),120),Korelasi!$A$5:$A$11,1),6))+(MIN(MAX(K22,30),120)-INDEX(Korelasi!$A$5:$A$11,MIN(MATCH(MIN(MAX(K22,30),120),Korelasi!$A$5:$A$11,1),6)))/(INDEX(Korelasi!$A$5:$A$11,MIN(MATCH(MIN(MAX(K22,30),120),Korelasi!$A$5:$A$11,1),6)+1)-INDEX(Korelasi!$A$5:$A$11,MIN(MATCH(MIN(MAX(K22,30),120),Korelasi!$A$5:$A$11,1),6)))*(INDEX(Korelasi!$C$5:$C$11,MIN(MATCH(MIN(MAX(K22,30),120),Korelasi!$A$5:$A$11,1),6)+1)-INDEX(Korelasi!$C$5:$C$11,MIN(MATCH(MIN(MAX(K22,30),120),Korelasi!$A$5:$A$11,1),6))))) | AF22: =IF(OR(F22="Sand",Y22=0),0,Input!$G$25*(D22/2)^2/(AE22*1E-4*31536000)) | AG22: =MAX(0,MIN(C22,Input!$G$15)-B22) | AH22: =MAX(0,MIN(C22,Input!$G$15)-MAX(B22,$G$8)) | AI22: =MAX(0,MIN(C22,$G$106)-B22)
A23: 11 | B23: 15 | C23: 16.5 | D23: =C23-B23 | E23: =(B23+C23)/2 | F23: Sand | G23: 19 | H23: =IF(E23>$G$5,$G$7,$G$6) | I23: =I22+H23*D23 | J23: =I23-H23*D23/2-10*MAX(E23-$G$5,0) | M23: =IF(K23="","",K23-L23) | N23: 0.65 | O23: =IF(F23="Sand",0,Input!$G$19*G23) | P23: =IF(F23="Sand",27.1+0.3*MIN(Input!$G$20*G23,60)-0.00054*MIN(Input!$G$20*G23,60)^2,MIN(MAX(DEGREES(ASIN(0.8-0.094*LN(MAX(IF(M23="",10,M23),5)))),20),30)) | Q23: =IF(F23="Sand",Input!$G$21*Input!$G$20*G23,Input!$G$22*O23) | R23: =IF(F23="Sand",Input!$G$26,0.5) | S23: =Input!$G$10/2/E23 | T23: =Input!$G$11/2/E23 | U23: =1/(4*PI())*(2*S23*T23*SQRT(S23^2+T23^2+1)/(S23^2+T23^2+1+S23^2*T23^2)*(S23^2+T23^2+2)/(S23^2+T23^2+1)+ATAN2(S23^2+T23^2+1-S23^2*T23^2,2*S23*T23*SQRT(S23^2+T23^2+1))) | V23: =4*Input!$G$9*U23 | W23: =((Input!$G$11/Input!$G$10)*LN((1+SQRT((Input!$G$11/Input!$G$10)^2+1))*SQRT((Input!$G$11/Input!$G$10)^2+(C23/(Input!$G$10/2))^2)/((Input!$G$11/Input!$G$10)*(1+SQRT((Input!$G$11/Input!$G$10)^2+(C23/(Input!$G$10/2))^2+1))))+LN(((Input!$G$11/Input!$G$10)+SQRT((Input!$G$11/Input!$G$10)^2+1))*SQRT(1+(C23/(Input!$G$10/2))^2)/((Input!$G$11/Input!$G$10)+SQRT((Input!$G$11/Input!$G$10)^2+(C23/(Input!$G$10/2))^2+1))))/PI() | X23: =(C23/(Input!$G$10/2))/(2*PI())*ATAN((Input!$G$11/Input!$G$10)/((C23/(Input!$G$10/2))*SQRT((Input!$G$11/Input!$G$10)^2+(C23/(Input!$G$10/2))^2+1))) | Y23: =MAX(0,C23-MAX(B23,$G$8))/D23*IF(V23>=Input!$G$27*J23,1,0) | Z23: =4*Input!$G$9*(Input!$G$10/2)*(1-R23^2)/Q23*((W23-W22)+(1-2*R23)/(1-R23)*(X23-X22))*1000*Y23 | AA23: =IF(F23="Sand",0,0.009*(K23-10)) | AB23: =AA23*Input!$G$23 | AC23: =IF(F23="Sand",0,MAX(O23/Input!$G$24,J23)) | AD23: =IF(F23="Sand",0,1000*D23/(1+N23)*IF(J23+V23<=AC23,AB23*LOG10((J23+V23)/J23),AB23*LOG10(AC23/J23)+AA23*LOG10((J23+V23)/AC23)))*Y23 | AE23: =IF(F23="Sand",0,10^(INDEX(Korelasi!$C$5:$C$11,MIN(MATCH(MIN(MAX(K23,30),120),Korelasi!$A$5:$A$11,1),6))+(MIN(MAX(K23,30),120)-INDEX(Korelasi!$A$5:$A$11,MIN(MATCH(MIN(MAX(K23,30),120),Korelasi!$A$5:$A$11,1),6)))/(INDEX(Korelasi!$A$5:$A$11,MIN(MATCH(MIN(MAX(K23,30),120),Korelasi!$A$5:$A$11,1),6)+1)-INDEX(Korelasi!$A$5:$A$11,MIN(MATCH(MIN(MAX(K23,30),120),Korelasi!$A$5:$A$11,1),6)))*(INDEX(Korelasi!$C$5:$C$11,MIN(MATCH(MIN(MAX(K23,30),120),Korelasi!$A$5:$A$11,1),6)+1)-INDEX(Korelasi!$C$5:$C$11,MIN(MATCH(MIN(MAX(K23,30),120),Korelasi!$A$5:$A$11,1),6))))) | AF23: =IF(OR(F23="Sand",Y23=0),0,Input!$G$25*(D23/2)^2/(AE23*1E-4*31536000)) | AG23: =MAX(0,MIN(C23,Input!$G$15)-B23) | AH23: =MAX(0,MIN(C23,Input!$G$15)-MAX(B23,$G$8)) | AI23: =MAX(0,MIN(C23,$G$106)-B23)
A24: 12 | B24: 16.5 | C24: 18 | D24: =C24-B24 | E24: =(B24+C24)/2 | F24: Sand | G24: 12 | H24: =IF(E24>$G$5,$G$7,$G$6) | I24: =I23+H24*D24 | J24: =I24-H24*D24/2-10*MAX(E24-$G$5,0) | M24: =IF(K24="","",K24-L24) | N24: 0.48 | O24: =IF(F24="Sand",0,Input!$G$19*G24) | P24: =IF(F24="Sand",27.1+0.3*MIN(Input!$G$20*G24,60)-0.00054*MIN(Input!$G$20*G24,60)^2,MIN(MAX(DEGREES(ASIN(0.8-0.094*LN(MAX(IF(M24="",10,M24),5)))),20),30)) | Q24: =IF(F24="Sand",Input!$G$21*Input!$G$20*G24,Input!$G$22*O24) | R24: =IF(F24="Sand",Input!$G$26,0.5) | S24: =Input!$G$10/2/E24 | T24: =Input!$G$11/2/E24 | U24: =1/(4*PI())*(2*S24*T24*SQRT(S24^2+T24^2+1)/(S24^2+T24^2+1+S24^2*T24^2)*(S24^2+T24^2+2)/(S24^2+T24^2+1)+ATAN2(S24^2+T24^2+1-S24^2*T24^2,2*S24*T24*SQRT(S24^2+T24^2+1))) | V24: =4*Input!$G$9*U24 | W24: =((Input!$G$11/Input!$G$10)*LN((1+SQRT((Input!$G$11/Input!$G$10)^2+1))*SQRT((Input!$G$11/Input!$G$10)^2+(C24/(Input!$G$10/2))^2)/((Input!$G$11/Input!$G$10)*(1+SQRT((Input!$G$11/Input!$G$10)^2+(C24/(Input!$G$10/2))^2+1))))+LN(((Input!$G$11/Input!$G$10)+SQRT((Input!$G$11/Input!$G$10)^2+1))*SQRT(1+(C24/(Input!$G$10/2))^2)/((Input!$G$11/Input!$G$10)+SQRT((Input!$G$11/Input!$G$10)^2+(C24/(Input!$G$10/2))^2+1))))/PI() | X24: =(C24/(Input!$G$10/2))/(2*PI())*ATAN((Input!$G$11/Input!$G$10)/((C24/(Input!$G$10/2))*SQRT((Input!$G$11/Input!$G$10)^2+(C24/(Input!$G$10/2))^2+1))) | Y24: =MAX(0,C24-MAX(B24,$G$8))/D24*IF(V24>=Input!$G$27*J24,1,0) | Z24: =4*Input!$G$9*(Input!$G$10/2)*(1-R24^2)/Q24*((W24-W23)+(1-2*R24)/(1-R24)*(X24-X23))*1000*Y24 | AA24: =IF(F24="Sand",0,0.009*(K24-10)) | AB24: =AA24*Input!$G$23 | AC24: =IF(F24="Sand",0,MAX(O24/Input!$G$24,J24)) | AD24: =IF(F24="Sand",0,1000*D24/(1+N24)*IF(J24+V24<=AC24,AB24*LOG10((J24+V24)/J24),AB24*LOG10(AC24/J24)+AA24*LOG10((J24+V24)/AC24)))*Y24 | AE24: =IF(F24="Sand",0,10^(INDEX(Korelasi!$C$5:$C$11,MIN(MATCH(MIN(MAX(K24,30),120),Korelasi!$A$5:$A$11,1),6))+(MIN(MAX(K24,30),120)-INDEX(Korelasi!$A$5:$A$11,MIN(MATCH(MIN(MAX(K24,30),120),Korelasi!$A$5:$A$11,1),6)))/(INDEX(Korelasi!$A$5:$A$11,MIN(MATCH(MIN(MAX(K24,30),120),Korelasi!$A$5:$A$11,1),6)+1)-INDEX(Korelasi!$A$5:$A$11,MIN(MATCH(MIN(MAX(K24,30),120),Korelasi!$A$5:$A$11,1),6)))*(INDEX(Korelasi!$C$5:$C$11,MIN(MATCH(MIN(MAX(K24,30),120),Korelasi!$A$5:$A$11,1),6)+1)-INDEX(Korelasi!$C$5:$C$11,MIN(MATCH(MIN(MAX(K24,30),120),Korelasi!$A$5:$A$11,1),6))))) | AF24: =IF(OR(F24="Sand",Y24=0),0,Input!$G$25*(D24/2)^2/(AE24*1E-4*31536000)) | AG24: =MAX(0,MIN(C24,Input!$G$15)-B24) | AH24: =MAX(0,MIN(C24,Input!$G$15)-MAX(B24,$G$8)) | AI24: =MAX(0,MIN(C24,$G$106)-B24)
A25: 13 | B25: 18 | C25: 19.5 | D25: =C25-B25 | E25: =(B25+C25)/2 | F25: Sand | G25: 42 | H25: =IF(E25>$G$5,$G$7,$G$6) | I25: =I24+H25*D25 | J25: =I25-H25*D25/2-10*MAX(E25-$G$5,0) | M25: =IF(K25="","",K25-L25) | N25: 0.65 | O25: =IF(F25="Sand",0,Input!$G$19*G25) | P25: =IF(F25="Sand",27.1+0.3*MIN(Input!$G$20*G25,60)-0.00054*MIN(Input!$G$20*G25,60)^2,MIN(MAX(DEGREES(ASIN(0.8-0.094*LN(MAX(IF(M25="",10,M25),5)))),20),30)) | Q25: =IF(F25="Sand",Input!$G$21*Input!$G$20*G25,Input!$G$22*O25) | R25: =IF(F25="Sand",Input!$G$26,0.5) | S25: =Input!$G$10/2/E25 | T25: =Input!$G$11/2/E25 | U25: =1/(4*PI())*(2*S25*T25*SQRT(S25^2+T25^2+1)/(S25^2+T25^2+1+S25^2*T25^2)*(S25^2+T25^2+2)/(S25^2+T25^2+1)+ATAN2(S25^2+T25^2+1-S25^2*T25^2,2*S25*T25*SQRT(S25^2+T25^2+1))) | V25: =4*Input!$G$9*U25 | W25: =((Input!$G$11/Input!$G$10)*LN((1+SQRT((Input!$G$11/Input!$G$10)^2+1))*SQRT((Input!$G$11/Input!$G$10)^2+(C25/(Input!$G$10/2))^2)/((Input!$G$11/Input!$G$10)*(1+SQRT((Input!$G$11/Input!$G$10)^2+(C25/(Input!$G$10/2))^2+1))))+LN(((Input!$G$11/Input!$G$10)+SQRT((Input!$G$11/Input!$G$10)^2+1))*SQRT(1+(C25/(Input!$G$10/2))^2)/((Input!$G$11/Input!$G$10)+SQRT((Input!$G$11/Input!$G$10)^2+(C25/(Input!$G$10/2))^2+1))))/PI() | X25: =(C25/(Input!$G$10/2))/(2*PI())*ATAN((Input!$G$11/Input!$G$10)/((C25/(Input!$G$10/2))*SQRT((Input!$G$11/Input!$G$10)^2+(C25/(Input!$G$10/2))^2+1))) | Y25: =MAX(0,C25-MAX(B25,$G$8))/D25*IF(V25>=Input!$G$27*J25,1,0) | Z25: =4*Input!$G$9*(Input!$G$10/2)*(1-R25^2)/Q25*((W25-W24)+(1-2*R25)/(1-R25)*(X25-X24))*1000*Y25 | AA25: =IF(F25="Sand",0,0.009*(K25-10)) | AB25: =AA25*Input!$G$23 | AC25: =IF(F25="Sand",0,MAX(O25/Input!$G$24,J25)) | AD25: =IF(F25="Sand",0,1000*D25/(1+N25)*IF(J25+V25<=AC25,AB25*LOG10((J25+V25)/J25),AB25*LOG10(AC25/J25)+AA25*LOG10((J25+V25)/AC25)))*Y25 | AE25: =IF(F25="Sand",0,10^(INDEX(Korelasi!$C$5:$C$11,MIN(MATCH(MIN(MAX(K25,30),120),Korelasi!$A$5:$A$11,1),6))+(MIN(MAX(K25,30),120)-INDEX(Korelasi!$A$5:$A$11,MIN(MATCH(MIN(MAX(K25,30),120),Korelasi!$A$5:$A$11,1),6)))/(INDEX(Korelasi!$A$5:$A$11,MIN(MATCH(MIN(MAX(K25,30),120),Korelasi!$A$5:$A$11,1),6)+1)-INDEX(Korelasi!$A$5:$A$11,MIN(MATCH(MIN(MAX(K25,30),120),Korelasi!$A$5:$A$11,1),6)))*(INDEX(Korelasi!$C$5:$C$11,MIN(MATCH(MIN(MAX(K25,30),120),Korelasi!$A$5:$A$11,1),6)+1)-INDEX(Korelasi!$C$5:$C$11,MIN(MATCH(MIN(MAX(K25,30),120),Korelasi!$A$5:$A$11,1),6))))) | AF25: =IF(OR(F25="Sand",Y25=0),0,Input!$G$25*(D25/2)^2/(AE25*1E-4*31536000)) | AG25: =MAX(0,MIN(C25,Input!$G$15)-B25) | AH25: =MAX(0,MIN(C25,Input!$G$15)-MAX(B25,$G$8)) | AI25: =MAX(0,MIN(C25,$G$106)-B25)
A26: 14 | B26: 19.5 | C26: 21 | D26: =C26-B26 | E26: =(B26+C26)/2 | F26: Sand | G26: 49 | H26: =IF(E26>$G$5,$G$7,$G$6) | I26: =I25+H26*D26 | J26: =I26-H26*D26/2-10*MAX(E26-$G$5,0) | M26: =IF(K26="","",K26-L26) | N26: 0.848 | O26: =IF(F26="Sand",0,Input!$G$19*G26) | P26: =IF(F26="Sand",27.1+0.3*MIN(Input!$G$20*G26,60)-0.00054*MIN(Input!$G$20*G26,60)^2,MIN(MAX(DEGREES(ASIN(0.8-0.094*LN(MAX(IF(M26="",10,M26),5)))),20),30)) | Q26: =IF(F26="Sand",Input!$G$21*Input!$G$20*G26,Input!$G$22*O26) | R26: =IF(F26="Sand",Input!$G$26,0.5) | S26: =Input!$G$10/2/E26 | T26: =Input!$G$11/2/E26 | U26: =1/(4*PI())*(2*S26*T26*SQRT(S26^2+T26^2+1)/(S26^2+T26^2+1+S26^2*T26^2)*(S26^2+T26^2+2)/(S26^2+T26^2+1)+ATAN2(S26^2+T26^2+1-S26^2*T26^2,2*S26*T26*SQRT(S26^2+T26^2+1))) | V26: =4*Input!$G$9*U26 | W26: =((Input!$G$11/Input!$G$10)*LN((1+SQRT((Input!$G$11/Input!$G$10)^2+1))*SQRT((Input!$G$11/Input!$G$10)^2+(C26/(Input!$G$10/2))^2)/((Input!$G$11/Input!$G$10)*(1+SQRT((Input!$G$11/Input!$G$10)^2+(C26/(Input!$G$10/2))^2+1))))+LN(((Input!$G$11/Input!$G$10)+SQRT((Input!$G$11/Input!$G$10)^2+1))*SQRT(1+(C26/(Input!$G$10/2))^2)/((Input!$G$11/Input!$G$10)+SQRT((Input!$G$11/Input!$G$10)^2+(C26/(Input!$G$10/2))^2+1))))/PI() | X26: =(C26/(Input!$G$10/2))/(2*PI())*ATAN((Input!$G$11/Input!$G$10)/((C26/(Input!$G$10/2))*SQRT((Input!$G$11/Input!$G$10)^2+(C26/(Input!$G$10/2))^2+1))) | Y26: =MAX(0,C26-MAX(B26,$G$8))/D26*IF(V26>=Input!$G$27*J26,1,0) | Z26: =4*Input!$G$9*(Input!$G$10/2)*(1-R26^2)/Q26*((W26-W25)+(1-2*R26)/(1-R26)*(X26-X25))*1000*Y26 | AA26: =IF(F26="Sand",0,0.009*(K26-10)) | AB26: =AA26*Input!$G$23 | AC26: =IF(F26="Sand",0,MAX(O26/Input!$G$24,J26)) | AD26: =IF(F26="Sand",0,1000*D26/(1+N26)*IF(J26+V26<=AC26,AB26*LOG10((J26+V26)/J26),AB26*LOG10(AC26/J26)+AA26*LOG10((J26+V26)/AC26)))*Y26 | AE26: =IF(F26="Sand",0,10^(INDEX(Korelasi!$C$5:$C$11,MIN(MATCH(MIN(MAX(K26,30),120),Korelasi!$A$5:$A$11,1),6))+(MIN(MAX(K26,30),120)-INDEX(Korelasi!$A$5:$A$11,MIN(MATCH(MIN(MAX(K26,30),120),Korelasi!$A$5:$A$11,1),6)))/(INDEX(Korelasi!$A$5:$A$11,MIN(MATCH(MIN(MAX(K26,30),120),Korelasi!$A$5:$A$11,1),6)+1)-INDEX(Korelasi!$A$5:$A$11,MIN(MATCH(MIN(MAX(K26,30),120),Korelasi!$A$5:$A$11,1),6)))*(INDEX(Korelasi!$C$5:$C$11,MIN(MATCH(MIN(MAX(K26,30),120),Korelasi!$A$5:$A$11,1),6)+1)-INDEX(Korelasi!$C$5:$C$11,MIN(MATCH(MIN(MAX(K26,30),120),Korelasi!$A$5:$A$11,1),6))))) | AF26: =IF(OR(F26="Sand",Y26=0),0,Input!$G$25*(D26/2)^2/(AE26*1E-4*31536000)) | AG26: =MAX(0,MIN(C26,Input!$G$15)-B26) | AH26: =MAX(0,MIN(C26,Input!$G$15)-MAX(B26,$G$8)) | AI26: =MAX(0,MIN(C26,$G$106)-B26)
A27: 15 | B27: 21 | C27: 22.5 | D27: =C27-B27 | E27: =(B27+C27)/2 | F27: Sand | G27: 49 | H27: =IF(E27>$G$5,$G$7,$G$6) | I27: =I26+H27*D27 | J27: =I27-H27*D27/2-10*MAX(E27-$G$5,0) | M27: =IF(K27="","",K27-L27) | N27: 0.65 | O27: =IF(F27="Sand",0,Input!$G$19*G27) | P27: =IF(F27="Sand",27.1+0.3*MIN(Input!$G$20*G27,60)-0.00054*MIN(Input!$G$20*G27,60)^2,MIN(MAX(DEGREES(ASIN(0.8-0.094*LN(MAX(IF(M27="",10,M27),5)))),20),30)) | Q27: =IF(F27="Sand",Input!$G$21*Input!$G$20*G27,Input!$G$22*O27) | R27: =IF(F27="Sand",Input!$G$26,0.5) | S27: =Input!$G$10/2/E27 | T27: =Input!$G$11/2/E27 | U27: =1/(4*PI())*(2*S27*T27*SQRT(S27^2+T27^2+1)/(S27^2+T27^2+1+S27^2*T27^2)*(S27^2+T27^2+2)/(S27^2+T27^2+1)+ATAN2(S27^2+T27^2+1-S27^2*T27^2,2*S27*T27*SQRT(S27^2+T27^2+1))) | V27: =4*Input!$G$9*U27 | W27: =((Input!$G$11/Input!$G$10)*LN((1+SQRT((Input!$G$11/Input!$G$10)^2+1))*SQRT((Input!$G$11/Input!$G$10)^2+(C27/(Input!$G$10/2))^2)/((Input!$G$11/Input!$G$10)*(1+SQRT((Input!$G$11/Input!$G$10)^2+(C27/(Input!$G$10/2))^2+1))))+LN(((Input!$G$11/Input!$G$10)+SQRT((Input!$G$11/Input!$G$10)^2+1))*SQRT(1+(C27/(Input!$G$10/2))^2)/((Input!$G$11/Input!$G$10)+SQRT((Input!$G$11/Input!$G$10)^2+(C27/(Input!$G$10/2))^2+1))))/PI() | X27: =(C27/(Input!$G$10/2))/(2*PI())*ATAN((Input!$G$11/Input!$G$10)/((C27/(Input!$G$10/2))*SQRT((Input!$G$11/Input!$G$10)^2+(C27/(Input!$G$10/2))^2+1))) | Y27: =MAX(0,C27-MAX(B27,$G$8))/D27*IF(V27>=Input!$G$27*J27,1,0) | Z27: =4*Input!$G$9*(Input!$G$10/2)*(1-R27^2)/Q27*((W27-W26)+(1-2*R27)/(1-R27)*(X27-X26))*1000*Y27 | AA27: =IF(F27="Sand",0,0.009*(K27-10)) | AB27: =AA27*Input!$G$23 | AC27: =IF(F27="Sand",0,MAX(O27/Input!$G$24,J27)) | AD27: =IF(F27="Sand",0,1000*D27/(1+N27)*IF(J27+V27<=AC27,AB27*LOG10((J27+V27)/J27),AB27*LOG10(AC27/J27)+AA27*LOG10((J27+V27)/AC27)))*Y27 | AE27: =IF(F27="Sand",0,10^(INDEX(Korelasi!$C$5:$C$11,MIN(MATCH(MIN(MAX(K27,30),120),Korelasi!$A$5:$A$11,1),6))+(MIN(MAX(K27,30),120)-INDEX(Korelasi!$A$5:$A$11,MIN(MATCH(MIN(MAX(K27,30),120),Korelasi!$A$5:$A$11,1),6)))/(INDEX(Korelasi!$A$5:$A$11,MIN(MATCH(MIN(MAX(K27,30),120),Korelasi!$A$5:$A$11,1),6)+1)-INDEX(Korelasi!$A$5:$A$11,MIN(MATCH(MIN(MAX(K27,30),120),Korelasi!$A$5:$A$11,1),6)))*(INDEX(Korelasi!$C$5:$C$11,MIN(MATCH(MIN(MAX(K27,30),120),Korelasi!$A$5:$A$11,1),6)+1)-INDEX(Korelasi!$C$5:$C$11,MIN(MATCH(MIN(MAX(K27,30),120),Korelasi!$A$5:$A$11,1),6))))) | AF27: =IF(OR(F27="Sand",Y27=0),0,Input!$G$25*(D27/2)^2/(AE27*1E-4*31536000)) | AG27: =MAX(0,MIN(C27,Input!$G$15)-B27) | AH27: =MAX(0,MIN(C27,Input!$G$15)-MAX(B27,$G$8)) | AI27: =MAX(0,MIN(C27,$G$106)-B27)
A28: 16 | B28: 22.5 | C28: 24 | D28: =C28-B28 | E28: =(B28+C28)/2 | F28: Clay | G28: 44 | H28: =IF(E28>$G$5,$G$7,$G$6) | I28: =I27+H28*D28 | J28: =I28-H28*D28/2-10*MAX(E28-$G$5,0) | K28: 31.31 | L28: 20.24 | M28: =IF(K28="","",K28-L28) | N28: 0.662 | O28: =IF(F28="Sand",0,Input!$G$19*G28) | P28: =IF(F28="Sand",27.1+0.3*MIN(Input!$G$20*G28,60)-0.00054*MIN(Input!$G$20*G28,60)^2,MIN(MAX(DEGREES(ASIN(0.8-0.094*LN(MAX(IF(M28="",10,M28),5)))),20),30)) | Q28: =IF(F28="Sand",Input!$G$21*Input!$G$20*G28,Input!$G$22*O28) | R28: =IF(F28="Sand",Input!$G$26,0.5) | S28: =Input!$G$10/2/E28 | T28: =Input!$G$11/2/E28 | U28: =1/(4*PI())*(2*S28*T28*SQRT(S28^2+T28^2+1)/(S28^2+T28^2+1+S28^2*T28^2)*(S28^2+T28^2+2)/(S28^2+T28^2+1)+ATAN2(S28^2+T28^2+1-S28^2*T28^2,2*S28*T28*SQRT(S28^2+T28^2+1))) | V28: =4*Input!$G$9*U28 | W28: =((Input!$G$11/Input!$G$10)*LN((1+SQRT((Input!$G$11/Input!$G$10)^2+1))*SQRT((Input!$G$11/Input!$G$10)^2+(C28/(Input!$G$10/2))^2)/((Input!$G$11/Input!$G$10)*(1+SQRT((Input!$G$11/Input!$G$10)^2+(C28/(Input!$G$10/2))^2+1))))+LN(((Input!$G$11/Input!$G$10)+SQRT((Input!$G$11/Input!$G$10)^2+1))*SQRT(1+(C28/(Input!$G$10/2))^2)/((Input!$G$11/Input!$G$10)+SQRT((Input!$G$11/Input!$G$10)^2+(C28/(Input!$G$10/2))^2+1))))/PI() | X28: =(C28/(Input!$G$10/2))/(2*PI())*ATAN((Input!$G$11/Input!$G$10)/((C28/(Input!$G$10/2))*SQRT((Input!$G$11/Input!$G$10)^2+(C28/(Input!$G$10/2))^2+1))) | Y28: =MAX(0,C28-MAX(B28,$G$8))/D28*IF(V28>=Input!$G$27*J28,1,0) | Z28: =4*Input!$G$9*(Input!$G$10/2)*(1-R28^2)/Q28*((W28-W27)+(1-2*R28)/(1-R28)*(X28-X27))*1000*Y28 | AA28: =IF(F28="Sand",0,0.009*(K28-10)) | AB28: =AA28*Input!$G$23 | AC28: =IF(F28="Sand",0,MAX(O28/Input!$G$24,J28)) | AD28: =IF(F28="Sand",0,1000*D28/(1+N28)*IF(J28+V28<=AC28,AB28*LOG10((J28+V28)/J28),AB28*LOG10(AC28/J28)+AA28*LOG10((J28+V28)/AC28)))*Y28 | AE28: =IF(F28="Sand",0,10^(INDEX(Korelasi!$C$5:$C$11,MIN(MATCH(MIN(MAX(K28,30),120),Korelasi!$A$5:$A$11,1),6))+(MIN(MAX(K28,30),120)-INDEX(Korelasi!$A$5:$A$11,MIN(MATCH(MIN(MAX(K28,30),120),Korelasi!$A$5:$A$11,1),6)))/(INDEX(Korelasi!$A$5:$A$11,MIN(MATCH(MIN(MAX(K28,30),120),Korelasi!$A$5:$A$11,1),6)+1)-INDEX(Korelasi!$A$5:$A$11,MIN(MATCH(MIN(MAX(K28,30),120),Korelasi!$A$5:$A$11,1),6)))*(INDEX(Korelasi!$C$5:$C$11,MIN(MATCH(MIN(MAX(K28,30),120),Korelasi!$A$5:$A$11,1),6)+1)-INDEX(Korelasi!$C$5:$C$11,MIN(MATCH(MIN(MAX(K28,30),120),Korelasi!$A$5:$A$11,1),6))))) | AF28: =IF(OR(F28="Sand",Y28=0),0,Input!$G$25*(D28/2)^2/(AE28*1E-4*31536000)) | AG28: =MAX(0,MIN(C28,Input!$G$15)-B28) | AH28: =MAX(0,MIN(C28,Input!$G$15)-MAX(B28,$G$8)) | AI28: =MAX(0,MIN(C28,$G$106)-B28)
A29: 17 | B29: 24 | C29: 25.5 | D29: =C29-B29 | E29: =(B29+C29)/2 | F29: Clay | G29: 20 | H29: =IF(E29>$G$5,$G$7,$G$6) | I29: =I28+H29*D29 | J29: =I29-H29*D29/2-10*MAX(E29-$G$5,0) | K29: 34.63 | L29: 24.12 | M29: =IF(K29="","",K29-L29) | N29: 0.775 | O29: =IF(F29="Sand",0,Input!$G$19*G29) | P29: =IF(F29="Sand",27.1+0.3*MIN(Input!$G$20*G29,60)-0.00054*MIN(Input!$G$20*G29,60)^2,MIN(MAX(DEGREES(ASIN(0.8-0.094*LN(MAX(IF(M29="",10,M29),5)))),20),30)) | Q29: =IF(F29="Sand",Input!$G$21*Input!$G$20*G29,Input!$G$22*O29) | R29: =IF(F29="Sand",Input!$G$26,0.5) | S29: =Input!$G$10/2/E29 | T29: =Input!$G$11/2/E29 | U29: =1/(4*PI())*(2*S29*T29*SQRT(S29^2+T29^2+1)/(S29^2+T29^2+1+S29^2*T29^2)*(S29^2+T29^2+2)/(S29^2+T29^2+1)+ATAN2(S29^2+T29^2+1-S29^2*T29^2,2*S29*T29*SQRT(S29^2+T29^2+1))) | V29: =4*Input!$G$9*U29 | W29: =((Input!$G$11/Input!$G$10)*LN((1+SQRT((Input!$G$11/Input!$G$10)^2+1))*SQRT((Input!$G$11/Input!$G$10)^2+(C29/(Input!$G$10/2))^2)/((Input!$G$11/Input!$G$10)*(1+SQRT((Input!$G$11/Input!$G$10)^2+(C29/(Input!$G$10/2))^2+1))))+LN(((Input!$G$11/Input!$G$10)+SQRT((Input!$G$11/Input!$G$10)^2+1))*SQRT(1+(C29/(Input!$G$10/2))^2)/((Input!$G$11/Input!$G$10)+SQRT((Input!$G$11/Input!$G$10)^2+(C29/(Input!$G$10/2))^2+1))))/PI() | X29: =(C29/(Input!$G$10/2))/(2*PI())*ATAN((Input!$G$11/Input!$G$10)/((C29/(Input!$G$10/2))*SQRT((Input!$G$11/Input!$G$10)^2+(C29/(Input!$G$10/2))^2+1))) | Y29: =MAX(0,C29-MAX(B29,$G$8))/D29*IF(V29>=Input!$G$27*J29,1,0) | Z29: =4*Input!$G$9*(Input!$G$10/2)*(1-R29^2)/Q29*((W29-W28)+(1-2*R29)/(1-R29)*(X29-X28))*1000*Y29 | AA29: =IF(F29="Sand",0,0.009*(K29-10)) | AB29: =AA29*Input!$G$23 | AC29: =IF(F29="Sand",0,MAX(O29/Input!$G$24,J29)) | AD29: =IF(F29="Sand",0,1000*D29/(1+N29)*IF(J29+V29<=AC29,AB29*LOG10((J29+V29)/J29),AB29*LOG10(AC29/J29)+AA29*LOG10((J29+V29)/AC29)))*Y29 | AE29: =IF(F29="Sand",0,10^(INDEX(Korelasi!$C$5:$C$11,MIN(MATCH(MIN(MAX(K29,30),120),Korelasi!$A$5:$A$11,1),6))+(MIN(MAX(K29,30),120)-INDEX(Korelasi!$A$5:$A$11,MIN(MATCH(MIN(MAX(K29,30),120),Korelasi!$A$5:$A$11,1),6)))/(INDEX(Korelasi!$A$5:$A$11,MIN(MATCH(MIN(MAX(K29,30),120),Korelasi!$A$5:$A$11,1),6)+1)-INDEX(Korelasi!$A$5:$A$11,MIN(MATCH(MIN(MAX(K29,30),120),Korelasi!$A$5:$A$11,1),6)))*(INDEX(Korelasi!$C$5:$C$11,MIN(MATCH(MIN(MAX(K29,30),120),Korelasi!$A$5:$A$11,1),6)+1)-INDEX(Korelasi!$C$5:$C$11,MIN(MATCH(MIN(MAX(K29,30),120),Korelasi!$A$5:$A$11,1),6))))) | AF29: =IF(OR(F29="Sand",Y29=0),0,Input!$G$25*(D29/2)^2/(AE29*1E-4*31536000)) | AG29: =MAX(0,MIN(C29,Input!$G$15)-B29) | AH29: =MAX(0,MIN(C29,Input!$G$15)-MAX(B29,$G$8)) | AI29: =MAX(0,MIN(C29,$G$106)-B29)
A30: 18 | B30: 25.5 | C30: 27 | D30: =C30-B30 | E30: =(B30+C30)/2 | F30: Clay | G30: 21 | H30: =IF(E30>$G$5,$G$7,$G$6) | I30: =I29+H30*D30 | J30: =I30-H30*D30/2-10*MAX(E30-$G$5,0) | K30: 29.665 | L30: 19.806 | M30: =IF(K30="","",K30-L30) | N30: 0.401 | O30: =IF(F30="Sand",0,Input!$G$19*G30) | P30: =IF(F30="Sand",27.1+0.3*MIN(Input!$G$20*G30,60)-0.00054*MIN(Input!$G$20*G30,60)^2,MIN(MAX(DEGREES(ASIN(0.8-0.094*LN(MAX(IF(M30="",10,M30),5)))),20),30)) | Q30: =IF(F30="Sand",Input!$G$21*Input!$G$20*G30,Input!$G$22*O30) | R30: =IF(F30="Sand",Input!$G$26,0.5) | S30: =Input!$G$10/2/E30 | T30: =Input!$G$11/2/E30 | U30: =1/(4*PI())*(2*S30*T30*SQRT(S30^2+T30^2+1)/(S30^2+T30^2+1+S30^2*T30^2)*(S30^2+T30^2+2)/(S30^2+T30^2+1)+ATAN2(S30^2+T30^2+1-S30^2*T30^2,2*S30*T30*SQRT(S30^2+T30^2+1))) | V30: =4*Input!$G$9*U30 | W30: =((Input!$G$11/Input!$G$10)*LN((1+SQRT((Input!$G$11/Input!$G$10)^2+1))*SQRT((Input!$G$11/Input!$G$10)^2+(C30/(Input!$G$10/2))^2)/((Input!$G$11/Input!$G$10)*(1+SQRT((Input!$G$11/Input!$G$10)^2+(C30/(Input!$G$10/2))^2+1))))+LN(((Input!$G$11/Input!$G$10)+SQRT((Input!$G$11/Input!$G$10)^2+1))*SQRT(1+(C30/(Input!$G$10/2))^2)/((Input!$G$11/Input!$G$10)+SQRT((Input!$G$11/Input!$G$10)^2+(C30/(Input!$G$10/2))^2+1))))/PI() | X30: =(C30/(Input!$G$10/2))/(2*PI())*ATAN((Input!$G$11/Input!$G$10)/((C30/(Input!$G$10/2))*SQRT((Input!$G$11/Input!$G$10)^2+(C30/(Input!$G$10/2))^2+1))) | Y30: =MAX(0,C30-MAX(B30,$G$8))/D30*IF(V30>=Input!$G$27*J30,1,0) | Z30: =4*Input!$G$9*(Input!$G$10/2)*(1-R30^2)/Q30*((W30-W29)+(1-2*R30)/(1-R30)*(X30-X29))*1000*Y30 | AA30: =IF(F30="Sand",0,0.009*(K30-10)) | AB30: =AA30*Input!$G$23 | AC30: =IF(F30="Sand",0,MAX(O30/Input!$G$24,J30)) | AD30: =IF(F30="Sand",0,1000*D30/(1+N30)*IF(J30+V30<=AC30,AB30*LOG10((J30+V30)/J30),AB30*LOG10(AC30/J30)+AA30*LOG10((J30+V30)/AC30)))*Y30 | AE30: =IF(F30="Sand",0,10^(INDEX(Korelasi!$C$5:$C$11,MIN(MATCH(MIN(MAX(K30,30),120),Korelasi!$A$5:$A$11,1),6))+(MIN(MAX(K30,30),120)-INDEX(Korelasi!$A$5:$A$11,MIN(MATCH(MIN(MAX(K30,30),120),Korelasi!$A$5:$A$11,1),6)))/(INDEX(Korelasi!$A$5:$A$11,MIN(MATCH(MIN(MAX(K30,30),120),Korelasi!$A$5:$A$11,1),6)+1)-INDEX(Korelasi!$A$5:$A$11,MIN(MATCH(MIN(MAX(K30,30),120),Korelasi!$A$5:$A$11,1),6)))*(INDEX(Korelasi!$C$5:$C$11,MIN(MATCH(MIN(MAX(K30,30),120),Korelasi!$A$5:$A$11,1),6)+1)-INDEX(Korelasi!$C$5:$C$11,MIN(MATCH(MIN(MAX(K30,30),120),Korelasi!$A$5:$A$11,1),6))))) | AF30: =IF(OR(F30="Sand",Y30=0),0,Input!$G$25*(D30/2)^2/(AE30*1E-4*31536000)) | AG30: =MAX(0,MIN(C30,Input!$G$15)-B30) | AH30: =MAX(0,MIN(C30,Input!$G$15)-MAX(B30,$G$8)) | AI30: =MAX(0,MIN(C30,$G$106)-B30) | AJ30: LL/PL/e0 = rata-rata BH
A31: 19 | B31: 27 | C31: 28.5 | D31: =C31-B31 | E31: =(B31+C31)/2 | F31: Sand | G31: 21 | H31: =IF(E31>$G$5,$G$7,$G$6) | I31: =I30+H31*D31 | J31: =I31-H31*D31/2-10*MAX(E31-$G$5,0) | M31: =IF(K31="","",K31-L31) | N31: 0.474 | O31: =IF(F31="Sand",0,Input!$G$19*G31) | P31: =IF(F31="Sand",27.1+0.3*MIN(Input!$G$20*G31,60)-0.00054*MIN(Input!$G$20*G31,60)^2,MIN(MAX(DEGREES(ASIN(0.8-0.094*LN(MAX(IF(M31="",10,M31),5)))),20),30)) | Q31: =IF(F31="Sand",Input!$G$21*Input!$G$20*G31,Input!$G$22*O31) | R31: =IF(F31="Sand",Input!$G$26,0.5) | S31: =Input!$G$10/2/E31 | T31: =Input!$G$11/2/E31 | U31: =1/(4*PI())*(2*S31*T31*SQRT(S31^2+T31^2+1)/(S31^2+T31^2+1+S31^2*T31^2)*(S31^2+T31^2+2)/(S31^2+T31^2+1)+ATAN2(S31^2+T31^2+1-S31^2*T31^2,2*S31*T31*SQRT(S31^2+T31^2+1))) | V31: =4*Input!$G$9*U31 | W31: =((Input!$G$11/Input!$G$10)*LN((1+SQRT((Input!$G$11/Input!$G$10)^2+1))*SQRT((Input!$G$11/Input!$G$10)^2+(C31/(Input!$G$10/2))^2)/((Input!$G$11/Input!$G$10)*(1+SQRT((Input!$G$11/Input!$G$10)^2+(C31/(Input!$G$10/2))^2+1))))+LN(((Input!$G$11/Input!$G$10)+SQRT((Input!$G$11/Input!$G$10)^2+1))*SQRT(1+(C31/(Input!$G$10/2))^2)/((Input!$G$11/Input!$G$10)+SQRT((Input!$G$11/Input!$G$10)^2+(C31/(Input!$G$10/2))^2+1))))/PI() | X31: =(C31/(Input!$G$10/2))/(2*PI())*ATAN((Input!$G$11/Input!$G$10)/((C31/(Input!$G$10/2))*SQRT((Input!$G$11/Input!$G$10)^2+(C31/(Input!$G$10/2))^2+1))) | Y31: =MAX(0,C31-MAX(B31,$G$8))/D31*IF(V31>=Input!$G$27*J31,1,0) | Z31: =4*Input!$G$9*(Input!$G$10/2)*(1-R31^2)/Q31*((W31-W30)+(1-2*R31)/(1-R31)*(X31-X30))*1000*Y31 | AA31: =IF(F31="Sand",0,0.009*(K31-10)) | AB31: =AA31*Input!$G$23 | AC31: =IF(F31="Sand",0,MAX(O31/Input!$G$24,J31)) | AD31: =IF(F31="Sand",0,1000*D31/(1+N31)*IF(J31+V31<=AC31,AB31*LOG10((J31+V31)/J31),AB31*LOG10(AC31/J31)+AA31*LOG10((J31+V31)/AC31)))*Y31 | AE31: =IF(F31="Sand",0,10^(INDEX(Korelasi!$C$5:$C$11,MIN(MATCH(MIN(MAX(K31,30),120),Korelasi!$A$5:$A$11,1),6))+(MIN(MAX(K31,30),120)-INDEX(Korelasi!$A$5:$A$11,MIN(MATCH(MIN(MAX(K31,30),120),Korelasi!$A$5:$A$11,1),6)))/(INDEX(Korelasi!$A$5:$A$11,MIN(MATCH(MIN(MAX(K31,30),120),Korelasi!$A$5:$A$11,1),6)+1)-INDEX(Korelasi!$A$5:$A$11,MIN(MATCH(MIN(MAX(K31,30),120),Korelasi!$A$5:$A$11,1),6)))*(INDEX(Korelasi!$C$5:$C$11,MIN(MATCH(MIN(MAX(K31,30),120),Korelasi!$A$5:$A$11,1),6)+1)-INDEX(Korelasi!$C$5:$C$11,MIN(MATCH(MIN(MAX(K31,30),120),Korelasi!$A$5:$A$11,1),6))))) | AF31: =IF(OR(F31="Sand",Y31=0),0,Input!$G$25*(D31/2)^2/(AE31*1E-4*31536000)) | AG31: =MAX(0,MIN(C31,Input!$G$15)-B31) | AH31: =MAX(0,MIN(C31,Input!$G$15)-MAX(B31,$G$8)) | AI31: =MAX(0,MIN(C31,$G$106)-B31)
