Workbook
Name Excel_BuiltIn_Print_Area_1: #REF!
Name Excel_BuiltIn_Print_Area_1: #REF!
Name Excel_BuiltIn_Print_Area_3: #REF!
Name Excel_BuiltIn_Print_Area_3: #REF!
Name Excel_BuiltIn_Print_Titles_1: #REF!
Name Excel_BuiltIn_Print_Titles_1: #REF!
Name Pile0: #REF!
Name Pile0: #REF!
Name Pile9: #REF!
Name Pile9: #REF!

Sheet Soil Parameter (BH-02)
B2: Borehole | C2: Depth | F2: Cc | G2: Cr | H2: e0 | I2: Pc (kg/cm²) | J2: mv (cm²/kg) | K2: Cv (cm²/s) | M2: Catatan: SI Bora Pulu tidak memiliki uji konsolidasi (oedometer).
B3: BH-02 | C3: 11.4 | D3: - | E3: 12 | F3: 0.119 | G3: 0.024 | H3: 0.645 | I3: 5.79 | J3: 0.0037 | K3: 0.003 | M3: e0 = hasil uji lab (indeks). Cc = 0,009(LL-10) (Terzaghi & Peck 1967); Cr = 0,2Cc;
B4: BH-02 | C4: 15 | D4: - | E4: 15.45 | F4: 0.111 | G4: 0.022 | H4: 0.464 | I4: 2.78 | J4: 0.0033 | K4: 0.003 | M4: Pc = cu/0,22 (Mesri 1975) dgn cu = 5N; mv = 0,435C/[(1+e0)σ'v]; Cv dari LL (NAVFAC DM-7.1).
B5: BH-02 | C5: 23.4 | D5: - | E5: 24 | F5: 0.081 | G5: 0.016 | H5: 0.628 | I5: 5.56 | J5: 0.0016 | K5: 0.003 | M5: Sampel lab berbutir halus BH-02: 3
B28: Depth GWL | C28: 7 | D28: m
B29: Layer | C29: Top | D29: Middle | E29: Bottom | F29: H | G29: N | H29: Soil Type | I29: γ sat | J29: Gs | K29: Wn | L29: e0 | M29: Sr | N29: n | O29: LL | P29: PL | Q29: PI | R29: LI | T29: Cu | U29: Strength | W29: Cc | X29: Cr | Y29: σ | Z29: u | AA29: Po' | AB29: Pc | AC29: OCR | AD29: Consolidation | AE29: mv | AF29: Cv
C30: m | D30: m | E30: m | I30: (kN/m3) | T30: (kPa) | U30: c' (kPa) | V30: ø' (°) | Y30: (kN/m2) | Z30: (kN/m2) | AA30: (kN/m2) | AB30: (kN/m2) | AE30: (cm2/kg) | AF30: (cm2/s)
B32: Layer 1 | C32: 0 | D32: =C32+(E32-C32)/2 | E32: =C33 | F32: =ABS(IF(AND(C32="",E32=""),"",C32-E32)) | G32: 48 | H32: sand | I32: 18.5 | J32: 2.647 | K32: 9.92 | L32: 0.546 | M32: 47.391 | N32: 35.32 | Q32: =IF(OR(O32="",P32=""),"",O32-P32) | R32: =IFERROR((K32-P32)/Q32,"") | U32: 0 | V32: 41.2 | W32: 0 | X32: 0 | Y32: =Y31+(D32-D31)*I32 | Z32: =10*MAX(D32-$C$28,0) | AA32: =Y32-Z32 | AC32: =IFERROR(AB32/AA32,"") | AD32: =IF(AB32="","-",IF(AB32>(AA32),"OC","NC-OC"))
B33: Layer 2 | C33: 7.5 | D33: =C33+(E33-C33)/2 | E33: =C34 | F33: =ABS(IF(AND(C33="",E33=""),"",C33-E33)) | G33: 22 | H33: sand | I33: 18.4 | J33: 2.645 | K33: 18.267 | L33: 0.687 | M33: 69.868 | N33: 40.72 | Q33: =IF(OR(O33="",P33=""),"",O33-P33) | R33: =IFERROR((K33-P33)/Q33,"") | U33: 0 | V33: 33.9 | W33: 0 | X33: 0 | Y33: =Y32+(D33-D32)*I33 | Z33: =10*MAX(D33-$C$28,0) | AA33: =Y33-Z33 | AC33: =IFERROR(AB33/AA33,"") | AD33: =IF(AB33="","-",IF(AB33>(AA33),"OC","NC-OC"))
B34: Layer 3 | C34: 13.5 | D34: =C34+(E34-C34)/2 | E34: =C35 | F34: =ABS(IF(AND(C34="",E34=""),"",C34-E34)) | G34: 47 | H34: sand | I34: 18.4 | J34: 2.645 | K34: 17.54 | L34: 0.565 | M34: 82.05 | N34: 36.1 | Q34: =IF(OR(O34="",P34=""),"",O34-P34) | R34: =IFERROR((K34-P34)/Q34,"") | U34: 0 | V34: 41 | W34: 0 | X34: 0 | Y34: =Y33+(D34-D33)*I34 | Z34: =10*MAX(D34-$C$28,0) | AA34: =Y34-Z34 | AC34: =IFERROR(AB34/AA34,"") | AD34: =IF(AB34="","-",IF(AB34>(AA34),"OC","NC-OC"))
B35: Layer 4 | C35: 15 | D35: =C35+(E35-C35)/2 | E35: =C36 | F35: =ABS(IF(AND(C35="",E35=""),"",C35-E35)) | G35: 24 | H35: sand | I35: 18.4 | J35: 2.669 | K35: 18.434 | L35: 0.684 | M35: 72.363 | N35: 40.62 | Q35: =IF(OR(O35="",P35=""),"",O35-P35) | R35: =IFERROR((K35-P35)/Q35,"") | U35: 0 | V35: 34.5 | W35: 0 | X35: 0 | Y35: =Y34+(D35-D34)*I35 | Z35: =10*MAX(D35-$C$28,0) | AA35: =Y35-Z35 | AC35: =IFERROR(AB35/AA35,"") | AD35: =IF(AB35="","-",IF(AB35>(AA35),"OC","NC-OC"))
B36: Layer 5 | C36: 24 | D36: =C36+(E36-C36)/2 | E36: =C37 | F36: =ABS(IF(AND(C36="",E36=""),"",C36-E36)) | G36: 44 | H36: sand | I36: 18.4 | J36: 2.65 | L36: 0.65 | N36: 39.39 | Q36: =IF(OR(O36="",P36=""),"",O36-P36) | R36: =IFERROR((K36-P36)/Q36,"") | U36: 0 | V36: 40.2 | W36: 0 | X36: 0 | Y36: =Y35+(D36-D35)*I36 | Z36: =10*MAX(D36-$C$28,0) | AA36: =Y36-Z36 | AC36: =IFERROR(AB36/AA36,"") | AD36: =IF(AB36="","-",IF(AB36>(AA36),"OC","NC-OC"))
B37: Layer 6 | C37: 25.5 | D37: =C37+(E37-C37)/2 | E37: =C38 | F37: =ABS(IF(AND(C37="",E37=""),"",C37-E37)) | G37: 26 | H37: sand | I37: 18.4 | J37: 2.686 | K37: 11.5 | L37: 0.73 | M37: 42.305 | N37: 42.2 | Q37: =IF(OR(O37="",P37=""),"",O37-P37) | R37: =IFERROR((K37-P37)/Q37,"") | U37: 0 | V37: 35.1 | W37: 0 | X37: 0 | Y37: =Y36+(D37-D36)*I37 | Z37: =10*MAX(D37-$C$28,0) | AA37: =Y37-Z37 | AC37: =IFERROR(AB37/AA37,"") | AD37: =IF(AB37="","-",IF(AB37>(AA37),"OC","NC-OC"))
B38: Layer 7 | C38: 28.5 | D38: =C38+(E38-C38)/2 | E38: =C39 | F38: =ABS(IF(AND(C38="",E38=""),"",C38-E38)) | G38: 44 | H38: sand | I38: 18.4 | J38: 2.65 | L38: 0.65 | N38: 39.39 | Q38: =IF(OR(O38="",P38=""),"",O38-P38) | R38: =IFERROR((K38-P38)/Q38,"") | U38: 0 | V38: 40.2 | W38: 0 | X38: 0 | Y38: =Y37+(D38-D37)*I38 | Z38: =10*MAX(D38-$C$28,0) | AA38: =Y38-Z38 | AC38: =IFERROR(AB38/AA38,"") | AD38: =IF(AB38="","-",IF(AB38>(AA38),"OC","NC-OC"))
B39: Layer 8 | C39: 33 | D39: =C39+(E39-C39)/2 | E39: =C40 | F39: =ABS(IF(AND(C39="",E39=""),"",C39-E39)) | G39: 26 | H39: sand | I39: 18.4 | J39: 2.65 | L39: 0.65 | N39: 39.39 | Q39: =IF(OR(O39="",P39=""),"",O39-P39) | R39: =IFERROR((K39-P39)/Q39,"") | U39: 0 | V39: 35.1 | W39: 0 | X39: 0 | Y39: =Y38+(D39-D38)*I39 | Z39: =10*MAX(D39-$C$28,0) | AA39: =Y39-Z39 | AC39: =IFERROR(AB39/AA39,"") | AD39: =IF(AB39="","-",IF(AB39>(AA39),"OC","NC-OC"))
B40: Layer 9 | C40: 34.5 | D40: =C40+(E40-C40)/2 | E40: =C41 | F40: =ABS(IF(AND(C40="",E40=""),"",C40-E40)) | G40: 49 | H40: sand | I40: 18.4 | J40: 2.65 | L40: 0.65 | N40: 39.39 | Q40: =IF(OR(O40="",P40=""),"",O40-P40) | R40: =IFERROR((K40-P40)/Q40,"") | U40: 0 | V40: 41.5 | W40: 0 | X40: 0 | Y40: =Y39+(D40-D39)*I40 | Z40: =10*MAX(D40-$C$28,0) | AA40: =Y40-Z40 | AC40: =IFERROR(AB40/AA40,"") | AD40: =IF(AB40="","-",IF(AB40>(AA40),"OC","NC-OC"))
B41: Layer 10 | C41: 48 | D41: =C41+(E41-C41)/2 | E41: =C42 | F41: =ABS(IF(AND(C41="",E41=""),"",C41-E41)) | G41: 29 | H41: sand | I41: 18.4 | J41: 2.65 | L41: 0.65 | N41: 39.39 | Q41: =IF(OR(O41="",P41=""),"",O41-P41) | R41: =IFERROR((K41-P41)/Q41,"") | U41: 0 | V41: 36 | W41: 0 | X41: 0 | Y41: =Y40+(D41-D40)*I41 | Z41: =10*MAX(D41-$C$28,0) | AA41: =Y41-Z41 | AC41: =IFERROR(AB41/AA41,"") | AD41: =IF(AB41="","-",IF(AB41>(AA41),"OC","NC-OC"))
B42: Layer 11 | C42: 54 | D42: =C42+(E42-C42)/2 | E42: =C43 | F42: =ABS(IF(AND(C42="",E42=""),"",C42-E42)) | G42: 50 | H42: sand | I42: 18.4 | J42: 2.65 | L42: 0.65 | N42: 39.39 | Q42: =IF(OR(O42="",P42=""),"",O42-P42) | R42: =IFERROR((K42-P42)/Q42,"") | U42: 0 | V42: 41.8 | W42: 0 | X42: 0 | Y42: =Y41+(D42-D41)*I42 | Z42: =10*MAX(D42-$C$28,0) | AA42: =Y42-Z42 | AC42: =IFERROR(AB42/AA42,"") | AD42: =IF(AB42="","-",IF(AB42>(AA42),"OC","NC-OC"))
B43: Layer 12 | C43: 58.5 | D43: =C43+(E43-C43)/2 | E43: =C44 | F43: =ABS(IF(AND(C43="",E43=""),"",C43-E43)) | G43: 34 | H43: sand | I43: 18.4 | J43: 2.65 | L43: 0.65 | N43: 39.39 | Q43: =IF(OR(O43="",P43=""),"",O43-P43) | R43: =IFERROR((K43-P43)/Q43,"") | U43: 0 | V43: 37.4 | W43: 0 | X43: 0 | Y43: =Y42+(D43-D42)*I43 | Z43: =10*MAX(D43-$C$28,0) | AA43: =Y43-Z43 | AC43: =IFERROR(AB43/AA43,"") | AD43: =IF(AB43="","-",IF(AB43>(AA43),"OC","NC-OC"))
C44: 60 | AF44: =IFERROR(AVERAGE(AF32:AF43),0.001)
B45: Rencana Beban Timbunan | C45: ='BH-02 (H=2 m) - Replacement'!AA101 | D45: kN/m2 | AF45: =AF44
B47: Korelasi: γ = Tabel 5.1 laporan likuefaksi (atas/bawah MAT); cu = 5N; c' = 0,1cu; φ' pasir = Wolff (1989), N60 = 1,083N;
B48: φ' lanau/lempung = sin φ' = 0,8 - 0,094 ln(PI) (Terzaghi, Peck & Mesri 1996); LL/PL/Gs/w/e0 = rata-rata uji lab pada lapisan, bila kosong rata-rata BH.

Sheet BH-02 (H=2 m) - Replacement
F2: PROJECT : | J2: GEOTHERMAL WELLPAD PSPE BORA PULU - SIGI, SULAWESI TENGAH | Y2: Prepared by : | AC2: Date
F3: CLIENTS : | J3: PT EDC PANAS BUMI INDONESIA | Y3: DF | AC3: 46301
F4: LOCATION : | J4: BH-02 (Wellpad A) | Y4: Verified by : | AC4: Date
F5: SHEET : | J5: BEARING CAPACITY AND SLOPE STABILITY ANALYSIS | Y5: BC | AC5: 46301
B7: 1. ANALYSIS OF BEARING CAPACITY OF EMBANKMENT FOUNDATION
B8: The following presents the bearing capacity analysis of the subgrade at the proposed embankment location.
B9: This assessment evaluates whether the subgrade soil is adequate to meet the planned bearing capacity requirements based on
B10: the considered working loads. (ref: Perencanaan Jalan Pendekat Jembatan Pdt-11-2003)
R12: Parameters in the soil bearing capacity analysis
C21: Figure Illustration of embankment bearing capacity
B23: 1.1. PARAMETER
B24: Unit weight parameters
B25: Unit weight of ground water, | X25: gw = | AA25: 10 | AD25: kN/m3
B26: Unit weight of reinforced concrete, | X26: gc1 = | AA26: 25 | AD26: kN/m3
B27: Unit weight of concrete | X27: gc2 = | AA27: 24 | AD27: kN/m3
B28: Unit weight of selected fill material | X28: gg = | AA28: 17 | AD28: kN/m3
B30: Embankment parameters
B31: Unit weight of embankment, | X31: g1 = | AA31: 16.5 | AD31: kN/m3
B32: Effective shear cohesion of embankment, | X32: c1' = | AA32: 10 | AD32: kN/m2
B33: Effective internal friction of embankment, | X33: ϕ1' = | AA33: 25 | AD33: °
B34: Depth of replacement, | X34: Df = | AA34: 0 | AD34: m
B36: Soil parameters
B37: Borehole initial | X37: BH = | AA37: BH-02
B38: CPT initial | X38: S = | AA38: -
B39: Station investigations | X39: STA = | AA39: -
B40: Ground water level | X40: GWL = | AA40: 7 | AD40: m
B42: Table 1. Soil parameters
B43: Layer | D43: Depth | H43: qc kg/cm2 | J43: NSPT | L43: PI (%) | N43: Soil Desc. | Q43: g2 | T43: g2 eff | W43: cu | Z43: c' | AC43: ϕ'
D44: ti (m) | F44: zi (m) | Q44: (kN/m3) | T44: (kN/m3) | W44: (kN/m2) | Z44: (kN/m2) | AC44: ( ° )
F45: 0
B46: 1 | D46: =F46-F45 | F46: 1 | J46: 50 | L46: - | N46: Sand | Q46: 18.5 | T46: =Q46-10 | W46: 0 | Z46: =IF(N46="Sand",1,W46*0.1) | AC46: 41.8 | AG46: Sand
B47: 2 | D47: =F47-F46 | F47: 2 | J47: 50 | L47: - | N47: Sand | Q47: 18.5 | T47: =Q47-10 | W47: 0 | Z47: =IF(N47="Sand",1,W47*0.1) | AC47: 41.8 | AG47: Silt
B48: 3 | D48: =F48-F47 | F48: 3 | J48: 50 | L48: - | N48: Sand | Q48: 18.5 | T48: =Q48-10 | W48: 0 | Z48: =IF(N48="Sand",1,W48*0.1) | AC48: 41.8 | AG48: Clay
B49: 4 | D49: =F49-F48 | F49: 4 | J49: 50 | L49: - | N49: Sand | Q49: 18.5 | T49: =Q49-10 | W49: 0 | Z49: =IF(N49="Sand",1,W49*0.1) | AC49: 41.8
B50: 5 | D50: =F50-F49 | F50: 5 | J50: 41 | L50: - | N50: Sand | Q50: 18.5 | T50: =Q50-10 | W50: 0 | Z50: =IF(N50="Sand",1,W50*0.1) | AC50: 39.4
AA61: Sheet : | AD61: 1
B63: 1.2. SOIL BEARING CAPACITY
B64: The bearing capacity of the subgrade is evaluated using the shallow foundation theory proposed by Terzaghi (1943). For cohesive soils (clay), the analysis focuses on the undrained condition, as it typically represents the most critical state for stability (Principle of Foundation Engineering, Braja M. Das, 2007)
C67: Qu = (Cu x Nc) + (g x D x (Nq - 1))
B68: Where,
...
