Workbook

Sheet Input
C2: PROJECT : | H2: GEOTHERMAL WELLPAD PSPE BORA PULU - SIGI, CENTRAL SULAWESI | X2: Prepared by : | AB2: Date
C3: CLIENT : | H3: PT EDC PANAS BUMI INDONESIA | X3: DF | AB3: 46301
C4: LOCATION : | H4: All boreholes (BH-01 to BH-05) | X4: Verified by : | AB4: Date
C5: SHEET : | H5: DESIGN INPUT & CORRELATIONS | X5: BC | AB5: 46301
C7: 1. DESIGN INPUT
C8: Input cells are shaded blue. All borehole sheets and the summary are calculated from this sheet.
C10: 1.1. Design load
C11: Height of embankment fill | O11: design brief | X11: Hf = | AA11: 2 | AD11: m
C12: Unit weight of compacted fill | O12: assumed | X12: γf = | AA12: 18 | AD12: kN/m³
C13: Uniform surcharge on platform | O13: design brief | X13: qs = | AA13: 100 | AD13: kPa
C14: Total pressure on subgrade | O14: q = Hf·γf + qs | X14: q = | AA14: =$AA$11*$AA$12+$AA$13 -> 136 | AD14: kPa
C15: Width of embankment area | O15: design brief | X15: B = | AA15: 74 | AD15: m
C16: Length of embankment area (L ≥ B) | O16: design brief | X16: L = | AA16: 202 | AD16: m
C18: 1.2. Design criteria
C19: Factor of safety for bearing capacity | O19: SNI 8460:2017 | X19: SF = | AA19: 3 | AD19: -
C20: Depth for averaging shear strength | X20: Hb = | AA20: 5 | AD20: m
C21: Influence depth limit: Δσz / σ'v0 ≥ | X21: ratio = | AA21: 0.2 | AD21: -
C22: Allowable total settlement (assumed) | X22: S all = | AA22: 100 | AD22: mm
C23: Embankment side slope, horizontal : 1 vertical | O23: 1V : nH | X23: n = | AA23: 2 | AD23: -
C24: Required FS against lateral squeeze | O24: FHWA-NHI-06-088 | X24: FS req = | AA24: 1.5 | AD24: -
C25: Upper limit of squeezing factor Nc* (0 = no limit) | O25: optional, conservative | X25: Nc*max = | AA25: 0 | AD25: -
C27: 1.3. Replacement material
C28: Unit weight of compacted granular fill | X28: γr = | AA28: 19 | AD28: kN/m³
C29: Friction angle of granular fill | X29: φ'r = | AA29: 25 | AD29: °
C32: 2. CORRELATIONS (used where no laboratory test is available)
C34: Undrained shear strength, cu = k·N | O34: Stroud (1974) | X34: k = | AA34: 5 | AD34: kPa
C35: Energy correction, N60 = CE·N | O35: liquefaction report | X35: CE = | AA35: 1.083 | AD35: -
C36: Sand modulus, Es = k·N60 | O36: Kulhawy & Mayne (1990) | X36: k = | AA36: 1000 | AD36: kPa
C37: Silt/clay undrained modulus, Eu = k·cu | O37: Bowles (1996) | X37: k = | AA37: 500 | AD37: -
C38: Poisson ratio of sand (drained) | O38: silt/clay undrained ν = 0.5 | X38: ν = | AA38: 0.3 | AD38: -
C39: Recompression ratio Cr / Cc | O39: Das (2019) | X39: Cr/Cc = | AA39: 0.2 | AD39: -
C40: Strength ratio su / σ'p | O40: Mesri (1975) | X40: ratio = | AA40: 0.22 | AD40: -
C41: Time factor for 90 % consolidation | O41: Terzaghi | X41: Tv = | AA41: 0.848 | AD41: -
C43: Compression index Cc = 0.009 (LL - 10) (Terzaghi & Peck, 1967).
C44: Sand friction angle φ' = 27.1 + 0.3 N60 - 0.00054 N60² (Wolff, 1989).
C45: Silt/clay friction angle sin φ' = 0.8 - 0.094 ln(PI) (Terzaghi, Peck & Mesri, 1996), limited to 20° - 30°.
C46: No oedometer test is available; Cc, Cr, σ'p and Cv are correlated values.
C48: 3. COEFFICIENT OF CONSOLIDATION vs LIQUID LIMIT (NAVFAC DM-7.1)
C49: LL | I49: Cv | Q49: log10 Cv
C50: % | I50: cm²/s | Q50: -
...

Sheet Summary
C2: PROJECT : | H2: GEOTHERMAL WELLPAD PSPE BORA PULU - SIGI, CENTRAL SULAWESI | X2: Prepared by : | AB2: Date
C3: CLIENT : | H3: PT EDC PANAS BUMI INDONESIA | X3: DF | AB3: 46301
C4: LOCATION : | H4: All boreholes (BH-01 to BH-05) | X4: Verified by : | AB4: Date
C5: SHEET : | H5: SUMMARY - BEARING CAPACITY AND SETTLEMENT | X5: BC | AB5: 46301
C7: SUMMARY OF BEARING CAPACITY AND SETTLEMENT OF SUBGRADE
C8: ="Load: "&TEXT(Input!$AA$11,"0.0")&" m embankment fill + "&TEXT(Input!$AA$13,"0")&" kPa uniform surcharge → q = "&TEXT(Input!$AA$14,"0")&" kPa; loaded area "&TEXT(Input!$AA$15,"0")&" m × "&TEXT(Input!$AA$16,"0")&" m" -> Load: 2.0 m embankment fill + 100 kPa uniform surcharge → q = 136 kPa; loaded area 74 m × 202 m
C10: Item | M10: Unit | P10: BH-01 | S10: BH-02 | V10: BH-03 | Y10: BH-04 | AB10: BH-05
P11: Wellpad D | S11: Wellpad A | V11: Log Yard | Y11: Wellpad D | AB11: Wellpad A
C12: Silt/clay thickness within 0 - Hb | M12: m | P12: ='BH-01'!$AA$173 -> 3 | S12: ='BH-02'!$AA$173 -> 0 | V12: ='BH-03'!$AA$173 -> 0 | Y12: ='BH-04'!$AA$173 -> 3 | AB12: ='BH-05'!$AA$173 -> 0
C13: Average cu (silt/clay) | M13: kPa | P13: ='BH-01'!$AA$174 -> 25 | S13: ='BH-02'!$AA$174 -> 0 | V13: ='BH-03'!$AA$174 -> 0 | Y13: ='BH-04'!$AA$174 -> 25 | AB13: ='BH-05'!$AA$174 -> 0
C14: Average φ' | M14: ° | P14: ='BH-01'!$AA$175 -> 31.097197 | S14: ='BH-02'!$AA$175 -> 41.521062 | V14: ='BH-03'!$AA$175 -> 31.115962 | Y14: ='BH-04'!$AA$175 -> 34.599761 | AB14: ='BH-05'!$AA$175 -> 41.127766
C15: qall - without improvement | M15: kPa | P15: ='BH-01'!$AA$185 -> 147.33575 | S15: ='BH-02'!$AA$185 -> 16903.564 | V15: ='BH-03'!$AA$185 -> 2792.7422 | Y15: ='BH-04'!$AA$185 -> 147.33575 | AB15: ='BH-05'!$AA$185 -> 15595.999
C16: FS - without improvement | M16: - | P16: ='BH-01'!$AA$187 -> 3.2500534 | S16: ='BH-02'!$AA$187 -> 372.87273 | V16: ='BH-03'!$AA$187 -> 61.604608 | Y16: ='BH-04'!$AA$187 -> 3.2500534 | AB16: ='BH-05'!$AA$187 -> 344.0294
C17: Check - without improvement | P17: ='BH-01'!$X$189 -> qall ≥ q …. OK!! | S17: ='BH-02'!$X$189 -> qall ≥ q …. OK!! | V17: ='BH-03'!$X$189 -> qall ≥ q …. OK!! | Y17: ='BH-04'!$X$189 -> qall ≥ q …. OK!! | AB17: ='BH-05'!$X$189 -> qall ≥ q …. OK!!
C18: Replacement depth Dr | M18: m | P18: ='BH-01'!$AA$23 -> 0.5 | S18: ='BH-02'!$AA$23 -> 0 | V18: ='BH-03'!$AA$23 -> 0 | Y18: ='BH-04'!$AA$23 -> 0.5 | AB18: ='BH-05'!$AA$23 -> 0
C19: qall - design condition | M19: kPa | P19: ='BH-01'!$AA$204 -> 169.39736 | S19: ='BH-02'!$AA$204 -> 16903.564 | V19: ='BH-03'!$AA$204 -> 2792.7422 | Y19: ='BH-04'!$AA$204 -> 169.39736 | AB19: ='BH-05'!$AA$204 -> 15595.999
C20: FS - design condition | M20: - | P20: ='BH-01'!$AA$206 -> 3.7367065 | S20: ='BH-02'!$AA$206 -> 372.87273 | V20: ='BH-03'!$AA$206 -> 61.604608 | Y20: ='BH-04'!$AA$206 -> 3.7367065 | AB20: ='BH-05'!$AA$206 -> 344.0294
C21: Check - design condition | P21: ='BH-01'!$X$208 -> qall ≥ q …. OK!! | S21: ='BH-02'!$X$208 -> qall ≥ q …. OK!! | V21: ='BH-03'!$X$208 -> qall ≥ q …. OK!! | Y21: ='BH-04'!$X$208 -> qall ≥ q …. OK!! | AB21: ='BH-05'!$X$208 -> qall ≥ q …. OK!!
C22: Nc* (thin soft layer) - design | M22: - | P22: ='BH-01'!$AA$196 -> 18.94 | S22: ='BH-02'!$AA$196 -> 5.14 | V22: ='BH-03'!$AA$196 -> 5.14 | Y22: ='BH-04'!$AA$196 -> 18.94 | AB22: ='BH-05'!$AA$196 -> 5.14
C23: FS lateral squeeze - design | M23: - | P23: ='BH-01'!$AA$259 -> 2.9832516 | S23: ='BH-02'!$AA$259 -> n/a | V23: ='BH-03'!$AA$259 -> n/a | Y23: ='BH-04'!$AA$259 -> 2.9832516 | AB23: ='BH-05'!$AA$259 -> n/a
C24: Check lateral squeeze - design | P24: ='BH-01'!$X$260 -> FS ≥ FS req …. OK!! | S24: ='BH-02'!$X$260 -> No soft layer - n/a | V24: ='BH-03'!$X$260 -> No soft layer - n/a | Y24: ='BH-04'!$X$260 -> FS ≥ FS req …. OK!! | AB24: ='BH-05'!$X$260 -> No soft layer - n/a
C25: Allowable fill height (design) | M25: m | P25: ='BH-01'!$AA$207 -> 3.8554089 | S25: ='BH-02'!$AA$207 -> 933.53131 | V25: ='BH-03'!$AA$207 -> 149.59679 | Y25: ='BH-04'!$AA$207 -> 3.8554089 | AB25: ='BH-05'!$AA$207 -> 860.88885
C26: qa for 25 mm (granular soil) | M26: kPa | P26: ='BH-01'!$AA$225 -> 267.987 | S26: ='BH-02'!$AA$225 -> 731.00898 | V26: ='BH-03'!$AA$225 -> 189.07972 | Y26: ='BH-04'!$AA$225 -> 729.52016 | AB26: ='BH-05'!$AA$225 -> 708.67673
C27: Immediate settlement Si | M27: mm | P27: ='BH-01'!$AA$345 -> 93.56296 | S27: ='BH-02'!$AA$345 -> 130.95981 | V27: ='BH-03'!$AA$345 -> 138.7165 | Y27: ='BH-04'!$AA$345 -> 61.540226 | AB27: ='BH-05'!$AA$345 -> 104.5857
C28: Consolidation settlement Sc | M28: mm | P28: ='BH-01'!$AA$484 -> 139.1874 | S28: ='BH-02'!$AA$484 -> 0 | V28: ='BH-03'!$AA$484 -> 67.075646 | Y28: ='BH-04'!$AA$484 -> 178.41664 | AB28: ='BH-05'!$AA$484 -> 6.6895547
C29: Time for 90 % consolidation | M29: year | P29: ='BH-01'!$AA$485 -> 0.1225617 | S29: ='BH-02'!$AA$485 -> 0 | V29: ='BH-03'!$AA$485 -> 0.078514286 | Y29: ='BH-04'!$AA$485 -> 0.1225617 | AB29: ='BH-05'!$AA$485 -> 0.050418569
C30: Total settlement S = Si + Sc | M30: mm | P30: ='BH-01'!$AA$522 -> 232.75036 | S30: ='BH-02'!$AA$522 -> 130.95981 | V30: ='BH-03'!$AA$522 -> 205.79215 | Y30: ='BH-04'!$AA$522 -> 239.95686 | AB30: ='BH-05'!$AA$522 -> 111.27525
C32: NOTES
C33: 1. Bearing capacity: undrained (cu·Nc) where silt/clay exists within 0 - Hb; drained (Vesic) for granular soil.
C34: For a wide loaded area the Nγ term gives a very large drained capacity, i.e. shear failure does not govern;
C35: settlement governs the design.
C36: 2. Granular soil: (a) drained bearing capacity with φ' from N-SPT; (b) allowable pressure for 25 mm settlement
C37: (Meyerhof/Bowles); (c) sand is assumed to undergo immediate (elastic) settlement only - no primary
C38: consolidation; (d) loose saturated sand: add post-liquefaction settlement for the seismic case.
X73: Sheet : | AB73: 1

Sheet BH-01
C2: PROJECT : | H2: GEOTHERMAL WELLPAD PSPE BORA PULU - SIGI, CENTRAL SULAWESI | X2: Prepared by : | AB2: Date
C3: CLIENT : | H3: PT EDC PANAS BUMI INDONESIA | X3: DF | AB3: 46301
C4: LOCATION : | H4: BH-01 (Wellpad D) | X4: Verified by : | AB4: Date
C5: SHEET : | H5: BEARING CAPACITY AND SETTLEMENT OF SUBGRADE | X5: BC | AB5: 46301
C7: 1. GENERAL
C8: This sheet evaluates the bearing capacity, lateral squeeze, immediate settlement and primary consolidation settlement
C9: of the subgrade below the wellpad embankment (2 m fill + 100 kPa uniform surcharge) at the borehole location.
C11: 1.1. Load and loaded area
C12: Height of embankment fill | X12: Hf = | AA12: =Input!$AA$11 -> 2 | AD12: m
C13: Uniform surcharge | X13: qs = | AA13: =Input!$AA$13 -> 100 | AD13: kPa
C14: Total pressure on subgrade | O14: q = Hf·γf + qs | X14: q = | AA14: =Input!$AA$14 -> 136 | AD14: kPa
C15: Loaded area (assumed) | O15: B × L | X15: B = | AA15: =Input!$AA$15 -> 74 | AD15: m
X16: L = | AA16: =Input!$AA$16 -> 202 | AD16: m
C17: Embankment side slope | O17: 1V : nH | X17: n = | AA17: =Input!$AA$23 -> 2 | AD17: -
C19: 1.2. Borehole data
C20: Design groundwater level (below ground) | X20: GWL = | AA20: 9 | AD20: m
C21: Unit weight above GWL | X21: γ = | AA21: 17.8 | AD21: kN/m³
C22: Unit weight below GWL | X22: γsat = | AA22: 19.2 | AD22: kN/m³
C23: Replacement depth (design condition) | O23: 0 = no improvement | X23: Dr = | AA23: 1.5 | AD23: m
C41: Figure 1. Typical cross-section of the wellpad embankment, design load and subsoil
X73: Sheet : | AB73: 1
C74: PROJECT : | H74: GEOTHERMAL WELLPAD PSPE BORA PULU - SIGI, CENTRAL SULAWESI | X74: Prepared by : | AB74: Date
C75: CLIENT : | H75: PT EDC PANAS BUMI INDONESIA | X75: DF | AB75: 46301
C76: LOCATION : | H76: BH-01 (Wellpad D) | X76: Verified by : | AB76: Date
C77: SHEET : | H77: BEARING CAPACITY AND SETTLEMENT OF SUBGRADE | X77: BC | AB77: 46301
C79: 2. SOIL PARAMETERS
C80: Table 1. Soil parameters of BH-01 (sub-layers = SPT intervals) | AI80: Helper calculation per sub-layer (not printed)
C81: No | E81: Top | H81: Bottom | K81: Soil | N81: N-SPT | Q81: γ | T81: LL | V81: PI | X81: e0 | Z81: cu | AC81: φ' | AI81: top | AJ81: bot | AK81: h | AL81: z | AM81: typ | AN81: N | AO81: g | AP81: sv | AQ81: s0 | AR81: LL | AS81: PL | AT81: PI | AU81: e0 | AV81: cu | AW81: phi | AX81: E | AY81: nu | AZ81: m | BA81: n | BB81: I | BC81: ds | BD81: F1 | BE81: F2 | BF81: keep | BG81: Si | BH81: Cc | BI81: Cr | BJ81: sp | BK81: Sc | BL81: Cv | BM81: t90 | BN81: hb0 | BO81: hbr | BP81: St | BQ81: ket
E82: m | H82: m | Q82: kN/m³ | T82: % | V82: % | X82: - | Z82: kPa | AC82: °
C83: 1 | E83: =AI83 -> 0 | H83: =AJ83 -> 1.5 | K83: =AM83 -> Clay | N83: =AN83 -> 5 | Q83: =AO83 -> 17.8 | T83: =IF(AR83="","-",AR83) -> 29.665 | V83: =IF(AT83="","-",AT83) -> 9.859 | X83: =AU83 -> 0.681 | Z83: =AV83 -> 25 | AC83: =AW83 -> 30 | AI83: 0 | AJ83: 1.5 | AK83: =AJ83-AI83 -> 1.5 | AL83: =(AI83+AJ83)/2 -> 0.75 | AM83: Clay | AN83: 5 | AO83: =IF(AL83>$AA$20,$AA$22,$AA$21) -> 17.8 | AP83: =AO83*AK83 -> 26.7 | AQ83: =AP83-AO83*AK83/2-10*MAX(AL83-$AA$20,0) -> 13.35 | AR83: 29.665 | AS83: 19.806 | AT83: =IF(AR83="","",AR83-AS83) -> 9.859 | AU83: 0.681 | AV83: =IF(AM83="Sand",0,Input!$AA$34*AN83) -> 25 | AW83: =IF(AM83="Sand",27.1+0.3*MIN(Input!$AA$35*AN83,60)-0.00054*MIN(Input!$AA$35*AN83,60)^2,MIN(MAX(DEGREES(ASIN(0.8-0.094*LN(MAX(IF(AT83="",10,AT83),5)))),20),30)) -> 30 | AX83: =IF(AM83="Sand",Input!$AA$36*Input!$AA$35*AN83,Input!$AA$37*AV83) -> 12500 | AY83: =IF(AM83="Sand",Input!$AA$38,0.5) -> 0.5 | AZ83: =Input!$AA$15/2/AL83 -> 49.333333 | BA83: =Input!$AA$16/2/AL83 -> 134.66667 | BB83: =1/(4*PI())*(2*AZ83*BA83*SQRT(AZ83^2+BA83^2+1)/(AZ83^2+BA83^2+1+AZ83^2*BA83^2)*(AZ83^2+BA83^2+2)/(AZ83^2+BA83^2+1)+ATAN2(AZ83^2+BA83^2+1-AZ83^2*BA83^2,2*AZ83*BA83*SQRT(AZ83^2+BA83^2+1))) -> 0.2499991 | BC83: =4*Input!$AA$14*BB83 -> 135.99951 | BD83: =((Input!$AA$16/Input!$AA$15)*LN((1+SQRT((Input!$AA$16/Input!$AA$15)^2+1))*SQRT((Input!$AA$16/Input!$AA$15)^2+(AJ83/(Input!$AA$15/2))^2)/((Input!$AA$16/Input!$AA$15)*(1+SQRT((Input!$AA$16/Input!$AA$15)^2+(AJ83/(Input!$AA$15/2))^2+1))))+LN(((Input!$AA$16/Input!$AA$15)+SQRT((Input!$AA$16/Input!$AA$15)^2+1))*SQRT(1+(AJ83/(Input!$AA$15/2))^2)/((Input!$AA$16/Input!$AA$15)+SQRT((Input!$AA$16/Input!$AA$15)^2+(AJ83/(Input!$AA$15/2))^2+1))))/PI() -> 0.00027835774 | BE83: =(AJ83/(Input!$AA$15/2))/(2*PI())*ATAN((Input!$AA$16/Input!$AA$15)/((AJ83/(Input!$AA$15/2))*SQRT((Input!$AA$16/Input!$AA$15)^2+(AJ83/(Input!$AA$15/2))^2+1))) -> 0.0098567045 | BF83: =MAX(0,AJ83-MAX(AI83,$AA$23))/AK83*IF(BC83>=Input!$AA$21*AQ83,1,0) -> 0.66666667 | BG83: =4*Input!$AA$14*(Input!$AA$15/2)*(1-AY83^2)/AX83*((BD83-0)+(1-2*AY83)/(1-AY83)*(BE83-0))*1000*BF83 -> 0.22411138 | BH83: =IF(AM83="Sand",0,0.009*(AR83-10)) -> 0.176985 | BI83: =BH83*Input!$AA$39 -> 0.035397 | BJ83: =IF(AM83="Sand",0,MAX(AV83/Input!$AA$40,AQ83)) -> 113.63636 | BK83: =IF(AM83="Sand",0,1000*AK83/(1+AU83)*IF(AQ83+BC83<=BJ83,BI83*LOG10((AQ83+BC83)/AQ83),BI83*LOG10(BJ83/AQ83)+BH83*LOG10((AQ83+BC83)/BJ83)))*BF83 -> 32.079841 | BL83: =IF(AM83="Sand",0,10^(INDEX(Input!$Q$51:$Q$57,MIN(MATCH(MIN(MAX(AR83,30),120),Input!$C$51:$C$57,1),6))+(MIN(MAX(AR83,30),120)-INDEX(Input!$C$51:$C$57,MIN(MATCH(MIN(MAX(AR83,30),120),Input!$C$51:$C$57,1),6)))/(INDEX(Input!$C$51:$C$57,MIN(MATCH(MIN(MAX(AR83,30),120),Input!$C$51:$C$57,1),6)+1)-INDEX(Input!$C$51:$C$57,MIN(MATCH(MIN(MAX(AR83,30),120),Input!$C$51:$C$57,1),6)))*(INDEX(Input!$Q$51:$Q$57,MIN(MATCH(MIN(MAX(AR83,30),120),Input!$C$51:$C$57,1),6)+1)-INDEX(Input!$Q$51:$Q$57,MIN(MATCH(MIN(MAX(AR83,30),120),Input!$C$51:$C$57,1),6))))) -> 0.003 | BM83: =IF(OR(AM83="Sand",BF83=0),0,Input!$AA$41*(AK83/2)^2/(BL83*0.0001*31536000)) -> 0.050418569 | BN83: =MAX(0,MIN(AJ83,Input!$AA$20)-AI83) -> 1.5 | BO83: =MAX(0,MIN(AJ83,Input!$AA$20)-MAX(AI83,$AA$23)) -> 1 | BP83: =BG83+BK83 -> 32.303952 | BQ83: 0-1.5 m not tested: N of next layer; LL/PL/e0 = borehole average
C84: 2 | E84: =AI84 -> 1.5 | H84: =AJ84 -> 3 | K84: =AM84 -> Clay | N84: =AN84 -> 5 | Q84: =AO84 -> 17.8 | T84: =IF(AR84="","-",AR84) -> 29.665 | V84: =IF(AT84="","-",AT84) -> 9.859 | X84: =AU84 -> 0.952 | Z84: =AV84 -> 25 | AC84: =AW84 -> 30 | AI84: 1.5 | AJ84: 3 | AK84: =AJ84-AI84 -> 1.5 | AL84: =(AI84+AJ84)/2 -> 2.25 | AM84: Clay | AN84: 5 | AO84: =IF(AL84>$AA$20,$AA$22,$AA$21) -> 17.8 | AP84: =AP83+AO84*AK84 -> 53.4 | AQ84: =AP84-AO84*AK84/2-10*MAX(AL84-$AA$20,0) -> 40.05 | AR84: 29.665 | AS84: 19.806 | AT84: =IF(AR84="","",AR84-AS84) -> 9.859 | AU84: 0.952 | AV84: =IF(AM84="Sand",0,Input!$AA$34*AN84) -> 25 | AW84: =IF(AM84="Sand",27.1+0.3*MIN(Input!$AA$35*AN84,60)-0.00054*MIN(Input!$AA$35*AN84,60)^2,MIN(MAX(DEGREES(ASIN(0.8-0.094*LN(MAX(IF(AT84="",10,AT84),5)))),20),30)) -> 30 | AX84: =IF(AM84="Sand",Input!$AA$36*Input!$AA$35*AN84,Input!$AA$37*AV84) -> 12500 | AY84: =IF(AM84="Sand",Input!$AA$38,0.5) -> 0.5 | AZ84: =Input!$AA$15/2/AL84 -> 16.444444 | BA84: =Input!$AA$16/2/AL84 -> 44.888889 | BB84: =1/(4*PI())*(2*AZ84*BA84*SQRT(AZ84^2+BA84^2+1)/(AZ84^2+BA84^2+1+AZ84^2*BA84^2)*(AZ84^2+BA84^2+2)/(AZ84^2+BA84^2+1)+ATAN2(AZ84^2+BA84^2+1-AZ84^2*BA84^2,2*AZ84*BA84*SQRT(AZ84^2+BA84^2+1))) -> 0.24997579 | BC84: =4*Input!$AA$14*BB84 -> 135.98683 | BD84: =((Input!$AA$16/Input!$AA$15)*LN((1+SQRT((Input!$AA$16/Input!$AA$15)^2+1))*SQRT((Input!$AA$16/Input!$AA$15)^2+(AJ84/(Input!$AA$15/2))^2)/((Input!$AA$16/Input!$AA$15)*(1+SQRT((Input!$AA$16/Input!$AA$15)^2+(AJ84/(Input!$AA$15/2))^2+1))))+LN(((Input!$AA$16/Input!$AA$15)+SQRT((Input!$AA$16/Input!$AA$15)^2+1))*SQRT(1+(AJ84/(Input!$AA$15/2))^2)/((Input!$AA$16/Input!$AA$15)+SQRT((Input!$AA$16/Input!$AA$15)^2+(AJ84/(Input!$AA$15/2))^2+1))))/PI() -> 0.0011108169 | BE84: =(AJ84/(Input!$AA$15/2))/(2*PI())*ATAN((Input!$AA$16/Input!$AA$15)/((AJ84/(Input!$AA$15/2))*SQRT((Input!$AA$16/Input!$AA$15)^2+(AJ84/(Input!$AA$15/2))^2+1))) -> 0.019158291 | BF84: =MAX(0,AJ84-MAX(AI84,$AA$23))/AK84*IF(BC84>=Input!$AA$21*AQ84,1,0) -> 1 | BG84: =4*Input!$AA$14*(Input!$AA$15/2)*(1-AY84^2)/AX84*((BD84-BD83)+(1-2*AY84)/(1-AY84)*(BE84-BE83))*1000*BF84 -> 1.0053442 | BH84: =IF(AM84="Sand",0,0.009*(AR84-10)) -> 0.176985 | BI84: =BH84*Input!$AA$39 -> 0.035397 | BJ84: =IF(AM84="Sand",0,MAX(AV84/Input!$AA$40,AQ84)) -> 113.63636 | BK84: =IF(AM84="Sand",0,1000*AK84/(1+AU84)*IF(AQ84+BC84<=BJ84,BI84*LOG10((AQ84+BC84)/AQ84),BI84*LOG10(BJ84/AQ84)+BH84*LOG10((AQ84+BC84)/BJ84)))*BF84 -> 38.171799 | BL84: =IF(AM84="Sand",0,10^(INDEX(Input!$Q$51:$Q$57,MIN(MATCH(MIN(MAX(AR84,30),120),Input!$C$51:$C$57,1),6))+(MIN(MAX(AR84,30),120)-INDEX(Input!$C$51:$C$57,MIN(MATCH(MIN(MAX(AR84,30),120),Input!$C$51:$C$57,1),6)))/(INDEX(Input!$C$51:$C$57,MIN(MATCH(MIN(MAX(AR84,30),120),Input!$C$51:$C$57,1),6)+1)-INDEX(Input!$C$51:$C$57,MIN(MATCH(MIN(MAX(AR84,30),120),Input!$C$51:$C$57,1),6)))*(INDEX(Input!$Q$51:$Q$57,MIN(MATCH(MIN(MAX(AR84,30),120),Input!$C$51:$C$57,1),6)+1)-INDEX(Input!$Q$51:$Q$57,MIN(MATCH(MIN(MAX(AR84,30),120),Input!$C$51:$C$57,1),6))))) -> 0.003 | BM84: =IF(OR(AM84="Sand",BF84=0),0,Input!$AA$41*(AK84/2)^2/(BL84*0.0001*31536000)) -> 0.050418569 | BN84: =MAX(0,MIN(AJ84,Input!$AA$20)-AI84) -> 1.5 | BO84: =MAX(0,MIN(AJ84,Input!$AA$20)-MAX(AI84,$AA$23)) -> 1.5 | BP84: =BG84+BK84 -> 39.177143 | BQ84: LL/PL/e0 = borehole average
C85: 3 | E85: =AI85 -> 3 | H85: =AJ85 -> 5.5 | K85: =AM85 -> Sand | N85: =AN85 -> 18 | Q85: =AO85 -> 17.8 | T85: =IF(AR85="","-",AR85) -> - | V85: =IF(AT85="","-",AT85) -> - | X85: =AU85 -> 0.759 | Z85: =AV85 -> 0 | AC85: =AW85 -> 32.742991 | AI85: 3 | AJ85: 5.5 | AK85: =AJ85-AI85 -> 2.5 | AL85: =(AI85+AJ85)/2 -> 4.25 | AM85: Sand | AN85: 18 | AO85: =IF(AL85>$AA$20,$AA$22,$AA$21) -> 17.8 | AP85: =AP84+AO85*AK85 -> 97.9 | AQ85: =AP85-AO85*AK85/2-10*MAX(AL85-$AA$20,0) -> 75.65 | AT85: =IF(AR85="","",AR85-AS85) | AU85: 0.759 | AV85: =IF(AM85="Sand",0,Input!$AA$34*AN85) -> 0 | AW85: =IF(AM85="Sand",27.1+0.3*MIN(Input!$AA$35*AN85,60)-0.00054*MIN(Input!$AA$35*AN85,60)^2,MIN(MAX(DEGREES(ASIN(0.8-0.094*LN(MAX(IF(AT85="",10,AT85),5)))),20),30)) -> 32.742991 | AX85: =IF(AM85="Sand",Input!$AA$36*Input!$AA$35*AN85,Input!$AA$37*AV85) -> 19494 | AY85: =IF(AM85="Sand",Input!$AA$38,0.5) -> 0.3 | AZ85: =Input!$AA$15/2/AL85 -> 8.7058824 | BA85: =Input!$AA$16/2/AL85 -> 23.764706 | BB85: =1/(4*PI())*(2*AZ85*BA85*SQRT(AZ85^2+BA85^2+1)/(AZ85^2+BA85^2+1+AZ85^2*BA85^2)*(AZ85^2+BA85^2+2)/(AZ85^2+BA85^2+1)+ATAN2(AZ85^2+BA85^2+1-AZ85^2*BA85^2,2*AZ85*BA85*SQRT(AZ85^2+BA85^2+1))) -> 0.24983868 | BC85: =4*Input!$AA$14*BB85 -> 135.91224 | BD85: =((Input!$AA$16/Input!$AA$15)*LN((1+SQRT((Input!$AA$16/Input!$AA$15)^2+1))*SQRT((Input!$AA$16/Input!$AA$15)^2+(AJ85/(Input!$AA$15/2))^2)/((Input!$AA$16/Input!$AA$15)*(1+SQRT((Input!$AA$16/Input!$AA$15)^2+(AJ85/(Input!$AA$15/2))^2+1))))+LN(((Input!$AA$16/Input!$AA$15)+SQRT((Input!$AA$16/Input!$AA$15)^2+1))*SQRT(1+(AJ85/(Input!$AA$15/2))^2)/((Input!$AA$16/Input!$AA$15)+SQRT((Input!$AA$16/Input!$AA$15)^2+(AJ85/(Input!$AA$15/2))^2+1))))/PI() -> 0.0037062835 | BE85: =(AJ85/(Input!$AA$15/2))/(2*PI())*ATAN((Input!$AA$16/Input!$AA$15)/((AJ85/(Input!$AA$15/2))*SQRT((Input!$AA$16/Input!$AA$15)^2+(AJ85/(Input!$AA$15/2))^2+1))) -> 0.033442908 | BF85: =MAX(0,AJ85-MAX(AI85,$AA$23))/AK85*IF(BC85>=Input!$AA$21*AQ85,1,0) -> 1 | BG85: =4*Input!$AA$14*(Input!$AA$15/2)*(1-AY85^2)/AX85*((BD85-BD84)+(1-2*AY85)/(1-AY85)*(BE85-BE84))*1000*BF85 -> 10.10827 | BH85: =IF(AM85="Sand",0,0.009*(AR85-10)) -> 0 | BI85: =BH85*Input!$AA$39 -> 0 | BJ85: =IF(AM85="Sand",0,MAX(AV85/Input!$AA$40,AQ85)) -> 0 | BK85: =IF(AM85="Sand",0,1000*AK85/(1+AU85)*IF(AQ85+BC85<=BJ85,BI85*LOG10((AQ85+BC85)/AQ85),BI85*LOG10(BJ85/AQ85)+BH85*LOG10((AQ85+BC85)/BJ85)))*BF85 -> 0 | BL85: =IF(AM85="Sand",0,10^(INDEX(Input!$Q$51:$Q$57,MIN(MATCH(MIN(MAX(AR85,30),120),Input!$C$51:$C$57,1),6))+(MIN(MAX(AR85,30),120)-INDEX(Input!$C$51:$C$57,MIN(MATCH(MIN(MAX(AR85,30),120),Input!$C$51:$C$57,1),6)))/(INDEX(Input!$C$51:$C$57,MIN(MATCH(MIN(MAX(AR85,30),120),Input!$C$51:$C$57,1),6)+1)-INDEX(Input!$C$51:$C$57,MIN(MATCH(MIN(MAX(AR85,30),120),Input!$C$51:$C$57,1),6)))*(INDEX(Input!$Q$51:$Q$57,MIN(MATCH(MIN(MAX(AR85,30),120),Input!$C$51:$C$57,1),6)+1)-INDEX(Input!$Q$51:$Q$57,MIN(MATCH(MIN(MAX(AR85,30),120),Input!$C$51:$C$57,1),6))))) -> 0 | BM85: =IF(OR(AM85="Sand",BF85=0),0,Input!$AA$41*(AK85/2)^2/(BL85*0.0001*31536000)) -> 0 | BN85: =MAX(0,MIN(AJ85,Input!$AA$20)-AI85) -> 2 | BO85: =MAX(0,MIN(AJ85,Input!$AA$20)-MAX(AI85,$AA$23)) -> 2 | BP85: =BG85+BK85 -> 10.10827
C86: 4 | E86: =AI86 -> 5.5 | H86: =AJ86 -> 6 | K86: =AM86 -> Silt | N86: =AN86 -> 28 | Q86: =AO86 -> 17.8 | T86: =IF(AR86="","-",AR86) -> 29.665 | V86: =IF(AT86="","-",AT86) -> 9.859 | X86: =AU86 -> 0.681 | Z86: =AV86 -> 140 | AC86: =AW86 -> 30 | AI86: 5.5 | AJ86: 6 | AK86: =AJ86-AI86 -> 0.5 | AL86: =(AI86+AJ86)/2 -> 5.75 | AM86: Silt | AN86: 28 | AO86: =IF(AL86>$AA$20,$AA$22,$AA$21) -> 17.8 | AP86: =AP85+AO86*AK86 -> 106.8 | AQ86: =AP86-AO86*AK86/2-10*MAX(AL86-$AA$20,0) -> 102.35 | AR86: 29.665 | AS86: 19.806 | AT86: =IF(AR86="","",AR86-AS86) -> 9.859 | AU86: 0.681 | AV86: =IF(AM86="Sand",0,Input!$AA$34*AN86) -> 140 | AW86: =IF(AM86="Sand",27.1+0.3*MIN(Input!$AA$35*AN86,60)-0.00054*MIN(Input!$AA$35*AN86,60)^2,MIN(MAX(DEGREES(ASIN(0.8-0.094*LN(MAX(IF(AT86="",10,AT86),5)))),20),30)) -> 30 | AX86: =IF(AM86="Sand",Input!$AA$36*Input!$AA$35*AN86,Input!$AA$37*AV86) -> 70000 | AY86: =IF(AM86="Sand",Input!$AA$38,0.5) -> 0.5 | AZ86: =Input!$AA$15/2/AL86 -> 6.4347826 | BA86: =Input!$AA$16/2/AL86 -> 17.565217 | BB86: =1/(4*PI())*(2*AZ86*BA86*SQRT(AZ86^2+BA86^2+1)/(AZ86^2+BA86^2+1+AZ86^2*BA86^2)*(AZ86^2+BA86^2+2)/(AZ86^2+BA86^2+1)+ATAN2(AZ86^2+BA86^2+1-AZ86^2*BA86^2,2*AZ86*BA86*SQRT(AZ86^2+BA86^2+1))) -> 0.24960554 | BC86: =4*Input!$AA$14*BB86 -> 135.78541 | BD86: =((Input!$AA$16/Input!$AA$15)*LN((1+SQRT((Input!$AA$16/Input!$AA$15)^2+1))*SQRT((Input!$AA$16/Input!$AA$15)^2+(AJ86/(Input!$AA$15/2))^2)/((Input!$AA$16/Input!$AA$15)*(1+SQRT((Input!$AA$16/Input!$AA$15)^2+(AJ86/(Input!$AA$15/2))^2+1))))+LN(((Input!$AA$16/Input!$AA$15)+SQRT((Input!$AA$16/Input!$AA$15)^2+1))*SQRT(1+(AJ86/(Input!$AA$15/2))^2)/((Input!$AA$16/Input!$AA$15)+SQRT((Input!$AA$16/Input!$AA$15)^2+(AJ86/(Input!$AA$15/2))^2+1))))/PI() -> 0.0044021053 | BE86: =(AJ86/(Input!$AA$15/2))/(2*PI())*ATAN((Input!$AA$16/Input!$AA$15)/((AJ86/(Input!$AA$15/2))*SQRT((Input!$AA$16/Input!$AA$15)^2+(AJ86/(Input!$AA$15/2))^2+1))) -> 0.036120125 | BF86: =MAX(0,AJ86-MAX(AI86,$AA$23))/AK86*IF(BC86>=Input!$AA$21*AQ86,1,0) -> 1 | BG86: =4*Input!$AA$14*(Input!$AA$15/2)*(1-AY86^2)/AX86*((BD86-BD85)+(1-2*AY86)/(1-AY86)*(BE86-BE85))*1000*BF86 -> 0.15005894 | BH86: =IF(AM86="Sand",0,0.009*(AR86-10)) -> 0.176985 | BI86: =BH86*Input!$AA$39 -> 0.035397 | BJ86: =IF(AM86="Sand",0,MAX(AV86/Input!$AA$40,AQ86)) -> 636.36364 | BK86: =IF(AM86="Sand",0,1000*AK86/(1+AU86)*IF(AQ86+BC86<=BJ86,BI86*LOG10((AQ86+BC86)/AQ86),BI86*LOG10(BJ86/AQ86)+BH86*LOG10((AQ86+BC86)/BJ86)))*BF86 -> 3.8612014 | BL86: =IF(AM86="Sand",0,10^(INDEX(Input!$Q$51:$Q$57,MIN(MATCH(MIN(MAX(AR86,30),120),Input!$C$51:$C$57,1),6))+(MIN(MAX(AR86,30),120)-INDEX(Input!$C$51:$C$57,MIN(MATCH(MIN(MAX(AR86,30),120),Input!$C$51:$C$57,1),6)))/(INDEX(Input!$C$51:$C$57,MIN(MATCH(MIN(MAX(AR86,30),120),Input!$C$51:$C$57,1),6)+1)-INDEX(Input!$C$51:$C$57,MIN(MATCH(MIN(MAX(AR86,30),120),Input!$C$51:$C$57,1),6)))*(INDEX(Input!$Q$51:$Q$57,MIN(MATCH(MIN(MAX(AR86,30),120),Input!$C$51:$C$57,1),6)+1)-INDEX(Input!$Q$51:$Q$57,MIN(MATCH(MIN(MAX(AR86,30),120),Input!$C$51:$C$57,1),6))))) -> 0.003 | BM86: =IF(OR(AM86="Sand",BF86=0),0,Input!$AA$41*(AK86/2)^2/(BL86*0.0001*31536000)) -> 0.0056020633 | BN86: =MAX(0,MIN(AJ86,Input!$AA$20)-AI86) -> 0 | BO86: =MAX(0,MIN(AJ86,Input!$AA$20)-MAX(AI86,$AA$23)) -> 0 | BP86: =BG86+BK86 -> 4.0112603 | BQ86: LL/PL/e0 = borehole average
C87: 5 | E87: =AI87 -> 6 | H87: =AJ87 -> 7.5 | K87: =AM87 -> Silt | N87: =AN87 -> 30 | Q87: =AO87 -> 17.8 | T87: =IF(AR87="","-",AR87) -> 29.665 | V87: =IF(AT87="","-",AT87) -> 9.859 | X87: =AU87 -> 0.681 | Z87: =AV87 -> 150 | AC87: =AW87 -> 30 | AI87: 6 | AJ87: 7.5 | AK87: =AJ87-AI87 -> 1.5 | AL87: =(AI87+AJ87)/2 -> 6.75 | AM87: Silt | AN87: 30 | AO87: =IF(AL87>$AA$20,$AA$22,$AA$21) -> 17.8 | AP87: =AP86+AO87*AK87 -> 133.5 | AQ87: =AP87-AO87*AK87/2-10*MAX(AL87-$AA$20,0) -> 120.15 | AR87: 29.665 | AS87: 19.806 | AT87: =IF(AR87="","",AR87-AS87) -> 9.859 | AU87: 0.681 | AV87: =IF(AM87="Sand",0,Input!$AA$34*AN87) -> 150 | AW87: =IF(AM87="Sand",27.1+0.3*MIN(Input!$AA$35*AN87,60)-0.00054*MIN(Input!$AA$35*AN87,60)^2,MIN(MAX(DEGREES(ASIN(0.8-0.094*LN(MAX(IF(AT87="",10,AT87),5)))),20),30)) -> 30 | AX87: =IF(AM87="Sand",Input!$AA$36*Input!$AA$35*AN87,Input!$AA$37*AV87) -> 75000 | AY87: =IF(AM87="Sand",Input!$AA$38,0.5) -> 0.5 | AZ87: =Input!$AA$15/2/AL87 -> 5.4814815 | BA87: =Input!$AA$16/2/AL87 -> 14.962963 | BB87: =1/(4*PI())*(2*AZ87*BA87*SQRT(AZ87^2+BA87^2+1)/(AZ87^2+BA87^2+1+AZ87^2*BA87^2)*(AZ87^2+BA87^2+2)/(AZ87^2+BA87^2+1)+ATAN2(AZ87^2+BA87^2+1-AZ87^2*BA87^2,2*AZ87*BA87*SQRT(AZ87^2+BA87^2+1))) -> 0.24936854 | BC87: =4*Input!$AA$14*BB87 -> 135.65648 | BD87: =((Input!$AA$16/Input!$AA$15)*LN((1+SQRT((Input!$AA$16/Input!$AA$15)^2+1))*SQRT((Input!$AA$16/Input!$AA$15)^2+(AJ87/(Input!$AA$15/2))^2)/((Input!$AA$16/Input!$AA$15)*(1+SQRT((Input!$AA$16/Input!$AA$15)^2+(AJ87/(Input!$AA$15/2))^2+1))))+LN(((Input!$AA$16/Input!$AA$15)+SQRT((Input!$AA$16/Input!$AA$15)^2+1))*SQRT(1+(AJ87/(Input!$AA$15/2))^2)/((Input!$AA$16/Input!$AA$15)+SQRT((Input!$AA$16/Input!$AA$15)^2+(AJ87/(Input!$AA$15/2))^2+1))))/PI() -> 0.0068311102 | BE87: =(AJ87/(Input!$AA$15/2))/(2*PI())*ATAN((Input!$AA$16/Input!$AA$15)/((AJ87/(Input!$AA$15/2))*SQRT((Input!$AA$16/Input!$AA$15)^2+(AJ87/(Input!$AA$15/2))^2+1))) -> 0.043800367 | BF87: =MAX(0,AJ87-MAX(AI87,$AA$23))/AK87*IF(BC87>=Input!$AA$21*AQ87,1,0) -> 1 | BG87: =4*Input!$AA$14*(Input!$AA$15/2)*(1-AY87^2)/AX87*((BD87-BD86)+(1-2*AY87)/(1-AY87)*(BE87-BE86))*1000*BF87 -> 0.48891009 | BH87: =IF(AM87="Sand",0,0.009*(AR87-10)) -> 0.176985 | BI87: =BH87*Input!$AA$39 -> 0.035397 | BJ87: =IF(AM87="Sand",0,MAX(AV87/Input!$AA$40,AQ87)) -> 681.81818 | BK87: =IF(AM87="Sand",0,1000*AK87/(1+AU87)*IF(AQ87+BC87<=BJ87,BI87*LOG10((AQ87+BC87)/AQ87),BI87*LOG10(BJ87/AQ87)+BH87*LOG10((AQ87+BC87)/BJ87)))*BF87 -> 10.366028 | BL87: =IF(AM87="Sand",0,10^(INDEX(Input!$Q$51:$Q$57,MIN(MATCH(MIN(MAX(AR87,30),120),Input!$C$51:$C$57,1),6))+(MIN(MAX(AR87,30),120)-INDEX(Input!$C$51:$C$57,MIN(MATCH(MIN(MAX(AR87,30),120),Input!$C$51:$C$57,1),6)))/(INDEX(Input!$C$51:$C$57,MIN(MATCH(MIN(MAX(AR87,30),120),Input!$C$51:$C$57,1),6)+1)-INDEX(Input!$C$51:$C$57,MIN(MATCH(MIN(MAX(AR87,30),120),Input!$C$51:$C$57,1),6)))*(INDEX(Input!$Q$51:$Q$57,MIN(MATCH(MIN(MAX(AR87,30),120),Input!$C$51:$C$57,1),6)+1)-INDEX(Input!$Q$51:$Q$57,MIN(MATCH(MIN(MAX(AR87,30),120),Input!$C$51:$C$57,1),6))))) -> 0.003 | BM87: =IF(OR(AM87="Sand",BF87=0),0,Input!$AA$41*(AK87/2)^2/(BL87*0.0001*31536000)) -> 0.050418569 | BN87: =MAX(0,MIN(AJ87,Input!$AA$20)-AI87) -> 0 | BO87: =MAX(0,MIN(AJ87,Input!$AA$20)-MAX(AI87,$AA$23)) -> 0 | BP87: =BG87+BK87 -> 10.854939 | BQ87: LL/PL/e0 = borehole average
C88: 6 | E88: =AI88 -> 7.5 | H88: =AJ88 -> 9 | K88: =AM88 -> Sand | N88: =AN88 -> 35 | Q88: =AO88 -> 17.8 | T88: =IF(AR88="","-",AR88) -> - | V88: =IF(AT88="","-",AT88) -> - | X88: =AU88 -> 0.65 | Z88: =AV88 -> 0 | AC88: =AW88 -> 37.695634 | AI88: 7.5 | AJ88: 9 | AK88: =AJ88-AI88 -> 1.5 | AL88: =(AI88+AJ88)/2 -> 8.25 | AM88: Sand | AN88: 35 | AO88: =IF(AL88>$AA$20,$AA$22,$AA$21) -> 17.8 | AP88: =AP87+AO88*AK88 -> 160.2 | AQ88: =AP88-AO88*AK88/2-10*MAX(AL88-$AA$20,0) -> 146.85 | AT88: =IF(AR88="","",AR88-AS88) | AU88: 0.65 | AV88: =IF(AM88="Sand",0,Input!$AA$34*AN88) -> 0 | AW88: =IF(AM88="Sand",27.1+0.3*MIN(Input!$AA$35*AN88,60)-0.00054*MIN(Input!$AA$35*AN88,60)^2,MIN(MAX(DEGREES(ASIN(0.8-0.094*LN(MAX(IF(AT88="",10,AT88),5)))),20),30)) -> 37.695634 | AX88: =IF(AM88="Sand",Input!$AA$36*Input!$AA$35*AN88,Input!$AA$37*AV88) -> 37905 | AY88: =IF(AM88="Sand",Input!$AA$38,0.5) -> 0.3 | AZ88: =Input!$AA$15/2/AL88 -> 4.4848485 | BA88: =Input!$AA$16/2/AL88 -> 12.242424 | BB88: =1/(4*PI())*(2*AZ88*BA88*SQRT(AZ88^2+BA88^2+1)/(AZ88^2+BA88^2+1+AZ88^2*BA88^2)*(AZ88^2+BA88^2+2)/(AZ88^2+BA88^2+1)+ATAN2(AZ88^2+BA88^2+1-AZ88^2*BA88^2,2*AZ88*BA88*SQRT(AZ88^2+BA88^2+1))) -> 0.24886842 | BC88: =4*Input!$AA$14*BB88 -> 135.38442 | BD88: =((Input!$AA$16/Input!$AA$15)*LN((1+SQRT((Input!$AA$16/Input!$AA$15)^2+1))*SQRT((Input!$AA$16/Input!$AA$15)^2+(AJ88/(Input!$AA$15/2))^2)/((Input!$AA$16/Input!$AA$15)*(1+SQRT((Input!$AA$16/Input!$AA$15)^2+(AJ88/(Input!$AA$15/2))^2+1))))+LN(((Input!$AA$16/Input!$AA$15)+SQRT((Input!$AA$16/Input!$AA$15)^2+1))*SQRT(1+(AJ88/(Input!$AA$15/2))^2)/((Input!$AA$16/Input!$AA$15)+SQRT((Input!$AA$16/Input!$AA$15)^2+(AJ88/(Input!$AA$15/2))^2+1))))/PI() -> 0.0097554689 | BE88: =(AJ88/(Input!$AA$15/2))/(2*PI())*ATAN((Input!$AA$16/Input!$AA$15)/((AJ88/(Input!$AA$15/2))*SQRT((Input!$AA$16/Input!$AA$15)^2+(AJ88/(Input!$AA$15/2))^2+1))) -> 0.050964938 | BF88: =MAX(0,AJ88-MAX(AI88,$AA$23))/AK88*IF(BC88>=Input!$AA$21*AQ88,1,0) -> 1 | BG88: =4*Input!$AA$14*(Input!$AA$15/2)*(1-AY88^2)/AX88*((BD88-BD87)+(1-2*AY88)/(1-AY88)*(BE88-BE87))*1000*BF88 -> 3.3914356 | BH88: =IF(AM88="Sand",0,0.009*(AR88-10)) -> 0 | BI88: =BH88*Input!$AA$39 -> 0 | BJ88: =IF(AM88="Sand",0,MAX(AV88/Input!$AA$40,AQ88)) -> 0 | BK88: =IF(AM88="Sand",0,1000*AK88/(1+AU88)*IF(AQ88+BC88<=BJ88,BI88*LOG10((AQ88+BC88)/AQ88),BI88*LOG10(BJ88/AQ88)+BH88*LOG10((AQ88+BC88)/BJ88)))*BF88 -> 0 | BL88: =IF(AM88="Sand",0,10^(INDEX(Input!$Q$51:$Q$57,MIN(MATCH(MIN(MAX(AR88,30),120),Input!$C$51:$C$57,1),6))+(MIN(MAX(AR88,30),120)-INDEX(Input!$C$51:$C$57,MIN(MATCH(MIN(MAX(AR88,30),120),Input!$C$51:$C$57,1),6)))/(INDEX(Input!$C$51:$C$57,MIN(MATCH(MIN(MAX(AR88,30),120),Input!$C$51:$C$57,1),6)+1)-INDEX(Input!$C$51:$C$57,MIN(MATCH(MIN(MAX(AR88,30),120),Input!$C$51:$C$57,1),6)))*(INDEX(Input!$Q$51:$Q$57,MIN(MATCH(MIN(MAX(AR88,30),120),Input!$C$51:$C$57,1),6)+1)-INDEX(Input!$Q$51:$Q$57,MIN(MATCH(MIN(MAX(AR88,30),120),Input!$C$51:$C$57,1),6))))) -> 0 | BM88: =IF(OR(AM88="Sand",BF88=0),0,Input!$AA$41*(AK88/2)^2/(BL88*0.0001*31536000)) -> 0 | BN88: =MAX(0,MIN(AJ88,Input!$AA$20)-AI88) -> 0 | BO88: =MAX(0,MIN(AJ88,Input!$AA$20)-MAX(AI88,$AA$23)) -> 0 | BP88: =BG88+BK88 -> 3.3914356
C89: 7 | E89: =AI89 -> 9 | H89: =AJ89 -> 10.5 | K89: =AM89 -> Sand | N89: =AN89 -> 34 | Q89: =AO89 -> 19.2 | T89: =IF(AR89="","-",AR89) -> - | V89: =IF(AT89="","-",AT89) -> - | X89: =AU89 -> 0.465 | Z89: =AV89 -> 0 | AC89: =AW89 -> 37.414436 | AI89: 9 | AJ89: 10.5 | AK89: =AJ89-AI89 -> 1.5 | AL89: =(AI89+AJ89)/2 -> 9.75 | AM89: Sand | AN89: 34 | AO89: =IF(AL89>$AA$20,$AA$22,$AA$21) -> 19.2 | AP89: =AP88+AO89*AK89 -> 189 | AQ89: =AP89-AO89*AK89/2-10*MAX(AL89-$AA$20,0) -> 167.1 | AT89: =IF(AR89="","",AR89-AS89) | AU89: 0.465 | AV89: =IF(AM89="Sand",0,Input!$AA$34*AN89) -> 0 | AW89: =IF(AM89="Sand",27.1+0.3*MIN(Input!$AA$35*AN89,60)-0.00054*MIN(Input!$AA$35*AN89,60)^2,MIN(MAX(DEGREES(ASIN(0.8-0.094*LN(MAX(IF(AT89="",10,AT89),5)))),20),30)) -> 37.414436 | AX89: =IF(AM89="Sand",Input!$AA$36*Input!$AA$35*AN89,Input!$AA$37*AV89) -> 36822 | AY89: =IF(AM89="Sand",Input!$AA$38,0.5) -> 0.3 | AZ89: =Input!$AA$15/2/AL89 -> 3.7948718 | BA89: =Input!$AA$16/2/AL89 -> 10.358974 | BB89: =1/(4*PI())*(2*AZ89*BA89*SQRT(AZ89^2+BA89^2+1)/(AZ89^2+BA89^2+1+AZ89^2*BA89^2)*(AZ89^2+BA89^2+2)/(AZ89^2+BA89^2+1)+ATAN2(AZ89^2+BA89^2+1-AZ89^2*BA89^2,2*AZ89*BA89*SQRT(AZ89^2+BA89^2+1))) -> 0.24817291 | BC89: =4*Input!$AA$14*BB89 -> 135.00606 | BD89: =((Input!$AA$16/Input!$AA$15)*LN((1+SQRT((Input!$AA$16/Input!$AA$15)^2+1))*SQRT((Input!$AA$16/Input!$AA$15)^2+(AJ89/(Input!$AA$15/2))^2)/((Input!$AA$16/Input!$AA$15)*(1+SQRT((Input!$AA$16/Input!$AA$15)^2+(AJ89/(Input!$AA$15/2))^2+1))))+LN(((Input!$AA$16/Input!$AA$15)+SQRT((Input!$AA$16/Input!$AA$15)^2+1))*SQRT(1+(AJ89/(Input!$AA$15/2))^2)/((Input!$AA$16/Input!$AA$15)+SQRT((Input!$AA$16/Input!$AA$15)^2+(AJ89/(Input!$AA$15/2))^2+1))))/PI() -> 0.01315062 | BE89: =(AJ89/(Input!$AA$15/2))/(2*PI())*ATAN((Input!$AA$16/Input!$AA$15)/((AJ89/(Input!$AA$15/2))*SQRT((Input!$AA$16/Input!$AA$15)^2+(AJ89/(Input!$AA$15/2))^2+1))) -> 0.057630488 | BF89: =MAX(0,AJ89-MAX(AI89,$AA$23))/AK89*IF(BC89>=Input!$AA$21*AQ89,1,0) -> 1 | BG89: =4*Input!$AA$14*(Input!$AA$15/2)*(1-AY89^2)/AX89*((BD89-BD88)+(1-2*AY89)/(1-AY89)*(BE89-BE88))*1000*BF89 -> 3.5835261 | BH89: =IF(AM89="Sand",0,0.009*(AR89-10)) -> 0 | BI89: =BH89*Input!$AA$39 -> 0 | BJ89: =IF(AM89="Sand",0,MAX(AV89/Input!$AA$40,AQ89)) -> 0 | BK89: =IF(AM89="Sand",0,1000*AK89/(1+AU89)*IF(AQ89+BC89<=BJ89,BI89*LOG10((AQ89+BC89)/AQ89),BI89*LOG10(BJ89/AQ89)+BH89*LOG10((AQ89+BC89)/BJ89)))*BF89 -> 0 | BL89: =IF(AM89="Sand",0,10^(INDEX(Input!$Q$51:$Q$57,MIN(MATCH(MIN(MAX(AR89,30),120),Input!$C$51:$C$57,1),6))+(MIN(MAX(AR89,30),120)-INDEX(Input!$C$51:$C$57,MIN(MATCH(MIN(MAX(AR89,30),120),Input!$C$51:$C$57,1),6)))/(INDEX(Input!$C$51:$C$57,MIN(MATCH(MIN(MAX(AR89,30),120),Input!$C$51:$C$57,1),6)+1)-INDEX(Input!$C$51:$C$57,MIN(MATCH(MIN(MAX(AR89,30),120),Input!$C$51:$C$57,1),6)))*(INDEX(Input!$Q$51:$Q$57,MIN(MATCH(MIN(MAX(AR89,30),120),Input!$C$51:$C$57,1),6)+1)-INDEX(Input!$Q$51:$Q$57,MIN(MATCH(MIN(MAX(AR89,30),120),Input!$C$51:$C$57,1),6))))) -> 0 | BM89: =IF(OR(AM89="Sand",BF89=0),0,Input!$AA$41*(AK89/2)^2/(BL89*0.0001*31536000)) -> 0 | BN89: =MAX(0,MIN(AJ89,Input!$AA$20)-AI89) -> 0 | BO89: =MAX(0,MIN(AJ89,Input!$AA$20)-MAX(AI89,$AA$23)) -> 0 | BP89: =BG89+BK89 -> 3.5835261
C90: 8 | E90: =AI90 -> 10.5 | H90: =AJ90 -> 12 | K90: =AM90 -> Sand | N90: =AN90 -> 13 | Q90: =AO90 -> 19.2 | T90: =IF(AR90="","-",AR90) -> - | V90: =IF(AT90="","-",AT90) -> - | X90: =AU90 -> 0.65 | Z90: =AV90 -> 0 | AC90: =AW90 -> 31.216662 | AI90: 10.5 | AJ90: 12 | AK90: =AJ90-AI90 -> 1.5 | AL90: =(AI90+AJ90)/2 -> 11.25 | AM90: Sand | AN90: 13 | AO90: =IF(AL90>$AA$20,$AA$22,$AA$21) -> 19.2 | AP90: =AP89+AO90*AK90 -> 217.8 | AQ90: =AP90-AO90*AK90/2-10*MAX(AL90-$AA$20,0) -> 180.9 | AT90: =IF(AR90="","",AR90-AS90) | AU90: 0.65 | AV90: =IF(AM90="Sand",0,Input!$AA$34*AN90) -> 0 | AW90: =IF(AM90="Sand",27.1+0.3*MIN(Input!$AA$35*AN90,60)-0.00054*MIN(Input!$AA$35*AN90,60)^2,MIN(MAX(DEGREES(ASIN(0.8-0.094*LN(MAX(IF(AT90="",10,AT90),5)))),20),30)) -> 31.216662 | AX90: =IF(AM90="Sand",Input!$AA$36*Input!$AA$35*AN90,Input!$AA$37*AV90) -> 14079 | AY90: =IF(AM90="Sand",Input!$AA$38,0.5) -> 0.3 | AZ90: =Input!$AA$15/2/AL90 -> 3.2888889 | BA90: =Input!$AA$16/2/AL90 -> 8.9777778 | BB90: =1/(4*PI())*(2*AZ90*BA90*SQRT(AZ90^2+BA90^2+1)/(AZ90^2+BA90^2+1+AZ90^2*BA90^2)*(AZ90^2+BA90^2+2)/(AZ90^2+BA90^2+1)+ATAN2(AZ90^2+BA90^2+1-AZ90^2*BA90^2,2*AZ90*BA90*SQRT(AZ90^2+BA90^2+1))) -> 0.24726322 | BC90: =4*Input!$AA$14*BB90 -> 134.51119 | BD90: =((Input!$AA$16/Input!$AA$15)*LN((1+SQRT((Input!$AA$16/Input!$AA$15)^2+1))*SQRT((Input!$AA$16/Input!$AA$15)^2+(AJ90/(Input!$AA$15/2))^2)/((Input!$AA$16/Input!$AA$15)*(1+SQRT((Input!$AA$16/Input!$AA$15)^2+(AJ90/(Input!$AA$15/2))^2+1))))+LN(((Input!$AA$16/Input!$AA$15)+SQRT((Input!$AA$16/Input!$AA$15)^2+1))*SQRT(1+(AJ90/(Input!$AA$15/2))^2)/((Input!$AA$16/Input!$AA$15)+SQRT((Input!$AA$16/Input!$AA$15)^2+(AJ90/(Input!$AA$15/2))^2+1))))/PI() -> 0.016989259 | BE90: =(AJ90/(Input!$AA$15/2))/(2*PI())*ATAN((Input!$AA$16/Input!$AA$15)/((AJ90/(Input!$AA$15/2))*SQRT((Input!$AA$16/Input!$AA$15)^2+(AJ90/(Input!$AA$15/2))^2+1))) -> 0.06381565 | BF90: =MAX(0,AJ90-MAX(AI90,$AA$23))/AK90*IF(BC90>=Input!$AA$21*AQ90,1,0) -> 1 | BG90: =4*Input!$AA$14*(Input!$AA$15/2)*(1-AY90^2)/AX90*((BD90-BD89)+(1-2*AY90)/(1-AY90)*(BE90-BE89))*1000*BF90 -> 9.5921389 | BH90: =IF(AM90="Sand",0,0.009*(AR90-10)) -> 0 | BI90: =BH90*Input!$AA$39 -> 0 | BJ90: =IF(AM90="Sand",0,MAX(AV90/Input!$AA$40,AQ90)) -> 0 | BK90: =IF(AM90="Sand",0,1000*AK90/(1+AU90)*IF(AQ90+BC90<=BJ90,BI90*LOG10((AQ90+BC90)/AQ90),BI90*LOG10(BJ90/AQ90)+BH90*LOG10((AQ90+BC90)/BJ90)))*BF90 -> 0 | BL90: =IF(AM90="Sand",0,10^(INDEX(Input!$Q$51:$Q$57,MIN(MATCH(MIN(MAX(AR90,30),120),Input!$C$51:$C$57,1),6))+(MIN(MAX(AR90,30),120)-INDEX(Input!$C$51:$C$57,MIN(MATCH(MIN(MAX(AR90,30),120),Input!$C$51:$C$57,1),6)))/(INDEX(Input!$C$51:$C$57,MIN(MATCH(MIN(MAX(AR90,30),120),Input!$C$51:$C$57,1),6)+1)-INDEX(Input!$C$51:$C$57,MIN(MATCH(MIN(MAX(AR90,30),120),Input!$C$51:$C$57,1),6)))*(INDEX(Input!$Q$51:$Q$57,MIN(MATCH(MIN(MAX(AR90,30),120),Input!$C$51:$C$57,1),6)+1)-INDEX(Input!$Q$51:$Q$57,MIN(MATCH(MIN(MAX(AR90,30),120),Input!$C$51:$C$57,1),6))))) -> 0 | BM90: =IF(OR(AM90="Sand",BF90=0),0,Input!$AA$41*(AK90/2)^2/(BL90*0.0001*31536000)) -> 0 | BN90: =MAX(0,MIN(AJ90,Input!$AA$20)-AI90) -> 0 | BO90: =MAX(0,MIN(AJ90,Input!$AA$20)-MAX(AI90,$AA$23)) -> 0 | BP90: =BG90+BK90 -> 9.5921389
C91: 9 | E91: =AI91 -> 12 | H91: =AJ91 -> 13.5 | K91: =AM91 -> Sand | N91: =AN91 -> 17 | Q91: =AO91 -> 19.2 | T91: =IF(AR91="","-",AR91) -> - | V91: =IF(AT91="","-",AT91) -> - | X91: =AU91 -> 0.414 | Z91: =AV91 -> 0 | AC91: =AW91 -> 32.440259 | AI91: 12 | AJ91: 13.5 | AK91: =AJ91-AI91 -> 1.5 | AL91: =(AI91+AJ91)/2 -> 12.75 | AM91: Sand | AN91: 17 | AO91: =IF(AL91>$AA$20,$AA$22,$AA$21) -> 19.2 | AP91: =AP90+AO91*AK91 -> 246.6 | AQ91: =AP91-AO91*AK91/2-10*MAX(AL91-$AA$20,0) -> 194.7 | AT91: =IF(AR91="","",AR91-AS91) | AU91: 0.414 | AV91: =IF(AM91="Sand",0,Input!$AA$34*AN91) -> 0 | AW91: =IF(AM91="Sand",27.1+0.3*MIN(Input!$AA$35*AN91,60)-0.00054*MIN(Input!$AA$35*AN91,60)^2,MIN(MAX(DEGREES(ASIN(0.8-0.094*LN(MAX(IF(AT91="",10,AT91),5)))),20),30)) -> 32.440259 | AX91: =IF(AM91="Sand",Input!$AA$36*Input!$AA$35*AN91,Input!$AA$37*AV91) -> 18411 | AY91: =IF(AM91="Sand",Input!$AA$38,0.5) -> 0.3 | AZ91: =Input!$AA$15/2/AL91 -> 2.9019608 | BA91: =Input!$AA$16/2/AL91 -> 7.9215686 | BB91: =1/(4*PI())*(2*AZ91*BA91*SQRT(AZ91^2+BA91^2+1)/(AZ91^2+BA91^2+1+AZ91^2*BA91^2)*(AZ91^2+BA91^2+2)/(AZ91^2+BA91^2+1)+ATAN2(AZ91^2+BA91^2+1-AZ91^2*BA91^2,2*AZ91*BA91*SQRT(AZ91^2+BA91^2+1))) -> 0.24612697 | BC91: =4*Input!$AA$14*BB91 -> 133.89307 | BD91: =((Input!$AA$16/Input!$AA$15)*LN((1+SQRT((Input!$AA$16/Input!$AA$15)^2+1))*SQRT((Input!$AA$16/Input!$AA$15)^2+(AJ91/(Input!$AA$15/2))^2)/((Input!$AA$16/Input!$AA$15)*(1+SQRT((Input!$AA$16/Input!$AA$15)^2+(AJ91/(Input!$AA$15/2))^2+1))))+LN(((Input!$AA$16/Input!$AA$15)+SQRT((Input!$AA$16/Input!$AA$15)^2+1))*SQRT(1+(AJ91/(Input!$AA$15/2))^2)/((Input!$AA$16/Input!$AA$15)+SQRT((Input!$AA$16/Input!$AA$15)^2+(AJ91/(Input!$AA$15/2))^2+1))))/PI() -> 0.021242015 | BE91: =(AJ91/(Input!$AA$15/2))/(2*PI())*ATAN((Input!$AA$16/Input!$AA$15)/((AJ91/(Input!$AA$15/2))*SQRT((Input!$AA$16/Input!$AA$15)^2+(AJ91/(Input!$AA$15/2))^2+1))) -> 0.069540621 | BF91: =MAX(0,AJ91-MAX(AI91,$AA$23))/AK91*IF(BC91>=Input!$AA$21*AQ91,1,0) -> 1 | BG91: =4*Input!$AA$14*(Input!$AA$15/2)*(1-AY91^2)/AX91*((BD91-BD90)+(1-2*AY91)/(1-AY91)*(BE91-BE90))*1000*BF91 -> 7.4855398 | BH91: =IF(AM91="Sand",0,0.009*(AR91-10)) -> 0 | BI91: =BH91*Input!$AA$39 -> 0 | BJ91: =IF(AM91="Sand",0,MAX(AV91/Input!$AA$40,AQ91)) -> 0 | BK91: =IF(AM91="Sand",0,1000*AK91/(1+AU91)*IF(AQ91+BC91<=BJ91,BI91*LOG10((AQ91+BC91)/AQ91),BI91*LOG10(BJ91/AQ91)+BH91*LOG10((AQ91+BC91)/BJ91)))*BF91 -> 0 | BL91: =IF(AM91="Sand",0,10^(INDEX(Input!$Q$51:$Q$57,MIN(MATCH(MIN(MAX(AR91,30),120),Input!$C$51:$C$57,1),6))+(MIN(MAX(AR91,30),120)-INDEX(Input!$C$51:$C$57,MIN(MATCH(MIN(MAX(AR91,30),120),Input!$C$51:$C$57,1),6)))/(INDEX(Input!$C$51:$C$57,MIN(MATCH(MIN(MAX(AR91,30),120),Input!$C$51:$C$57,1),6)+1)-INDEX(Input!$C$51:$C$57,MIN(MATCH(MIN(MAX(AR91,30),120),Input!$C$51:$C$57,1),6)))*(INDEX(Input!$Q$51:$Q$57,MIN(MATCH(MIN(MAX(AR91,30),120),Input!$C$51:$C$57,1),6)+1)-INDEX(Input!$Q$51:$Q$57,MIN(MATCH(MIN(MAX(AR91,30),120),Input!$C$51:$C$57,1),6))))) -> 0 | BM91: =IF(OR(AM91="Sand",BF91=0),0,Input!$AA$41*(AK91/2)^2/(BL91*0.0001*31536000)) -> 0 | BN91: =MAX(0,MIN(AJ91,Input!$AA$20)-AI91) -> 0 | BO91: =MAX(0,MIN(AJ91,Input!$AA$20)-MAX(AI91,$AA$23)) -> 0 | BP91: =BG91+BK91 -> 7.4855398
C92: 10 | E92: =AI92 -> 13.5 | H92: =AJ92 -> 15 | K92: =AM92 -> Sand | N92: =AN92 -> 18 | Q92: =AO92 -> 19.2 | T92: =IF(AR92="","-",AR92) -> - | V92: =IF(AT92="","-",AT92) -> - | X92: =AU92 -> 0.747 | Z92: =AV92 -> 0 | AC92: =AW92 -> 32.742991 | AI92: 13.5 | AJ92: 15 | AK92: =AJ92-AI92 -> 1.5 | AL92: =(AI92+AJ92)/2 -> 14.25 | AM92: Sand | AN92: 18 | AO92: =IF(AL92>$AA$20,$AA$22,$AA$21) -> 19.2 | AP92: =AP91+AO92*AK92 -> 275.4 | AQ92: =AP92-AO92*AK92/2-10*MAX(AL92-$AA$20,0) -> 208.5 | AT92: =IF(AR92="","",AR92-AS92) | AU92: 0.747 | AV92: =IF(AM92="Sand",0,Input!$AA$34*AN92) -> 0 | AW92: =IF(AM92="Sand",27.1+0.3*MIN(Input!$AA$35*AN92,60)-0.00054*MIN(Input!$AA$35*AN92,60)^2,MIN(MAX(DEGREES(ASIN(0.8-0.094*LN(MAX(IF(AT92="",10,AT92),5)))),20),30)) -> 32.742991 | AX92: =IF(AM92="Sand",Input!$AA$36*Input!$AA$35*AN92,Input!$AA$37*AV92) -> 19494 | AY92: =IF(AM92="Sand",Input!$AA$38,0.5) -> 0.3 | AZ92: =Input!$AA$15/2/AL92 -> 2.5964912 | BA92: =Input!$AA$16/2/AL92 -> 7.0877193 | BB92: =1/(4*PI())*(2*AZ92*BA92*SQRT(AZ92^2+BA92^2+1)/(AZ92^2+BA92^2+1+AZ92^2*BA92^2)*(AZ92^2+BA92^2+2)/(AZ92^2+BA92^2+1)+ATAN2(AZ92^2+BA92^2+1-AZ92^2*BA92^2,2*AZ92*BA92*SQRT(AZ92^2+BA92^2+1))) -> 0.24475803 | BC92: =4*Input!$AA$14*BB92 -> 133.14837 | BD92: =((Input!$AA$16/Input!$AA$15)*LN((1+SQRT((Input!$AA$16/Input!$AA$15)^2+1))*SQRT((Input!$AA$16/Input!$AA$15)^2+(AJ92/(Input!$AA$15/2))^2)/((Input!$AA$16/Input!$AA$15)*(1+SQRT((Input!$AA$16/Input!$AA$15)^2+(AJ92/(Input!$AA$15/2))^2+1))))+LN(((Input!$AA$16/Input!$AA$15)+SQRT((Input!$AA$16/Input!$AA$15)^2+1))*SQRT(1+(AJ92/(Input!$AA$15/2))^2)/((Input!$AA$16/Input!$AA$15)+SQRT((Input!$AA$16/Input!$AA$15)^2+(AJ92/(Input!$AA$15/2))^2+1))))/PI() -> 0.025878119 | BE92: =(AJ92/(Input!$AA$15/2))/(2*PI())*ATAN((Input!$AA$16/Input!$AA$15)/((AJ92/(Input!$AA$15/2))*SQRT((Input!$AA$16/Input!$AA$15)^2+(AJ92/(Input!$AA$15/2))^2+1))) -> 0.074826746 | BF92: =MAX(0,AJ92-MAX(AI92,$AA$23))/AK92*IF(BC92>=Input!$AA$21*AQ92,1,0) -> 1 | BG92: =4*Input!$AA$14*(Input!$AA$15/2)*(1-AY92^2)/AX92*((BD92-BD91)+(1-2*AY92)/(1-AY92)*(BE92-BE91))*1000*BF92 -> 7.1942465 | BH92: =IF(AM92="Sand",0,0.009*(AR92-10)) -> 0 | BI92: =BH92*Input!$AA$39 -> 0 | BJ92: =IF(AM92="Sand",0,MAX(AV92/Input!$AA$40,AQ92)) -> 0 | BK92: =IF(AM92="Sand",0,1000*AK92/(1+AU92)*IF(AQ92+BC92<=BJ92,BI92*LOG10((AQ92+BC92)/AQ92),BI92*LOG10(BJ92/AQ92)+BH92*LOG10((AQ92+BC92)/BJ92)))*BF92 -> 0 | BL92: =IF(AM92="Sand",0,10^(INDEX(Input!$Q$51:$Q$57,MIN(MATCH(MIN(MAX(AR92,30),120),Input!$C$51:$C$57,1),6))+(MIN(MAX(AR92,30),120)-INDEX(Input!$C$51:$C$57,MIN(MATCH(MIN(MAX(AR92,30),120),Input!$C$51:$C$57,1),6)))/(INDEX(Input!$C$51:$C$57,MIN(MATCH(MIN(MAX(AR92,30),120),Input!$C$51:$C$57,1),6)+1)-INDEX(Input!$C$51:$C$57,MIN(MATCH(MIN(MAX(AR92,30),120),Input!$C$51:$C$57,1),6)))*(INDEX(Input!$Q$51:$Q$57,MIN(MATCH(MIN(MAX(AR92,30),120),Input!$C$51:$C$57,1),6)+1)-INDEX(Input!$Q$51:$Q$57,MIN(MATCH(MIN(MAX(AR92,30),120),Input!$C$51:$C$57,1),6))))) -> 0 | BM92: =IF(OR(AM92="Sand",BF92=0),0,Input!$AA$41*(AK92/2)^2/(BL92*0.0001*31536000)) -> 0 | BN92: =MAX(0,MIN(AJ92,Input!$AA$20)-AI92) -> 0 | BO92: =MAX(0,MIN(AJ92,Input!$AA$20)-MAX(AI92,$AA$23)) -> 0 | BP92: =BG92+BK92 -> 7.1942465
C93: 11 | E93: =AI93 -> 15 | H93: =AJ93 -> 16.5 | K93: =AM93 -> Sand | N93: =AN93 -> 19 | Q93: =AO93 -> 19.2 | T93: =IF(AR93="","-",AR93) -> - | V93: =IF(AT93="","-",AT93) -> - | X93: =AU93 -> 0.65 | Z93: =AV93 -> 0 | AC93: =AW93 -> 33.044457 | AI93: 15 | AJ93: 16.5 | AK93: =AJ93-AI93 -> 1.5 | AL93: =(AI93+AJ93)/2 -> 15.75 | AM93: Sand | AN93: 19 | AO93: =IF(AL93>$AA$20,$AA$22,$AA$21) -> 19.2 | AP93: =AP92+AO93*AK93 -> 304.2 | AQ93: =AP93-AO93*AK93/2-10*MAX(AL93-$AA$20,0) -> 222.3 | AT93: =IF(AR93="","",AR93-AS93) | AU93: 0.65 | AV93: =IF(AM93="Sand",0,Input!$AA$34*AN93) -> 0 | AW93: =IF(AM93="Sand",27.1+0.3*MIN(Input!$AA$35*AN93,60)-0.00054*MIN(Input!$AA$35*AN93,60)^2,MIN(MAX(DEGREES(ASIN(0.8-0.094*LN(MAX(IF(AT93="",10,AT93),5)))),20),30)) -> 33.044457 | AX93: =IF(AM93="Sand",Input!$AA$36*Input!$AA$35*AN93,Input!$AA$37*AV93) -> 20577 | AY93: =IF(AM93="Sand",Input!$AA$38,0.5) -> 0.3 | AZ93: =Input!$AA$15/2/AL93 -> 2.3492063 | BA93: =Input!$AA$16/2/AL93 -> 6.4126984 | BB93: =1/(4*PI())*(2*AZ93*BA93*SQRT(AZ93^2+BA93^2+1)/(AZ93^2+BA93^2+1+AZ93^2*BA93^2)*(AZ93^2+BA93^2+2)/(AZ93^2+BA93^2+1)+ATAN2(AZ93^2+BA93^2+1-AZ93^2*BA93^2,2*AZ93*BA93*SQRT(AZ93^2+BA93^2+1))) -> 0.24315603 | BC93: =4*Input!$AA$14*BB93 -> 132.27688 | BD93: =((Input!$AA$16/Input!$AA$15)*LN((1+SQRT((Input!$AA$16/Input!$AA$15)^2+1))*SQRT((Input!$AA$16/Input!$AA$15)^2+(AJ93/(Input!$AA$15/2))^2)/((Input!$AA$16/Input!$AA$15)*(1+SQRT((Input!$AA$16/Input!$AA$15)^2+(AJ93/(Input!$AA$15/2))^2+1))))+LN(((Input!$AA$16/Input!$AA$15)+SQRT((Input!$AA$16/Input!$AA$15)^2+1))*SQRT(1+(AJ93/(Input!$AA$15/2))^2)/((Input!$AA$16/Input!$AA$15)+SQRT((Input!$AA$16/Input!$AA$15)^2+(AJ93/(Input!$AA$15/2))^2+1))))/PI() -> 0.030866028 | BE93: =(AJ93/(Input!$AA$15/2))/(2*PI())*ATAN((Input!$AA$16/Input!$AA$15)/((AJ93/(Input!$AA$15/2))*SQRT((Input!$AA$16/Input!$AA$15)^2+(AJ93/(Input!$AA$15/2))^2+1))) -> 0.079696127 | BF93: =MAX(0,AJ93-MAX(AI93,$AA$23))/AK93*IF(BC93>=Input!$AA$21*AQ93,1,0) -> 1 | BG93: =4*Input!$AA$14*(Input!$AA$15/2)*(1-AY93^2)/AX93*((BD93-BD92)+(1-2*AY93)/(1-AY93)*(BE93-BE92))*1000*BF93 -> 6.9167814 | BH93: =IF(AM93="Sand",0,0.009*(AR93-10)) -> 0 | BI93: =BH93*Input!$AA$39 -> 0 | BJ93: =IF(AM93="Sand",0,MAX(AV93/Input!$AA$40,AQ93)) -> 0 | BK93: =IF(AM93="Sand",0,1000*AK93/(1+AU93)*IF(AQ93+BC93<=BJ93,BI93*LOG10((AQ93+BC93)/AQ93),BI93*LOG10(BJ93/AQ93)+BH93*LOG10((AQ93+BC93)/BJ93)))*BF93 -> 0 | BL93: =IF(AM93="Sand",0,10^(INDEX(Input!$Q$51:$Q$57,MIN(MATCH(MIN(MAX(AR93,30),120),Input!$C$51:$C$57,1),6))+(MIN(MAX(AR93,30),120)-INDEX(Input!$C$51:$C$57,MIN(MATCH(MIN(MAX(AR93,30),120),Input!$C$51:$C$57,1),6)))/(INDEX(Input!$C$51:$C$57,MIN(MATCH(MIN(MAX(AR93,30),120),Input!$C$51:$C$57,1),6)+1)-INDEX(Input!$C$51:$C$57,MIN(MATCH(MIN(MAX(AR93,30),120),Input!$C$51:$C$57,1),6)))*(INDEX(Input!$Q$51:$Q$57,MIN(MATCH(MIN(MAX(AR93,30),120),Input!$C$51:$C$57,1),6)+1)-INDEX(Input!$Q$51:$Q$57,MIN(MATCH(MIN(MAX(AR93,30),120),Input!$C$51:$C$57,1),6))))) -> 0 | BM93: =IF(OR(AM93="Sand",BF93=0),0,Input!$AA$41*(AK93/2)^2/(BL93*0.0001*31536000)) -> 0 | BN93: =MAX(0,MIN(AJ93,Input!$AA$20)-AI93) -> 0 | BO93: =MAX(0,MIN(AJ93,Input!$AA$20)-MAX(AI93,$AA$23)) -> 0 | BP93: =BG93+BK93 -> 6.9167814
...

Sheet BH-02
C2: PROJECT : | H2: GEOTHERMAL WELLPAD PSPE BORA PULU - SIGI, CENTRAL SULAWESI | X2: Prepared by : | AB2: Date
C3: CLIENT : | H3: PT EDC PANAS BUMI INDONESIA | X3: DF | AB3: 46301
C4: LOCATION : | H4: BH-02 (Wellpad A) | X4: Verified by : | AB4: Date
C5: SHEET : | H5: BEARING CAPACITY AND SETTLEMENT OF SUBGRADE | X5: BC | AB5: 46301
C7: 1. GENERAL
C8: This sheet evaluates the bearing capacity, lateral squeeze, immediate settlement and primary consolidation settlement
C9: of the subgrade below the wellpad embankment (2 m fill + 100 kPa uniform surcharge) at the borehole location.
C11: 1.1. Load and loaded area
C12: Height of embankment fill | X12: Hf = | AA12: =Input!$AA$11 -> 2 | AD12: m
C13: Uniform surcharge | X13: qs = | AA13: =Input!$AA$13 -> 100 | AD13: kPa
C14: Total pressure on subgrade | O14: q = Hf·γf + qs | X14: q = | AA14: =Input!$AA$14 -> 136 | AD14: kPa
C15: Loaded area (assumed) | O15: B × L | X15: B = | AA15: =Input!$AA$15 -> 74 | AD15: m
X16: L = | AA16: =Input!$AA$16 -> 202 | AD16: m
C17: Embankment side slope | O17: 1V : nH | X17: n = | AA17: =Input!$AA$23 -> 2 | AD17: -
C19: 1.2. Borehole data
C20: Design groundwater level (below ground) | X20: GWL = | AA20: 7 | AD20: m
C21: Unit weight above GWL | X21: γ = | AA21: 18.5 | AD21: kN/m³
C22: Unit weight below GWL | X22: γsat = | AA22: 18.4 | AD22: kN/m³
C23: Replacement depth (design condition) | O23: 0 = no improvement | X23: Dr = | AA23: 0 | AD23: m
C41: Figure 1. Typical cross-section of the wellpad embankment, design load and subsoil
X73: Sheet : | AB73: 1
C74: PROJECT : | H74: GEOTHERMAL WELLPAD PSPE BORA PULU - SIGI, CENTRAL SULAWESI | X74: Prepared by : | AB74: Date
C75: CLIENT : | H75: PT EDC PANAS BUMI INDONESIA | X75: DF | AB75: 46301
C76: LOCATION : | H76: BH-02 (Wellpad A) | X76: Verified by : | AB76: Date
C77: SHEET : | H77: BEARING CAPACITY AND SETTLEMENT OF SUBGRADE | X77: BC | AB77: 46301
C79: 2. SOIL PARAMETERS
C80: Table 1. Soil parameters of BH-02 (sub-layers = SPT intervals) | AI80: Helper calculation per sub-layer (not printed)
C81: No | E81: Top | H81: Bottom | K81: Soil | N81: N-SPT | Q81: γ | T81: LL | V81: PI | X81: e0 | Z81: cu | AC81: φ' | AI81: top | AJ81: bot | AK81: h | AL81: z | AM81: typ | AN81: N | AO81: g | AP81: sv | AQ81: s0 | AR81: LL | AS81: PL | AT81: PI | AU81: e0 | AV81: cu | AW81: phi | AX81: E | AY81: nu | AZ81: m | BA81: n | BB81: I | BC81: ds | BD81: F1 | BE81: F2 | BF81: keep | BG81: Si | BH81: Cc | BI81: Cr | BJ81: sp | BK81: Sc | BL81: Cv | BM81: t90 | BN81: hb0 | BO81: hbr | BP81: St | BQ81: ket
E82: m | H82: m | Q82: kN/m³ | T82: % | V82: % | X82: - | Z82: kPa | AC82: °
C83: 1 | E83: =AI83 -> 0 | H83: =AJ83 -> 1.5 | K83: =AM83 -> Sand | N83: =AN83 -> 50 | Q83: =AO83 -> 18.5 | T83: =IF(AR83="","-",AR83) -> - | V83: =IF(AT83="","-",AT83) -> - | X83: =AU83 -> 0.65 | Z83: =AV83 -> 0 | AC83: =AW83 -> 41.7616 | AI83: 0 | AJ83: 1.5 | AK83: =AJ83-AI83 -> 1.5 | AL83: =(AI83+AJ83)/2 -> 0.75 | AM83: Sand | AN83: 50 | AO83: =IF(AL83>$AA$20,$AA$22,$AA$21) -> 18.5 | AP83: =AO83*AK83 -> 27.75 | AQ83: =AP83-AO83*AK83/2-10*MAX(AL83-$AA$20,0) -> 13.875 | AT83: =IF(AR83="","",AR83-AS83) | AU83: 0.65 | AV83: =IF(AM83="Sand",0,Input!$AA$34*AN83) -> 0 | AW83: =IF(AM83="Sand",27.1+0.3*MIN(Input!$AA$35*AN83,60)-0.00054*MIN(Input!$AA$35*AN83,60)^2,MIN(MAX(DEGREES(ASIN(0.8-0.094*LN(MAX(IF(AT83="",10,AT83),5)))),20),30)) -> 41.7616 | AX83: =IF(AM83="Sand",Input!$AA$36*Input!$AA$35*AN83,Input!$AA$37*AV83) -> 54150 | AY83: =IF(AM83="Sand",Input!$AA$38,0.5) -> 0.3 | AZ83: =Input!$AA$15/2/AL83 -> 49.333333 | BA83: =Input!$AA$16/2/AL83 -> 134.66667 | BB83: =1/(4*PI())*(2*AZ83*BA83*SQRT(AZ83^2+BA83^2+1)/(AZ83^2+BA83^2+1+AZ83^2*BA83^2)*(AZ83^2+BA83^2+2)/(AZ83^2+BA83^2+1)+ATAN2(AZ83^2+BA83^2+1-AZ83^2*BA83^2,2*AZ83*BA83*SQRT(AZ83^2+BA83^2+1))) -> 0.2499991 | BC83: =4*Input!$AA$14*BB83 -> 135.99951 | BD83: =((Input!$AA$16/Input!$AA$15)*LN((1+SQRT((Input!$AA$16/Input!$AA$15)^2+1))*SQRT((Input!$AA$16/Input!$AA$15)^2+(AJ83/(Input!$AA$15/2))^2)/((Input!$AA$16/Input!$AA$15)*(1+SQRT((Input!$AA$16/Input!$AA$15)^2+(AJ83/(Input!$AA$15/2))^2+1))))+LN(((Input!$AA$16/Input!$AA$15)+SQRT((Input!$AA$16/Input!$AA$15)^2+1))*SQRT(1+(AJ83/(Input!$AA$15/2))^2)/((Input!$AA$16/Input!$AA$15)+SQRT((Input!$AA$16/Input!$AA$15)^2+(AJ83/(Input!$AA$15/2))^2+1))))/PI() -> 0.00027835774 | BE83: =(AJ83/(Input!$AA$15/2))/(2*PI())*ATAN((Input!$AA$16/Input!$AA$15)/((AJ83/(Input!$AA$15/2))*SQRT((Input!$AA$16/Input!$AA$15)^2+(AJ83/(Input!$AA$15/2))^2+1))) -> 0.0098567045 | BF83: =MAX(0,AJ83-MAX(AI83,$AA$23))/AK83*IF(BC83>=Input!$AA$21*AQ83,1,0) -> 1 | BG83: =4*Input!$AA$14*(Input!$AA$15/2)*(1-AY83^2)/AX83*((BD83-0)+(1-2*AY83)/(1-AY83)*(BE83-0))*1000*BF83 -> 1.9993411 | BH83: =IF(AM83="Sand",0,0.009*(AR83-10)) -> 0 | BI83: =BH83*Input!$AA$39 -> 0 | BJ83: =IF(AM83="Sand",0,MAX(AV83/Input!$AA$40,AQ83)) -> 0 | BK83: =IF(AM83="Sand",0,1000*AK83/(1+AU83)*IF(AQ83+BC83<=BJ83,BI83*LOG10((AQ83+BC83)/AQ83),BI83*LOG10(BJ83/AQ83)+BH83*LOG10((AQ83+BC83)/BJ83)))*BF83 -> 0 | BL83: =IF(AM83="Sand",0,10^(INDEX(Input!$Q$51:$Q$57,MIN(MATCH(MIN(MAX(AR83,30),120),Input!$C$51:$C$57,1),6))+(MIN(MAX(AR83,30),120)-INDEX(Input!$C$51:$C$57,MIN(MATCH(MIN(MAX(AR83,30),120),Input!$C$51:$C$57,1),6)))/(INDEX(Input!$C$51:$C$57,MIN(MATCH(MIN(MAX(AR83,30),120),Input!$C$51:$C$57,1),6)+1)-INDEX(Input!$C$51:$C$57,MIN(MATCH(MIN(MAX(AR83,30),120),Input!$C$51:$C$57,1),6)))*(INDEX(Input!$Q$51:$Q$57,MIN(MATCH(MIN(MAX(AR83,30),120),Input!$C$51:$C$57,1),6)+1)-INDEX(Input!$Q$51:$Q$57,MIN(MATCH(MIN(MAX(AR83,30),120),Input!$C$51:$C$57,1),6))))) -> 0 | BM83: =IF(OR(AM83="Sand",BF83=0),0,Input!$AA$41*(AK83/2)^2/(BL83*0.0001*31536000)) -> 0 | BN83: =MAX(0,MIN(AJ83,Input!$AA$20)-AI83) -> 1.5 | BO83: =MAX(0,MIN(AJ83,Input!$AA$20)-MAX(AI83,$AA$23)) -> 1.5 | BP83: =BG83+BK83 -> 1.9993411 | BQ83: 0-1.5 m not tested: N of next layer
C84: 2 | E84: =AI84 -> 1.5 | H84: =AJ84 -> 3 | K84: =AM84 -> Sand | N84: =AN84 -> 50 | Q84: =AO84 -> 18.5 | T84: =IF(AR84="","-",AR84) -> - | V84: =IF(AT84="","-",AT84) -> - | X84: =AU84 -> 0.65 | Z84: =AV84 -> 0 | AC84: =AW84 -> 41.7616 | AI84: 1.5 | AJ84: 3 | AK84: =AJ84-AI84 -> 1.5 | AL84: =(AI84+AJ84)/2 -> 2.25 | AM84: Sand | AN84: 50 | AO84: =IF(AL84>$AA$20,$AA$22,$AA$21) -> 18.5 | AP84: =AP83+AO84*AK84 -> 55.5 | AQ84: =AP84-AO84*AK84/2-10*MAX(AL84-$AA$20,0) -> 41.625 | AT84: =IF(AR84="","",AR84-AS84) | AU84: 0.65 | AV84: =IF(AM84="Sand",0,Input!$AA$34*AN84) -> 0 | AW84: =IF(AM84="Sand",27.1+0.3*MIN(Input!$AA$35*AN84,60)-0.00054*MIN(Input!$AA$35*AN84,60)^2,MIN(MAX(DEGREES(ASIN(0.8-0.094*LN(MAX(IF(AT84="",10,AT84),5)))),20),30)) -> 41.7616 | AX84: =IF(AM84="Sand",Input!$AA$36*Input!$AA$35*AN84,Input!$AA$37*AV84) -> 54150 | AY84: =IF(AM84="Sand",Input!$AA$38,0.5) -> 0.3 | AZ84: =Input!$AA$15/2/AL84 -> 16.444444 | BA84: =Input!$AA$16/2/AL84 -> 44.888889 | BB84: =1/(4*PI())*(2*AZ84*BA84*SQRT(AZ84^2+BA84^2+1)/(AZ84^2+BA84^2+1+AZ84^2*BA84^2)*(AZ84^2+BA84^2+2)/(AZ84^2+BA84^2+1)+ATAN2(AZ84^2+BA84^2+1-AZ84^2*BA84^2,2*AZ84*BA84*SQRT(AZ84^2+BA84^2+1))) -> 0.24997579 | BC84: =4*Input!$AA$14*BB84 -> 135.98683 | BD84: =((Input!$AA$16/Input!$AA$15)*LN((1+SQRT((Input!$AA$16/Input!$AA$15)^2+1))*SQRT((Input!$AA$16/Input!$AA$15)^2+(AJ84/(Input!$AA$15/2))^2)/((Input!$AA$16/Input!$AA$15)*(1+SQRT((Input!$AA$16/Input!$AA$15)^2+(AJ84/(Input!$AA$15/2))^2+1))))+LN(((Input!$AA$16/Input!$AA$15)+SQRT((Input!$AA$16/Input!$AA$15)^2+1))*SQRT(1+(AJ84/(Input!$AA$15/2))^2)/((Input!$AA$16/Input!$AA$15)+SQRT((Input!$AA$16/Input!$AA$15)^2+(AJ84/(Input!$AA$15/2))^2+1))))/PI() -> 0.0011108169 | BE84: =(AJ84/(Input!$AA$15/2))/(2*PI())*ATAN((Input!$AA$16/Input!$AA$15)/((AJ84/(Input!$AA$15/2))*SQRT((Input!$AA$16/Input!$AA$15)^2+(AJ84/(Input!$AA$15/2))^2+1))) -> 0.019158291 | BF84: =MAX(0,AJ84-MAX(AI84,$AA$23))/AK84*IF(BC84>=Input!$AA$21*AQ84,1,0) -> 1 | BG84: =4*Input!$AA$14*(Input!$AA$15/2)*(1-AY84^2)/AX84*((BD84-BD83)+(1-2*AY84)/(1-AY84)*(BE84-BE83))*1000*BF84 -> 2.0794707 | BH84: =IF(AM84="Sand",0,0.009*(AR84-10)) -> 0 | BI84: =BH84*Input!$AA$39 -> 0 | BJ84: =IF(AM84="Sand",0,MAX(AV84/Input!$AA$40,AQ84)) -> 0 | BK84: =IF(AM84="Sand",0,1000*AK84/(1+AU84)*IF(AQ84+BC84<=BJ84,BI84*LOG10((AQ84+BC84)/AQ84),BI84*LOG10(BJ84/AQ84)+BH84*LOG10((AQ84+BC84)/BJ84)))*BF84 -> 0 | BL84: =IF(AM84="Sand",0,10^(INDEX(Input!$Q$51:$Q$57,MIN(MATCH(MIN(MAX(AR84,30),120),Input!$C$51:$C$57,1),6))+(MIN(MAX(AR84,30),120)-INDEX(Input!$C$51:$C$57,MIN(MATCH(MIN(MAX(AR84,30),120),Input!$C$51:$C$57,1),6)))/(INDEX(Input!$C$51:$C$57,MIN(MATCH(MIN(MAX(AR84,30),120),Input!$C$51:$C$57,1),6)+1)-INDEX(Input!$C$51:$C$57,MIN(MATCH(MIN(MAX(AR84,30),120),Input!$C$51:$C$57,1),6)))*(INDEX(Input!$Q$51:$Q$57,MIN(MATCH(MIN(MAX(AR84,30),120),Input!$C$51:$C$57,1),6)+1)-INDEX(Input!$Q$51:$Q$57,MIN(MATCH(MIN(MAX(AR84,30),120),Input!$C$51:$C$57,1),6))))) -> 0 | BM84: =IF(OR(AM84="Sand",BF84=0),0,Input!$AA$41*(AK84/2)^2/(BL84*0.0001*31536000)) -> 0 | BN84: =MAX(0,MIN(AJ84,Input!$AA$20)-AI84) -> 1.5 | BO84: =MAX(0,MIN(AJ84,Input!$AA$20)-MAX(AI84,$AA$23)) -> 1.5 | BP84: =BG84+BK84 -> 2.0794707
C85: 3 | E85: =AI85 -> 3 | H85: =AJ85 -> 4.5 | K85: =AM85 -> Sand | N85: =AN85 -> 50 | Q85: =AO85 -> 18.5 | T85: =IF(AR85="","-",AR85) -> - | V85: =IF(AT85="","-",AT85) -> - | X85: =AU85 -> 0.65 | Z85: =AV85 -> 0 | AC85: =AW85 -> 41.7616 | AI85: 3 | AJ85: 4.5 | AK85: =AJ85-AI85 -> 1.5 | AL85: =(AI85+AJ85)/2 -> 3.75 | AM85: Sand | AN85: 50 | AO85: =IF(AL85>$AA$20,$AA$22,$AA$21) -> 18.5 | AP85: =AP84+AO85*AK85 -> 83.25 | AQ85: =AP85-AO85*AK85/2-10*MAX(AL85-$AA$20,0) -> 69.375 | AT85: =IF(AR85="","",AR85-AS85) | AU85: 0.65 | AV85: =IF(AM85="Sand",0,Input!$AA$34*AN85) -> 0 | AW85: =IF(AM85="Sand",27.1+0.3*MIN(Input!$AA$35*AN85,60)-0.00054*MIN(Input!$AA$35*AN85,60)^2,MIN(MAX(DEGREES(ASIN(0.8-0.094*LN(MAX(IF(AT85="",10,AT85),5)))),20),30)) -> 41.7616 | AX85: =IF(AM85="Sand",Input!$AA$36*Input!$AA$35*AN85,Input!$AA$37*AV85) -> 54150 | AY85: =IF(AM85="Sand",Input!$AA$38,0.5) -> 0.3 | AZ85: =Input!$AA$15/2/AL85 -> 9.8666667 | BA85: =Input!$AA$16/2/AL85 -> 26.933333 | BB85: =1/(4*PI())*(2*AZ85*BA85*SQRT(AZ85^2+BA85^2+1)/(AZ85^2+BA85^2+1+AZ85^2*BA85^2)*(AZ85^2+BA85^2+2)/(AZ85^2+BA85^2+1)+ATAN2(AZ85^2+BA85^2+1-AZ85^2*BA85^2,2*AZ85*BA85*SQRT(AZ85^2+BA85^2+1))) -> 0.2498888 | BC85: =4*Input!$AA$14*BB85 -> 135.93951 | BD85: =((Input!$AA$16/Input!$AA$15)*LN((1+SQRT((Input!$AA$16/Input!$AA$15)^2+1))*SQRT((Input!$AA$16/Input!$AA$15)^2+(AJ85/(Input!$AA$15/2))^2)/((Input!$AA$16/Input!$AA$15)*(1+SQRT((Input!$AA$16/Input!$AA$15)^2+(AJ85/(Input!$AA$15/2))^2+1))))+LN(((Input!$AA$16/Input!$AA$15)+SQRT((Input!$AA$16/Input!$AA$15)^2+1))*SQRT(1+(AJ85/(Input!$AA$15/2))^2)/((Input!$AA$16/Input!$AA$15)+SQRT((Input!$AA$16/Input!$AA$15)^2+(AJ85/(Input!$AA$15/2))^2+1))))/PI() -> 0.0024896187 | BE85: =(AJ85/(Input!$AA$15/2))/(2*PI())*ATAN((Input!$AA$16/Input!$AA$15)/((AJ85/(Input!$AA$15/2))*SQRT((Input!$AA$16/Input!$AA$15)^2+(AJ85/(Input!$AA$15/2))^2+1))) -> 0.027909941 | BF85: =MAX(0,AJ85-MAX(AI85,$AA$23))/AK85*IF(BC85>=Input!$AA$21*AQ85,1,0) -> 1 | BG85: =4*Input!$AA$14*(Input!$AA$15/2)*(1-AY85^2)/AX85*((BD85-BD84)+(1-2*AY85)/(1-AY85)*(BE85-BE84))*1000*BF85 -> 2.1579772 | BH85: =IF(AM85="Sand",0,0.009*(AR85-10)) -> 0 | BI85: =BH85*Input!$AA$39 -> 0 | BJ85: =IF(AM85="Sand",0,MAX(AV85/Input!$AA$40,AQ85)) -> 0 | BK85: =IF(AM85="Sand",0,1000*AK85/(1+AU85)*IF(AQ85+BC85<=BJ85,BI85*LOG10((AQ85+BC85)/AQ85),BI85*LOG10(BJ85/AQ85)+BH85*LOG10((AQ85+BC85)/BJ85)))*BF85 -> 0 | BL85: =IF(AM85="Sand",0,10^(INDEX(Input!$Q$51:$Q$57,MIN(MATCH(MIN(MAX(AR85,30),120),Input!$C$51:$C$57,1),6))+(MIN(MAX(AR85,30),120)-INDEX(Input!$C$51:$C$57,MIN(MATCH(MIN(MAX(AR85,30),120),Input!$C$51:$C$57,1),6)))/(INDEX(Input!$C$51:$C$57,MIN(MATCH(MIN(MAX(AR85,30),120),Input!$C$51:$C$57,1),6)+1)-INDEX(Input!$C$51:$C$57,MIN(MATCH(MIN(MAX(AR85,30),120),Input!$C$51:$C$57,1),6)))*(INDEX(Input!$Q$51:$Q$57,MIN(MATCH(MIN(MAX(AR85,30),120),Input!$C$51:$C$57,1),6)+1)-INDEX(Input!$Q$51:$Q$57,MIN(MATCH(MIN(MAX(AR85,30),120),Input!$C$51:$C$57,1),6))))) -> 0 | BM85: =IF(OR(AM85="Sand",BF85=0),0,Input!$AA$41*(AK85/2)^2/(BL85*0.0001*31536000)) -> 0 | BN85: =MAX(0,MIN(AJ85,Input!$AA$20)-AI85) -> 1.5 | BO85: =MAX(0,MIN(AJ85,Input!$AA$20)-MAX(AI85,$AA$23)) -> 1.5 | BP85: =BG85+BK85 -> 2.1579772
