Workbook

Sheet Input
C2: PROJECT : | H2: GEOTHERMAL WELLPAD PSPE BORA PULU - SIGI, CENTRAL SULAWESI | X2: Prepared by : | AB2: Date
C3: CLIENT : | H3: PT EDC PANAS BUMI INDONESIA | X3: DF | AB3: 46301
C4: LOCATION : | H4: All boreholes (BH-01 to BH-05) | X4: Verified by : | AB4: Date
C5: SHEET : | H5: DESIGN INPUT & CORRELATIONS | X5: BC | AB5: 46301
C7: 1. DESIGN INPUT
C8: Input cells are shaded blue. All borehole sheets and the summary are calculated from this sheet.
C10: 1.1. Design load
C11: Height of embankment fill | O11: design brief | X11: Hf = | AA11: 2 | AD11: m
C12: Unit weight of compacted fill | O12: assumed | X12: γf = | AA12: 18 | AD12: kN/m³
C13: Uniform surcharge on platform | O13: design brief | X13: qs = | AA13: 100 | AD13: kPa
C14: Total pressure on subgrade | O14: q = Hf·γf + qs | X14: q = | AA14: =$AA$11*$AA$12+$AA$13 | AD14: kPa
C15: Width of loaded area (assumed) | O15: to be confirmed | X15: B = | AA15: 40 | AD15: m
C16: Length of loaded area (assumed, L ≥ B) | O16: to be confirmed | X16: L = | AA16: 60 | AD16: m
C18: 1.2. Design criteria
C19: Factor of safety for bearing capacity | O19: SNI 8460:2017 | X19: SF = | AA19: 3 | AD19: -
C20: Depth for averaging shear strength | O20: as previous template | X20: Hb = | AA20: 5 | AD20: m
C21: Influence depth limit: Δσz / σ'v0 ≥ | O21: Das (2019) | X21: ratio = | AA21: 0.1 | AD21: -
C22: Allowable total settlement (assumed) | O22: to be confirmed | X22: S all = | AA22: 100 | AD22: mm
C24: 1.3. Replacement material
C25: Unit weight of compacted granular fill | O25: assumed | X25: γr = | AA25: 19 | AD25: kN/m³
C26: Friction angle of granular fill | O26: assumed | X26: φ'r = | AA26: 35 | AD26: °
C27: Replacement depth Dr is entered on each borehole sheet.
C29: 2. CORRELATIONS (used where no laboratory test is available)
C31: Undrained shear strength, cu = k·N | O31: Stroud (1974) | X31: k = | AA31: 5 | AD31: kPa
C32: Energy correction, N60 = CE·N | O32: liquefaction report | X32: CE = | AA32: 1.083 | AD32: -
C33: Sand modulus, Es = k·N60 | O33: Kulhawy & Mayne (1990) | X33: k = | AA33: 1000 | AD33: kPa
C34: Silt/clay undrained modulus, Eu = k·cu | O34: Bowles (1996) | X34: k = | AA34: 500 | AD34: -
C35: Poisson ratio of sand (drained) | O35: silt/clay undrained ν = 0.5 | X35: ν = | AA35: 0.3 | AD35: -
C36: Recompression ratio Cr / Cc | O36: Das (2019) | X36: Cr/Cc = | AA36: 0.2 | AD36: -
C37: Strength ratio su / σ'p | O37: Mesri (1975) | X37: ratio = | AA37: 0.22 | AD37: -
C38: Time factor for 90 % consolidation | O38: Terzaghi | X38: Tv = | AA38: 0.848 | AD38: -
C40: Compression index Cc = 0.009 (LL - 10) (Terzaghi & Peck, 1967).
C41: Sand friction angle φ' = 27.1 + 0.3 N60 - 0.00054 N60² (Wolff, 1989).
C42: Silt/clay friction angle sin φ' = 0.8 - 0.094 ln(PI) (Terzaghi, Peck & Mesri, 1996), limited to 20° - 30°.
C43: No oedometer test is available; Cc, Cr, σ'p and Cv are correlated values.
C45: 3. COEFFICIENT OF CONSOLIDATION vs LIQUID LIMIT (NAVFAC DM-7.1)
C46: LL | I46: Cv | Q46: log10 Cv
C47: % | I47: cm²/s | Q47: -
C48: 30 | I48: 0.003 | Q48: =LOG10(I48)
C49: 40 | I49: 0.0015 | Q49: =LOG10(I49)
...

Sheet Summary
C2: PROJECT : | H2: GEOTHERMAL WELLPAD PSPE BORA PULU - SIGI, CENTRAL SULAWESI | X2: Prepared by : | AB2: Date
C3: CLIENT : | H3: PT EDC PANAS BUMI INDONESIA | X3: DF | AB3: 46301
C4: LOCATION : | H4: All boreholes (BH-01 to BH-05) | X4: Verified by : | AB4: Date
C5: SHEET : | H5: SUMMARY - BEARING CAPACITY AND SETTLEMENT | X5: BC | AB5: 46301
C7: SUMMARY OF BEARING CAPACITY AND SETTLEMENT OF SUBGRADE
C8: ="Load: "&TEXT(Input!$AA$11,"0.0")&" m embankment fill + "&TEXT(Input!$AA$13,"0")&" kPa uniform surcharge → q = "&TEXT(Input!$AA$14,"0")&" kPa; loaded area "&TEXT(Input!$AA$15,"0")&" m × "&TEXT(Input!$AA$16,"0")&" m"
C10: Item | M10: Unit | P10: BH-01 | S10: BH-02 | V10: BH-03 | Y10: BH-04 | AB10: BH-05
P11: Wellpad D | S11: Wellpad A | V11: Log Yard | Y11: Wellpad D | AB11: Wellpad A
C12: Silt/clay thickness within 0 - Hb | M12: m | P12: ='BH-01'!$AA$86 | S12: ='BH-02'!$AA$86 | V12: ='BH-03'!$AA$86 | Y12: ='BH-04'!$AA$86 | AB12: ='BH-05'!$AA$86
C13: Average cu (silt/clay) | M13: kPa | P13: ='BH-01'!$AA$87 | S13: ='BH-02'!$AA$87 | V13: ='BH-03'!$AA$87 | Y13: ='BH-04'!$AA$87 | AB13: ='BH-05'!$AA$87
C14: Average φ' | M14: ° | P14: ='BH-01'!$AA$88 | S14: ='BH-02'!$AA$88 | V14: ='BH-03'!$AA$88 | Y14: ='BH-04'!$AA$88 | AB14: ='BH-05'!$AA$88
C15: qall - without improvement | M15: kPa | P15: ='BH-01'!$AA$97 | S15: ='BH-02'!$AA$97 | V15: ='BH-03'!$AA$97 | Y15: ='BH-04'!$AA$97 | AB15: ='BH-05'!$AA$97
C16: FS - without improvement | M16: - | P16: ='BH-01'!$AA$99 | S16: ='BH-02'!$AA$99 | V16: ='BH-03'!$AA$99 | Y16: ='BH-04'!$AA$99 | AB16: ='BH-05'!$AA$99
C17: Check - without improvement | P17: ='BH-01'!$X$101 | S17: ='BH-02'!$X$101 | V17: ='BH-03'!$X$101 | Y17: ='BH-04'!$X$101 | AB17: ='BH-05'!$X$101
C18: Replacement depth Dr | M18: m | P18: ='BH-01'!$AA$22 | S18: ='BH-02'!$AA$22 | V18: ='BH-03'!$AA$22 | Y18: ='BH-04'!$AA$22 | AB18: ='BH-05'!$AA$22
C19: qall - design condition | M19: kPa | P19: ='BH-01'!$AA$115 | S19: ='BH-02'!$AA$115 | V19: ='BH-03'!$AA$115 | Y19: ='BH-04'!$AA$115 | AB19: ='BH-05'!$AA$115
C20: FS - design condition | M20: - | P20: ='BH-01'!$AA$117 | S20: ='BH-02'!$AA$117 | V20: ='BH-03'!$AA$117 | Y20: ='BH-04'!$AA$117 | AB20: ='BH-05'!$AA$117
C21: Check - design condition | P21: ='BH-01'!$X$119 | S21: ='BH-02'!$X$119 | V21: ='BH-03'!$X$119 | Y21: ='BH-04'!$X$119 | AB21: ='BH-05'!$X$119
C22: Allowable fill height (design) | M22: m | P22: ='BH-01'!$AA$118 | S22: ='BH-02'!$AA$118 | V22: ='BH-03'!$AA$118 | Y22: ='BH-04'!$AA$118 | AB22: ='BH-05'!$AA$118
C23: qa for 25 mm (granular soil) | M23: kPa | P23: ='BH-01'!$AA$123 | S23: ='BH-02'!$AA$123 | V23: ='BH-03'!$AA$123 | Y23: ='BH-04'!$AA$123 | AB23: ='BH-05'!$AA$123
C24: Immediate settlement Si | M24: mm | P24: ='BH-01'!$AA$201 | S24: ='BH-02'!$AA$201 | V24: ='BH-03'!$AA$201 | Y24: ='BH-04'!$AA$201 | AB24: ='BH-05'!$AA$201
C25: Sand settlement - B&B check | M25: mm | P25: ='BH-01'!$AA$229 | S25: ='BH-02'!$AA$229 | V25: ='BH-03'!$AA$229 | Y25: ='BH-04'!$AA$229 | AB25: ='BH-05'!$AA$229
C26: Consolidation settlement Sc | M26: mm | P26: ='BH-01'!$AA$280 | S26: ='BH-02'!$AA$280 | V26: ='BH-03'!$AA$280 | Y26: ='BH-04'!$AA$280 | AB26: ='BH-05'!$AA$280
C27: Time for 90 % consolidation | M27: year | P27: ='BH-01'!$AA$281 | S27: ='BH-02'!$AA$281 | V27: ='BH-03'!$AA$281 | Y27: ='BH-04'!$AA$281 | AB27: ='BH-05'!$AA$281
C28: Total settlement S = Si + Sc | M28: mm | P28: ='BH-01'!$AA$305 | S28: ='BH-02'!$AA$305 | V28: ='BH-03'!$AA$305 | Y28: ='BH-04'!$AA$305 | AB28: ='BH-05'!$AA$305
C30: NOTES
C31: 1. Bearing capacity: undrained (cu·Nc) where silt/clay exists within 0 - Hb; drained (Vesic) for granular soil.
C32: For a wide loaded area the Nγ term gives a very large drained capacity, i.e. shear failure does not govern;
C33: settlement governs the design.
C34: 2. Granular soil: (a) drained bearing capacity with φ' from N-SPT; (b) allowable pressure for 25 mm settlement
C35: (Meyerhof/Bowles); (c) immediate settlement by the layered elastic method (upper bound, constant E) and by
C36: Burland & Burbidge (empirical, more realistic for sand); (d) no primary consolidation in sand; (e) loose
C37: saturated sand: add post-liquefaction settlement for the seismic case.
C38: 3. The loaded area B × L (Input sheet) is an assumption (40 m × 60 m). Settlement is sensitive to the loaded
C39: area.
C40: 4. Post-liquefaction settlement (liquefaction report, Table 5.4): BH-01 289, BH-02 383, BH-03 227, BH-04 159,
C41: BH-05 100 mm - assessed separately.
... C45: compacted granular fill is applied.
X73: Sheet : | AB73: 1

Sheet BH-01
C2: PROJECT : | H2: GEOTHERMAL WELLPAD PSPE BORA PULU - SIGI, CENTRAL SULAWESI | X2: Prepared by : | AB2: Date
C3: CLIENT : | H3: PT EDC PANAS BUMI INDONESIA | X3: DF | AB3: 46301
C4: LOCATION : | H4: BH-01 (Wellpad D) | X4: Verified by : | AB4: Date
C5: SHEET : | H5: BEARING CAPACITY AND SETTLEMENT OF SUBGRADE | X5: BC | AB5: 46301
C7: 1. GENERAL
C8: This sheet evaluates the bearing capacity, immediate settlement and primary consolidation settlement of the subgrade
C9: below the wellpad embankment (2 m fill + 100 kPa uniform surcharge) at the borehole location.
C11: 1.1. Load and loaded area
C12: Height of embankment fill | O12: (Input) | X12: Hf = | AA12: =Input!$AA$11 | AD12: m
C13: Uniform surcharge | O13: (Input) | X13: qs = | AA13: =Input!$AA$13 | AD13: kPa
C14: Total pressure on subgrade | O14: q = Hf·γf + qs | X14: q = | AA14: =Input!$AA$14 | AD14: kPa
C15: Loaded area (assumed) | O15: B × L | X15: B = | AA15: =Input!$AA$15 | AD15: m
X16: L = | AA16: =Input!$AA$16 | AD16: m
C18: 1.2. Borehole data
C19: Design groundwater level (below ground) | O19: liquefaction report | X19: GWL = | AA19: 9 | AD19: m
C20: Unit weight above GWL | O20: report Table 5.1 | X20: γ = | AA20: 17.8 | AD20: kN/m³
C21: Unit weight below GWL | O21: report Table 5.1 | X21: γsat = | AA21: 19.2 | AD21: kN/m³
C22: Replacement depth (design condition) | O22: 0 = no improvement | X22: Dr = | AA22: 3 | AD22: m
C24: 2. SOIL PARAMETERS
C25: Table 1. Soil parameters of BH-01 (sub-layers = SPT intervals) | AI25: Helper calculation per sub-layer (not printed)
C26: No | E26: Top | H26: Bottom | K26: Soil | N26: N-SPT | Q26: γ | T26: LL | V26: PI | X26: e0 | Z26: cu | AC26: φ' | AI26: top | AJ26: bot | AK26: h | AL26: z | AM26: typ | AN26: N | AO26: g | AP26: sv | AQ26: s0 | AR26: LL | AS26: PL | AT26: PI | AU26: e0 | AV26: cu | AW26: phi | AX26: E | AY26: nu | AZ26: m | BA26: n | BB26: I | BC26: ds | BD26: F1 | BE26: F2 | BF26: keep | BG26: Si | BH26: Cc | BI26: Cr | BJ26: sp | BK26: Sc | BL26: Cv | BM26: t90 | BN26: hb0 | BO26: hbr | BP26: hzi | BQ26: ket
E27: m | H27: m | Q27: kN/m³ | T27: % | V27: % | X27: - | Z27: kPa | AC27: °
C28: 1 | E28: =AI28 | H28: =AJ28 | K28: =AM28 | N28: =AN28 | Q28: =AO28 | T28: =IF(AR28="","-",AR28) | V28: =IF(AT28="","-",AT28) | X28: =AU28 | Z28: =AV28 | AC28: =AW28 | AI28: 0 | AJ28: 1.5 | AK28: =AJ28-AI28 | AL28: =(AI28+AJ28)/2 | AM28: Clay | AN28: 5 | AO28: =IF(AL28>$AA$19,$AA$21,$AA$20) | AP28: =AO28*AK28 | AQ28: =AP28-AO28*AK28/2-10*MAX(AL28-$AA$19,0) | AR28: 29.665 | AS28: 19.806 | AT28: =IF(AR28="","",AR28-AS28) | AU28: 0.681 | AV28: =IF(AM28="Sand",0,Input!$AA$31*AN28) | AW28: =IF(AM28="Sand",27.1+0.3*MIN(Input!$AA$32*AN28,60)-0.00054*MIN(Input!$AA$32*AN28,60)^2,MIN(MAX(DEGREES(ASIN(0.8-0.094*LN(MAX(IF(AT28="",10,AT28),5)))),20),30)) | AX28: =IF(AM28="Sand",Input!$AA$33*Input!$AA$32*AN28,Input!$AA$34*AV28) | AY28: =IF(AM28="Sand",Input!$AA$35,0.5) | AZ28: =Input!$AA$15/2/AL28 | BA28: =Input!$AA$16/2/AL28 | BB28: =1/(4*PI())*(2*AZ28*BA28*SQRT(AZ28^2+BA28^2+1)/(AZ28^2+BA28^2+1+AZ28^2*BA28^2)*(AZ28^2+BA28^2+2)/(AZ28^2+BA28^2+1)+ATAN2(AZ28^2+BA28^2+1-AZ28^2*BA28^2,2*AZ28*BA28*SQRT(AZ28^2+BA28^2+1))) | BC28: =4*Input!$AA$14*BB28 | BD28: =((Input!$AA$16/Input!$AA$15)*LN((1+SQRT((Input!$AA$16/Input!$AA$15)^2+1))*SQRT((Input!$AA$16/Input!$AA$15)^2+(AJ28/(Input!$AA$15/2))^2)/((Input!$AA$16/Input!$AA$15)*(1+SQRT((Input!$AA$16/Input!$AA$15)^2+(AJ28/(Input!$AA$15/2))^2+1))))+LN(((Input!$AA$16/Input!$AA$15)+SQRT((Input!$AA$16/Input!$AA$15)^2+1))*SQRT(1+(AJ28/(Input!$AA$15/2))^2)/((Input!$AA$16/Input!$AA$15)+SQRT((Input!$AA$16/Input!$AA$15)^2+(AJ28/(Input!$AA$15/2))^2+1))))/PI() | BE28: =(AJ28/(Input!$AA$15/2))/(2*PI())*ATAN((Input!$AA$16/Input!$AA$15)/((AJ28/(Input!$AA$15/2))*SQRT((Input!$AA$16/Input!$AA$15)^2+(AJ28/(Input!$AA$15/2))^2+1))) | BF28: =MAX(0,AJ28-MAX(AI28,$AA$22))/AK28*IF(BC28>=Input!$AA$21*AQ28,1,0) | BG28: =4*Input!$AA$14*(Input!$AA$15/2)*(1-AY28^2)/AX28*((BD28-0)+(1-2*AY28)/(1-AY28)*(BE28-0))*1000*BF28 | BH28: =IF(AM28="Sand",0,0.009*(AR28-10)) | BI28: =BH28*Input!$AA$36 | BJ28: =IF(AM28="Sand",0,MAX(AV28/Input!$AA$37,AQ28)) | BK28: =IF(AM28="Sand",0,1000*AK28/(1+AU28)*IF(AQ28+BC28<=BJ28,BI28*LOG10((AQ28+BC28)/AQ28),BI28*LOG10(BJ28/AQ28)+BH28*LOG10((AQ28+BC28)/BJ28)))*BF28 | BL28: =IF(AM28="Sand",0,10^(INDEX(Input!$Q$48:$Q$54,MIN(MATCH(MIN(MAX(AR28,30),120),Input!$C$48:$C$54,1),6))+(MIN(MAX(AR28,30),120)-INDEX(Input!$C$48:$C$54,MIN(MATCH(MIN(MAX(AR28,30),120),Input!$C$48:$C$54,1),6)))/(INDEX(Input!$C$48:$C$54,MIN(MATCH(MIN(MAX(AR28,30),120),Input!$C$48:$C$54,1),6)+1)-INDEX(Input!$C$48:$C$54,MIN(MATCH(MIN(MAX(AR28,30),120),Input!$C$48:$C$54,1),6)))*(INDEX(Input!$Q$48:$Q$54,MIN(MATCH(MIN(MAX(AR28,30),120),Input!$C$48:$C$54,1),6)+1)-INDEX(Input!$Q$48:$Q$54,MIN(MATCH(MIN(MAX(AR28,30),120),Input!$C$48:$C$54,1),6))))) | BM28: =IF(OR(AM28="Sand",BF28=0),0,Input!$AA$38*(AK28/2)^2/(BL28*1E-4*31536000)) | BN28: =MAX(0,MIN(AJ28,Input!$AA$20)-AI28) | BO28: =MAX(0,MIN(AJ28,Input!$AA$20)-MAX(AI28,$AA$22)) | BP28: =MAX(0,MIN(AJ28,$AA$225)-AI28) | BQ28: 0-1.5 m not tested: N of next layer; LL/PL/e0 = borehole average
C29: 2 | E29: =AI29 | H29: =AJ29 | K29: =AM29 | N29: =AN29 | Q29: =AO29 | T29: =IF(AR29="","-",AR29) | V29: =IF(AT29="","-",AT29) | X29: =AU29 | Z29: =AV29 | AC29: =AW29 | AI29: 1.5 | AJ29: 3 | AK29: =AJ29-AI29 | AL29: =(AI29+AJ29)/2 | AM29: Clay | AN29: 5 | AO29: =IF(AL29>$AA$19,$AA$21,$AA$20) | AP29: =AP28+AO29*AK29 | AQ29: =AP29-AO29*AK29/2-10*MAX(AL29-$AA$19,0) | AR29: 29.665 | AS29: 19.806 | AT29: =IF(AR29="","",AR29-AS29) | AU29: 0.952 | AV29: =IF(AM29="Sand",0,Input!$AA$31*AN29) | AW29: =IF(AM29="Sand",27.1+0.3*MIN(Input!$AA$32*AN29,60)-0.00054*MIN(Input!$AA$32*AN29,60)^2,MIN(MAX(DEGREES(ASIN(0.8-0.094*LN(MAX(IF(AT29="",10,AT29),5)))),20),30)) | AX29: =IF(AM29="Sand",Input!$AA$33*Input!$AA$32*AN29,Input!$AA$34*AV29) | AY29: =IF(AM29="Sand",Input!$AA$35,0.5) | AZ29: =Input!$AA$15/2/AL29 | BA29: =Input!$AA$16/2/AL29 | BB29: =1/(4*PI())*(2*AZ29*BA29*SQRT(AZ29^2+BA29^2+1)/(AZ29^2+BA29^2+1+AZ29^2*BA29^2)*(AZ29^2+BA29^2+2)/(AZ29^2+BA29^2+1)+ATAN2(AZ29^2+BA29^2+1-AZ29^2*BA29^2,2*AZ29*BA29*SQRT(AZ29^2+BA29^2+1))) | BC29: =4*Input!$AA$14*BB29 | BD29: =((Input!$AA$16/Input!$AA$15)*LN((1+SQRT((Input!$AA$16/Input!$AA$15)^2+1))*SQRT((Input!$AA$16/Input!$AA$15)^2+(AJ29/(Input!$AA$15/2))^2)/((Input!$AA$16/Input!$AA$15)*(1+SQRT((Input!$AA$16/Input!$AA$15)^2+(AJ29/(Input!$AA$15/2))^2+1))))+LN(((Input!$AA$16/Input!$AA$15)+SQRT((Input!$AA$16/Input!$AA$15)^2+1))*SQRT(1+(AJ29/(Input!$AA$15/2))^2)/((Input!$AA$16/Input!$AA$15)+SQRT((Input!$AA$16/Input!$AA$15)^2+(AJ29/(Input!$AA$15/2))^2+1))))/PI() | BE29: =(AJ29/(Input!$AA$15/2))/(2*PI())*ATAN((Input!$AA$16/Input!$AA$15)/((AJ29/(Input!$AA$15/2))*SQRT((Input!$AA$16/Input!$AA$15)^2+(AJ29/(Input!$AA$15/2))^2+1))) | BF29: =MAX(0,AJ29-MAX(AI29,$AA$22))/AK29*IF(BC29>=Input!$AA$21*AQ29,1,0) | BG29: =4*Input!$AA$14*(Input!$AA$15/2)*(1-AY29^2)/AX29*((BD29-BD28)+(1-2*AY29)/(1-AY29)*(BE29-BE28))*1000*BF29 | BH29: =IF(AM29="Sand",0,0.009*(AR29-10)) | BI29: =BH29*Input!$AA$36 | BJ29: =IF(AM29="Sand",0,MAX(AV29/Input!$AA$37,AQ29)) | BK29: =IF(AM29="Sand",0,1000*AK29/(1+AU29)*IF(AQ29+BC29<=BJ29,BI29*LOG10((AQ29+BC29)/AQ29),BI29*LOG10(BJ29/AQ29)+BH29*LOG10((AQ29+BC29)/BJ29)))*BF29 | BL29: =IF(AM29="Sand",0,10^(INDEX(Input!$Q$48:$Q$54,MIN(MATCH(MIN(MAX(AR29,30),120),Input!$C$48:$C$54,1),6))+(MIN(MAX(AR29,30),120)-INDEX(Input!$C$48:$C$54,MIN(MATCH(MIN(MAX(AR29,30),120),Input!$C$48:$C$54,1),6)))/(INDEX(Input!$C$48:$C$54,MIN(MATCH(MIN(MAX(AR29,30),120),Input!$C$48:$C$54,1),6)+1)-INDEX(Input!$C$48:$C$54,MIN(MATCH(MIN(MAX(AR29,30),120),Input!$C$48:$C$54,1),6)))*(INDEX(Input!$Q$48:$Q$54,MIN(MATCH(MIN(MAX(AR29,30),120),Input!$C$48:$C$54,1),6)+1)-INDEX(Input!$Q$48:$Q$54,MIN(MATCH(MIN(MAX(AR29,30),120),Input!$C$48:$C$54,1),6))))) | BM29: =IF(OR(AM29="Sand",BF29=0),0,Input!$AA$38*(AK29/2)^2/(BL29*1E-4*31536000)) | BN29: =MAX(0,MIN(AJ29,Input!$AA$20)-AI29) | BO29: =MAX(0,MIN(AJ29,Input!$AA$20)-MAX(AI29,$AA$22)) | BP29: =MAX(0,MIN(AJ29,$AA$225)-AI29) | BQ29: LL/PL/e0 = borehole average
C30: 3 | E30: =AI30 | H30: =AJ30 | K30: =AM30 | N30: =AN30 | Q30: =AO30 | T30: =IF(AR30="","-",AR30) | V30: =IF(AT30="","-",AT30) | X30: =AU30 | Z30: =AV30 | AC30: =AW30 | AI30: 3 | AJ30: 5.5 | AK30: =AJ30-AI30 | AL30: =(AI30+AJ30)/2 | AM30: Sand | AN30: 18 | AO30: =IF(AL30>$AA$19,$AA$21,$AA$20) | AP30: =AP29+AO30*AK30 | AQ30: =AP30-AO30*AK30/2-10*MAX(AL30-$AA$19,0) | AT30: =IF(AR30="","",AR30-AS30) | AU30: 0.759 | AV30: =IF(AM30="Sand",0,Input!$AA$31*AN30) | AW30: =IF(AM30="Sand",27.1+0.3*MIN(Input!$AA$32*AN30,60)-0.00054*MIN(Input!$AA$32*AN30,60)^2,MIN(MAX(DEGREES(ASIN(0.8-0.094*LN(MAX(IF(AT30="",10,AT30),5)))),20),30)) | AX30: =IF(AM30="Sand",Input!$AA$33*Input!$AA$32*AN30,Input!$AA$34*AV30) | AY30: =IF(AM30="Sand",Input!$AA$35,0.5) | AZ30: =Input!$AA$15/2/AL30 | BA30: =Input!$AA$16/2/AL30 | BB30: =1/(4*PI())*(2*AZ30*BA30*SQRT(AZ30^2+BA30^2+1)/(AZ30^2+BA30^2+1+AZ30^2*BA30^2)*(AZ30^2+BA30^2+2)/(AZ30^2+BA30^2+1)+ATAN2(AZ30^2+BA30^2+1-AZ30^2*BA30^2,2*AZ30*BA30*SQRT(AZ30^2+BA30^2+1))) | BC30: =4*Input!$AA$14*BB30 | BD30: =((Input!$AA$16/Input!$AA$15)*LN((1+SQRT((Input!$AA$16/Input!$AA$15)^2+1))*SQRT((Input!$AA$16/Input!$AA$15)^2+(AJ30/(Input!$AA$15/2))^2)/((Input!$AA$16/Input!$AA$15)*(1+SQRT((Input!$AA$16/Input!$AA$15)^2+(AJ30/(Input!$AA$15/2))^2+1))))+LN(((Input!$AA$16/Input!$AA$15)+SQRT((Input!$AA$16/Input!$AA$15)^2+1))*SQRT(1+(AJ30/(Input!$AA$15/2))^2)/((Input!$AA$16/Input!$AA$15)+SQRT((Input!$AA$16/Input!$AA$15)^2+(AJ30/(Input!$AA$15/2))^2+1))))/PI() | BE30: =(AJ30/(Input!$AA$15/2))/(2*PI())*ATAN((Input!$AA$16/Input!$AA$15)/((AJ30/(Input!$AA$15/2))*SQRT((Input!$AA$16/Input!$AA$15)^2+(AJ30/(Input!$AA$15/2))^2+1))) | BF30: =MAX(0,AJ30-MAX(AI30,$AA$22))/AK30*IF(BC30>=Input!$AA$21*AQ30,1,0) | BG30: =4*Input!$AA$14*(Input!$AA$15/2)*(1-AY30^2)/AX30*((BD30-BD29)+(1-2*AY30)/(1-AY30)*(BE30-BE29))*1000*BF30 | BH30: =IF(AM30="Sand",0,0.009*(AR30-10)) | BI30: =BH30*Input!$AA$36 | BJ30: =IF(AM30="Sand",0,MAX(AV30/Input!$AA$37,AQ30)) | BK30: =IF(AM30="Sand",0,1000*AK30/(1+AU30)*IF(AQ30+BC30<=BJ30,BI30*LOG10((AQ30+BC30)/AQ30),BI30*LOG10(BJ30/AQ30)+BH30*LOG10((AQ30+BC30)/BJ30)))*BF30 | BL30: =IF(AM30="Sand",0,10^(INDEX(Input!$Q$48:$Q$54,MIN(MATCH(MIN(MAX(AR30,30),120),Input!$C$48:$C$54,1),6))+(MIN(MAX(AR30,30),120)-INDEX(Input!$C$48:$C$54,MIN(MATCH(MIN(MAX(AR30,30),120),Input!$C$48:$C$54,1),6)))/(INDEX(Input!$C$48:$C$54,MIN(MATCH(MIN(MAX(AR30,30),120),Input!$C$48:$C$54,1),6)+1)-INDEX(Input!$C$48:$C$54,MIN(MATCH(MIN(MAX(AR30,30),120),Input!$C$48:$C$54,1),6)))*(INDEX(Input!$Q$48:$Q$54,MIN(MATCH(MIN(MAX(AR30,30),120),Input!$C$48:$C$54,1),6)+1)-INDEX(Input!$Q$48:$Q$54,MIN(MATCH(MIN(MAX(AR30,30),120),Input!$C$48:$C$54,1),6))))) | BM30: =IF(OR(AM30="Sand",BF30=0),0,Input!$AA$38*(AK30/2)^2/(BL30*1E-4*31536000)) | BN30: =MAX(0,MIN(AJ30,Input!$AA$20)-AI30) | BO30: =MAX(0,MIN(AJ30,Input!$AA$20)-MAX(AI30,$AA$22)) | BP30: =MAX(0,MIN(AJ30,$AA$225)-AI30)
C31: 4 | E31: =AI31 | H31: =AJ31 | K31: =AM31 | N31: =AN31 | Q31: =AO31 | T31: =IF(AR31="","-",AR31) | V31: =IF(AT31="","-",AT31) | X31: =AU31 | Z31: =AV31 | AC31: =AW31 | AI31: 5.5 | AJ31: 6 | AK31: =AJ31-AI31 | AL31: =(AI31+AJ31)/2 | AM31: Silt | AN31: 28 | AO31: =IF(AL31>$AA$19,$AA$21,$AA$20) | AP31: =AP30+AO31*AK31 | AQ31: =AP31-AO31*AK31/2-10*MAX(AL31-$AA$19,0) | AR31: 29.665 | AS31: 19.806 | AT31: =IF(AR31="","",AR31-AS31) | AU31: 0.681 | AV31: =IF(AM31="Sand",0,Input!$AA$31*AN31) | AW31: =IF(AM31="Sand",27.1+0.3*MIN(Input!$AA$32*AN31,60)-0.00054*MIN(Input!$AA$32*AN31,60)^2,MIN(MAX(DEGREES(ASIN(0.8-0.094*LN(MAX(IF(AT31="",10,AT31),5)))),20),30)) | AX31: =IF(AM31="Sand",Input!$AA$33*Input!$AA$32*AN31,Input!$AA$34*AV31) | AY31: =IF(AM31="Sand",Input!$AA$35,0.5) | AZ31: =Input!$AA$15/2/AL31 | BA31: =Input!$AA$16/2/AL31 | BB31: =1/(4*PI())*(2*AZ31*BA31*SQRT(AZ31^2+BA31^2+1)/(AZ31^2+BA31^2+1+AZ31^2*BA31^2)*(AZ31^2+BA31^2+2)/(AZ31^2+BA31^2+1)+ATAN2(AZ31^2+BA31^2+1-AZ31^2*BA31^2,2*AZ31*BA31*SQRT(AZ31^2+BA31^2+1))) | BC31: =4*Input!$AA$14*BB31 | BD31: =((Input!$AA$16/Input!$AA$15)*LN((1+SQRT((Input!$AA$16/Input!$AA$15)^2+1))*SQRT((Input!$AA$16/Input!$AA$15)^2+(AJ31/(Input!$AA$15/2))^2)/((Input!$AA$16/Input!$AA$15)*(1+SQRT((Input!$AA$16/Input!$AA$15)^2+(AJ31/(Input!$AA$15/2))^2+1))))+LN(((Input!$AA$16/Input!$AA$15)+SQRT((Input!$AA$16/Input!$AA$15)^2+1))*SQRT(1+(AJ31/(Input!$AA$15/2))^2)/((Input!$AA$16/Input!$AA$15)+SQRT((Input!$AA$16/Input!$AA$15)^2+(AJ31/(Input!$AA$15/2))^2+1))))/PI() | BE31: =(AJ31/(Input!$AA$15/2))/(2*PI())*ATAN((Input!$AA$16/Input!$AA$15)/((AJ31/(Input!$AA$15/2))*SQRT((Input!$AA$16/Input!$AA$15)^2+(AJ31/(Input!$AA$15/2))^2+1))) | BF31: =MAX(0,AJ31-MAX(AI31,$AA$22))/AK31*IF(BC31>=Input!$AA$21*AQ31,1,0) | BG31: =4*Input!$AA$14*(Input!$AA$15/2)*(1-AY31^2)/AX31*((BD31-BD30)+(1-2*AY31)/(1-AY31)*(BE31-BE30))*1000*BF31 | BH31: =IF(AM31="Sand",0,0.009*(AR31-10)) | BI31: =BH31*Input!$AA$36 | BJ31: =IF(AM31="Sand",0,MAX(AV31/Input!$AA$37,AQ31)) | BK31: =IF(AM31="Sand",0,1000*AK31/(1+AU31)*IF(AQ31+BC31<=BJ31,BI31*LOG10((AQ31+BC31)/AQ31),BI31*LOG10(BJ31/AQ31)+BH31*LOG10((AQ31+BC31)/BJ31)))*BF31 | BL31: =IF(AM31="Sand",0,10^(INDEX(Input!$Q$48:$Q$54,MIN(MATCH(MIN(MAX(AR31,30),120),Input!$C$48:$C$54,1),6))+(MIN(MAX(AR31,30),120)-INDEX(Input!$C$48:$C$54,MIN(MATCH(MIN(MAX(AR31,30),120),Input!$C$48:$C$54,1),6)))/(INDEX(Input!$C$48:$C$54,MIN(MATCH(MIN(MAX(AR31,30),120),Input!$C$48:$C$54,1),6)+1)-INDEX(Input!$C$48:$C$54,MIN(MATCH(MIN(MAX(AR31,30),120),Input!$C$48:$C$54,1),6)))*(INDEX(Input!$Q$48:$Q$54,MIN(MATCH(MIN(MAX(AR31,30),120),Input!$C$48:$C$54,1),6)+1)-INDEX(Input!$Q$48:$Q$54,MIN(MATCH(MIN(MAX(AR31,30),120),Input!$C$48:$C$54,1),6))))) | BM31: =IF(OR(AM31="Sand",BF31=0),0,Input!$AA$38*(AK31/2)^2/(BL31*1E-4*31536000)) | BN31: =MAX(0,MIN(AJ31,Input!$AA$20)-AI31) | BO31: =MAX(0,MIN(AJ31,Input!$AA$20)-MAX(AI31,$AA$22)) | BP31: =MAX(0,MIN(AJ31,$AA$225)-AI31) | BQ31: LL/PL/e0 = borehole average
C32: 5 | E32: =AI32 | H32: =AJ32 | K32: =AM32 | N32: =AN32 | Q32: =AO32 | T32: =IF(AR32="","-",AR32) | V32: =IF(AT32="","-",AT32) | X32: =AU32 | Z32: =AV32 | AC32: =AW32 | AI32: 6 | AJ32: 7.5 | AK32: =AJ32-AI32 | AL32: =(AI32+AJ32)/2 | AM32: Silt | AN32: 30 | AO32: =IF(AL32>$AA$19,$AA$21,$AA$20) | AP32: =AP31+AO32*AK32 | AQ32: =AP32-AO32*AK32/2-10*MAX(AL32-$AA$19,0) | AR32: 29.665 | AS32: 19.806 | AT32: =IF(AR32="","",AR32-AS32) | AU32: 0.681 | AV32: =IF(AM32="Sand",0,Input!$AA$31*AN32) | AW32: =IF(AM32="Sand",27.1+0.3*MIN(Input!$AA$32*AN32,60)-0.00054*MIN(Input!$AA$32*AN32,60)^2,MIN(MAX(DEGREES(ASIN(0.8-0.094*LN(MAX(IF(AT32="",10,AT32),5)))),20),30)) | AX32: =IF(AM32="Sand",Input!$AA$33*Input!$AA$32*AN32,Input!$AA$34*AV32) | AY32: =IF(AM32="Sand",Input!$AA$35,0.5) | AZ32: =Input!$AA$15/2/AL32 | BA32: =Input!$AA$16/2/AL32 | BB32: =1/(4*PI())*(2*AZ32*BA32*SQRT(AZ32^2+BA32^2+1)/(AZ32^2+BA32^2+1+AZ32^2*BA32^2)*(AZ32^2+BA32^2+2)/(AZ32^2+BA32^2+1)+ATAN2(AZ32^2+BA32^2+1-AZ32^2*BA32^2,2*AZ32*BA32*SQRT(AZ32^2+BA32^2+1))) | BC32: =4*Input!$AA$14*BB32 | BD32: =((Input!$AA$16/Input!$AA$15)*LN((1+SQRT((Input!$AA$16/Input!$AA$15)^2+1))*SQRT((Input!$AA$16/Input!$AA$15)^2+(AJ32/(Input!$AA$15/2))^2)/((Input!$AA$16/Input!$AA$15)*(1+SQRT((Input!$AA$16/Input!$AA$15)^2+(AJ32/(Input!$AA$15/2))^2+1))))+LN(((Input!$AA$16/Input!$AA$15)+SQRT((Input!$AA$16/Input!$AA$15)^2+1))*SQRT(1+(AJ32/(Input!$AA$15/2))^2)/((Input!$AA$16/Input!$AA$15)+SQRT((Input!$AA$16/Input!$AA$15)^2+(AJ32/(Input!$AA$15/2))^2+1))))/PI() | BE32: =(AJ32/(Input!$AA$15/2))/(2*PI())*ATAN((Input!$AA$16/Input!$AA$15)/((AJ32/(Input!$AA$15/2))*SQRT((Input!$AA$16/Input!$AA$15)^2+(AJ32/(Input!$AA$15/2))^2+1))) | BF32: =MAX(0,AJ32-MAX(AI32,$AA$22))/AK32*IF(BC32>=Input!$AA$21*AQ32,1,0) | BG32: =4*Input!$AA$14*(Input!$AA$15/2)*(1-AY32^2)/AX32*((BD32-BD31)+(1-2*AY32)/(1-AY32)*(BE32-BE31))*1000*BF32 | BH32: =IF(AM32="Sand",0,0.009*(AR32-10)) | BI32: =BH32*Input!$AA$36 | BJ32: =IF(AM32="Sand",0,MAX(AV32/Input!$AA$37,AQ32)) | BK32: =IF(AM32="Sand",0,1000*AK32/(1+AU32)*IF(AQ32+BC32<=BJ32,BI32*LOG10((AQ32+BC32)/AQ32),BI32*LOG10(BJ32/AQ32)+BH32*LOG10((AQ32+BC32)/BJ32)))*BF32 | BL32: =IF(AM32="Sand",0,10^(INDEX(Input!$Q$48:$Q$54,MIN(MATCH(MIN(MAX(AR32,30),120),Input!$C$48:$C$54,1),6))+(MIN(MAX(AR32,30),120)-INDEX(Input!$C$48:$C$54,MIN(MATCH(MIN(MAX(AR32,30),120),Input!$C$48:$C$54,1),6)))/(INDEX(Input!$C$48:$C$54,MIN(MATCH(MIN(MAX(AR32,30),120),Input!$C$48:$C$54,1),6)+1)-INDEX(Input!$C$48:$C$54,MIN(MATCH(MIN(MAX(AR32,30),120),Input!$C$48:$C$54,1),6)))*(INDEX(Input!$Q$48:$Q$54,MIN(MATCH(MIN(MAX(AR32,30),120),Input!$C$48:$C$54,1),6)+1)-INDEX(Input!$Q$48:$Q$54,MIN(MATCH(MIN(MAX(AR32,30),120),Input!$C$48:$C$54,1),6))))) | BM32: =IF(OR(AM32="Sand",BF32=0),0,Input!$AA$38*(AK32/2)^2/(BL32*1E-4*31536000)) | BN32: =MAX(0,MIN(AJ32,Input!$AA$20)-AI32) | BO32: =MAX(0,MIN(AJ32,Input!$AA$20)-MAX(AI32,$AA$22)) | BP32: =MAX(0,MIN(AJ32,$AA$225)-AI32) | BQ32: LL/PL/e0 = borehole average
C33: 6 | E33: =AI33 | H33: =AJ33 | K33: =AM33 | N33: =AN33 | Q33: =AO33 | T33: =IF(AR33="","-",AR33) | V33: =IF(AT33="","-",AT33) | X33: =AU33 | Z33: =AV33 | AC33: =AW33 | AI33: 7.5 | AJ33: 9 | AK33: =AJ33-AI33 | AL33: =(AI33+AJ33)/2 | AM33: Sand | AN33: 35 | AO33: =IF(AL33>$AA$19,$AA$21,$AA$20) | AP33: =AP32+AO33*AK33 | AQ33: =AP33-AO33*AK33/2-10*MAX(AL33-$AA$19,0) | AT33: =IF(AR33="","",AR33-AS33) | AU33: 0.65 | AV33: =IF(AM33="Sand",0,Input!$AA$31*AN33) | AW33: =IF(AM33="Sand",27.1+0.3*MIN(Input!$AA$32*AN33,60)-0.00054*MIN(Input!$AA$32*AN33,60)^2,MIN(MAX(DEGREES(ASIN(0.8-0.094*LN(MAX(IF(AT33="",10,AT33),5)))),20),30)) | AX33: =IF(AM33="Sand",Input!$AA$33*Input!$AA$32*AN33,Input!$AA$34*AV33) | AY33: =IF(AM33="Sand",Input!$AA$35,0.5) | AZ33: =Input!$AA$15/2/AL33 | BA33: =Input!$AA$16/2/AL33 | BB33: =1/(4*PI())*(2*AZ33*BA33*SQRT(AZ33^2+BA33^2+1)/(AZ33^2+BA33^2+1+AZ33^2*BA33^2)*(AZ33^2+BA33^2+2)/(AZ33^2+BA33^2+1)+ATAN2(AZ33^2+BA33^2+1-AZ33^2*BA33^2,2*AZ33*BA33*SQRT(AZ33^2+BA33^2+1))) | BC33: =4*Input!$AA$14*BB33 | BD33: =((Input!$AA$16/Input!$AA$15)*LN((1+SQRT((Input!$AA$16/Input!$AA$15)^2+1))*SQRT((Input!$AA$16/Input!$AA$15)^2+(AJ33/(Input!$AA$15/2))^2)/((Input!$AA$16/Input!$AA$15)*(1+SQRT((Input!$AA$16/Input!$AA$15)^2+(AJ33/(Input!$AA$15/2))^2+1))))+LN(((Input!$AA$16/Input!$AA$15)+SQRT((Input!$AA$16/Input!$AA$15)^2+1))*SQRT(1+(AJ33/(Input!$AA$15/2))^2)/((Input!$AA$16/Input!$AA$15)+SQRT((Input!$AA$16/Input!$AA$15)^2+(AJ33/(Input!$AA$15/2))^2+1))))/PI() | BE33: =(AJ33/(Input!$AA$15/2))/(2*PI())*ATAN((Input!$AA$16/Input!$AA$15)/((AJ33/(Input!$AA$15/2))*SQRT((Input!$AA$16/Input!$AA$15)^2+(AJ33/(Input!$AA$15/2))^2+1))) | BF33: =MAX(0,AJ33-MAX(AI33,$AA$22))/AK33*IF(BC33>=Input!$AA$21*AQ33,1,0) | BG33: =4*Input!$AA$14*(Input!$AA$15/2)*(1-AY33^2)/AX33*((BD33-BD32)+(1-2*AY33)/(1-AY33)*(BE33-BE32))*1000*BF33 | BH33: =IF(AM33="Sand",0,0.009*(AR33-10)) | BI33: =BH33*Input!$AA$36 | BJ33: =IF(AM33="Sand",0,MAX(AV33/Input!$AA$37,AQ33)) | BK33: =IF(AM33="Sand",0,1000*AK33/(1+AU33)*IF(AQ33+BC33<=BJ33,BI33*LOG10((AQ33+BC33)/AQ33),BI33*LOG10(BJ33/AQ33)+BH33*LOG10((AQ33+BC33)/BJ33)))*BF33 | BL33: =IF(AM33="Sand",0,10^(INDEX(Input!$Q$48:$Q$54,MIN(MATCH(MIN(MAX(AR33,30),120),Input!$C$48:$C$54,1),6))+(MIN(MAX(AR33,30),120)-INDEX(Input!$C$48:$C$54,MIN(MATCH(MIN(MAX(AR33,30),120),Input!$C$48:$C$54,1),6)))/(INDEX(Input!$C$48:$C$54,MIN(MATCH(MIN(MAX(AR33,30),120),Input!$C$48:$C$54,1),6)+1)-INDEX(Input!$C$48:$C$54,MIN(MATCH(MIN(MAX(AR33,30),120),Input!$C$48:$C$54,1),6)))*(INDEX(Input!$Q$48:$Q$54,MIN(MATCH(MIN(MAX(AR33,30),120),Input!$C$48:$C$54,1),6)+1)-INDEX(Input!$Q$48:$Q$54,MIN(MATCH(MIN(MAX(AR33,30),120),Input!$C$48:$C$54,1),6))))) | BM33: =IF(OR(AM33="Sand",BF33=0),0,Input!$AA$38*(AK33/2)^2/(BL33*1E-4*31536000)) | BN33: =MAX(0,MIN(AJ33,Input!$AA$20)-AI33) | BO33: =MAX(0,MIN(AJ33,Input!$AA$20)-MAX(AI33,$AA$22)) | BP33: =MAX(0,MIN(AJ33,$AA$225)-AI33)
C34: 7 | E34: =AI34 | H34: =AJ34 | K34: =AM34 | N34: =AN34 | Q34: =AO34 | T34: =IF(AR34="","-",AR34) | V34: =IF(AT34="","-",AT34) | X34: =AU34 | Z34: =AV34 | AC34: =AW34 | AI34: 9 | AJ34: 10.5 | AK34: =AJ34-AI34 | AL34: =(AI34+AJ34)/2 | AM34: Sand | AN34: 34 | AO34: =IF(AL34>$AA$19,$AA$21,$AA$20) | AP34: =AP33+AO34*AK34 | AQ34: =AP34-AO34*AK34/2-10*MAX(AL34-$AA$19,0) | AT34: =IF(AR34="","",AR34-AS34) | AU34: 0.465 | AV34: =IF(AM34="Sand",0,Input!$AA$31*AN34) | AW34: =IF(AM34="Sand",27.1+0.3*MIN(Input!$AA$32*AN34,60)-0.00054*MIN(Input!$AA$32*AN34,60)^2,MIN(MAX(DEGREES(ASIN(0.8-0.094*LN(MAX(IF(AT34="",10,AT34),5)))),20),30)) | AX34: =IF(AM34="Sand",Input!$AA$33*Input!$AA$32*AN34,Input!$AA$34*AV34) | AY34: =IF(AM34="Sand",Input!$AA$35,0.5) | AZ34: =Input!$AA$15/2/AL34 | BA34: =Input!$AA$16/2/AL34 | BB34: =1/(4*PI())*(2*AZ34*BA34*SQRT(AZ34^2+BA34^2+1)/(AZ34^2+BA34^2+1+AZ34^2*BA34^2)*(AZ34^2+BA34^2+2)/(AZ34^2+BA34^2+1)+ATAN2(AZ34^2+BA34^2+1-AZ34^2*BA34^2,2*AZ34*BA34*SQRT(AZ34^2+BA34^2+1))) | BC34: =4*Input!$AA$14*BB34 | BD34: =((Input!$AA$16/Input!$AA$15)*LN((1+SQRT((Input!$AA$16/Input!$AA$15)^2+1))*SQRT((Input!$AA$16/Input!$AA$15)^2+(AJ34/(Input!$AA$15/2))^2)/((Input!$AA$16/Input!$AA$15)*(1+SQRT((Input!$AA$16/Input!$AA$15)^2+(AJ34/(Input!$AA$15/2))^2+1))))+LN(((Input!$AA$16/Input!$AA$15)+SQRT((Input!$AA$16/Input!$AA$15)^2+1))*SQRT(1+(AJ34/(Input!$AA$15/2))^2)/((Input!$AA$16/Input!$AA$15)+SQRT((Input!$AA$16/Input!$AA$15)^2+(AJ34/(Input!$AA$15/2))^2+1))))/PI() | BE34: =(AJ34/(Input!$AA$15/2))/(2*PI())*ATAN((Input!$AA$16/Input!$AA$15)/((AJ34/(Input!$AA$15/2))*SQRT((Input!$AA$16/Input!$AA$15)^2+(AJ34/(Input!$AA$15/2))^2+1))) | BF34: =MAX(0,AJ34-MAX(AI34,$AA$22))/AK34*IF(BC34>=Input!$AA$21*AQ34,1,0) | BG34: =4*Input!$AA$14*(Input!$AA$15/2)*(1-AY34^2)/AX34*((BD34-BD33)+(1-2*AY34)/(1-AY34)*(BE34-BE33))*1000*BF34 | BH34: =IF(AM34="Sand",0,0.009*(AR34-10)) | BI34: =BH34*Input!$AA$36 | BJ34: =IF(AM34="Sand",0,MAX(AV34/Input!$AA$37,AQ34)) | BK34: =IF(AM34="Sand",0,1000*AK34/(1+AU34)*IF(AQ34+BC34<=BJ34,BI34*LOG10((AQ34+BC34)/AQ34),BI34*LOG10(BJ34/AQ34)+BH34*LOG10((AQ34+BC34)/BJ34)))*BF34 | BL34: =IF(AM34="Sand",0,10^(INDEX(Input!$Q$48:$Q$54,MIN(MATCH(MIN(MAX(AR34,30),120),Input!$C$48:$C$54,1),6))+(MIN(MAX(AR34,30),120)-INDEX(Input!$C$48:$C$54,MIN(MATCH(MIN(MAX(AR34,30),120),Input!$C$48:$C$54,1),6)))/(INDEX(Input!$C$48:$C$54,MIN(MATCH(MIN(MAX(AR34,30),120),Input!$C$48:$C$54,1),6)+1)-INDEX(Input!$C$48:$C$54,MIN(MATCH(MIN(MAX(AR34,30),120),Input!$C$48:$C$54,1),6)))*(INDEX(Input!$Q$48:$Q$54,MIN(MATCH(MIN(MAX(AR34,30),120),Input!$C$48:$C$54,1),6)+1)-INDEX(Input!$Q$48:$Q$54,MIN(MATCH(MIN(MAX(AR34,30),120),Input!$C$48:$C$54,1),6))))) | BM34: =IF(OR(AM34="Sand",BF34=0),0,Input!$AA$38*(AK34/2)^2/(BL34*1E-4*31536000)) | BN34: =MAX(0,MIN(AJ34,Input!$AA$20)-AI34) | BO34: =MAX(0,MIN(AJ34,Input!$AA$20)-MAX(AI34,$AA$22)) | BP34: =MAX(0,MIN(AJ34,$AA$225)-AI34)
C35: 8 | E35: =AI35 | H35: =AJ35 | K35: =AM35 | N35: =AN35 | Q35: =AO35 | T35: =IF(AR35="","-",AR35) | V35: =IF(AT35="","-",AT35) | X35: =AU35 | Z35: =AV35 | AC35: =AW35 | AI35: 10.5 | AJ35: 12 | AK35: =AJ35-AI35 | AL35: =(AI35+AJ35)/2 | AM35: Sand | AN35: 13 | AO35: =IF(AL35>$AA$19,$AA$21,$AA$20) | AP35: =AP34+AO35*AK35 | AQ35: =AP35-AO35*AK35/2-10*MAX(AL35-$AA$19,0) | AT35: =IF(AR35="","",AR35-AS35) | AU35: 0.65 | AV35: =IF(AM35="Sand",0,Input!$AA$31*AN35) | AW35: =IF(AM35="Sand",27.1+0.3*MIN(Input!$AA$32*AN35,60)-0.00054*MIN(Input!$AA$32*AN35,60)^2,MIN(MAX(DEGREES(ASIN(0.8-0.094*LN(MAX(IF(AT35="",10,AT35),5)))),20),30)) | AX35: =IF(AM35="Sand",Input!$AA$33*Input!$AA$32*AN35,Input!$AA$34*AV35) | AY35: =IF(AM35="Sand",Input!$AA$35,0.5) | AZ35: =Input!$AA$15/2/AL35 | BA35: =Input!$AA$16/2/AL35 | BB35: =1/(4*PI())*(2*AZ35*BA35*SQRT(AZ35^2+BA35^2+1)/(AZ35^2+BA35^2+1+AZ35^2*BA35^2)*(AZ35^2+BA35^2+2)/(AZ35^2+BA35^2+1)+ATAN2(AZ35^2+BA35^2+1-AZ35^2*BA35^2,2*AZ35*BA35*SQRT(AZ35^2+BA35^2+1))) | BC35: =4*Input!$AA$14*BB35 | BD35: =((Input!$AA$16/Input!$AA$15)*LN((1+SQRT((Input!$AA$16/Input!$AA$15)^2+1))*SQRT((Input!$AA$16/Input!$AA$15)^2+(AJ35/(Input!$AA$15/2))^2)/((Input!$AA$16/Input!$AA$15)*(1+SQRT((Input!$AA$16/Input!$AA$15)^2+(AJ35/(Input!$AA$15/2))^2+1))))+LN(((Input!$AA$16/Input!$AA$15)+SQRT((Input!$AA$16/Input!$AA$15)^2+1))*SQRT(1+(AJ35/(Input!$AA$15/2))^2)/((Input!$AA$16/Input!$AA$15)+SQRT((Input!$AA$16/Input!$AA$15)^2+(AJ35/(Input!$AA$15/2))^2+1))))/PI() | BE35: =(AJ35/(Input!$AA$15/2))/(2*PI())*ATAN((Input!$AA$16/Input!$AA$15)/((AJ35/(Input!$AA$15/2))*SQRT((Input!$AA$16/Input!$AA$15)^2+(AJ35/(Input!$AA$15/2))^2+1))) | BF35: =MAX(0,AJ35-MAX(AI35,$AA$22))/AK35*IF(BC35>=Input!$AA$21*AQ35,1,0) | BG35: =4*Input!$AA$14*(Input!$AA$15/2)*(1-AY35^2)/AX35*((BD35-BD34)+(1-2*AY35)/(1-AY35)*(BE35-BE34))*1000*BF35 | BH35: =IF(AM35="Sand",0,0.009*(AR35-10)) | BI35: =BH35*Input!$AA$36 | BJ35: =IF(AM35="Sand",0,MAX(AV35/Input!$AA$37,AQ35)) | BK35: =IF(AM35="Sand",0,1000*AK35/(1+AU35)*IF(AQ35+BC35<=BJ35,BI35*LOG10((AQ35+BC35)/AQ35),BI35*LOG10(BJ35/AQ35)+BH35*LOG10((AQ35+BC35)/BJ35)))*BF35 | BL35: =IF(AM35="Sand",0,10^(INDEX(Input!$Q$48:$Q$54,MIN(MATCH(MIN(MAX(AR35,30),120),Input!$C$48:$C$54,1),6))+(MIN(MAX(AR35,30),120)-INDEX(Input!$C$48:$C$54,MIN(MATCH(MIN(MAX(AR35,30),120),Input!$C$48:$C$54,1),6)))/(INDEX(Input!$C$48:$C$54,MIN(MATCH(MIN(MAX(AR35,30),120),Input!$C$48:$C$54,1),6)+1)-INDEX(Input!$C$48:$C$54,MIN(MATCH(MIN(MAX(AR35,30),120),Input!$C$48:$C$54,1),6)))*(INDEX(Input!$Q$48:$Q$54,MIN(MATCH(MIN(MAX(AR35,30),120),Input!$C$48:$C$54,1),6)+1)-INDEX(Input!$Q$48:$Q$54,MIN(MATCH(MIN(MAX(AR35,30),120),Input!$C$48:$C$54,1),6))))) | BM35: =IF(OR(AM35="Sand",BF35=0),0,Input!$AA$38*(AK35/2)^2/(BL35*1E-4*31536000)) | BN35: =MAX(0,MIN(AJ35,Input!$AA$20)-AI35) | BO35: =MAX(0,MIN(AJ35,Input!$AA$20)-MAX(AI35,$AA$22)) | BP35: =MAX(0,MIN(AJ35,$AA$225)-AI35)
C36: 9 | E36: =AI36 | H36: =AJ36 | K36: =AM36 | N36: =AN36 | Q36: =AO36 | T36: =IF(AR36="","-",AR36) | V36: =IF(AT36="","-",AT36) | X36: =AU36 | Z36: =AV36 | AC36: =AW36 | AI36: 12 | AJ36: 13.5 | AK36: =AJ36-AI36 | AL36: =(AI36+AJ36)/2 | AM36: Sand | AN36: 17 | AO36: =IF(AL36>$AA$19,$AA$21,$AA$20) | AP36: =AP35+AO36*AK36 | AQ36: =AP36-AO36*AK36/2-10*MAX(AL36-$AA$19,0) | AT36: =IF(AR36="","",AR36-AS36) | AU36: 0.414 | AV36: =IF(AM36="Sand",0,Input!$AA$31*AN36) | AW36: =IF(AM36="Sand",27.1+0.3*MIN(Input!$AA$32*AN36,60)-0.00054*MIN(Input!$AA$32*AN36,60)^2,MIN(MAX(DEGREES(ASIN(0.8-0.094*LN(MAX(IF(AT36="",10,AT36),5)))),20),30)) | AX36: =IF(AM36="Sand",Input!$AA$33*Input!$AA$32*AN36,Input!$AA$34*AV36) | AY36: =IF(AM36="Sand",Input!$AA$35,0.5) | AZ36: =Input!$AA$15/2/AL36 | BA36: =Input!$AA$16/2/AL36 | BB36: =1/(4*PI())*(2*AZ36*BA36*SQRT(AZ36^2+BA36^2+1)/(AZ36^2+BA36^2+1+AZ36^2*BA36^2)*(AZ36^2+BA36^2+2)/(AZ36^2+BA36^2+1)+ATAN2(AZ36^2+BA36^2+1-AZ36^2*BA36^2,2*AZ36*BA36*SQRT(AZ36^2+BA36^2+1))) | BC36: =4*Input!$AA$14*BB36 | BD36: =((Input!$AA$16/Input!$AA$15)*LN((1+SQRT((Input!$AA$16/Input!$AA$15)^2+1))*SQRT((Input!$AA$16/Input!$AA$15)^2+(AJ36/(Input!$AA$15/2))^2)/((Input!$AA$16/Input!$AA$15)*(1+SQRT((Input!$AA$16/Input!$AA$15)^2+(AJ36/(Input!$AA$15/2))^2+1))))+LN(((Input!$AA$16/Input!$AA$15)+SQRT((Input!$AA$16/Input!$AA$15)^2+1))*SQRT(1+(AJ36/(Input!$AA$15/2))^2)/((Input!$AA$16/Input!$AA$15)+SQRT((Input!$AA$16/Input!$AA$15)^2+(AJ36/(Input!$AA$15/2))^2+1))))/PI() | BE36: =(AJ36/(Input!$AA$15/2))/(2*PI())*ATAN((Input!$AA$16/Input!$AA$15)/((AJ36/(Input!$AA$15/2))*SQRT((Input!$AA$16/Input!$AA$15)^2+(AJ36/(Input!$AA$15/2))^2+1))) | BF36: =MAX(0,AJ36-MAX(AI36,$AA$22))/AK36*IF(BC36>=Input!$AA$21*AQ36,1,0) | BG36: =4*Input!$AA$14*(Input!$AA$15/2)*(1-AY36^2)/AX36*((BD36-BD35)+(1-2*AY36)/(1-AY36)*(BE36-BE35))*1000*BF36 | BH36: =IF(AM36="Sand",0,0.009*(AR36-10)) | BI36: =BH36*Input!$AA$36 | BJ36: =IF(AM36="Sand",0,MAX(AV36/Input!$AA$37,AQ36)) | BK36: =IF(AM36="Sand",0,1000*AK36/(1+AU36)*IF(AQ36+BC36<=BJ36,BI36*LOG10((AQ36+BC36)/AQ36),BI36*LOG10(BJ36/AQ36)+BH36*LOG10((AQ36+BC36)/BJ36)))*BF36 | BL36: =IF(AM36="Sand",0,10^(INDEX(Input!$Q$48:$Q$54,MIN(MATCH(MIN(MAX(AR36,30),120),Input!$C$48:$C$54,1),6))+(MIN(MAX(AR36,30),120)-INDEX(Input!$C$48:$C$54,MIN(MATCH(MIN(MAX(AR36,30),120),Input!$C$48:$C$54,1),6)))/(INDEX(Input!$C$48:$C$54,MIN(MATCH(MIN(MAX(AR36,30),120),Input!$C$48:$C$54,1),6)+1)-INDEX(Input!$C$48:$C$54,MIN(MATCH(MIN(MAX(AR36,30),120),Input!$C$48:$C$54,1),6)))*(INDEX(Input!$Q$48:$Q$54,MIN(MATCH(MIN(MAX(AR36,30),120),Input!$C$48:$C$54,1),6)+1)-INDEX(Input!$Q$48:$Q$54,MIN(MATCH(MIN(MAX(AR36,30),120),Input!$C$48:$C$54,1),6))))) | BM36: =IF(OR(AM36="Sand",BF36=0),0,Input!$AA$38*(AK36/2)^2/(BL36*1E-4*31536000)) | BN36: =MAX(0,MIN(AJ36,Input!$AA$20)-AI36) | BO36: =MAX(0,MIN(AJ36,Input!$AA$20)-MAX(AI36,$AA$22)) | BP36: =MAX(0,MIN(AJ36,$AA$225)-AI36)
C37: 10 | E37: =AI37 | H37: =AJ37 | K37: =AM37 | N37: =AN37 | Q37: =AO37 | T37: =IF(AR37="","-",AR37) | V37: =IF(AT37="","-",AT37) | X37: =AU37 | Z37: =AV37 | AC37: =AW37 | AI37: 13.5 | AJ37: 15 | AK37: =AJ37-AI37 | AL37: =(AI37+AJ37)/2 | AM37: Sand | AN37: 18 | AO37: =IF(AL37>$AA$19,$AA$21,$AA$20) | AP37: =AP36+AO37*AK37 | AQ37: =AP37-AO37*AK37/2-10*MAX(AL37-$AA$19,0) | AT37: =IF(AR37="","",AR37-AS37) | AU37: 0.747 | AV37: =IF(AM37="Sand",0,Input!$AA$31*AN37) | AW37: =IF(AM37="Sand",27.1+0.3*MIN(Input!$AA$32*AN37,60)-0.00054*MIN(Input!$AA$32*AN37,60)^2,MIN(MAX(DEGREES(ASIN(0.8-0.094*LN(MAX(IF(AT37="",10,AT37),5)))),20),30)) | AX37: =IF(AM37="Sand",Input!$AA$33*Input!$AA$32*AN37,Input!$AA$34*AV37) | AY37: =IF(AM37="Sand",Input!$AA$35,0.5) | AZ37: =Input!$AA$15/2/AL37 | BA37: =Input!$AA$16/2/AL37 | BB37: =1/(4*PI())*(2*AZ37*BA37*SQRT(AZ37^2+BA37^2+1)/(AZ37^2+BA37^2+1+AZ37^2*BA37^2)*(AZ37^2+BA37^2+2)/(AZ37^2+BA37^2+1)+ATAN2(AZ37^2+BA37^2+1-AZ37^2*BA37^2,2*AZ37*BA37*SQRT(AZ37^2+BA37^2+1))) | BC37: =4*Input!$AA$14*BB37 | BD37: =((Input!$AA$16/Input!$AA$15)*LN((1+SQRT((Input!$AA$16/Input!$AA$15)^2+1))*SQRT((Input!$AA$16/Input!$AA$15)^2+(AJ37/(Input!$AA$15/2))^2)/((Input!$AA$16/Input!$AA$15)*(1+SQRT((Input!$AA$16/Input!$AA$15)^2+(AJ37/(Input!$AA$15/2))^2+1))))+LN(((Input!$AA$16/Input!$AA$15)+SQRT((Input!$AA$16/Input!$AA$15)^2+1))*SQRT(1+(AJ37/(Input!$AA$15/2))^2)/((Input!$AA$16/Input!$AA$15)+SQRT((Input!$AA$16/Input!$AA$15)^2+(AJ37/(Input!$AA$15/2))^2+1))))/PI() | BE37: =(AJ37/(Input!$AA$15/2))/(2*PI())*ATAN((Input!$AA$16/Input!$AA$15)/((AJ37/(Input!$AA$15/2))*SQRT((Input!$AA$16/Input!$AA$15)^2+(AJ37/(Input!$AA$15/2))^2+1))) | BF37: =MAX(0,AJ37-MAX(AI37,$AA$22))/AK37*IF(BC37>=Input!$AA$21*AQ37,1,0) | BG37: =4*Input!$AA$14*(Input!$AA$15/2)*(1-AY37^2)/AX37*((BD37-BD36)+(1-2*AY37)/(1-AY37)*(BE37-BE36))*1000*BF37 | BH37: =IF(AM37="Sand",0,0.009*(AR37-10)) | BI37: =BH37*Input!$AA$36 | BJ37: =IF(AM37="Sand",0,MAX(AV37/Input!$AA$37,AQ37)) | BK37: =IF(AM37="Sand",0,1000*AK37/(1+AU37)*IF(AQ37+BC37<=BJ37,BI37*LOG10((AQ37+BC37)/AQ37),BI37*LOG10(BJ37/AQ37)+BH37*LOG10((AQ37+BC37)/BJ37)))*BF37 | BL37: =IF(AM37="Sand",0,10^(INDEX(Input!$Q$48:$Q$54,MIN(MATCH(MIN(MAX(AR37,30),120),Input!$C$48:$C$54,1),6))+(MIN(MAX(AR37,30),120)-INDEX(Input!$C$48:$C$54,MIN(MATCH(MIN(MAX(AR37,30),120),Input!$C$48:$C$54,1),6)))/(INDEX(Input!$C$48:$C$54,MIN(MATCH(MIN(MAX(AR37,30),120),Input!$C$48:$C$54,1),6)+1)-INDEX(Input!$C$48:$C$54,MIN(MATCH(MIN(MAX(AR37,30),120),Input!$C$48:$C$54,1),6)))*(INDEX(Input!$Q$48:$Q$54,MIN(MATCH(MIN(MAX(AR37,30),120),Input!$C$48:$C$54,1),6)+1)-INDEX(Input!$Q$48:$Q$54,MIN(MATCH(MIN(MAX(AR37,30),120),Input!$C$48:$C$54,1),6))))) | BM37: =IF(OR(AM37="Sand",BF37=0),0,Input!$AA$38*(AK37/2)^2/(BL37*1E-4*31536000)) | BN37: =MAX(0,MIN(AJ37,Input!$AA$20)-AI37) | BO37: =MAX(0,MIN(AJ37,Input!$AA$20)-MAX(AI37,$AA$22)) | BP37: =MAX(0,MIN(AJ37,$AA$225)-AI37)
C38: 11 | E38: =AI38 | H38: =AJ38 | K38: =AM38 | N38: =AN38 | Q38: =AO38 | T38: =IF(AR38="","-",AR38) | V38: =IF(AT38="","-",AT38) | X38: =AU38 | Z38: =AV38 | AC38: =AW38 | AI38: 15 | AJ38: 16.5 | AK38: =AJ38-AI38 | AL38: =(AI38+AJ38)/2 | AM38: Sand | AN38: 19 | AO38: =IF(AL38>$AA$19,$AA$21,$AA$20) | AP38: =AP37+AO38*AK38 | AQ38: =AP38-AO38*AK38/2-10*MAX(AL38-$AA$19,0) | AT38: =IF(AR38="","",AR38-AS38) | AU38: 0.65 | AV38: =IF(AM38="Sand",0,Input!$AA$31*AN38) | AW38: =IF(AM38="Sand",27.1+0.3*MIN(Input!$AA$32*AN38,60)-0.00054*MIN(Input!$AA$32*AN38,60)^2,MIN(MAX(DEGREES(ASIN(0.8-0.094*LN(MAX(IF(AT38="",10,AT38),5)))),20),30)) | AX38: =IF(AM38="Sand",Input!$AA$33*Input!$AA$32*AN38,Input!$AA$34*AV38) | AY38: =IF(AM38="Sand",Input!$AA$35,0.5) | AZ38: =Input!$AA$15/2/AL38 | BA38: =Input!$AA$16/2/AL38 | BB38: =1/(4*PI())*(2*AZ38*BA38*SQRT(AZ38^2+BA38^2+1)/(AZ38^2+BA38^2+1+AZ38^2*BA38^2)*(AZ38^2+BA38^2+2)/(AZ38^2+BA38^2+1)+ATAN2(AZ38^2+BA38^2+1-AZ38^2*BA38^2,2*AZ38*BA38*SQRT(AZ38^2+BA38^2+1))) | BC38: =4*Input!$AA$14*BB38 | BD38: =((Input!$AA$16/Input!$AA$15)*LN((1+SQRT((Input!$AA$16/Input!$AA$15)^2+1))*SQRT((Input!$AA$16/Input!$AA$15)^2+(AJ38/(Input!$AA$15/2))^2)/((Input!$AA$16/Input!$AA$15)*(1+SQRT((Input!$AA$16/Input!$AA$15)^2+(AJ38/(Input!$AA$15/2))^2+1))))+LN(((Input!$AA$16/Input!$AA$15)+SQRT((Input!$AA$16/Input!$AA$15)^2+1))*SQRT(1+(AJ38/(Input!$AA$15/2))^2)/((Input!$AA$16/Input!$AA$15)+SQRT((Input!$AA$16/Input!$AA$15)^2+(AJ38/(Input!$AA$15/2))^2+1))))/PI() | BE38: =(AJ38/(Input!$AA$15/2))/(2*PI())*ATAN((Input!$AA$16/Input!$AA$15)/((AJ38/(Input!$AA$15/2))*SQRT((Input!$AA$16/Input!$AA$15)^2+(AJ38/(Input!$AA$15/2))^2+1))) | BF38: =MAX(0,AJ38-MAX(AI38,$AA$22))/AK38*IF(BC38>=Input!$AA$21*AQ38,1,0) | BG38: =4*Input!$AA$14*(Input!$AA$15/2)*(1-AY38^2)/AX38*((BD38-BD37)+(1-2*AY38)/(1-AY38)*(BE38-BE37))*1000*BF38 | BH38: =IF(AM38="Sand",0,0.009*(AR38-10)) | BI38: =BH38*Input!$AA$36 | BJ38: =IF(AM38="Sand",0,MAX(AV38/Input!$AA$37,AQ38)) | BK38: =IF(AM38="Sand",0,1000*AK38/(1+AU38)*IF(AQ38+BC38<=BJ38,BI38*LOG10((AQ38+BC38)/AQ38),BI38*LOG10(BJ38/AQ38)+BH38*LOG10((AQ38+BC38)/BJ38)))*BF38 | BL38: =IF(AM38="Sand",0,10^(INDEX(Input!$Q$48:$Q$54,MIN(MATCH(MIN(MAX(AR38,30),120),Input!$C$48:$C$54,1),6))+(MIN(MAX(AR38,30),120)-INDEX(Input!$C$48:$C$54,MIN(MATCH(MIN(MAX(AR38,30),120),Input!$C$48:$C$54,1),6)))/(INDEX(Input!$C$48:$C$54,MIN(MATCH(MIN(MAX(AR38,30),120),Input!$C$48:$C$54,1),6)+1)-INDEX(Input!$C$48:$C$54,MIN(MATCH(MIN(MAX(AR38,30),120),Input!$C$48:$C$54,1),6)))*(INDEX(Input!$Q$48:$Q$54,MIN(MATCH(MIN(MAX(AR38,30),120),Input!$C$48:$C$54,1),6)+1)-INDEX(Input!$Q$48:$Q$54,MIN(MATCH(MIN(MAX(AR38,30),120),Input!$C$48:$C$54,1),6))))) | BM38: =IF(OR(AM38="Sand",BF38=0),0,Input!$AA$38*(AK38/2)^2/(BL38*1E-4*31536000)) | BN38: =MAX(0,MIN(AJ38,Input!$AA$20)-AI38) | BO38: =MAX(0,MIN(AJ38,Input!$AA$20)-MAX(AI38,$AA$22)) | BP38: =MAX(0,MIN(AJ38,$AA$225)-AI38)
C39: 12 | E39: =AI39 | H39: =AJ39 | K39: =AM39 | N39: =AN39 | Q39: =AO39 | T39: =IF(AR39="","-",AR39) | V39: =IF(AT39="","-",AT39) | X39: =AU39 | Z39: =AV39 | AC39: =AW39 | AI39: 16.5 | AJ39: 18 | AK39: =AJ39-AI39 | AL39: =(AI39+AJ39)/2 | AM39: Sand | AN39: 12 | AO39: =IF(AL39>$AA$19,$AA$21,$AA$20) | AP39: =AP38+AO39*AK39 | AQ39: =AP39-AO39*AK39/2-10*MAX(AL39-$AA$19,0) | AT39: =IF(AR39="","",AR39-AS39) | AU39: 0.48 | AV39: =IF(AM39="Sand",0,Input!$AA$31*AN39) | AW39: =IF(AM39="Sand",27.1+0.3*MIN(Input!$AA$32*AN39,60)-0.00054*MIN(Input!$AA$32*AN39,60)^2,MIN(MAX(DEGREES(ASIN(0.8-0.094*LN(MAX(IF(AT39="",10,AT39),5)))),20),30)) | AX39: =IF(AM39="Sand",Input!$AA$33*Input!$AA$32*AN39,Input!$AA$34*AV39) | AY39: =IF(AM39="Sand",Input!$AA$35,0.5) | AZ39: =Input!$AA$15/2/AL39 | BA39: =Input!$AA$16/2/AL39 | BB39: =1/(4*PI())*(2*AZ39*BA39*SQRT(AZ39^2+BA39^2+1)/(AZ39^2+BA39^2+1+AZ39^2*BA39^2)*(AZ39^2+BA39^2+2)/(AZ39^2+BA39^2+1)+ATAN2(AZ39^2+BA39^2+1-AZ39^2*BA39^2,2*AZ39*BA39*SQRT(AZ39^2+BA39^2+1))) | BC39: =4*Input!$AA$14*BB39 | BD39: =((Input!$AA$16/Input!$AA$15)*LN((1+SQRT((Input!$AA$16/Input!$AA$15)^2+1))*SQRT((Input!$AA$16/Input!$AA$15)^2+(AJ39/(Input!$AA$15/2))^2)/((Input!$AA$16/Input!$AA$15)*(1+SQRT((Input!$AA$16/Input!$AA$15)^2+(AJ39/(Input!$AA$15/2))^2+1))))+LN(((Input!$AA$16/Input!$AA$15)+SQRT((Input!$AA$16/Input!$AA$15)^2+1))*SQRT(1+(AJ39/(Input!$AA$15/2))^2)/((Input!$AA$16/Input!$AA$15)+SQRT((Input!$AA$16/Input!$AA$15)^2+(AJ39/(Input!$AA$15/2))^2+1))))/PI() | BE39: =(AJ39/(Input!$AA$15/2))/(2*PI())*ATAN((Input!$AA$16/Input!$AA$15)/((AJ39/(Input!$AA$15/2))*SQRT((Input!$AA$16/Input!$AA$15)^2+(AJ39/(Input!$AA$15/2))^2+1))) | BF39: =MAX(0,AJ39-MAX(AI39,$AA$22))/AK39*IF(BC39>=Input!$AA$21*AQ39,1,0) | BG39: =4*Input!$AA$14*(Input!$AA$15/2)*(1-AY39^2)/AX39*((BD39-BD38)+(1-2*AY39)/(1-AY39)*(BE39-BE38))*1000*BF39 | BH39: =IF(AM39="Sand",0,0.009*(AR39-10)) | BI39: =BH39*Input!$AA$36 | BJ39: =IF(AM39="Sand",0,MAX(AV39/Input!$AA$37,AQ39)) | BK39: =IF(AM39="Sand",0,1000*AK39/(1+AU39)*IF(AQ39+BC39<=BJ39,BI39*LOG10((AQ39+BC39)/AQ39),BI39*LOG10(BJ39/AQ39)+BH39*LOG10((AQ39+BC39)/BJ39)))*BF39 | BL39: =IF(AM39="Sand",0,10^(INDEX(Input!$Q$48:$Q$54,MIN(MATCH(MIN(MAX(AR39,30),120),Input!$C$48:$C$54,1),6))+(MIN(MAX(AR39,30),120)-INDEX(Input!$C$48:$C$54,MIN(MATCH(MIN(MAX(AR39,30),120),Input!$C$48:$C$54,1),6)))/(INDEX(Input!$C$48:$C$54,MIN(MATCH(MIN(MAX(AR39,30),120),Input!$C$48:$C$54,1),6)+1)-INDEX(Input!$C$48:$C$54,MIN(MATCH(MIN(MAX(AR39,30),120),Input!$C$48:$C$54,1),6)))*(INDEX(Input!$Q$48:$Q$54,MIN(MATCH(MIN(MAX(AR39,30),120),Input!$C$48:$C$54,1),6)+1)-INDEX(Input!$Q$48:$Q$54,MIN(MATCH(MIN(MAX(AR39,30),120),Input!$C$48:$C$54,1),6))))) | BM39: =IF(OR(AM39="Sand",BF39=0),0,Input!$AA$38*(AK39/2)^2/(BL39*1E-4*31536000)) | BN39: =MAX(0,MIN(AJ39,Input!$AA$20)-AI39) | BO39: =MAX(0,MIN(AJ39,Input!$AA$20)-MAX(AI39,$AA$22)) | BP39: =MAX(0,MIN(AJ39,$AA$225)-AI39)
C40: 13 | E40: =AI40 | H40: =AJ40 | K40: =AM40 | N40: =AN40 | Q40: =AO40 | T40: =IF(AR40="","-",AR40) | V40: =IF(AT40="","-",AT40) | X40: =AU40 | Z40: =AV40 | AC40: =AW40 | AI40: 18 | AJ40: 19.5 | AK40: =AJ40-AI40 | AL40: =(AI40+AJ40)/2 | AM40: Sand | AN40: 42 | AO40: =IF(AL40>$AA$19,$AA$21,$AA$20) | AP40: =AP39+AO40*AK40 | AQ40: =AP40-AO40*AK40/2-10*MAX(AL40-$AA$19,0) | AT40: =IF(AR40="","",AR40-AS40) | AU40: 0.65 | AV40: =IF(AM40="Sand",0,Input!$AA$31*AN40) | AW40: =IF(AM40="Sand",27.1+0.3*MIN(Input!$AA$32*AN40,60)-0.00054*MIN(Input!$AA$32*AN40,60)^2,MIN(MAX(DEGREES(ASIN(0.8-0.094*LN(MAX(IF(AT40="",10,AT40),5)))),20),30)) | AX40: =IF(AM40="Sand",Input!$AA$33*Input!$AA$32*AN40,Input!$AA$34*AV40) | AY40: =IF(AM40="Sand",Input!$AA$35,0.5) | AZ40: =Input!$AA$15/2/AL40 | BA40: =Input!$AA$16/2/AL40 | BB40: =1/(4*PI())*(2*AZ40*BA40*SQRT(AZ40^2+BA40^2+1)/(AZ40^2+BA40^2+1+AZ40^2*BA40^2)*(AZ40^2+BA40^2+2)/(AZ40^2+BA40^2+1)+ATAN2(AZ40^2+BA40^2+1-AZ40^2*BA40^2,2*AZ40*BA40*SQRT(AZ40^2+BA40^2+1))) | BC40: =4*Input!$AA$14*BB40 | BD40: =((Input!$AA$16/Input!$AA$15)*LN((1+SQRT((Input!$AA$16/Input!$AA$15)^2+1))*SQRT((Input!$AA$16/Input!$AA$15)^2+(AJ40/(Input!$AA$15/2))^2)/((Input!$AA$16/Input!$AA$15)*(1+SQRT((Input!$AA$16/Input!$AA$15)^2+(AJ40/(Input!$AA$15/2))^2+1))))+LN(((Input!$AA$16/Input!$AA$15)+SQRT((Input!$AA$16/Input!$AA$15)^2+1))*SQRT(1+(AJ40/(Input!$AA$15/2))^2)/((Input!$AA$16/Input!$AA$15)+SQRT((Input!$AA$16/Input!$AA$15)^2+(AJ40/(Input!$AA$15/2))^2+1))))/PI() | BE40: =(AJ40/(Input!$AA$15/2))/(2*PI())*ATAN((Input!$AA$16/Input!$AA$15)/((AJ40/(Input!$AA$15/2))*SQRT((Input!$AA$16/Input!$AA$15)^2+(AJ40/(Input!$AA$15/2))^2+1))) | BF40: =MAX(0,AJ40-MAX(AI40,$AA$22))/AK40*IF(BC40>=Input!$AA$21*AQ40,1,0) | BG40: =4*Input!$AA$14*(Input!$AA$15/2)*(1-AY40^2)/AX40*((BD40-BD39)+(1-2*AY40)/(1-AY40)*(BE40-BE39))*1000*BF40 | BH40: =IF(AM40="Sand",0,0.009*(AR40-10)) | BI40: =BH40*Input!$AA$36 | BJ40: =IF(AM40="Sand",0,MAX(AV40/Input!$AA$37,AQ40)) | BK40: =IF(AM40="Sand",0,1000*AK40/(1+AU40)*IF(AQ40+BC40<=BJ40,BI40*LOG10((AQ40+BC40)/AQ40),BI40*LOG10(BJ40/AQ40)+BH40*LOG10((AQ40+BC40)/BJ40)))*BF40 | BL40: =IF(AM40="Sand",0,10^(INDEX(Input!$Q$48:$Q$54,MIN(MATCH(MIN(MAX(AR40,30),120),Input!$C$48:$C$54,1),6))+(MIN(MAX(AR40,30),120)-INDEX(Input!$C$48:$C$54,MIN(MATCH(MIN(MAX(AR40,30),120),Input!$C$48:$C$54,1),6)))/(INDEX(Input!$C$48:$C$54,MIN(MATCH(MIN(MAX(AR40,30),120),Input!$C$48:$C$54,1),6)+1)-INDEX(Input!$C$48:$C$54,MIN(MATCH(MIN(MAX(AR40,30),120),Input!$C$48:$C$54,1),6)))*(INDEX(Input!$Q$48:$Q$54,MIN(MATCH(MIN(MAX(AR40,30),120),Input!$C$48:$C$54,1),6)+1)-INDEX(Input!$Q$48:$Q$54,MIN(MATCH(MIN(MAX(AR40,30),120),Input!$C$48:$C$54,1),6))))) | BM40: =IF(OR(AM40="Sand",BF40=0),0,Input!$AA$38*(AK40/2)^2/(BL40*1E-4*31536000)) | BN40: =MAX(0,MIN(AJ40,Input!$AA$20)-AI40) | BO40: =MAX(0,MIN(AJ40,Input!$AA$20)-MAX(AI40,$AA$22)) | BP40: =MAX(0,MIN(AJ40,$AA$225)-AI40)
C41: 14 | E41: =AI41 | H41: =AJ41 | K41: =AM41 | N41: =AN41 | Q41: =AO41 | T41: =IF(AR41="","-",AR41) | V41: =IF(AT41="","-",AT41) | X41: =AU41 | Z41: =AV41 | AC41: =AW41 | AI41: 19.5 | AJ41: 21 | AK41: =AJ41-AI41 | AL41: =(AI41+AJ41)/2 | AM41: Sand | AN41: 49 | AO41: =IF(AL41>$AA$19,$AA$21,$AA$20) | AP41: =AP40+AO41*AK41 | AQ41: =AP41-AO41*AK41/2-10*MAX(AL41-$AA$19,0) | AT41: =IF(AR41="","",AR41-AS41) | AU41: 0.848 | AV41: =IF(AM41="Sand",0,Input!$AA$31*AN41) | AW41: =IF(AM41="Sand",27.1+0.3*MIN(Input!$AA$32*AN41,60)-0.00054*MIN(Input!$AA$32*AN41,60)^2,MIN(MAX(DEGREES(ASIN(0.8-0.094*LN(MAX(IF(AT41="",10,AT41),5)))),20),30)) | AX41: =IF(AM41="Sand",Input!$AA$33*Input!$AA$32*AN41,Input!$AA$34*AV41) | AY41: =IF(AM41="Sand",Input!$AA$35,0.5) | AZ41: =Input!$AA$15/2/AL41 | BA41: =Input!$AA$16/2/AL41 | BB41: =1/(4*PI())*(2*AZ41*BA41*SQRT(AZ41^2+BA41^2+1)/(AZ41^2+BA41^2+1+AZ41^2*BA41^2)*(AZ41^2+BA41^2+2)/(AZ41^2+BA41^2+1)+ATAN2(AZ41^2+BA41^2+1-AZ41^2*BA41^2,2*AZ41*BA41*SQRT(AZ41^2+BA41^2+1))) | BC41: =4*Input!$AA$14*BB41 | BD41: =((Input!$AA$16/Input!$AA$15)*LN((1+SQRT((Input!$AA$16/Input!$AA$15)^2+1))*SQRT((Input!$AA$16/Input!$AA$15)^2+(AJ41/(Input!$AA$15/2))^2)/((Input!$AA$16/Input!$AA$15)*(1+SQRT((Input!$AA$16/Input!$AA$15)^2+(AJ41/(Input!$AA$15/2))^2+1))))+LN(((Input!$AA$16/Input!$AA$15)+SQRT((Input!$AA$16/Input!$AA$15)^2+1))*SQRT(1+(AJ41/(Input!$AA$15/2))^2)/((Input!$AA$16/Input!$AA$15)+SQRT((Input!$AA$16/Input!$AA$15)^2+(AJ41/(Input!$AA$15/2))^2+1))))/PI() | BE41: =(AJ41/(Input!$AA$15/2))/(2*PI())*ATAN((Input!$AA$16/Input!$AA$15)/((AJ41/(Input!$AA$15/2))*SQRT((Input!$AA$16/Input!$AA$15)^2+(AJ41/(Input!$AA$15/2))^2+1))) | BF41: =MAX(0,AJ41-MAX(AI41,$AA$22))/AK41*IF(BC41>=Input!$AA$21*AQ41,1,0) | BG41: =4*Input!$AA$14*(Input!$AA$15/2)*(1-AY41^2)/AX41*((BD41-BD40)+(1-2*AY41)/(1-AY41)*(BE41-BE40))*1000*BF41 | BH41: =IF(AM41="Sand",0,0.009*(AR41-10)) | BI41: =BH41*Input!$AA$36 | BJ41: =IF(AM41="Sand",0,MAX(AV41/Input!$AA$37,AQ41)) | BK41: =IF(AM41="Sand",0,1000*AK41/(1+AU41)*IF(AQ41+BC41<=BJ41,BI41*LOG10((AQ41+BC41)/AQ41),BI41*LOG10(BJ41/AQ41)+BH41*LOG10((AQ41+BC41)/BJ41)))*BF41 | BL41: =IF(AM41="Sand",0,10^(INDEX(Input!$Q$48:$Q$54,MIN(MATCH(MIN(MAX(AR41,30),120),Input!$C$48:$C$54,1),6))+(MIN(MAX(AR41,30),120)-INDEX(Input!$C$48:$C$54,MIN(MATCH(MIN(MAX(AR41,30),120),Input!$C$48:$C$54,1),6)))/(INDEX(Input!$C$48:$C$54,MIN(MATCH(MIN(MAX(AR41,30),120),Input!$C$48:$C$54,1),6)+1)-INDEX(Input!$C$48:$C$54,MIN(MATCH(MIN(MAX(AR41,30),120),Input!$C$48:$C$54,1),6)))*(INDEX(Input!$Q$48:$Q$54,MIN(MATCH(MIN(MAX(AR41,30),120),Input!$C$48:$C$54,1),6)+1)-INDEX(Input!$Q$48:$Q$54,MIN(MATCH(MIN(MAX(AR41,30),120),Input!$C$48:$C$54,1),6))))) | BM41: =IF(OR(AM41="Sand",BF41=0),0,Input!$AA$38*(AK41/2)^2/(BL41*1E-4*31536000)) | BN41: =MAX(0,MIN(AJ41,Input!$AA$20)-AI41) | BO41: =MAX(0,MIN(AJ41,Input!$AA$20)-MAX(AI41,$AA$22)) | BP41: =MAX(0,MIN(AJ41,$AA$225)-AI41)
C42: 15 | E42: =AI42 | H42: =AJ42 | K42: =AM42 | N42: =AN42 | Q42: =AO42 | T42: =IF(AR42="","-",AR42) | V42: =IF(AT42="","-",AT42) | X42: =AU42 | Z42: =AV42 | AC42: =AW42 | AI42: 21 | AJ42: 22.5 | AK42: =AJ42-AI42 | AL42: =(AI42+AJ42)/2 | AM42: Sand | AN42: 49 | AO42: =IF(AL42>$AA$19,$AA$21,$AA$20) | AP42: =AP41+AO42*AK42 | AQ42: =AP42-AO42*AK42/2-10*MAX(AL42-$AA$19,0) | AT42: =IF(AR42="","",AR42-AS42) | AU42: 0.65 | AV42: =IF(AM42="Sand",0,Input!$AA$31*AN42) | AW42: =IF(AM42="Sand",27.1+0.3*MIN(Input!$AA$32*AN42,60)-0.00054*MIN(Input!$AA$32*AN42,60)^2,MIN(MAX(DEGREES(ASIN(0.8-0.094*LN(MAX(IF(AT42="",10,AT42),5)))),20),30)) | AX42: =IF(AM42="Sand",Input!$AA$33*Input!$AA$32*AN42,Input!$AA$34*AV42) | AY42: =IF(AM42="Sand",Input!$AA$35,0.5) | AZ42: =Input!$AA$15/2/AL42 | BA42: =Input!$AA$16/2/AL42 | BB42: =1/(4*PI())*(2*AZ42*BA42*SQRT(AZ42^2+BA42^2+1)/(AZ42^2+BA42^2+1+AZ42^2*BA42^2)*(AZ42^2+BA42^2+2)/(AZ42^2+BA42^2+1)+ATAN2(AZ42^2+BA42^2+1-AZ42^2*BA42^2,2*AZ42*BA42*SQRT(AZ42^2+BA42^2+1))) | BC42: =4*Input!$AA$14*BB42 | BD42: =((Input!$AA$16/Input!$AA$15)*LN((1+SQRT((Input!$AA$16/Input!$AA$15)^2+1))*SQRT((Input!$AA$16/Input!$AA$15)^2+(AJ42/(Input!$AA$15/2))^2)/((Input!$AA$16/Input!$AA$15)*(1+SQRT((Input!$AA$16/Input!$AA$15)^2+(AJ42/(Input!$AA$15/2))^2+1))))+LN(((Input!$AA$16/Input!$AA$15)+SQRT((Input!$AA$16/Input!$AA$15)^2+1))*SQRT(1+(AJ42/(Input!$AA$15/2))^2)/((Input!$AA$16/Input!$AA$15)+SQRT((Input!$AA$16/Input!$AA$15)^2+(AJ42/(Input!$AA$15/2))^2+1))))/PI() | BE42: =(AJ42/(Input!$AA$15/2))/(2*PI())*ATAN((Input!$AA$16/Input!$AA$15)/((AJ42/(Input!$AA$15/2))*SQRT((Input!$AA$16/Input!$AA$15)^2+(AJ42/(Input!$AA$15/2))^2+1))) | BF42: =MAX(0,AJ42-MAX(AI42,$AA$22))/AK42*IF(BC42>=Input!$AA$21*AQ42,1,0) | BG42: =4*Input!$AA$14*(Input!$AA$15/2)*(1-AY42^2)/AX42*((BD42-BD41)+(1-2*AY42)/(1-AY42)*(BE42-BE41))*1000*BF42 | BH42: =IF(AM42="Sand",0,0.009*(AR42-10)) | BI42: =BH42*Input!$AA$36 | BJ42: =IF(AM42="Sand",0,MAX(AV42/Input!$AA$37,AQ42)) | BK42: =IF(AM42="Sand",0,1000*AK42/(1+AU42)*IF(AQ42+BC42<=BJ42,BI42*LOG10((AQ42+BC42)/AQ42),BI42*LOG10(BJ42/AQ42)+BH42*LOG10((AQ42+BC42)/BJ42)))*BF42 | BL42: =IF(AM42="Sand",0,10^(INDEX(Input!$Q$48:$Q$54,MIN(MATCH(MIN(MAX(AR42,30),120),Input!$C$48:$C$54,1),6))+(MIN(MAX(AR42,30),120)-INDEX(Input!$C$48:$C$54,MIN(MATCH(MIN(MAX(AR42,30),120),Input!$C$48:$C$54,1),6)))/(INDEX(Input!$C$48:$C$54,MIN(MATCH(MIN(MAX(AR42,30),120),Input!$C$48:$C$54,1),6)+1)-INDEX(Input!$C$48:$C$54,MIN(MATCH(MIN(MAX(AR42,30),120),Input!$C$48:$C$54,1),6)))*(INDEX(Input!$Q$48:$Q$54,MIN(MATCH(MIN(MAX(AR42,30),120),Input!$C$48:$C$54,1),6)+1)-INDEX(Input!$Q$48:$Q$54,MIN(MATCH(MIN(MAX(AR42,30),120),Input!$C$48:$C$54,1),6))))) | BM42: =IF(OR(AM42="Sand",BF42=0),0,Input!$AA$38*(AK42/2)^2/(BL42*1E-4*31536000)) | BN42: =MAX(0,MIN(AJ42,Input!$AA$20)-AI42) | BO42: =MAX(0,MIN(AJ42,Input!$AA$20)-MAX(AI42,$AA$22)) | BP42: =MAX(0,MIN(AJ42,$AA$225)-AI42)
C43: 16 | E43: =AI43 | H43: =AJ43 | K43: =AM43 | N43: =AN43 | Q43: =AO43 | T43: =IF(AR43="","-",AR43) | V43: =IF(AT43="","-",AT43) | X43: =AU43 | Z43: =AV43 | AC43: =AW43 | AI43: 22.5 | AJ43: 24 | AK43: =AJ43-AI43 | AL43: =(AI43+AJ43)/2 | AM43: Clay | AN43: 44 | AO43: =IF(AL43>$AA$19,$AA$21,$AA$20) | AP43: =AP42+AO43*AK43 | AQ43: =AP43-AO43*AK43/2-10*MAX(AL43-$AA$19,0) | AR43: 31.31 | AS43: 20.24 | AT43: =IF(AR43="","",AR43-AS43) | AU43: 0.662 | AV43: =IF(AM43="Sand",0,Input!$AA$31*AN43) | AW43: =IF(AM43="Sand",27.1+0.3*MIN(Input!$AA$32*AN43,60)-0.00054*MIN(Input!$AA$32*AN43,60)^2,MIN(MAX(DEGREES(ASIN(0.8-0.094*LN(MAX(IF(AT43="",10,AT43),5)))),20),30)) | AX43: =IF(AM43="Sand",Input!$AA$33*Input!$AA$32*AN43,Input!$AA$34*AV43) | AY43: =IF(AM43="Sand",Input!$AA$35,0.5) | AZ43: =Input!$AA$15/2/AL43 | BA43: =Input!$AA$16/2/AL43 | BB43: =1/(4*PI())*(2*AZ43*BA43*SQRT(AZ43^2+BA43^2+1)/(AZ43^2+BA43^2+1+AZ43^2*BA43^2)*(AZ43^2+BA43^2+2)/(AZ43^2+BA43^2+1)+ATAN2(AZ43^2+BA43^2+1-AZ43^2*BA43^2,2*AZ43*BA43*SQRT(AZ43^2+BA43^2+1))) | BC43: =4*Input!$AA$14*BB43 | BD43: =((Input!$AA$16/Input!$AA$15)*LN((1+SQRT((Input!$AA$16/Input!$AA$15)^2+1))*SQRT((Input!$AA$16/Input!$AA$15)^2+(AJ43/(Input!$AA$15/2))^2)/((Input!$AA$16/Input!$AA$15)*(1+SQRT((Input!$AA$16/Input!$AA$15)^2+(AJ43/(Input!$AA$15/2))^2+1))))+LN(((Input!$AA$16/Input!$AA$15)+SQRT((Input!$AA$16/Input!$AA$15)^2+1))*SQRT(1+(AJ43/(Input!$AA$15/2))^2)/((Input!$AA$16/Input!$AA$15)+SQRT((Input!$AA$16/Input!$AA$15)^2+(AJ43/(Input!$AA$15/2))^2+1))))/PI() | BE43: =(AJ43/(Input!$AA$15/2))/(2*PI())*ATAN((Input!$AA$16/Input!$AA$15)/((AJ43/(Input!$AA$15/2))*SQRT((Input!$AA$16/Input!$AA$15)^2+(AJ43/(Input!$AA$15/2))^2+1))) | BF43: =MAX(0,AJ43-MAX(AI43,$AA$22))/AK43*IF(BC43>=Input!$AA$21*AQ43,1,0) | BG43: =4*Input!$AA$14*(Input!$AA$15/2)*(1-AY43^2)/AX43*((BD43-BD42)+(1-2*AY43)/(1-AY43)*(BE43-BE42))*1000*BF43 | BH43: =IF(AM43="Sand",0,0.009*(AR43-10)) | BI43: =BH43*Input!$AA$36 | BJ43: =IF(AM43="Sand",0,MAX(AV43/Input!$AA$37,AQ43)) | BK43: =IF(AM43="Sand",0,1000*AK43/(1+AU43)*IF(AQ43+BC43<=BJ43,BI43*LOG10((AQ43+BC43)/AQ43),BI43*LOG10(BJ43/AQ43)+BH43*LOG10((AQ43+BC43)/BJ43)))*BF43 | BL43: =IF(AM43="Sand",0,10^(INDEX(Input!$Q$48:$Q$54,MIN(MATCH(MIN(MAX(AR43,30),120),Input!$C$48:$C$54,1),6))+(MIN(MAX(AR43,30),120)-INDEX(Input!$C$48:$C$54,MIN(MATCH(MIN(MAX(AR43,30),120),Input!$C$48:$C$54,1),6)))/(INDEX(Input!$C$48:$C$54,MIN(MATCH(MIN(MAX(AR43,30),120),Input!$C$48:$C$54,1),6)+1)-INDEX(Input!$C$48:$C$54,MIN(MATCH(MIN(MAX(AR43,30),120),Input!$C$48:$C$54,1),6)))*(INDEX(Input!$Q$48:$Q$54,MIN(MATCH(MIN(MAX(AR43,30),120),Input!$C$48:$C$54,1),6)+1)-INDEX(Input!$Q$48:$Q$54,MIN(MATCH(MIN(MAX(AR43,30),120),Input!$C$48:$C$54,1),6))))) | BM43: =IF(OR(AM43="Sand",BF43=0),0,Input!$AA$38*(AK43/2)^2/(BL43*1E-4*31536000)) | BN43: =MAX(0,MIN(AJ43,Input!$AA$20)-AI43) | BO43: =MAX(0,MIN(AJ43,Input!$AA$20)-MAX(AI43,$AA$22)) | BP43: =MAX(0,MIN(AJ43,$AA$225)-AI43)
C44: 17 | E44: =AI44 | H44: =AJ44 | K44: =AM44 | N44: =AN44 | Q44: =AO44 | T44: =IF(AR44="","-",AR44) | V44: =IF(AT44="","-",AT44) | X44: =AU44 | Z44: =AV44 | AC44: =AW44 | AI44: 24 | AJ44: 25.5 | AK44: =AJ44-AI44 | AL44: =(AI44+AJ44)/2 | AM44: Clay | AN44: 20 | AO44: =IF(AL44>$AA$19,$AA$21,$AA$20) | AP44: =AP43+AO44*AK44 | AQ44: =AP44-AO44*AK44/2-10*MAX(AL44-$AA$19,0) | AR44: 34.63 | AS44: 24.12 | AT44: =IF(AR44="","",AR44-AS44) | AU44: 0.775 | AV44: =IF(AM44="Sand",0,Input!$AA$31*AN44) | AW44: =IF(AM44="Sand",27.1+0.3*MIN(Input!$AA$32*AN44,60)-0.00054*MIN(Input!$AA$32*AN44,60)^2,MIN(MAX(DEGREES(ASIN(0.8-0.094*LN(MAX(IF(AT44="",10,AT44),5)))),20),30)) | AX44: =IF(AM44="Sand",Input!$AA$33*Input!$AA$32*AN44,Input!$AA$34*AV44) | AY44: =IF(AM44="Sand",Input!$AA$35,0.5) | AZ44: =Input!$AA$15/2/AL44 | BA44: =Input!$AA$16/2/AL44 | BB44: =1/(4*PI())*(2*AZ44*BA44*SQRT(AZ44^2+BA44^2+1)/(AZ44^2+BA44^2+1+AZ44^2*BA44^2)*(AZ44^2+BA44^2+2)/(AZ44^2+BA44^2+1)+ATAN2(AZ44^2+BA44^2+1-AZ44^2*BA44^2,2*AZ44*BA44*SQRT(AZ44^2+BA44^2+1))) | BC44: =4*Input!$AA$14*BB44 | BD44: =((Input!$AA$16/Input!$AA$15)*LN((1+SQRT((Input!$AA$16/Input!$AA$15)^2+1))*SQRT((Input!$AA$16/Input!$AA$15)^2+(AJ44/(Input!$AA$15/2))^2)/((Input!$AA$16/Input!$AA$15)*(1+SQRT((Input!$AA$16/Input!$AA$15)^2+(AJ44/(Input!$AA$15/2))^2+1))))+LN(((Input!$AA$16/Input!$AA$15)+SQRT((Input!$AA$16/Input!$AA$15)^2+1))*SQRT(1+(AJ44/(Input!$AA$15/2))^2)/((Input!$AA$16/Input!$AA$15)+SQRT((Input!$AA$16/Input!$AA$15)^2+(AJ44/(Input!$AA$15/2))^2+1))))/PI() | BE44: =(AJ44/(Input!$AA$15/2))/(2*PI())*ATAN((Input!$AA$16/Input!$AA$15)/((AJ44/(Input!$AA$15/2))*SQRT((Input!$AA$16/Input!$AA$15)^2+(AJ44/(Input!$AA$15/2))^2+1))) | BF44: =MAX(0,AJ44-MAX(AI44,$AA$22))/AK44*IF(BC44>=Input!$AA$21*AQ44,1,0) | BG44: =4*Input!$AA$14*(Input!$AA$15/2)*(1-AY44^2)/AX44*((BD44-BD43)+(1-2*AY44)/(1-AY44)*(BE44-BE43))*1000*BF44 | BH44: =IF(AM44="Sand",0,0.009*(AR44-10)) | BI44: =BH44*Input!$AA$36 | BJ44: =IF(AM44="Sand",0,MAX(AV44/Input!$AA$37,AQ44)) | BK44: =IF(AM44="Sand",0,1000*AK44/(1+AU44)*IF(AQ44+BC44<=BJ44,BI44*LOG10((AQ44+BC44)/AQ44),BI44*LOG10(BJ44/AQ44)+BH44*LOG10((AQ44+BC44)/BJ44)))*BF44 | BL44: =IF(AM44="Sand",0,10^(INDEX(Input!$Q$48:$Q$54,MIN(MATCH(MIN(MAX(AR44,30),120),Input!$C$48:$C$54,1),6))+(MIN(MAX(AR44,30),120)-INDEX(Input!$C$48:$C$54,MIN(MATCH(MIN(MAX(AR44,30),120),Input!$C$48:$C$54,1),6)))/(INDEX(Input!$C$48:$C$54,MIN(MATCH(MIN(MAX(AR44,30),120),Input!$C$48:$C$54,1),6)+1)-INDEX(Input!$C$48:$C$54,MIN(MATCH(MIN(MAX(AR44,30),120),Input!$C$48:$C$54,1),6)))*(INDEX(Input!$Q$48:$Q$54,MIN(MATCH(MIN(MAX(AR44,30),120),Input!$C$48:$C$54,1),6)+1)-INDEX(Input!$Q$48:$Q$54,MIN(MATCH(MIN(MAX(AR44,30),120),Input!$C$48:$C$54,1),6))))) | BM44: =IF(OR(AM44="Sand",BF44=0),0,Input!$AA$38*(AK44/2)^2/(BL44*1E-4*31536000)) | BN44: =MAX(0,MIN(AJ44,Input!$AA$20)-AI44) | BO44: =MAX(0,MIN(AJ44,Input!$AA$20)-MAX(AI44,$AA$22)) | BP44: =MAX(0,MIN(AJ44,$AA$225)-AI44)
