Workbook

Sheet Input
A1: PERHITUNGAN DAYA DUKUNG AKSIAL BORED PILE
A2: Geotechnical Investigation & DED Geothermal Wellpad - PSPE Bora Pulu
A3: Lokasi: Wellpad D | Titik bor: BH-04 | Fondasi: Bored pile D1000
A5: A. DATA TIANG
A6: Jenis tiang | C6: Bored pile
A7: Diameter tiang | B7: D | C7: 1 | D7: m
A8: Keliling | B8: p | C8: =PI()*C7 | D8: m
A9: Luas penampang | B9: Ap | C9: =PI()*C7^2/4 | D9: m²
A10: Berat isi beton | B10: γc | C10: 2.4 | D10: t/m³
A11: Kedalaman cut-off (kepala tiang) | B11: zc | C11: 1 | D11: m | E11: dari muka tanah
A13: B. DATA TANAH & LIKUEFAKSI
A14: Muka air tanah desain | B14: GWL | C14: 9 | D14: m | E14: Report BP-00-GEO-RPT-003, Tabel 3.2
A15: Dasar zona likuefaksi (lapisan L terdalam) | B15: zL | C15: =_xlfn.MAXIFS('Data Tanah'!$C$7:$C$47,'Data Tanah'!$H$7:$H$47,"L") | D15: m | E15: otomatis dari kolom Likuefaksi (L/NL) di sheet Data Tanah; 0 = tidak ada likuefaksi
A16: Berat isi tanah di atas GWL | B16: γ1 | C16: 18.5 | D16: kN/m³ | E16: Report Tabel 5.1
A17: Berat isi tanah di bawah GWL | B17: γ2 | C17: 18.4 | D17: kN/m³ | E17: Report Tabel 5.1
A18: φ tanah terlikuifaksi (resettled), butir kasar | B18: φL | C18: 30 | D18: ° | E18: Caltrans GM Step 4-6 (SW, SP, SM)
A19: φ tanah terlikuifaksi (resettled), butir halus | B19: φL | C19: 25 | D19: ° | E19: Caltrans GM Step 4-6 (ML)
A20: Penurunan tanah di permukaan akibat likuefaksi | B20: δg | C20: =MAX('Data Tanah'!$Q$7:$Q$47) | D20: mm | E20: otomatis = Σ εv·tebal lapisan L (Data Tanah kolom P-Q)
A21: Relative settlement mobilisasi friksi (1% D) | B21: zmax | C21: =0.01*C7*1000 | D21: mm | E21: Caltrans GM Tabel 1 (drilled shaft, pasir)
A22: Garis A-A' (batas bawah zona downdrag) | B22: zA-A' | C22: =_xlfn.MAXIFS('Data Tanah'!$C$7:$C$47,'Data Tanah'!$Q$7:$Q$47,">"&Input!$C$21) | D22: m | E22: otomatis: dasar lapisan terdalam yang penurunan tanahnya > zmax (Caltrans Step 4-5, δpile diabaikan); 0 = tanpa downdrag
A23: Manifestasi permukaan (1 = ya, 0 = tidak) | C23: 1 | D23: - | E23: Caltrans Step 3-2; 1 = friksi di atas dasar likuefaksi diabaikan
A24: εv default lapisan L tanpa data | C24: 3 | D24: % | E24: dipakai bila kolom εv (Data Tanah) kosong pada lapisan L
A25: C. PARAMETER TAHANAN
A26: Awal friksi - kondisi statis | C26: 2 | D26: m | E26: sesuai perhitungan sebelumnya
A27: Awal friksi - kondisi likuefaksi | C27: 2.5 | D27: m | E27: sesuai perhitungan sebelumnya
A28: Friksi diabaikan di atas ujung tiang | C28: 1 | D28: × D | E28: O'Neill & Reese (1999)
A29: Friksi pasir: fs = k·N | B29: k | C29: 0.3 | D29: t/m²/N | E29: ≈ 3N kPa
A30: Batas friksi | B30: fs,max | C30: 15 | D30: t/m² | E30: ≈ 150 kPa
A31: Faktor adhesi lempung | B31: α | C31: 0.55 | D31: - | E31: Reese & O'Neill
A32: Kuat geser undrained lempung: cu = k·N | C32: 0.5 | D32: t/m²/N
A33: Tahanan ujung pasir: qb = k·N | C33: 57.5 | D33: kPa/N | E33: O'Neill & Reese (1999)
A34: Batas tahanan ujung pasir | C34: 2870 | D34: kPa | E34: O'Neill & Reese (1999)
A35: Faktor daya dukung lempung | B35: Nc | C35: 9 | D35: - | E35: qb = Nc·cu
A36: Jendela rata-rata qb: di atas ujung | C36: 1 | D36: × D
A37: Jendela rata-rata qb: di bawah ujung | C37: 2 | D37: × D
A38: Tahanan tarik ultimit: Tult = k·Qs | C38: 0.7 | D38: -
A40: D. FAKTOR KEAMANAN
A41: SF friksi - statis | C41: 2.5 | D41: -
A42: SF ujung - statis | C42: 3 | D42: -
A43: SF tarik - statis | C43: 3 | D43: -
...

Sheet Data Tanah
A1: DATA TANAH & PARAMETER LAPISAN
A2: Geotechnical Investigation & DED Geothermal Wellpad - PSPE Bora Pulu
A3: =Input!A3
A5: No | B5: Atas | C5: Bawah | D5: Tebal | E5: Tengah | F5: Jenis | G5: N-SPT | H5: Likuefaksi | I5: cu | J5: σ'v tengah | K5: fs statis | L5: fs likuefaksi | M5: fs downdrag | N5: qb | O5: Keterangan | P5: εv | Q5: Penurunan tanah di puncak lapisan
B6: m | C6: m | D6: m | E6: m | H6: L / NL | I6: t/m² | J6: t/m² | K6: t/m² | L6: t/m² | M6: t/m² | N6: t/m² | P6: % | Q6: mm
A7: 1 | B7: 0 | C7: =B7+D7 | D7: 1.5 | E7: =B7+D7/2 | F7: Clay | G7: 0 | H7: NL | I7: =IF(F7="Clay",Input!$C$32*G7,0) | J7: =Input!$C$16/9.81*MIN(E7,Input!$C$14)+(Input!$C$17/9.81-1)*MAX(E7-Input!$C$14,0) | K7: =IF(F7="Clay",MIN(Input!$C$31*I7,Input!$C$30),MIN(Input!$C$29*G7,Input!$C$30)) | L7: =IF(H7="L",0,K7) | M7: =IF(H7="L",MIN((1-SIN(RADIANS(IF(F7="Clay",Input!$C$19,Input!$C$18))))*TAN(RADIANS(2/3*IF(F7="Clay",Input!$C$19,Input!$C$18)))*J7,Input!$C$30),IF(F7="Clay",K7,MIN(K7,MIN(MAX(1.5-0.245*SQRT(E7),0.25),1.2)*MIN(G7/15,1)*J7,Input!$C$30))) | N7: =IF(F7="Clay",Input!$C$35*I7,MIN(Input!$C$33*G7,Input!$C$34)/9.81) | Q7: =10*SUMPRODUCT(--($B$7:$B$47>=B7),--($H$7:$H$47="L"),$D$7:$D$47,$P$7:$P$47+($P$7:$P$47="")*Input!$C$24)
A8: 2 | B8: 1.5 | C8: =B8+D8 | D8: 1.5 | E8: =B8+D8/2 | F8: Clay | G8: 5 | H8: NL | I8: =IF(F8="Clay",Input!$C$32*G8,0) | J8: =Input!$C$16/9.81*MIN(E8,Input!$C$14)+(Input!$C$17/9.81-1)*MAX(E8-Input!$C$14,0) | K8: =IF(F8="Clay",MIN(Input!$C$31*I8,Input!$C$30),MIN(Input!$C$29*G8,Input!$C$30)) | L8: =IF(H8="L",0,K8) | M8: =IF(H8="L",MIN((1-SIN(RADIANS(IF(F8="Clay",Input!$C$19,Input!$C$18))))*TAN(RADIANS(2/3*IF(F8="Clay",Input!$C$19,Input!$C$18)))*J8,Input!$C$30),IF(F8="Clay",K8,MIN(K8,MIN(MAX(1.5-0.245*SQRT(E8),0.25),1.2)*MIN(G8/15,1)*J8,Input!$C$30))) | N8: =IF(F8="Clay",Input!$C$35*I8,MIN(Input!$C$33*G8,Input!$C$34)/9.81) | P8: 0.56 | Q8: =10*SUMPRODUCT(--($B$7:$B$47>=B8),--($H$7:$H$47="L"),$D$7:$D$47,$P$7:$P$47+($P$7:$P$47="")*Input!$C$24)
A9: 3 | B9: 3 | C9: =B9+D9 | D9: 2.5 | E9: =B9+D9/2 | F9: Sand | G9: 49 | H9: NL | I9: =IF(F9="Clay",Input!$C$32*G9,0) | J9: =Input!$C$16/9.81*MIN(E9,Input!$C$14)+(Input!$C$17/9.81-1)*MAX(E9-Input!$C$14,0) | K9: =IF(F9="Clay",MIN(Input!$C$31*I9,Input!$C$30),MIN(Input!$C$29*G9,Input!$C$30)) | L9: =IF(H9="L",0,K9) | M9: =IF(H9="L",MIN((1-SIN(RADIANS(IF(F9="Clay",Input!$C$19,Input!$C$18))))*TAN(RADIANS(2/3*IF(F9="Clay",Input!$C$19,Input!$C$18)))*J9,Input!$C$30),IF(F9="Clay",K9,MIN(K9,MIN(MAX(1.5-0.245*SQRT(E9),0.25),1.2)*MIN(G9/15,1)*J9,Input!$C$30))) | N9: =IF(F9="Clay",Input!$C$35*I9,MIN(Input!$C$33*G9,Input!$C$34)/9.81) | P9: 1.27 | Q9: =10*SUMPRODUCT(--($B$7:$B$47>=B9),--($H$7:$H$47="L"),$D$7:$D$47,$P$7:$P$47+($P$7:$P$47="")*Input!$C$24)
A10: 4 | B10: 5.5 | C10: =B10+D10 | D10: 0.5 | E10: =B10+D10/2 | F10: Sand | G10: 44 | H10: NL | I10: =IF(F10="Clay",Input!$C$32*G10,0) | J10: =Input!$C$16/9.81*MIN(E10,Input!$C$14)+(Input!$C$17/9.81-1)*MAX(E10-Input!$C$14,0) | K10: =IF(F10="Clay",MIN(Input!$C$31*I10,Input!$C$30),MIN(Input!$C$29*G10,Input!$C$30)) | L10: =IF(H10="L",0,K10) | M10: =IF(H10="L",MIN((1-SIN(RADIANS(IF(F10="Clay",Input!$C$19,Input!$C$18))))*TAN(RADIANS(2/3*IF(F10="Clay",Input!$C$19,Input!$C$18)))*J10,Input!$C$30),IF(F10="Clay",K10,MIN(K10,MIN(MAX(1.5-0.245*SQRT(E10),0.25),1.2)*MIN(G10/15,1)*J10,Input!$C$30))) | N10: =IF(F10="Clay",Input!$C$35*I10,MIN(Input!$C$33*G10,Input!$C$34)/9.81) | Q10: =10*SUMPRODUCT(--($B$7:$B$47>=B10),--($H$7:$H$47="L"),$D$7:$D$47,$P$7:$P$47+($P$7:$P$47="")*Input!$C$24)
A11: 5 | B11: 6 | C11: =B11+D11 | D11: 1.5 | E11: =B11+D11/2 | F11: Sand | G11: 30 | H11: NL | I11: =IF(F11="Clay",Input!$C$32*G11,0) | J11: =Input!$C$16/9.81*MIN(E11,Input!$C$14)+(Input!$C$17/9.81-1)*MAX(E11-Input!$C$14,0) | K11: =IF(F11="Clay",MIN(Input!$C$31*I11,Input!$C$30),MIN(Input!$C$29*G11,Input!$C$30)) | L11: =IF(H11="L",0,K11) | M11: =IF(H11="L",MIN((1-SIN(RADIANS(IF(F11="Clay",Input!$C$19,Input!$C$18))))*TAN(RADIANS(2/3*IF(F11="Clay",Input!$C$19,Input!$C$18)))*J11,Input!$C$30),IF(F11="Clay",K11,MIN(K11,MIN(MAX(1.5-0.245*SQRT(E11),0.25),1.2)*MIN(G11/15,1)*J11,Input!$C$30))) | N11: =IF(F11="Clay",Input!$C$35*I11,MIN(Input!$C$33*G11,Input!$C$34)/9.81) | P11: 0.26 | Q11: =10*SUMPRODUCT(--($B$7:$B$47>=B11),--($H$7:$H$47="L"),$D$7:$D$47,$P$7:$P$47+($P$7:$P$47="")*Input!$C$24)
A12: 6 | B12: 7.5 | C12: =B12+D12 | D12: 1.5 | E12: =B12+D12/2 | F12: Clay | G12: 14 | H12: NL | I12: =IF(F12="Clay",Input!$C$32*G12,0) | J12: =Input!$C$16/9.81*MIN(E12,Input!$C$14)+(Input!$C$17/9.81-1)*MAX(E12-Input!$C$14,0) | K12: =IF(F12="Clay",MIN(Input!$C$31*I12,Input!$C$30),MIN(Input!$C$29*G12,Input!$C$30)) | L12: =IF(H12="L",0,K12) | M12: =IF(H12="L",MIN((1-SIN(RADIANS(IF(F12="Clay",Input!$C$19,Input!$C$18))))*TAN(RADIANS(2/3*IF(F12="Clay",Input!$C$19,Input!$C$18)))*J12,Input!$C$30),IF(F12="Clay",K12,MIN(K12,MIN(MAX(1.5-0.245*SQRT(E12),0.25),1.2)*MIN(G12/15,1)*J12,Input!$C$30))) | N12: =IF(F12="Clay",Input!$C$35*I12,MIN(Input!$C$33*G12,Input!$C$34)/9.81) | P12: 0.56 | Q12: =10*SUMPRODUCT(--($B$7:$B$47>=B12),--($H$7:$H$47="L"),$D$7:$D$47,$P$7:$P$47+($P$7:$P$47="")*Input!$C$24)
A13: 7 | B13: 9 | C13: =B13+D13 | D13: 1.5 | E13: =B13+D13/2 | F13: Clay | G13: 12 | H13: NL | I13: =IF(F13="Clay",Input!$C$32*G13,0) | J13: =Input!$C$16/9.81*MIN(E13,Input!$C$14)+(Input!$C$17/9.81-1)*MAX(E13-Input!$C$14,0) | K13: =IF(F13="Clay",MIN(Input!$C$31*I13,Input!$C$30),MIN(Input!$C$29*G13,Input!$C$30)) | L13: =IF(H13="L",0,K13) | M13: =IF(H13="L",MIN((1-SIN(RADIANS(IF(F13="Clay",Input!$C$19,Input!$C$18))))*TAN(RADIANS(2/3*IF(F13="Clay",Input!$C$19,Input!$C$18)))*J13,Input!$C$30),IF(F13="Clay",K13,MIN(K13,MIN(MAX(1.5-0.245*SQRT(E13),0.25),1.2)*MIN(G13/15,1)*J13,Input!$C$30))) | N13: =IF(F13="Clay",Input!$C$35*I13,MIN(Input!$C$33*G13,Input!$C$34)/9.81) | P13: 0.56 | Q13: =10*SUMPRODUCT(--($B$7:$B$47>=B13),--($H$7:$H$47="L"),$D$7:$D$47,$P$7:$P$47+($P$7:$P$47="")*Input!$C$24)
A14: 8 | B14: 10.5 | C14: =B14+D14 | D14: 1.5 | E14: =B14+D14/2 | F14: Sand | G14: 18 | H14: L | I14: =IF(F14="Clay",Input!$C$32*G14,0) | J14: =Input!$C$16/9.81*MIN(E14,Input!$C$14)+(Input!$C$17/9.81-1)*MAX(E14-Input!$C$14,0) | K14: =IF(F14="Clay",MIN(Input!$C$31*I14,Input!$C$30),MIN(Input!$C$29*G14,Input!$C$30)) | L14: =IF(H14="L",0,K14) | M14: =IF(H14="L",MIN((1-SIN(RADIANS(IF(F14="Clay",Input!$C$19,Input!$C$18))))*TAN(RADIANS(2/3*IF(F14="Clay",Input!$C$19,Input!$C$18)))*J14,Input!$C$30),IF(F14="Clay",K14,MIN(K14,MIN(MAX(1.5-0.245*SQRT(E14),0.25),1.2)*MIN(G14/15,1)*J14,Input!$C$30))) | N14: =IF(F14="Clay",Input!$C$35*I14,MIN(Input!$C$33*G14,Input!$C$34)/9.81) | P14: 3.45 | Q14: =10*SUMPRODUCT(--($B$7:$B$47>=B14),--($H$7:$H$47="L"),$D$7:$D$47,$P$7:$P$47+($P$7:$P$47="")*Input!$C$24)
A15: 9 | B15: 12 | C15: =B15+D15 | D15: 1.5 | E15: =B15+D15/2 | F15: Clay | G15: 26 | H15: L | I15: =IF(F15="Clay",Input!$C$32*G15,0) | J15: =Input!$C$16/9.81*MIN(E15,Input!$C$14)+(Input!$C$17/9.81-1)*MAX(E15-Input!$C$14,0) | K15: =IF(F15="Clay",MIN(Input!$C$31*I15,Input!$C$30),MIN(Input!$C$29*G15,Input!$C$30)) | L15: =IF(H15="L",0,K15) | M15: =IF(H15="L",MIN((1-SIN(RADIANS(IF(F15="Clay",Input!$C$19,Input!$C$18))))*TAN(RADIANS(2/3*IF(F15="Clay",Input!$C$19,Input!$C$18)))*J15,Input!$C$30),IF(F15="Clay",K15,MIN(K15,MIN(MAX(1.5-0.245*SQRT(E15),0.25),1.2)*MIN(G15/15,1)*J15,Input!$C$30))) | N15: =IF(F15="Clay",Input!$C$35*I15,MIN(Input!$C$33*G15,Input!$C$34)/9.81) | P15: 2.68 | Q15: =10*SUMPRODUCT(--($B$7:$B$47>=B15),--($H$7:$H$47="L"),$D$7:$D$47,$P$7:$P$47+($P$7:$P$47="")*Input!$C$24)
A16: 10 | B16: 13.5 | C16: =B16+D16 | D16: 1.5 | E16: =B16+D16/2 | F16: Clay | G16: 15 | H16: NL | I16: =IF(F16="Clay",Input!$C$32*G16,0) | J16: =Input!$C$16/9.81*MIN(E16,Input!$C$14)+(Input!$C$17/9.81-1)*MAX(E16-Input!$C$14,0) | K16: =IF(F16="Clay",MIN(Input!$C$31*I16,Input!$C$30),MIN(Input!$C$29*G16,Input!$C$30)) | L16: =IF(H16="L",0,K16) | M16: =IF(H16="L",MIN((1-SIN(RADIANS(IF(F16="Clay",Input!$C$19,Input!$C$18))))*TAN(RADIANS(2/3*IF(F16="Clay",Input!$C$19,Input!$C$18)))*J16,Input!$C$30),IF(F16="Clay",K16,MIN(K16,MIN(MAX(1.5-0.245*SQRT(E16),0.25),1.2)*MIN(G16/15,1)*J16,Input!$C$30))) | N16: =IF(F16="Clay",Input!$C$35*I16,MIN(Input!$C$33*G16,Input!$C$34)/9.81) | P16: 0.56 | Q16: =10*SUMPRODUCT(--($B$7:$B$47>=B16),--($H$7:$H$47="L"),$D$7:$D$47,$P$7:$P$47+($P$7:$P$47="")*Input!$C$24)
A17: 11 | B17: 15 | C17: =B17+D17 | D17: 1.5 | E17: =B17+D17/2 | F17: Clay | G17: 15 | H17: NL | I17: =IF(F17="Clay",Input!$C$32*G17,0) | J17: =Input!$C$16/9.81*MIN(E17,Input!$C$14)+(Input!$C$17/9.81-1)*MAX(E17-Input!$C$14,0) | K17: =IF(F17="Clay",MIN(Input!$C$31*I17,Input!$C$30),MIN(Input!$C$29*G17,Input!$C$30)) | L17: =IF(H17="L",0,K17) | M17: =IF(H17="L",MIN((1-SIN(RADIANS(IF(F17="Clay",Input!$C$19,Input!$C$18))))*TAN(RADIANS(2/3*IF(F17="Clay",Input!$C$19,Input!$C$18)))*J17,Input!$C$30),IF(F17="Clay",K17,MIN(K17,MIN(MAX(1.5-0.245*SQRT(E17),0.25),1.2)*MIN(G17/15,1)*J17,Input!$C$30))) | N17: =IF(F17="Clay",Input!$C$35*I17,MIN(Input!$C$33*G17,Input!$C$34)/9.81) | P17: 0.56 | Q17: =10*SUMPRODUCT(--($B$7:$B$47>=B17),--($H$7:$H$47="L"),$D$7:$D$47,$P$7:$P$47+($P$7:$P$47="")*Input!$C$24)
A18: 12 | B18: 16.5 | C18: =B18+D18 | D18: 1.5 | E18: =B18+D18/2 | F18: Clay | G18: 21 | H18: NL | I18: =IF(F18="Clay",Input!$C$32*G18,0) | J18: =Input!$C$16/9.81*MIN(E18,Input!$C$14)+(Input!$C$17/9.81-1)*MAX(E18-Input!$C$14,0) | K18: =IF(F18="Clay",MIN(Input!$C$31*I18,Input!$C$30),MIN(Input!$C$29*G18,Input!$C$30)) | L18: =IF(H18="L",0,K18) | M18: =IF(H18="L",MIN((1-SIN(RADIANS(IF(F18="Clay",Input!$C$19,Input!$C$18))))*TAN(RADIANS(2/3*IF(F18="Clay",Input!$C$19,Input!$C$18)))*J18,Input!$C$30),IF(F18="Clay",K18,MIN(K18,MIN(MAX(1.5-0.245*SQRT(E18),0.25),1.2)*MIN(G18/15,1)*J18,Input!$C$30))) | N18: =IF(F18="Clay",Input!$C$35*I18,MIN(Input!$C$33*G18,Input!$C$34)/9.81) | P18: 0.43 | Q18: =10*SUMPRODUCT(--($B$7:$B$47>=B18),--($H$7:$H$47="L"),$D$7:$D$47,$P$7:$P$47+($P$7:$P$47="")*Input!$C$24)
A19: 13 | B19: 18 | C19: =B19+D19 | D19: 1.5 | E19: =B19+D19/2 | F19: Sand | G19: 18 | H19: NL | I19: =IF(F19="Clay",Input!$C$32*G19,0) | J19: =Input!$C$16/9.81*MIN(E19,Input!$C$14)+(Input!$C$17/9.81-1)*MAX(E19-Input!$C$14,0) | K19: =IF(F19="Clay",MIN(Input!$C$31*I19,Input!$C$30),MIN(Input!$C$29*G19,Input!$C$30)) | L19: =IF(H19="L",0,K19) | M19: =IF(H19="L",MIN((1-SIN(RADIANS(IF(F19="Clay",Input!$C$19,Input!$C$18))))*TAN(RADIANS(2/3*IF(F19="Clay",Input!$C$19,Input!$C$18)))*J19,Input!$C$30),IF(F19="Clay",K19,MIN(K19,MIN(MAX(1.5-0.245*SQRT(E19),0.25),1.2)*MIN(G19/15,1)*J19,Input!$C$30))) | N19: =IF(F19="Clay",Input!$C$35*I19,MIN(Input!$C$33*G19,Input!$C$34)/9.81) | P19: 4.44 | Q19: =10*SUMPRODUCT(--($B$7:$B$47>=B19),--($H$7:$H$47="L"),$D$7:$D$47,$P$7:$P$47+($P$7:$P$47="")*Input!$C$24)
A20: 14 | B20: 19.5 | C20: =B20+D20 | D20: 1.5 | E20: =B20+D20/2 | F20: Clay | G20: 41 | H20: NL | I20: =IF(F20="Clay",Input!$C$32*G20,0) | J20: =Input!$C$16/9.81*MIN(E20,Input!$C$14)+(Input!$C$17/9.81-1)*MAX(E20-Input!$C$14,0) | K20: =IF(F20="Clay",MIN(Input!$C$31*I20,Input!$C$30),MIN(Input!$C$29*G20,Input!$C$30)) | L20: =IF(H20="L",0,K20) | M20: =IF(H20="L",MIN((1-SIN(RADIANS(IF(F20="Clay",Input!$C$19,Input!$C$18))))*TAN(RADIANS(2/3*IF(F20="Clay",Input!$C$19,Input!$C$18)))*J20,Input!$C$30),IF(F20="Clay",K20,MIN(K20,MIN(MAX(1.5-0.245*SQRT(E20),0.25),1.2)*MIN(G20/15,1)*J20,Input!$C$30))) | N20: =IF(F20="Clay",Input!$C$35*I20,MIN(Input!$C$33*G20,Input!$C$34)/9.81) | P20: 0.26 | Q20: =10*SUMPRODUCT(--($B$7:$B$47>=B20),--($H$7:$H$47="L"),$D$7:$D$47,$P$7:$P$47+($P$7:$P$47="")*Input!$C$24)
A21: 15 | B21: 21 | C21: =B21+D21 | D21: 1.5 | E21: =B21+D21/2 | F21: Sand | G21: 36 | H21: NL | I21: =IF(F21="Clay",Input!$C$32*G21,0) | J21: =Input!$C$16/9.81*MIN(E21,Input!$C$14)+(Input!$C$17/9.81-1)*MAX(E21-Input!$C$14,0) | K21: =IF(F21="Clay",MIN(Input!$C$31*I21,Input!$C$30),MIN(Input!$C$29*G21,Input!$C$30)) | L21: =IF(H21="L",0,K21) | M21: =IF(H21="L",MIN((1-SIN(RADIANS(IF(F21="Clay",Input!$C$19,Input!$C$18))))*TAN(RADIANS(2/3*IF(F21="Clay",Input!$C$19,Input!$C$18)))*J21,Input!$C$30),IF(F21="Clay",K21,MIN(K21,MIN(MAX(1.5-0.245*SQRT(E21),0.25),1.2)*MIN(G21/15,1)*J21,Input!$C$30))) | N21: =IF(F21="Clay",Input!$C$35*I21,MIN(Input!$C$33*G21,Input!$C$34)/9.81) | P21: 1.05 | Q21: =10*SUMPRODUCT(--($B$7:$B$47>=B21),--($H$7:$H$47="L"),$D$7:$D$47,$P$7:$P$47+($P$7:$P$47="")*Input!$C$24)
A22: 16 | B22: 22.5 | C22: =B22+D22 | D22: 1.5 | E22: =B22+D22/2 | F22: Clay | G22: 35 | H22: NL | I22: =IF(F22="Clay",Input!$C$32*G22,0) | J22: =Input!$C$16/9.81*MIN(E22,Input!$C$14)+(Input!$C$17/9.81-1)*MAX(E22-Input!$C$14,0) | K22: =IF(F22="Clay",MIN(Input!$C$31*I22,Input!$C$30),MIN(Input!$C$29*G22,Input!$C$30)) | L22: =IF(H22="L",0,K22) | M22: =IF(H22="L",MIN((1-SIN(RADIANS(IF(F22="Clay",Input!$C$19,Input!$C$18))))*TAN(RADIANS(2/3*IF(F22="Clay",Input!$C$19,Input!$C$18)))*J22,Input!$C$30),IF(F22="Clay",K22,MIN(K22,MIN(MAX(1.5-0.245*SQRT(E22),0.25),1.2)*MIN(G22/15,1)*J22,Input!$C$30))) | N22: =IF(F22="Clay",Input!$C$35*I22,MIN(Input!$C$33*G22,Input!$C$34)/9.81) | Q22: =10*SUMPRODUCT(--($B$7:$B$47>=B22),--($H$7:$H$47="L"),$D$7:$D$47,$P$7:$P$47+($P$7:$P$47="")*Input!$C$24)
A23: 17 | B23: 24 | C23: =B23+D23 | D23: 1.5 | E23: =B23+D23/2 | F23: Clay | G23: 24 | H23: NL | I23: =IF(F23="Clay",Input!$C$32*G23,0) | J23: =Input!$C$16/9.81*MIN(E23,Input!$C$14)+(Input!$C$17/9.81-1)*MAX(E23-Input!$C$14,0) | K23: =IF(F23="Clay",MIN(Input!$C$31*I23,Input!$C$30),MIN(Input!$C$29*G23,Input!$C$30)) | L23: =IF(H23="L",0,K23) | M23: =IF(H23="L",MIN((1-SIN(RADIANS(IF(F23="Clay",Input!$C$19,Input!$C$18))))*TAN(RADIANS(2/3*IF(F23="Clay",Input!$C$19,Input!$C$18)))*J23,Input!$C$30),IF(F23="Clay",K23,MIN(K23,MIN(MAX(1.5-0.245*SQRT(E23),0.25),1.2)*MIN(G23/15,1)*J23,Input!$C$30))) | N23: =IF(F23="Clay",Input!$C$35*I23,MIN(Input!$C$33*G23,Input!$C$34)/9.81) | Q23: =10*SUMPRODUCT(--($B$7:$B$47>=B23),--($H$7:$H$47="L"),$D$7:$D$47,$P$7:$P$47+($P$7:$P$47="")*Input!$C$24)
A24: 18 | B24: 25.5 | C24: =B24+D24 | D24: 1.5 | E24: =B24+D24/2 | F24: Clay | G24: 21 | H24: NL | I24: =IF(F24="Clay",Input!$C$32*G24,0) | J24: =Input!$C$16/9.81*MIN(E24,Input!$C$14)+(Input!$C$17/9.81-1)*MAX(E24-Input!$C$14,0) | K24: =IF(F24="Clay",MIN(Input!$C$31*I24,Input!$C$30),MIN(Input!$C$29*G24,Input!$C$30)) | L24: =IF(H24="L",0,K24) | M24: =IF(H24="L",MIN((1-SIN(RADIANS(IF(F24="Clay",Input!$C$19,Input!$C$18))))*TAN(RADIANS(2/3*IF(F24="Clay",Input!$C$19,Input!$C$18)))*J24,Input!$C$30),IF(F24="Clay",K24,MIN(K24,MIN(MAX(1.5-0.245*SQRT(E24),0.25),1.2)*MIN(G24/15,1)*J24,Input!$C$30))) | N24: =IF(F24="Clay",Input!$C$35*I24,MIN(Input!$C$33*G24,Input!$C$34)/9.81) | Q24: =10*SUMPRODUCT(--($B$7:$B$47>=B24),--($H$7:$H$47="L"),$D$7:$D$47,$P$7:$P$47+($P$7:$P$47="")*Input!$C$24)
A25: 19 | B25: 27 | C25: =B25+D25 | D25: 1.5 | E25: =B25+D25/2 | F25: Sand | G25: 21 | H25: NL | I25: =IF(F25="Clay",Input!$C$32*G25,0) | J25: =Input!$C$16/9.81*MIN(E25,Input!$C$14)+(Input!$C$17/9.81-1)*MAX(E25-Input!$C$14,0) | K25: =IF(F25="Clay",MIN(Input!$C$31*I25,Input!$C$30),MIN(Input!$C$29*G25,Input!$C$30)) | L25: =IF(H25="L",0,K25) | M25: =IF(H25="L",MIN((1-SIN(RADIANS(IF(F25="Clay",Input!$C$19,Input!$C$18))))*TAN(RADIANS(2/3*IF(F25="Clay",Input!$C$19,Input!$C$18)))*J25,Input!$C$30),IF(F25="Clay",K25,MIN(K25,MIN(MAX(1.5-0.245*SQRT(E25),0.25),1.2)*MIN(G25/15,1)*J25,Input!$C$30))) | N25: =IF(F25="Clay",Input!$C$35*I25,MIN(Input!$C$33*G25,Input!$C$34)/9.81) | Q25: =10*SUMPRODUCT(--($B$7:$B$47>=B25),--($H$7:$H$47="L"),$D$7:$D$47,$P$7:$P$47+($P$7:$P$47="")*Input!$C$24)
A26: 20 | B26: 28.5 | C26: =B26+D26 | D26: 1.5 | E26: =B26+D26/2 | F26: Clay | G26: 48 | H26: NL | I26: =IF(F26="Clay",Input!$C$32*G26,0) | J26: =Input!$C$16/9.81*MIN(E26,Input!$C$14)+(Input!$C$17/9.81-1)*MAX(E26-Input!$C$14,0) | K26: =IF(F26="Clay",MIN(Input!$C$31*I26,Input!$C$30),MIN(Input!$C$29*G26,Input!$C$30)) | L26: =IF(H26="L",0,K26) | M26: =IF(H26="L",MIN((1-SIN(RADIANS(IF(F26="Clay",Input!$C$19,Input!$C$18))))*TAN(RADIANS(2/3*IF(F26="Clay",Input!$C$19,Input!$C$18)))*J26,Input!$C$30),IF(F26="Clay",K26,MIN(K26,MIN(MAX(1.5-0.245*SQRT(E26),0.25),1.2)*MIN(G26/15,1)*J26,Input!$C$30))) | N26: =IF(F26="Clay",Input!$C$35*I26,MIN(Input!$C$33*G26,Input!$C$34)/9.81) | Q26: =10*SUMPRODUCT(--($B$7:$B$47>=B26),--($H$7:$H$47="L"),$D$7:$D$47,$P$7:$P$47+($P$7:$P$47="")*Input!$C$24)
A27: 21 | B27: 30 | C27: =B27+D27 | D27: 1.5 | E27: =B27+D27/2 | F27: Clay | G27: 50 | H27: NL | I27: =IF(F27="Clay",Input!$C$32*G27,0) | J27: =Input!$C$16/9.81*MIN(E27,Input!$C$14)+(Input!$C$17/9.81-1)*MAX(E27-Input!$C$14,0) | K27: =IF(F27="Clay",MIN(Input!$C$31*I27,Input!$C$30),MIN(Input!$C$29*G27,Input!$C$30)) | L27: =IF(H27="L",0,K27) | M27: =IF(H27="L",MIN((1-SIN(RADIANS(IF(F27="Clay",Input!$C$19,Input!$C$18))))*TAN(RADIANS(2/3*IF(F27="Clay",Input!$C$19,Input!$C$18)))*J27,Input!$C$30),IF(F27="Clay",K27,MIN(K27,MIN(MAX(1.5-0.245*SQRT(E27),0.25),1.2)*MIN(G27/15,1)*J27,Input!$C$30))) | N27: =IF(F27="Clay",Input!$C$35*I27,MIN(Input!$C$33*G27,Input!$C$34)/9.81) | Q27: =10*SUMPRODUCT(--($B$7:$B$47>=B27),--($H$7:$H$47="L"),$D$7:$D$47,$P$7:$P$47+($P$7:$P$47="")*Input!$C$24)
A28: 22 | B28: 31.5 | C28: =B28+D28 | D28: 1.5 | E28: =B28+D28/2 | F28: Clay | G28: 50 | H28: NL | I28: =IF(F28="Clay",Input!$C$32*G28,0) | J28: =Input!$C$16/9.81*MIN(E28,Input!$C$14)+(Input!$C$17/9.81-1)*MAX(E28-Input!$C$14,0) | K28: =IF(F28="Clay",MIN(Input!$C$31*I28,Input!$C$30),MIN(Input!$C$29*G28,Input!$C$30)) | L28: =IF(H28="L",0,K28) | M28: =IF(H28="L",MIN((1-SIN(RADIANS(IF(F28="Clay",Input!$C$19,Input!$C$18))))*TAN(RADIANS(2/3*IF(F28="Clay",Input!$C$19,Input!$C$18)))*J28,Input!$C$30),IF(F28="Clay",K28,MIN(K28,MIN(MAX(1.5-0.245*SQRT(E28),0.25),1.2)*MIN(G28/15,1)*J28,Input!$C$30))) | N28: =IF(F28="Clay",Input!$C$35*I28,MIN(Input!$C$33*G28,Input!$C$34)/9.81) | Q28: =10*SUMPRODUCT(--($B$7:$B$47>=B28),--($H$7:$H$47="L"),$D$7:$D$47,$P$7:$P$47+($P$7:$P$47="")*Input!$C$24)
A29: 23 | B29: 33 | C29: =B29+D29 | D29: 1.5 | E29: =B29+D29/2 | F29: Clay | G29: 50 | H29: NL | I29: =IF(F29="Clay",Input!$C$32*G29,0) | J29: =Input!$C$16/9.81*MIN(E29,Input!$C$14)+(Input!$C$17/9.81-1)*MAX(E29-Input!$C$14,0) | K29: =IF(F29="Clay",MIN(Input!$C$31*I29,Input!$C$30),MIN(Input!$C$29*G29,Input!$C$30)) | L29: =IF(H29="L",0,K29) | M29: =IF(H29="L",MIN((1-SIN(RADIANS(IF(F29="Clay",Input!$C$19,Input!$C$18))))*TAN(RADIANS(2/3*IF(F29="Clay",Input!$C$19,Input!$C$18)))*J29,Input!$C$30),IF(F29="Clay",K29,MIN(K29,MIN(MAX(1.5-0.245*SQRT(E29),0.25),1.2)*MIN(G29/15,1)*J29,Input!$C$30))) | N29: =IF(F29="Clay",Input!$C$35*I29,MIN(Input!$C$33*G29,Input!$C$34)/9.81) | Q29: =10*SUMPRODUCT(--($B$7:$B$47>=B29),--($H$7:$H$47="L"),$D$7:$D$47,$P$7:$P$47+($P$7:$P$47="")*Input!$C$24)
A30: 24 | B30: 34.5 | C30: =B30+D30 | D30: 1.5 | E30: =B30+D30/2 | F30: Clay | G30: 50 | H30: NL | I30: =IF(F30="Clay",Input!$C$32*G30,0) | J30: =Input!$C$16/9.81*MIN(E30,Input!$C$14)+(Input!$C$17/9.81-1)*MAX(E30-Input!$C$14,0) | K30: =IF(F30="Clay",MIN(Input!$C$31*I30,Input!$C$30),MIN(Input!$C$29*G30,Input!$C$30)) | L30: =IF(H30="L",0,K30) | M30: =IF(H30="L",MIN((1-SIN(RADIANS(IF(F30="Clay",Input!$C$19,Input!$C$18))))*TAN(RADIANS(2/3*IF(F30="Clay",Input!$C$19,Input!$C$18)))*J30,Input!$C$30),IF(F30="Clay",K30,MIN(K30,MIN(MAX(1.5-0.245*SQRT(E30),0.25),1.2)*MIN(G30/15,1)*J30,Input!$C$30))) | N30: =IF(F30="Clay",Input!$C$35*I30,MIN(Input!$C$33*G30,Input!$C$34)/9.81) | Q30: =10*SUMPRODUCT(--($B$7:$B$47>=B30),--($H$7:$H$47="L"),$D$7:$D$47,$P$7:$P$47+($P$7:$P$47="")*Input!$C$24)
A31: 25 | B31: 36 | C31: =B31+D31 | D31: 1.5 | E31: =B31+D31/2 | F31: Sand | G31: 50 | H31: NL | I31: =IF(F31="Clay",Input!$C$32*G31,0) | J31: =Input!$C$16/9.81*MIN(E31,Input!$C$14)+(Input!$C$17/9.81-1)*MAX(E31-Input!$C$14,0) | K31: =IF(F31="Clay",MIN(Input!$C$31*I31,Input!$C$30),MIN(Input!$C$29*G31,Input!$C$30)) | L31: =IF(H31="L",0,K31) | M31: =IF(H31="L",MIN((1-SIN(RADIANS(IF(F31="Clay",Input!$C$19,Input!$C$18))))*TAN(RADIANS(2/3*IF(F31="Clay",Input!$C$19,Input!$C$18)))*J31,Input!$C$30),IF(F31="Clay",K31,MIN(K31,MIN(MAX(1.5-0.245*SQRT(E31),0.25),1.2)*MIN(G31/15,1)*J31,Input!$C$30))) | N31: =IF(F31="Clay",Input!$C$35*I31,MIN(Input!$C$33*G31,Input!$C$34)/9.81) | Q31: =10*SUMPRODUCT(--($B$7:$B$47>=B31),--($H$7:$H$47="L"),$D$7:$D$47,$P$7:$P$47+($P$7:$P$47="")*Input!$C$24)
A32: 26 | B32: 37.5 | C32: =B32+D32 | D32: 1.5 | E32: =B32+D32/2 | F32: Clay | G32: 50 | H32: NL | I32: =IF(F32="Clay",Input!$C$32*G32,0) | J32: =Input!$C$16/9.81*MIN(E32,Input!$C$14)+(Input!$C$17/9.81-1)*MAX(E32-Input!$C$14,0) | K32: =IF(F32="Clay",MIN(Input!$C$31*I32,Input!$C$30),MIN(Input!$C$29*G32,Input!$C$30)) | L32: =IF(H32="L",0,K32) | M32: =IF(H32="L",MIN((1-SIN(RADIANS(IF(F32="Clay",Input!$C$19,Input!$C$18))))*TAN(RADIANS(2/3*IF(F32="Clay",Input!$C$19,Input!$C$18)))*J32,Input!$C$30),IF(F32="Clay",K32,MIN(K32,MIN(MAX(1.5-0.245*SQRT(E32),0.25),1.2)*MIN(G32/15,1)*J32,Input!$C$30))) | N32: =IF(F32="Clay",Input!$C$35*I32,MIN(Input!$C$33*G32,Input!$C$34)/9.81) | Q32: =10*SUMPRODUCT(--($B$7:$B$47>=B32),--($H$7:$H$47="L"),$D$7:$D$47,$P$7:$P$47+($P$7:$P$47="")*Input!$C$24)
A33: 27 | B33: 39 | C33: =B33+D33 | D33: 1.5 | E33: =B33+D33/2 | F33: Clay | G33: 50 | H33: NL | I33: =IF(F33="Clay",Input!$C$32*G33,0) | J33: =Input!$C$16/9.81*MIN(E33,Input!$C$14)+(Input!$C$17/9.81-1)*MAX(E33-Input!$C$14,0) | K33: =IF(F33="Clay",MIN(Input!$C$31*I33,Input!$C$30),MIN(Input!$C$29*G33,Input!$C$30)) | L33: =IF(H33="L",0,K33) | M33: =IF(H33="L",MIN((1-SIN(RADIANS(IF(F33="Clay",Input!$C$19,Input!$C$18))))*TAN(RADIANS(2/3*IF(F33="Clay",Input!$C$19,Input!$C$18)))*J33,Input!$C$30),IF(F33="Clay",K33,MIN(K33,MIN(MAX(1.5-0.245*SQRT(E33),0.25),1.2)*MIN(G33/15,1)*J33,Input!$C$30))) | N33: =IF(F33="Clay",Input!$C$35*I33,MIN(Input!$C$33*G33,Input!$C$34)/9.81) | Q33: =10*SUMPRODUCT(--($B$7:$B$47>=B33),--($H$7:$H$47="L"),$D$7:$D$47,$P$7:$P$47+($P$7:$P$47="")*Input!$C$24)
... A47: 41 | B47: 59.5 | C47: =B47+D47 | D47: 0.5 | E47: =B47+D47/2 | F47: Sand | G47: 46 | H47: NL | I47: =IF(F47="Clay",Input!$C$32*G47,0) | J47: =Input!$C$16/9.81*MIN(E47,Input!$C$14)+(Input!$C$17/9.81-1)*MAX(E47-Input!$C$14,0) | K47: =IF(F47="Clay",MIN(Input!$C$31*I47,Input!$C$30),MIN(Input!$C$29*G47,Input!$C$30)) | L47: =IF(H47="L",0,K47) | M47: =IF(H47="L",MIN((1-SIN(RADIANS(IF(F47="Clay",Input!$C$19,Input!$C$18))))*TAN(RADIANS(2/3*IF(F47="Clay",Input!$C$19,Input!$C$18)))*J47,Input!$C$30),IF(F47="Clay",K47,MIN(K47,MIN(MAX(1.5-0.245*SQRT(E47),0.25),1.2)*MIN(G47/15,1)*J47,Input!$C$30))) | N47: =IF(F47="Clay",Input!$C$35*I47,MIN(Input!$C$33*G47,Input!$C$34)/9.81) | Q47: =10*SUMPRODUCT(--($B$7:$B$47>=B47),--($H$7:$H$47="L"),$D$7:$D$47,$P$7:$P$47+($P$7:$P$47="")*Input!$C$24)
A49: Catatan: fs downdrag lapisan L = (1 - sin φL)·tan(2φL/3)·σ'v (Caltrans: φL = 30° kasar / 25° halus); lapisan NL pasir = metode β (FHWA), dibatasi fs statis.
A50: qb pasir = k·N (kPa) ≤ batas, dikonversi ke t/m²; qb lempung = Nc·cu. Kolom kuning = data input borehole.
A51: εv = regangan volumetrik pasca-likuefaksi (Ishihara & Yoshimine 1992, tabel penurunan laporan likuefaksi). Penurunan tanah di puncak lapisan = Σ εv·tebal lapisan L di bawahnya. Lapisan NL tidak menyumbang penurunan.

Sheet Kap. Statis
A1: KAPASITAS AKSIAL - KONDISI STATIS (TANPA LIKUEFAKSI)
A2: Geotechnical Investigation & DED Geothermal Wellpad - PSPE Bora Pulu
A3: =Input!A3
A5: Ujung tiang minimum (kondisi statis) | E5: =IFERROR(ROUND(1/(1/_xlfn.SINGLE(_xlfn.MINIFS(A12:A127,L12:L127,TRUE))),2),"> data") | F5: m
A6: Panjang efektif dari cut-off | E6: =IF(ISNUMBER(E5),E5-Input!$C$11,"-") | F6: m
A7: Qa = Qs/SF + Qb/SF - W'p ; Ta = 0,7·Qs/SF + W'p | E7: =Input!C41&" / "&Input!C42 | F7: SF fs / qb
A10: Ujung tiang | B10: Elevasi | C10: L efektif | D10: Qs | E10: qb rata-rata | F10: Qb | G10: Qult | H10: W'p | I10: Qa tekan | J10: Qa tekan | K10: Beban P | L10: OK* | M10: Ta tarik | N10: Ta tarik
A11: m | B11: m | C11: m | D11: ton | E11: t/m² | F11: ton | G11: ton | H11: ton | I11: ton | J11: kN | K11: kN | M11: ton | N11: kN
A12: 2 | B12: =-A12 | C12: =A12-Input!$C$11 | D12: =Input!$C$8*SUMPRODUCT('Data Tanah'!$K$7:$K$47,((((('Data Tanah'!$C$7:$C$47+A12-Input!$C$28*Input!$C$7)-ABS('Data Tanah'!$C$7:$C$47-(A12-Input!$C$28*Input!$C$7)))/2-(('Data Tanah'!$B$7:$B$47+Input!$C$26)+ABS('Data Tanah'!$B$7:$B$47-(Input!$C$26)))/2)+ABS((('Data Tanah'!$C$7:$C$47+A12-Input!$C$28*Input!$C$7)-ABS('Data Tanah'!$C$7:$C$47-(A12-Input!$C$28*Input!$C$7)))/2-(('Data Tanah'!$B$7:$B$47+Input!$C$26)+ABS('Data Tanah'!$B$7:$B$47-(Input!$C$26)))/2))/2)) | E12: =IFERROR(AVERAGEIFS('Data Tanah'!$N$7:$N$47,'Data Tanah'!$E$7:$E$47,">="&(A12-Input!$C$36*Input!$C$7),'Data Tanah'!$E$7:$E$47,"<="&(A12+Input!$C$37*Input!$C$7)),INDEX('Data Tanah'!$N$7:$N$47,MATCH(A12,'Data Tanah'!$B$7:$B$47,1))) | F12: =E12*Input!$C$9 | G12: =D12+F12 | H12: =Input!$C$9*(Input!$C$10*MAX(MIN(A12,Input!$C$14)-Input!$C$11,0)+(Input!$C$10-1)*MAX(A12-MAX(Input!$C$14,Input!$C$11),0)) | I12: =D12/Input!$C$41+F12/Input!$C$42-H12 | J12: =I12*9.81 | K12: =Input!$C$48 | L12: =AND(J12>=K12,L13) | M12: =Input!$C$38*D12/Input!$C$43+H12 | N12: =M12*9.81
A13: 2.5 | B13: =-A13 | C13: =A13-Input!$C$11 | D13: =Input!$C$8*SUMPRODUCT('Data Tanah'!$K$7:$K$47,((((('Data Tanah'!$C$7:$C$47+A13-Input!$C$28*Input!$C$7)-ABS('Data Tanah'!$C$7:$C$47-(A13-Input!$C$28*Input!$C$7)))/2-(('Data Tanah'!$B$7:$B$47+Input!$C$26)+ABS('Data Tanah'!$B$7:$B$47-(Input!$C$26)))/2)+ABS((('Data Tanah'!$C$7:$C$47+A13-Input!$C$28*Input!$C$7)-ABS('Data Tanah'!$C$7:$C$47-(A13-Input!$C$28*Input!$C$7)))/2-(('Data Tanah'!$B$7:$B$47+Input!$C$26)+ABS('Data Tanah'!$B$7:$B$47-(Input!$C$26)))/2))/2)) | E13: =IFERROR(AVERAGEIFS('Data Tanah'!$N$7:$N$47,'Data Tanah'!$E$7:$E$47,">="&(A13-Input!$C$36*Input!$C$7),'Data Tanah'!$E$7:$E$47,"<="&(A13+Input!$C$37*Input!$C$7)),INDEX('Data Tanah'!$N$7:$N$47,MATCH(A13,'Data Tanah'!$B$7:$B$47,1))) | F13: =E13*Input!$C$9 | G13: =D13+F13 | H13: =Input!$C$9*(Input!$C$10*MAX(MIN(A13,Input!$C$14)-Input!$C$11,0)+(Input!$C$10-1)*MAX(A13-MAX(Input!$C$14,Input!$C$11),0)) | I13: =D13/Input!$C$41+F13/Input!$C$42-H13 | J13: =I13*9.81 | K13: =Input!$C$48 | L13: =AND(J13>=K13,L14) | M13: =Input!$C$38*D13/Input!$C$43+H13 | N13: =M13*9.81
A14: 3 | B14: =-A14 | C14: =A14-Input!$C$11 | D14: =Input!$C$8*SUMPRODUCT('Data Tanah'!$K$7:$K$47,((((('Data Tanah'!$C$7:$C$47+A14-Input!$C$28*Input!$C$7)-ABS('Data Tanah'!$C$7:$C$47-(A14-Input!$C$28*Input!$C$7)))/2-(('Data Tanah'!$B$7:$B$47+Input!$C$26)+ABS('Data Tanah'!$B$7:$B$47-(Input!$C$26)))/2)+ABS((('Data Tanah'!$C$7:$C$47+A14-Input!$C$28*Input!$C$7)-ABS('Data Tanah'!$C$7:$C$47-(A14-Input!$C$28*Input!$C$7)))/2-(('Data Tanah'!$B$7:$B$47+Input!$C$26)+ABS('Data Tanah'!$B$7:$B$47-(Input!$C$26)))/2))/2)) | E14: =IFERROR(AVERAGEIFS('Data Tanah'!$N$7:$N$47,'Data Tanah'!$E$7:$E$47,">="&(A14-Input!$C$36*Input!$C$7),'Data Tanah'!$E$7:$E$47,"<="&(A14+Input!$C$37*Input!$C$7)),INDEX('Data Tanah'!$N$7:$N$47,MATCH(A14,'Data Tanah'!$B$7:$B$47,1))) | F14: =E14*Input!$C$9 | G14: =D14+F14 | H14: =Input!$C$9*(Input!$C$10*MAX(MIN(A14,Input!$C$14)-Input!$C$11,0)+(Input!$C$10-1)*MAX(A14-MAX(Input!$C$14,Input!$C$11),0)) | I14: =D14/Input!$C$41+F14/Input!$C$42-H14 | J14: =I14*9.81 | K14: =Input!$C$48 | L14: =AND(J14>=K14,L15) | M14: =Input!$C$38*D14/Input!$C$43+H14 | N14: =M14*9.81
A15: 3.5 | B15: =-A15 | C15: =A15-Input!$C$11 | D15: =Input!$C$8*SUMPRODUCT('Data Tanah'!$K$7:$K$47,((((('Data Tanah'!$C$7:$C$47+A15-Input!$C$28*Input!$C$7)-ABS('Data Tanah'!$C$7:$C$47-(A15-Input!$C$28*Input!$C$7)))/2-(('Data Tanah'!$B$7:$B$47+Input!$C$26)+ABS('Data Tanah'!$B$7:$B$47-(Input!$C$26)))/2)+ABS((('Data Tanah'!$C$7:$C$47+A15-Input!$C$28*Input!$C$7)-ABS('Data Tanah'!$C$7:$C$47-(A15-Input!$C$28*Input!$C$7)))/2-(('Data Tanah'!$B$7:$B$47+Input!$C$26)+ABS('Data Tanah'!$B$7:$B$47-(Input!$C$26)))/2))/2)) | E15: =IFERROR(AVERAGEIFS('Data Tanah'!$N$7:$N$47,'Data Tanah'!$E$7:$E$47,">="&(A15-Input!$C$36*Input!$C$7),'Data Tanah'!$E$7:$E$47,"<="&(A15+Input!$C$37*Input!$C$7)),INDEX('Data Tanah'!$N$7:$N$47,MATCH(A15,'Data Tanah'!$B$7:$B$47,1))) | F15: =E15*Input!$C$9 | G15: =D15+F15 | H15: =Input!$C$9*(Input!$C$10*MAX(MIN(A15,Input!$C$14)-Input!$C$11,0)+(Input!$C$10-1)*MAX(A15-MAX(Input!$C$14,Input!$C$11),0)) | I15: =D15/Input!$C$41+F15/Input!$C$42-H15 | J15: =I15*9.81 | K15: =Input!$C$48 | L15: =AND(J15>=K15,L16) | M15: =Input!$C$38*D15/Input!$C$43+H15 | N15: =M15*9.81
A16: 4 | B16: =-A16 | C16: =A16-Input!$C$11 | D16: =Input!$C$8*SUMPRODUCT('Data Tanah'!$K$7:$K$47,((((('Data Tanah'!$C$7:$C$47+A16-Input!$C$28*Input!$C$7)-ABS('Data Tanah'!$C$7:$C$47-(A16-Input!$C$28*Input!$C$7)))/2-(('Data Tanah'!$B$7:$B$47+Input!$C$26)+ABS('Data Tanah'!$B$7:$B$47-(Input!$C$26)))/2)+ABS((('Data Tanah'!$C$7:$C$47+A16-Input!$C$28*Input!$C$7)-ABS('Data Tanah'!$C$7:$C$47-(A16-Input!$C$28*Input!$C$7)))/2-(('Data Tanah'!$B$7:$B$47+Input!$C$26)+ABS('Data Tanah'!$B$7:$B$47-(Input!$C$26)))/2))/2)) | E16: =IFERROR(AVERAGEIFS('Data Tanah'!$N$7:$N$47,'Data Tanah'!$E$7:$E$47,">="&(A16-Input!$C$36*Input!$C$7),'Data Tanah'!$E$7:$E$47,"<="&(A16+Input!$C$37*Input!$C$7)),INDEX('Data Tanah'!$N$7:$N$47,MATCH(A16,'Data Tanah'!$B$7:$B$47,1))) | F16: =E16*Input!$C$9 | G16: =D16+F16 | H16: =Input!$C$9*(Input!$C$10*MAX(MIN(A16,Input!$C$14)-Input!$C$11,0)+(Input!$C$10-1)*MAX(A16-MAX(Input!$C$14,Input!$C$11),0)) | I16: =D16/Input!$C$41+F16/Input!$C$42-H16 | J16: =I16*9.81 | K16: =Input!$C$48 | L16: =AND(J16>=K16,L17) | M16: =Input!$C$38*D16/Input!$C$43+H16 | N16: =M16*9.81
A17: 4.5 | B17: =-A17 | C17: =A17-Input!$C$11 | D17: =Input!$C$8*SUMPRODUCT('Data Tanah'!$K$7:$K$47,((((('Data Tanah'!$C$7:$C$47+A17-Input!$C$28*Input!$C$7)-ABS('Data Tanah'!$C$7:$C$47-(A17-Input!$C$28*Input!$C$7)))/2-(('Data Tanah'!$B$7:$B$47+Input!$C$26)+ABS('Data Tanah'!$B$7:$B$47-(Input!$C$26)))/2)+ABS((('Data Tanah'!$C$7:$C$47+A17-Input!$C$28*Input!$C$7)-ABS('Data Tanah'!$C$7:$C$47-(A17-Input!$C$28*Input!$C$7)))/2-(('Data Tanah'!$B$7:$B$47+Input!$C$26)+ABS('Data Tanah'!$B$7:$B$47-(Input!$C$26)))/2))/2)) | E17: =IFERROR(AVERAGEIFS('Data Tanah'!$N$7:$N$47,'Data Tanah'!$E$7:$E$47,">="&(A17-Input!$C$36*Input!$C$7),'Data Tanah'!$E$7:$E$47,"<="&(A17+Input!$C$37*Input!$C$7)),INDEX('Data Tanah'!$N$7:$N$47,MATCH(A17,'Data Tanah'!$B$7:$B$47,1))) | F17: =E17*Input!$C$9 | G17: =D17+F17 | H17: =Input!$C$9*(Input!$C$10*MAX(MIN(A17,Input!$C$14)-Input!$C$11,0)+(Input!$C$10-1)*MAX(A17-MAX(Input!$C$14,Input!$C$11),0)) | I17: =D17/Input!$C$41+F17/Input!$C$42-H17 | J17: =I17*9.81 | K17: =Input!$C$48 | L17: =AND(J17>=K17,L18) | M17: =Input!$C$38*D17/Input!$C$43+H17 | N17: =M17*9.81
A18: 5 | B18: =-A18 | C18: =A18-Input!$C$11 | D18: =Input!$C$8*SUMPRODUCT('Data Tanah'!$K$7:$K$47,((((('Data Tanah'!$C$7:$C$47+A18-Input!$C$28*Input!$C$7)-ABS('Data Tanah'!$C$7:$C$47-(A18-Input!$C$28*Input!$C$7)))/2-(('Data Tanah'!$B$7:$B$47+Input!$C$26)+ABS('Data Tanah'!$B$7:$B$47-(Input!$C$26)))/2)+ABS((('Data Tanah'!$C$7:$C$47+A18-Input!$C$28*Input!$C$7)-ABS('Data Tanah'!$C$7:$C$47-(A18-Input!$C$28*Input!$C$7)))/2-(('Data Tanah'!$B$7:$B$47+Input!$C$26)+ABS('Data Tanah'!$B$7:$B$47-(Input!$C$26)))/2))/2)) | E18: =IFERROR(AVERAGEIFS('Data Tanah'!$N$7:$N$47,'Data Tanah'!$E$7:$E$47,">="&(A18-Input!$C$36*Input!$C$7),'Data Tanah'!$E$7:$E$47,"<="&(A18+Input!$C$37*Input!$C$7)),INDEX('Data Tanah'!$N$7:$N$47,MATCH(A18,'Data Tanah'!$B$7:$B$47,1))) | F18: =E18*Input!$C$9 | G18: =D18+F18 | H18: =Input!$C$9*(Input!$C$10*MAX(MIN(A18,Input!$C$14)-Input!$C$11,0)+(Input!$C$10-1)*MAX(A18-MAX(Input!$C$14,Input!$C$11),0)) | I18: =D18/Input!$C$41+F18/Input!$C$42-H18 | J18: =I18*9.81 | K18: =Input!$C$48 | L18: =AND(J18>=K18,L19) | M18: =Input!$C$38*D18/Input!$C$43+H18 | N18: =M18*9.81
A19: 5.5 | B19: =-A19 | C19: =A19-Input!$C$11 | D19: =Input!$C$8*SUMPRODUCT('Data Tanah'!$K$7:$K$47,((((('Data Tanah'!$C$7:$C$47+A19-Input!$C$28*Input!$C$7)-ABS('Data Tanah'!$C$7:$C$47-(A19-Input!$C$28*Input!$C$7)))/2-(('Data Tanah'!$B$7:$B$47+Input!$C$26)+ABS('Data Tanah'!$B$7:$B$47-(Input!$C$26)))/2)+ABS((('Data Tanah'!$C$7:$C$47+A19-Input!$C$28*Input!$C$7)-ABS('Data Tanah'!$C$7:$C$47-(A19-Input!$C$28*Input!$C$7)))/2-(('Data Tanah'!$B$7:$B$47+Input!$C$26)+ABS('Data Tanah'!$B$7:$B$47-(Input!$C$26)))/2))/2)) | E19: =IFERROR(AVERAGEIFS('Data Tanah'!$N$7:$N$47,'Data Tanah'!$E$7:$E$47,">="&(A19-Input!$C$36*Input!$C$7),'Data Tanah'!$E$7:$E$47,"<="&(A19+Input!$C$37*Input!$C$7)),INDEX('Data Tanah'!$N$7:$N$47,MATCH(A19,'Data Tanah'!$B$7:$B$47,1))) | F19: =E19*Input!$C$9 | G19: =D19+F19 | H19: =Input!$C$9*(Input!$C$10*MAX(MIN(A19,Input!$C$14)-Input!$C$11,0)+(Input!$C$10-1)*MAX(A19-MAX(Input!$C$14,Input!$C$11),0)) | I19: =D19/Input!$C$41+F19/Input!$C$42-H19 | J19: =I19*9.81 | K19: =Input!$C$48 | L19: =AND(J19>=K19,L20) | M19: =Input!$C$38*D19/Input!$C$43+H19 | N19: =M19*9.81
A20: 6 | B20: =-A20 | C20: =A20-Input!$C$11 | D20: =Input!$C$8*SUMPRODUCT('Data Tanah'!$K$7:$K$47,((((('Data Tanah'!$C$7:$C$47+A20-Input!$C$28*Input!$C$7)-ABS('Data Tanah'!$C$7:$C$47-(A20-Input!$C$28*Input!$C$7)))/2-(('Data Tanah'!$B$7:$B$47+Input!$C$26)+ABS('Data Tanah'!$B$7:$B$47-(Input!$C$26)))/2)+ABS((('Data Tanah'!$C$7:$C$47+A20-Input!$C$28*Input!$C$7)-ABS('Data Tanah'!$C$7:$C$47-(A20-Input!$C$28*Input!$C$7)))/2-(('Data Tanah'!$B$7:$B$47+Input!$C$26)+ABS('Data Tanah'!$B$7:$B$47-(Input!$C$26)))/2))/2)) | E20: =IFERROR(AVERAGEIFS('Data Tanah'!$N$7:$N$47,'Data Tanah'!$E$7:$E$47,">="&(A20-Input!$C$36*Input!$C$7),'Data Tanah'!$E$7:$E$47,"<="&(A20+Input!$C$37*Input!$C$7)),INDEX('Data Tanah'!$N$7:$N$47,MATCH(A20,'Data Tanah'!$B$7:$B$47,1))) | F20: =E20*Input!$C$9 | G20: =D20+F20 | H20: =Input!$C$9*(Input!$C$10*MAX(MIN(A20,Input!$C$14)-Input!$C$11,0)+(Input!$C$10-1)*MAX(A20-MAX(Input!$C$14,Input!$C$11),0)) | I20: =D20/Input!$C$41+F20/Input!$C$42-H20 | J20: =I20*9.81 | K20: =Input!$C$48 | L20: =AND(J20>=K20,L21) | M20: =Input!$C$38*D20/Input!$C$43+H20 | N20: =M20*9.81
A21: 6.5 | B21: =-A21 | C21: =A21-Input!$C$11 | D21: =Input!$C$8*SUMPRODUCT('Data Tanah'!$K$7:$K$47,((((('Data Tanah'!$C$7:$C$47+A21-Input!$C$28*Input!$C$7)-ABS('Data Tanah'!$C$7:$C$47-(A21-Input!$C$28*Input!$C$7)))/2-(('Data Tanah'!$B$7:$B$47+Input!$C$26)+ABS('Data Tanah'!$B$7:$B$47-(Input!$C$26)))/2)+ABS((('Data Tanah'!$C$7:$C$47+A21-Input!$C$28*Input!$C$7)-ABS('Data Tanah'!$C$7:$C$47-(A21-Input!$C$28*Input!$C$7)))/2-(('Data Tanah'!$B$7:$B$47+Input!$C$26)+ABS('Data Tanah'!$B$7:$B$47-(Input!$C$26)))/2))/2)) | E21: =IFERROR(AVERAGEIFS('Data Tanah'!$N$7:$N$47,'Data Tanah'!$E$7:$E$47,">="&(A21-Input!$C$36*Input!$C$7),'Data Tanah'!$E$7:$E$47,"<="&(A21+Input!$C$37*Input!$C$7)),INDEX('Data Tanah'!$N$7:$N$47,MATCH(A21,'Data Tanah'!$B$7:$B$47,1))) | F21: =E21*Input!$C$9 | G21: =D21+F21 | H21: =Input!$C$9*(Input!$C$10*MAX(MIN(A21,Input!$C$14)-Input!$C$11,0)+(Input!$C$10-1)*MAX(A21-MAX(Input!$C$14,Input!$C$11),0)) | I21: =D21/Input!$C$41+F21/Input!$C$42-H21 | J21: =I21*9.81 | K21: =Input!$C$48 | L21: =AND(J21>=K21,L22) | M21: =Input!$C$38*D21/Input!$C$43+H21 | N21: =M21*9.81
A22: 7 | B22: =-A22 | C22: =A22-Input!$C$11 | D22: =Input!$C$8*SUMPRODUCT('Data Tanah'!$K$7:$K$47,((((('Data Tanah'!$C$7:$C$47+A22-Input!$C$28*Input!$C$7)-ABS('Data Tanah'!$C$7:$C$47-(A22-Input!$C$28*Input!$C$7)))/2-(('Data Tanah'!$B$7:$B$47+Input!$C$26)+ABS('Data Tanah'!$B$7:$B$47-(Input!$C$26)))/2)+ABS((('Data Tanah'!$C$7:$C$47+A22-Input!$C$28*Input!$C$7)-ABS('Data Tanah'!$C$7:$C$47-(A22-Input!$C$28*Input!$C$7)))/2-(('Data Tanah'!$B$7:$B$47+Input!$C$26)+ABS('Data Tanah'!$B$7:$B$47-(Input!$C$26)))/2))/2)) | E22: =IFERROR(AVERAGEIFS('Data Tanah'!$N$7:$N$47,'Data Tanah'!$E$7:$E$47,">="&(A22-Input!$C$36*Input!$C$7),'Data Tanah'!$E$7:$E$47,"<="&(A22+Input!$C$37*Input!$C$7)),INDEX('Data Tanah'!$N$7:$N$47,MATCH(A22,'Data Tanah'!$B$7:$B$47,1))) | F22: =E22*Input!$C$9 | G22: =D22+F22 | H22: =Input!$C$9*(Input!$C$10*MAX(MIN(A22,Input!$C$14)-Input!$C$11,0)+(Input!$C$10-1)*MAX(A22-MAX(Input!$C$14,Input!$C$11),0)) | I22: =D22/Input!$C$41+F22/Input!$C$42-H22 | J22: =I22*9.81 | K22: =Input!$C$48 | L22: =AND(J22>=K22,L23) | M22: =Input!$C$38*D22/Input!$C$43+H22 | N22: =M22*9.81
A23: 7.5 | B23: =-A23 | C23: =A23-Input!$C$11 | D23: =Input!$C$8*SUMPRODUCT('Data Tanah'!$K$7:$K$47,((((('Data Tanah'!$C$7:$C$47+A23-Input!$C$28*Input!$C$7)-ABS('Data Tanah'!$C$7:$C$47-(A23-Input!$C$28*Input!$C$7)))/2-(('Data Tanah'!$B$7:$B$47+Input!$C$26)+ABS('Data Tanah'!$B$7:$B$47-(Input!$C$26)))/2)+ABS((('Data Tanah'!$C$7:$C$47+A23-Input!$C$28*Input!$C$7)-ABS('Data Tanah'!$C$7:$C$47-(A23-Input!$C$28*Input!$C$7)))/2-(('Data Tanah'!$B$7:$B$47+Input!$C$26)+ABS('Data Tanah'!$B$7:$B$47-(Input!$C$26)))/2))/2)) | E23: =IFERROR(AVERAGEIFS('Data Tanah'!$N$7:$N$47,'Data Tanah'!$E$7:$E$47,">="&(A23-Input!$C$36*Input!$C$7),'Data Tanah'!$E$7:$E$47,"<="&(A23+Input!$C$37*Input!$C$7)),INDEX('Data Tanah'!$N$7:$N$47,MATCH(A23,'Data Tanah'!$B$7:$B$47,1))) | F23: =E23*Input!$C$9 | G23: =D23+F23 | H23: =Input!$C$9*(Input!$C$10*MAX(MIN(A23,Input!$C$14)-Input!$C$11,0)+(Input!$C$10-1)*MAX(A23-MAX(Input!$C$14,Input!$C$11),0)) | I23: =D23/Input!$C$41+F23/Input!$C$42-H23 | J23: =I23*9.81 | K23: =Input!$C$48 | L23: =AND(J23>=K23,L24) | M23: =Input!$C$38*D23/Input!$C$43+H23 | N23: =M23*9.81
... A126: 59 | B126: =-A126 | C126: =A126-Input!$C$11 | D126: =Input!$C$8*SUMPRODUCT('Data Tanah'!$K$7:$K$47,((((('Data Tanah'!$C$7:$C$47+A126-Input!$C$28*Input!$C$7)-ABS('Data Tanah'!$C$7:$C$47-(A126-Input!$C$28*Input!$C$7)))/2-(('Data Tanah'!$B$7:$B$47+Input!$C$26)+ABS('Data Tanah'!$B$7:$B$47-(Input!$C$26)))/2)+ABS((('Data Tanah'!$C$7:$C$47+A126-Input!$C$28*Input!$C$7)-ABS('Data Tanah'!$C$7:$C$47-(A126-Input!$C$28*Input!$C$7)))/2-(('Data Tanah'!$B$7:$B$47+Input!$C$26)+ABS('Data Tanah'!$B$7:$B$47-(Input!$C$26)))/2))/2)) | E126: =IFERROR(AVERAGEIFS('Data Tanah'!$N$7:$N$47,'Data Tanah'!$E$7:$E$47,">="&(A126-Input!$C$36*Input!$C$7),'Data Tanah'!$E$7:$E$47,"<="&(A126+Input!$C$37*Input!$C$7)),INDEX('Data Tanah'!$N$7:$N$47,MATCH(A126,'Data Tanah'!$B$7:$B$47,1))) | F126: =E126*Input!$C$9 | G126: =D126+F126 | H126: =Input!$C$9*(Input!$C$10*MAX(MIN(A126,Input!$C$14)-Input!$C$11,0)+(Input!$C$10-1)*MAX(A126-MAX(Input!$C$14,Input!$C$11),0)) | I126: =D126/Input!$C$41+F126/Input!$C$42-H126 | J126: =I126*9.81 | K126: =Input!$C$48 | L126: =AND(J126>=K126,L127) | M126: =Input!$C$38*D126/Input!$C$43+H126 | N126: =M126*9.81
A127: 59.5 | B127: =-A127 | C127: =A127-Input!$C$11 | D127: =Input!$C$8*SUMPRODUCT('Data Tanah'!$K$7:$K$47,((((('Data Tanah'!$C$7:$C$47+A127-Input!$C$28*Input!$C$7)-ABS('Data Tanah'!$C$7:$C$47-(A127-Input!$C$28*Input!$C$7)))/2-(('Data Tanah'!$B$7:$B$47+Input!$C$26)+ABS('Data Tanah'!$B$7:$B$47-(Input!$C$26)))/2)+ABS((('Data Tanah'!$C$7:$C$47+A127-Input!$C$28*Input!$C$7)-ABS('Data Tanah'!$C$7:$C$47-(A127-Input!$C$28*Input!$C$7)))/2-(('Data Tanah'!$B$7:$B$47+Input!$C$26)+ABS('Data Tanah'!$B$7:$B$47-(Input!$C$26)))/2))/2)) | E127: =IFERROR(AVERAGEIFS('Data Tanah'!$N$7:$N$47,'Data Tanah'!$E$7:$E$47,">="&(A127-Input!$C$36*Input!$C$7),'Data Tanah'!$E$7:$E$47,"<="&(A127+Input!$C$37*Input!$C$7)),INDEX('Data Tanah'!$N$7:$N$47,MATCH(A127,'Data Tanah'!$B$7:$B$47,1))) | F127: =E127*Input!$C$9 | G127: =D127+F127 | H127: =Input!$C$9*(Input!$C$10*MAX(MIN(A127,Input!$C$14)-Input!$C$11,0)+(Input!$C$10-1)*MAX(A127-MAX(Input!$C$14,Input!$C$11),0)) | I127: =D127/Input!$C$41+F127/Input!$C$42-H127 | J127: =I127*9.81 | K127: =Input!$C$48 | L127: =J127>=K127 | M127: =Input!$C$38*D127/Input!$C$43+H127 | N127: =M127*9.81
A129: * OK = kriteria terpenuhi pada kedalaman ini dan semua kedalaman di bawahnya.

Sheet Kap. Likuefaksi
A1: KAPASITAS AKSIAL - KONDISI LIKUEFAKSI (EXTREME EVENT I - COMPRESSION)
A2: Geotechnical Investigation & DED Geothermal Wellpad - PSPE Bora Pulu
A3: =Input!A3
A5: Ujung tiang minimum (kondisi likuefaksi) | E5: =IFERROR(ROUND(1/(1/_xlfn.MINIFS(A12:A127,L12:L127,TRUE)),2),"> data") | F5: m
A6: Panjang efektif dari cut-off | E6: =IF(ISNUMBER(E5),E5-Input!$C$11,"-") | F6: m
A7: Qa = R_N/SF - W'p | E7: =Input!$C$44 | F7: SF
A10: Ujung tiang | B10: Elevasi | C10: L efektif | D10: Qs (di bawah zona likuefaksi) | E10: Lap. L dalam 1,5D ujung? | F10: Qb | G10: R_N | H10: W'p | I10: Qa tekan | J10: Qa tekan | K10: Beban Q_EQ | L10: OK* | M10: Ta tarik | N10: Ta tarik
A11: m | B11: m | C11: m | D11: ton | F11: ton | G11: ton | H11: ton | I11: ton | J11: kN | K11: kN | M11: ton | N11: kN
A12: 2 | B12: =-A12 | C12: =A12-Input!$C$11 | D12: =Input!$C$8*SUMPRODUCT('Data Tanah'!$L$7:$L$47,((((('Data Tanah'!$C$7:$C$47+A12-Input!$C$28*Input!$C$7)-ABS('Data Tanah'!$C$7:$C$47-(A12-Input!$C$28*Input!$C$7)))/2-(('Data Tanah'!$B$7:$B$47+IF(Input!$C$23=1,MAX(Input!$C$27,Input!$C$15),Input!$C$27))+ABS('Data Tanah'!$B$7:$B$47-(IF(Input!$C$23=1,MAX(Input!$C$27,Input!$C$15),Input!$C$27))))/2)+ABS((('Data Tanah'!$C$7:$C$47+A12-Input!$C$28*Input!$C$7)-ABS('Data Tanah'!$C$7:$C$47-(A12-Input!$C$28*Input!$C$7)))/2-(('Data Tanah'!$B$7:$B$47+IF(Input!$C$23=1,MAX(Input!$C$27,Input!$C$15),Input!$C$27))+ABS('Data Tanah'!$B$7:$B$47-(IF(Input!$C$23=1,MAX(Input!$C$27,Input!$C$15),Input!$C$27))))/2))/2)) | E12: =IF(SUMPRODUCT(--('Data Tanah'!$H$7:$H$47="L"),((((('Data Tanah'!$C$7:$C$47+A12+1.5*Input!$C$7)-ABS('Data Tanah'!$C$7:$C$47-(A12+1.5*Input!$C$7)))/2-(('Data Tanah'!$B$7:$B$47+A12-1.5*Input!$C$7)+ABS('Data Tanah'!$B$7:$B$47-(A12-1.5*Input!$C$7)))/2)+ABS((('Data Tanah'!$C$7:$C$47+A12+1.5*Input!$C$7)-ABS('Data Tanah'!$C$7:$C$47-(A12+1.5*Input!$C$7)))/2-(('Data Tanah'!$B$7:$B$47+A12-1.5*Input!$C$7)+ABS('Data Tanah'!$B$7:$B$47-(A12-1.5*Input!$C$7)))/2))/2))>0,"Ya","Tidak") | F12: =IF(OR(E12="Ya",AND(Input!$C$23=1,A12<=Input!$C$15)),0,IFERROR(AVERAGEIFS('Data Tanah'!$N$7:$N$47,'Data Tanah'!$E$7:$E$47,">="&(A12-Input!$C$36*Input!$C$7),'Data Tanah'!$E$7:$E$47,"<="&(A12+Input!$C$37*Input!$C$7)),INDEX('Data Tanah'!$N$7:$N$47,MATCH(A12,'Data Tanah'!$B$7:$B$47,1)))*Input!$C$9) | G12: =D12+F12 | H12: =Input!$C$9*(Input!$C$10*MAX(MIN(A12,Input!$C$14)-Input!$C$11,0)+(Input!$C$10-1)*MAX(A12-MAX(Input!$C$14,Input!$C$11),0)) | I12: =G12/Input!$C$44-H12 | J12: =I12*9.81 | K12: =Input!$C$49 | L12: =AND(J12>=K12,L13) | M12: =IF(D12>0,Input!$C$38*D12/Input!$C$44,0)+H12 | N12: =M12*9.81
A13: 2.5 | B13: =-A13 | C13: =A13-Input!$C$11 | D13: =Input!$C$8*SUMPRODUCT('Data Tanah'!$L$7:$L$47,((((('Data Tanah'!$C$7:$C$47+A13-Input!$C$28*Input!$C$7)-ABS('Data Tanah'!$C$7:$C$47-(A13-Input!$C$28*Input!$C$7)))/2-(('Data Tanah'!$B$7:$B$47+IF(Input!$C$23=1,MAX(Input!$C$27,Input!$C$15),Input!$C$27))+ABS('Data Tanah'!$B$7:$B$47-(IF(Input!$C$23=1,MAX(Input!$C$27,Input!$C$15),Input!$C$27))))/2)+ABS((('Data Tanah'!$C$7:$C$47+A13-Input!$C$28*Input!$C$7)-ABS('Data Tanah'!$C$7:$C$47-(A13-Input!$C$28*Input!$C$7)))/2-(('Data Tanah'!$B$7:$B$47+IF(Input!$C$23=1,MAX(Input!$C$27,Input!$C$15),Input!$C$27))+ABS('Data Tanah'!$B$7:$B$47-(IF(Input!$C$23=1,MAX(Input!$C$27,Input!$C$15),Input!$C$27))))/2))/2)) | E13: =IF(SUMPRODUCT(--('Data Tanah'!$H$7:$H$47="L"),((((('Data Tanah'!$C$7:$C$47+A13+1.5*Input!$C$7)-ABS('Data Tanah'!$C$7:$C$47-(A13+1.5*Input!$C$7)))/2-(('Data Tanah'!$B$7:$B$47+A13-1.5*Input!$C$7)+ABS('Data Tanah'!$B$7:$B$47-(A13-1.5*Input!$C$7)))/2)+ABS((('Data Tanah'!$C$7:$C$47+A13+1.5*Input!$C$7)-ABS('Data Tanah'!$C$7:$C$47-(A13+1.5*Input!$C$7)))/2-(('Data Tanah'!$B$7:$B$47+A13-1.5*Input!$C$7)+ABS('Data Tanah'!$B$7:$B$47-(A13-1.5*Input!$C$7)))/2))/2))>0,"Ya","Tidak") | F13: =IF(OR(E13="Ya",AND(Input!$C$23=1,A13<=Input!$C$15)),0,IFERROR(AVERAGEIFS('Data Tanah'!$N$7:$N$47,'Data Tanah'!$E$7:$E$47,">="&(A13-Input!$C$36*Input!$C$7),'Data Tanah'!$E$7:$E$47,"<="&(A13+Input!$C$37*Input!$C$7)),INDEX('Data Tanah'!$N$7:$N$47,MATCH(A13,'Data Tanah'!$B$7:$B$47,1)))*Input!$C$9) | G13: =D13+F13 | H13: =Input!$C$9*(Input!$C$10*MAX(MIN(A13,Input!$C$14)-Input!$C$11,0)+(Input!$C$10-1)*MAX(A13-MAX(Input!$C$14,Input!$C$11),0)) | I13: =G13/Input!$C$44-H13 | J13: =I13*9.81 | K13: =Input!$C$49 | L13: =AND(J13>=K13,L14) | M13: =IF(D13>0,Input!$C$38*D13/Input!$C$44,0)+H13 | N13: =M13*9.81
A14: 3 | B14: =-A14 | C14: =A14-Input!$C$11 | D14: =Input!$C$8*SUMPRODUCT('Data Tanah'!$L$7:$L$47,((((('Data Tanah'!$C$7:$C$47+A14-Input!$C$28*Input!$C$7)-ABS('Data Tanah'!$C$7:$C$47-(A14-Input!$C$28*Input!$C$7)))/2-(('Data Tanah'!$B$7:$B$47+IF(Input!$C$23=1,MAX(Input!$C$27,Input!$C$15),Input!$C$27))+ABS('Data Tanah'!$B$7:$B$47-(IF(Input!$C$23=1,MAX(Input!$C$27,Input!$C$15),Input!$C$27))))/2)+ABS((('Data Tanah'!$C$7:$C$47+A14-Input!$C$28*Input!$C$7)-ABS('Data Tanah'!$C$7:$C$47-(A14-Input!$C$28*Input!$C$7)))/2-(('Data Tanah'!$B$7:$B$47+IF(Input!$C$23=1,MAX(Input!$C$27,Input!$C$15),Input!$C$27))+ABS('Data Tanah'!$B$7:$B$47-(IF(Input!$C$23=1,MAX(Input!$C$27,Input!$C$15),Input!$C$27))))/2))/2)) | E14: =IF(SUMPRODUCT(--('Data Tanah'!$H$7:$H$47="L"),((((('Data Tanah'!$C$7:$C$47+A14+1.5*Input!$C$7)-ABS('Data Tanah'!$C$7:$C$47-(A14+1.5*Input!$C$7)))/2-(('Data Tanah'!$B$7:$B$47+A14-1.5*Input!$C$7)+ABS('Data Tanah'!$B$7:$B$47-(A14-1.5*Input!$C$7)))/2)+ABS((('Data Tanah'!$C$7:$C$47+A14+1.5*Input!$C$7)-ABS('Data Tanah'!$C$7:$C$47-(A14+1.5*Input!$C$7)))/2-(('Data Tanah'!$B$7:$B$47+A14-1.5*Input!$C$7)+ABS('Data Tanah'!$B$7:$B$47-(A14-1.5*Input!$C$7)))/2))/2))>0,"Ya","Tidak") | F14: =IF(OR(E14="Ya",AND(Input!$C$23=1,A14<=Input!$C$15)),0,IFERROR(AVERAGEIFS('Data Tanah'!$N$7:$N$47,'Data Tanah'!$E$7:$E$47,">="&(A14-Input!$C$36*Input!$C$7),'Data Tanah'!$E$7:$E$47,"<="&(A14+Input!$C$37*Input!$C$7)),INDEX('Data Tanah'!$N$7:$N$47,MATCH(A14,'Data Tanah'!$B$7:$B$47,1)))*Input!$C$9) | G14: =D14+F14 | H14: =Input!$C$9*(Input!$C$10*MAX(MIN(A14,Input!$C$14)-Input!$C$11,0)+(Input!$C$10-1)*MAX(A14-MAX(Input!$C$14,Input!$C$11),0)) | I14: =G14/Input!$C$44-H14 | J14: =I14*9.81 | K14: =Input!$C$49 | L14: =AND(J14>=K14,L15) | M14: =IF(D14>0,Input!$C$38*D14/Input!$C$44,0)+H14 | N14: =M14*9.81
A15: 3.5 | B15: =-A15 | C15: =A15-Input!$C$11 | D15: =Input!$C$8*SUMPRODUCT('Data Tanah'!$L$7:$L$47,((((('Data Tanah'!$C$7:$C$47+A15-Input!$C$28*Input!$C$7)-ABS('Data Tanah'!$C$7:$C$47-(A15-Input!$C$28*Input!$C$7)))/2-(('Data Tanah'!$B$7:$B$47+IF(Input!$C$23=1,MAX(Input!$C$27,Input!$C$15),Input!$C$27))+ABS('Data Tanah'!$B$7:$B$47-(IF(Input!$C$23=1,MAX(Input!$C$27,Input!$C$15),Input!$C$27))))/2)+ABS((('Data Tanah'!$C$7:$C$47+A15-Input!$C$28*Input!$C$7)-ABS('Data Tanah'!$C$7:$C$47-(A15-Input!$C$28*Input!$C$7)))/2-(('Data Tanah'!$B$7:$B$47+IF(Input!$C$23=1,MAX(Input!$C$27,Input!$C$15),Input!$C$27))+ABS('Data Tanah'!$B$7:$B$47-(IF(Input!$C$23=1,MAX(Input!$C$27,Input!$C$15),Input!$C$27))))/2))/2)) | E15: =IF(SUMPRODUCT(--('Data Tanah'!$H$7:$H$47="L"),((((('Data Tanah'!$C$7:$C$47+A15+1.5*Input!$C$7)-ABS('Data Tanah'!$C$7:$C$47-(A15+1.5*Input!$C$7)))/2-(('Data Tanah'!$B$7:$B$47+A15-1.5*Input!$C$7)+ABS('Data Tanah'!$B$7:$B$47-(A15-1.5*Input!$C$7)))/2)+ABS((('Data Tanah'!$C$7:$C$47+A15+1.5*Input!$C$7)-ABS('Data Tanah'!$C$7:$C$47-(A15+1.5*Input!$C$7)))/2-(('Data Tanah'!$B$7:$B$47+A15-1.5*Input!$C$7)+ABS('Data Tanah'!$B$7:$B$47-(A15-1.5*Input!$C$7)))/2))/2))>0,"Ya","Tidak") | F15: =IF(OR(E15="Ya",AND(Input!$C$23=1,A15<=Input!$C$15)),0,IFERROR(AVERAGEIFS('Data Tanah'!$N$7:$N$47,'Data Tanah'!$E$7:$E$47,">="&(A15-Input!$C$36*Input!$C$7),'Data Tanah'!$E$7:$E$47,"<="&(A15+Input!$C$37*Input!$C$7)),INDEX('Data Tanah'!$N$7:$N$47,MATCH(A15,'Data Tanah'!$B$7:$B$47,1)))*Input!$C$9) | G15: =D15+F15 | H15: =Input!$C$9*(Input!$C$10*MAX(MIN(A15,Input!$C$14)-Input!$C$11,0)+(Input!$C$10-1)*MAX(A15-MAX(Input!$C$14,Input!$C$11),0)) | I15: =G15/Input!$C$44-H15 | J15: =I15*9.81 | K15: =Input!$C$49 | L15: =AND(J15>=K15,L16) | M15: =IF(D15>0,Input!$C$38*D15/Input!$C$44,0)+H15 | N15: =M15*9.81
A16: 4 | B16: =-A16 | C16: =A16-Input!$C$11 | D16: =Input!$C$8*SUMPRODUCT('Data Tanah'!$L$7:$L$47,((((('Data Tanah'!$C$7:$C$47+A16-Input!$C$28*Input!$C$7)-ABS('Data Tanah'!$C$7:$C$47-(A16-Input!$C$28*Input!$C$7)))/2-(('Data Tanah'!$B$7:$B$47+IF(Input!$C$23=1,MAX(Input!$C$27,Input!$C$15),Input!$C$27))+ABS('Data Tanah'!$B$7:$B$47-(IF(Input!$C$23=1,MAX(Input!$C$27,Input!$C$15),Input!$C$27))))/2)+ABS((('Data Tanah'!$C$7:$C$47+A16-Input!$C$28*Input!$C$7)-ABS('Data Tanah'!$C$7:$C$47-(A16-Input!$C$28*Input!$C$7)))/2-(('Data Tanah'!$B$7:$B$47+IF(Input!$C$23=1,MAX(Input!$C$27,Input!$C$15),Input!$C$27))+ABS('Data Tanah'!$B$7:$B$47-(IF(Input!$C$23=1,MAX(Input!$C$27,Input!$C$15),Input!$C$27))))/2))/2)) | E16: =IF(SUMPRODUCT(--('Data Tanah'!$H$7:$H$47="L"),((((('Data Tanah'!$C$7:$C$47+A16+1.5*Input!$C$7)-ABS('Data Tanah'!$C$7:$C$47-(A16+1.5*Input!$C$7)))/2-(('Data Tanah'!$B$7:$B$47+A16-1.5*Input!$C$7)+ABS('Data Tanah'!$B$7:$B$47-(A16-1.5*Input!$C$7)))/2)+ABS((('Data Tanah'!$C$7:$C$47+A16+1.5*Input!$C$7)-ABS('Data Tanah'!$C$7:$C$47-(A16+1.5*Input!$C$7)))/2-(('Data Tanah'!$B$7:$B$47+A16-1.5*Input!$C$7)+ABS('Data Tanah'!$B$7:$B$47-(A16-1.5*Input!$C$7)))/2))/2))>0,"Ya","Tidak") | F16: =IF(OR(E16="Ya",AND(Input!$C$23=1,A16<=Input!$C$15)),0,IFERROR(AVERAGEIFS('Data Tanah'!$N$7:$N$47,'Data Tanah'!$E$7:$E$47,">="&(A16-Input!$C$36*Input!$C$7),'Data Tanah'!$E$7:$E$47,"<="&(A16+Input!$C$37*Input!$C$7)),INDEX('Data Tanah'!$N$7:$N$47,MATCH(A16,'Data Tanah'!$B$7:$B$47,1)))*Input!$C$9) | G16: =D16+F16 | H16: =Input!$C$9*(Input!$C$10*MAX(MIN(A16,Input!$C$14)-Input!$C$11,0)+(Input!$C$10-1)*MAX(A16-MAX(Input!$C$14,Input!$C$11),0)) | I16: =G16/Input!$C$44-H16 | J16: =I16*9.81 | K16: =Input!$C$49 | L16: =AND(J16>=K16,L17) | M16: =IF(D16>0,Input!$C$38*D16/Input!$C$44,0)+H16 | N16: =M16*9.81
A17: 4.5 | B17: =-A17 | C17: =A17-Input!$C$11 | D17: =Input!$C$8*SUMPRODUCT('Data Tanah'!$L$7:$L$47,((((('Data Tanah'!$C$7:$C$47+A17-Input!$C$28*Input!$C$7)-ABS('Data Tanah'!$C$7:$C$47-(A17-Input!$C$28*Input!$C$7)))/2-(('Data Tanah'!$B$7:$B$47+IF(Input!$C$23=1,MAX(Input!$C$27,Input!$C$15),Input!$C$27))+ABS('Data Tanah'!$B$7:$B$47-(IF(Input!$C$23=1,MAX(Input!$C$27,Input!$C$15),Input!$C$27))))/2)+ABS((('Data Tanah'!$C$7:$C$47+A17-Input!$C$28*Input!$C$7)-ABS('Data Tanah'!$C$7:$C$47-(A17-Input!$C$28*Input!$C$7)))/2-(('Data Tanah'!$B$7:$B$47+IF(Input!$C$23=1,MAX(Input!$C$27,Input!$C$15),Input!$C$27))+ABS('Data Tanah'!$B$7:$B$47-(IF(Input!$C$23=1,MAX(Input!$C$27,Input!$C$15),Input!$C$27))))/2))/2)) | E17: =IF(SUMPRODUCT(--('Data Tanah'!$H$7:$H$47="L"),((((('Data Tanah'!$C$7:$C$47+A17+1.5*Input!$C$7)-ABS('Data Tanah'!$C$7:$C$47-(A17+1.5*Input!$C$7)))/2-(('Data Tanah'!$B$7:$B$47+A17-1.5*Input!$C$7)+ABS('Data Tanah'!$B$7:$B$47-(A17-1.5*Input!$C$7)))/2)+ABS((('Data Tanah'!$C$7:$C$47+A17+1.5*Input!$C$7)-ABS('Data Tanah'!$C$7:$C$47-(A17+1.5*Input!$C$7)))/2-(('Data Tanah'!$B$7:$B$47+A17-1.5*Input!$C$7)+ABS('Data Tanah'!$B$7:$B$47-(A17-1.5*Input!$C$7)))/2))/2))>0,"Ya","Tidak") | F17: =IF(OR(E17="Ya",AND(Input!$C$23=1,A17<=Input!$C$15)),0,IFERROR(AVERAGEIFS('Data Tanah'!$N$7:$N$47,'Data Tanah'!$E$7:$E$47,">="&(A17-Input!$C$36*Input!$C$7),'Data Tanah'!$E$7:$E$47,"<="&(A17+Input!$C$37*Input!$C$7)),INDEX('Data Tanah'!$N$7:$N$47,MATCH(A17,'Data Tanah'!$B$7:$B$47,1)))*Input!$C$9) | G17: =D17+F17 | H17: =Input!$C$9*(Input!$C$10*MAX(MIN(A17,Input!$C$14)-Input!$C$11,0)+(Input!$C$10-1)*MAX(A17-MAX(Input!$C$14,Input!$C$11),0)) | I17: =G17/Input!$C$44-H17 | J17: =I17*9.81 | K17: =Input!$C$49 | L17: =AND(J17>=K17,L18) | M17: =IF(D17>0,Input!$C$38*D17/Input!$C$44,0)+H17 | N17: =M17*9.81
A18: 5 | B18: =-A18 | C18: =A18-Input!$C$11 | D18: =Input!$C$8*SUMPRODUCT('Data Tanah'!$L$7:$L$47,((((('Data Tanah'!$C$7:$C$47+A18-Input!$C$28*Input!$C$7)-ABS('Data Tanah'!$C$7:$C$47-(A18-Input!$C$28*Input!$C$7)))/2-(('Data Tanah'!$B$7:$B$47+IF(Input!$C$23=1,MAX(Input!$C$27,Input!$C$15),Input!$C$27))+ABS('Data Tanah'!$B$7:$B$47-(IF(Input!$C$23=1,MAX(Input!$C$27,Input!$C$15),Input!$C$27))))/2)+ABS((('Data Tanah'!$C$7:$C$47+A18-Input!$C$28*Input!$C$7)-ABS('Data Tanah'!$C$7:$C$47-(A18-Input!$C$28*Input!$C$7)))/2-(('Data Tanah'!$B$7:$B$47+IF(Input!$C$23=1,MAX(Input!$C$27,Input!$C$15),Input!$C$27))+ABS('Data Tanah'!$B$7:$B$47-(IF(Input!$C$23=1,MAX(Input!$C$27,Input!$C$15),Input!$C$27))))/2))/2)) | E18: =IF(SUMPRODUCT(--('Data Tanah'!$H$7:$H$47="L"),((((('Data Tanah'!$C$7:$C$47+A18+1.5*Input!$C$7)-ABS('Data Tanah'!$C$7:$C$47-(A18+1.5*Input!$C$7)))/2-(('Data Tanah'!$B$7:$B$47+A18-1.5*Input!$C$7)+ABS('Data Tanah'!$B$7:$B$47-(A18-1.5*Input!$C$7)))/2)+ABS((('Data Tanah'!$C$7:$C$47+A18+1.5*Input!$C$7)-ABS('Data Tanah'!$C$7:$C$47-(A18+1.5*Input!$C$7)))/2-(('Data Tanah'!$B$7:$B$47+A18-1.5*Input!$C$7)+ABS('Data Tanah'!$B$7:$B$47-(A18-1.5*Input!$C$7)))/2))/2))>0,"Ya","Tidak") | F18: =IF(OR(E18="Ya",AND(Input!$C$23=1,A18<=Input!$C$15)),0,IFERROR(AVERAGEIFS('Data Tanah'!$N$7:$N$47,'Data Tanah'!$E$7:$E$47,">="&(A18-Input!$C$36*Input!$C$7),'Data Tanah'!$E$7:$E$47,"<="&(A18+Input!$C$37*Input!$C$7)),INDEX('Data Tanah'!$N$7:$N$47,MATCH(A18,'Data Tanah'!$B$7:$B$47,1)))*Input!$C$9) | G18: =D18+F18 | H18: =Input!$C$9*(Input!$C$10*MAX(MIN(A18,Input!$C$14)-Input!$C$11,0)+(Input!$C$10-1)*MAX(A18-MAX(Input!$C$14,Input!$C$11),0)) | I18: =G18/Input!$C$44-H18 | J18: =I18*9.81 | K18: =Input!$C$49 | L18: =AND(J18>=K18,L19) | M18: =IF(D18>0,Input!$C$38*D18/Input!$C$44,0)+H18 | N18: =M18*9.81
A19: 5.5 | B19: =-A19 | C19: =A19-Input!$C$11 | D19: =Input!$C$8*SUMPRODUCT('Data Tanah'!$L$7:$L$47,((((('Data Tanah'!$C$7:$C$47+A19-Input!$C$28*Input!$C$7)-ABS('Data Tanah'!$C$7:$C$47-(A19-Input!$C$28*Input!$C$7)))/2-(('Data Tanah'!$B$7:$B$47+IF(Input!$C$23=1,MAX(Input!$C$27,Input!$C$15),Input!$C$27))+ABS('Data Tanah'!$B$7:$B$47-(IF(Input!$C$23=1,MAX(Input!$C$27,Input!$C$15),Input!$C$27))))/2)+ABS((('Data Tanah'!$C$7:$C$47+A19-Input!$C$28*Input!$C$7)-ABS('Data Tanah'!$C$7:$C$47-(A19-Input!$C$28*Input!$C$7)))/2-(('Data Tanah'!$B$7:$B$47+IF(Input!$C$23=1,MAX(Input!$C$27,Input!$C$15),Input!$C$27))+ABS('Data Tanah'!$B$7:$B$47-(IF(Input!$C$23=1,MAX(Input!$C$27,Input!$C$15),Input!$C$27))))/2))/2)) | E19: =IF(SUMPRODUCT(--('Data Tanah'!$H$7:$H$47="L"),((((('Data Tanah'!$C$7:$C$47+A19+1.5*Input!$C$7)-ABS('Data Tanah'!$C$7:$C$47-(A19+1.5*Input!$C$7)))/2-(('Data Tanah'!$B$7:$B$47+A19-1.5*Input!$C$7)+ABS('Data Tanah'!$B$7:$B$47-(A19-1.5*Input!$C$7)))/2)+ABS((('Data Tanah'!$C$7:$C$47+A19+1.5*Input!$C$7)-ABS('Data Tanah'!$C$7:$C$47-(A19+1.5*Input!$C$7)))/2-(('Data Tanah'!$B$7:$B$47+A19-1.5*Input!$C$7)+ABS('Data Tanah'!$B$7:$B$47-(A19-1.5*Input!$C$7)))/2))/2))>0,"Ya","Tidak") | F19: =IF(OR(E19="Ya",AND(Input!$C$23=1,A19<=Input!$C$15)),0,IFERROR(AVERAGEIFS('Data Tanah'!$N$7:$N$47,'Data Tanah'!$E$7:$E$47,">="&(A19-Input!$C$36*Input!$C$7),'Data Tanah'!$E$7:$E$47,"<="&(A19+Input!$C$37*Input!$C$7)),INDEX('Data Tanah'!$N$7:$N$47,MATCH(A19,'Data Tanah'!$B$7:$B$47,1)))*Input!$C$9) | G19: =D19+F19 | H19: =Input!$C$9*(Input!$C$10*MAX(MIN(A19,Input!$C$14)-Input!$C$11,0)+(Input!$C$10-1)*MAX(A19-MAX(Input!$C$14,Input!$C$11),0)) | I19: =G19/Input!$C$44-H19 | J19: =I19*9.81 | K19: =Input!$C$49 | L19: =AND(J19>=K19,L20) | M19: =IF(D19>0,Input!$C$38*D19/Input!$C$44,0)+H19 | N19: =M19*9.81
A20: 6 | B20: =-A20 | C20: =A20-Input!$C$11 | D20: =Input!$C$8*SUMPRODUCT('Data Tanah'!$L$7:$L$47,((((('Data Tanah'!$C$7:$C$47+A20-Input!$C$28*Input!$C$7)-ABS('Data Tanah'!$C$7:$C$47-(A20-Input!$C$28*Input!$C$7)))/2-(('Data Tanah'!$B$7:$B$47+IF(Input!$C$23=1,MAX(Input!$C$27,Input!$C$15),Input!$C$27))+ABS('Data Tanah'!$B$7:$B$47-(IF(Input!$C$23=1,MAX(Input!$C$27,Input!$C$15),Input!$C$27))))/2)+ABS((('Data Tanah'!$C$7:$C$47+A20-Input!$C$28*Input!$C$7)-ABS('Data Tanah'!$C$7:$C$47-(A20-Input!$C$28*Input!$C$7)))/2-(('Data Tanah'!$B$7:$B$47+IF(Input!$C$23=1,MAX(Input!$C$27,Input!$C$15),Input!$C$27))+ABS('Data Tanah'!$B$7:$B$47-(IF(Input!$C$23=1,MAX(Input!$C$27,Input!$C$15),Input!$C$27))))/2))/2)) | E20: =IF(SUMPRODUCT(--('Data Tanah'!$H$7:$H$47="L"),((((('Data Tanah'!$C$7:$C$47+A20+1.5*Input!$C$7)-ABS('Data Tanah'!$C$7:$C$47-(A20+1.5*Input!$C$7)))/2-(('Data Tanah'!$B$7:$B$47+A20-1.5*Input!$C$7)+ABS('Data Tanah'!$B$7:$B$47-(A20-1.5*Input!$C$7)))/2)+ABS((('Data Tanah'!$C$7:$C$47+A20+1.5*Input!$C$7)-ABS('Data Tanah'!$C$7:$C$47-(A20+1.5*Input!$C$7)))/2-(('Data Tanah'!$B$7:$B$47+A20-1.5*Input!$C$7)+ABS('Data Tanah'!$B$7:$B$47-(A20-1.5*Input!$C$7)))/2))/2))>0,"Ya","Tidak") | F20: =IF(OR(E20="Ya",AND(Input!$C$23=1,A20<=Input!$C$15)),0,IFERROR(AVERAGEIFS('Data Tanah'!$N$7:$N$47,'Data Tanah'!$E$7:$E$47,">="&(A20-Input!$C$36*Input!$C$7),'Data Tanah'!$E$7:$E$47,"<="&(A20+Input!$C$37*Input!$C$7)),INDEX('Data Tanah'!$N$7:$N$47,MATCH(A20,'Data Tanah'!$B$7:$B$47,1)))*Input!$C$9) | G20: =D20+F20 | H20: =Input!$C$9*(Input!$C$10*MAX(MIN(A20,Input!$C$14)-Input!$C$11,0)+(Input!$C$10-1)*MAX(A20-MAX(Input!$C$14,Input!$C$11),0)) | I20: =G20/Input!$C$44-H20 | J20: =I20*9.81 | K20: =Input!$C$49 | L20: =AND(J20>=K20,L21) | M20: =IF(D20>0,Input!$C$38*D20/Input!$C$44,0)+H20 | N20: =M20*9.81
